10/Jan/2024 18:33:59   INFO  /home/alprostov/PycharmProjects/sakhlis/sakhlis/web/app_site/tasks.py changed, reloading.  None
INFO:django.utils.autoreload:/home/alprostov/PycharmProjects/sakhlis/sakhlis/web/app_site/tasks.py changed, reloading.
10/Jan/2024 18:34:01   INFO  Watching for file changes with StatReloader  None
10/Jan/2024 18:37:46   INFO  /home/alprostov/PycharmProjects/sakhlis/sakhlis/web/app_site/utils.py changed, reloading.  None
INFO:django.utils.autoreload:/home/alprostov/PycharmProjects/sakhlis/sakhlis/web/app_site/utils.py changed, reloading.
10/Jan/2024 18:37:47   INFO  Watching for file changes with StatReloader  None
10/Jan/2024 18:37:51   INFO  "GET / HTTP/1.1" 200 43211  None
INFO:django.server:"GET / HTTP/1.1" 200 43211
10/Jan/2024 18:37:51   WARNING  "GET /static/js/counter.js HTTP/1.1" 404 1798  None
WARNING:django.server:"GET /static/js/counter.js HTTP/1.1" 404 1798
10/Jan/2024 18:37:53   INFO  "GET /list_order HTTP/1.1" 200 53823  None
INFO:django.server:"GET /list_order HTTP/1.1" 200 53823
10/Jan/2024 18:37:53   WARNING  "GET /static/js/counter.js HTTP/1.1" 404 1798  None
WARNING:django.server:"GET /static/js/counter.js HTTP/1.1" 404 1798
10/Jan/2024 18:37:55   INFO  "GET /list_order/1139 HTTP/1.1" 200 25087  None
INFO:django.server:"GET /list_order/1139 HTTP/1.1" 200 25087
10/Jan/2024 18:37:55   WARNING  "GET /static/js/counter.js HTTP/1.1" 404 1798  None
WARNING:django.server:"GET /static/js/counter.js HTTP/1.1" 404 1798
10/Jan/2024 18:37:57   INFO  "GET /list_order/pdf/1139 HTTP/1.1" 200 2713  None
INFO:django.server:"GET /list_order/pdf/1139 HTTP/1.1" 200 2713
10/Jan/2024 18:40:58   INFO  /home/alprostov/PycharmProjects/sakhlis/sakhlis/web/app_site/views.py changed, reloading.  None
INFO:django.utils.autoreload:/home/alprostov/PycharmProjects/sakhlis/sakhlis/web/app_site/views.py changed, reloading.
10/Jan/2024 18:40:59   INFO  Watching for file changes with StatReloader  None
10/Jan/2024 18:41:48   INFO  /home/alprostov/PycharmProjects/sakhlis/sakhlis/web/app_site/utils.py changed, reloading.  None
10/Jan/2024 18:41:49   INFO  Watching for file changes with StatReloader  None
10/Jan/2024 18:41:55   INFO  "GET /list_order/1139 HTTP/1.1" 200 25089  None
INFO:django.server:"GET /list_order/1139 HTTP/1.1" 200 25089
10/Jan/2024 18:41:55   WARNING  "GET /static/js/counter.js HTTP/1.1" 404 1798  None
WARNING:django.server:"GET /static/js/counter.js HTTP/1.1" 404 1798
10/Jan/2024 18:42:00   INFO  "GET /list_order/pdf/1139 HTTP/1.1" 200 2713  None
INFO:django.server:"GET /list_order/pdf/1139 HTTP/1.1" 200 2713
10/Jan/2024 18:43:02   INFO  /home/alprostov/PycharmProjects/sakhlis/sakhlis/web/app_site/utils.py changed, reloading.  None
INFO:django.utils.autoreload:/home/alprostov/PycharmProjects/sakhlis/sakhlis/web/app_site/utils.py changed, reloading.
10/Jan/2024 18:43:03   INFO  Watching for file changes with StatReloader  None
10/Jan/2024 18:43:09   INFO  "GET /list_order?work_status=RCV HTTP/1.1" 200 27811  None
INFO:django.server:"GET /list_order?work_status=RCV HTTP/1.1" 200 27811
10/Jan/2024 18:43:09   WARNING  "GET /static/js/counter.js HTTP/1.1" 404 1798  None
WARNING:django.server:"GET /static/js/counter.js HTTP/1.1" 404 1798
10/Jan/2024 18:43:10   INFO  "GET /list_order/1112 HTTP/1.1" 200 24867  None
INFO:django.server:"GET /list_order/1112 HTTP/1.1" 200 24867
10/Jan/2024 18:43:10   WARNING  "GET /static/js/counter.js HTTP/1.1" 404 1798  None
WARNING:django.server:"GET /static/js/counter.js HTTP/1.1" 404 1798
10/Jan/2024 18:43:15   INFO  "GET /list_order?work_status=RCV HTTP/1.1" 200 27809  None
INFO:django.server:"GET /list_order?work_status=RCV HTTP/1.1" 200 27809
10/Jan/2024 18:43:16   WARNING  "GET /static/js/counter.js HTTP/1.1" 404 1798  None
WARNING:django.server:"GET /static/js/counter.js HTTP/1.1" 404 1798
10/Jan/2024 18:43:17   INFO  "GET /list_order/1096 HTTP/1.1" 200 25178  None
INFO:django.server:"GET /list_order/1096 HTTP/1.1" 200 25178
10/Jan/2024 18:43:18   WARNING  "GET /static/js/counter.js HTTP/1.1" 404 1798  None
WARNING:django.server:"GET /static/js/counter.js HTTP/1.1" 404 1798
10/Jan/2024 18:43:22   INFO  "GET /changestatus?order_pk=1096&work_status=END HTTP/1.1" 200 32  None
INFO:django.server:"GET /changestatus?order_pk=1096&work_status=END HTTP/1.1" 200 32
10/Jan/2024 18:43:22   INFO  "GET /__debug__/history_sidebar/?store_id=aa297295d3fb4482a9b8c2cdeb7a85cd HTTP/1.1" 200 13389  None
INFO:django.server:"GET /__debug__/history_sidebar/?store_id=aa297295d3fb4482a9b8c2cdeb7a85cd HTTP/1.1" 200 13389
10/Jan/2024 18:43:26   INFO  "GET /list_order/pdf/1096 HTTP/1.1" 200 2706  None
INFO:django.server:"GET /list_order/pdf/1096 HTTP/1.1" 200 2706
10/Jan/2024 18:46:47   INFO  /home/alprostov/PycharmProjects/sakhlis/sakhlis/web/app_site/views.py changed, reloading.  None
INFO:django.utils.autoreload:/home/alprostov/PycharmProjects/sakhlis/sakhlis/web/app_site/views.py changed, reloading.
10/Jan/2024 18:46:49   INFO  Watching for file changes with StatReloader  None
10/Jan/2024 18:47:47   INFO  /home/alprostov/PycharmProjects/sakhlis/sakhlis/web/app_site/utils.py changed, reloading.  None
INFO:django.utils.autoreload:/home/alprostov/PycharmProjects/sakhlis/sakhlis/web/app_site/utils.py changed, reloading.
10/Jan/2024 18:47:49   INFO  Watching for file changes with StatReloader  None
10/Jan/2024 18:49:12   INFO  /home/alprostov/PycharmProjects/sakhlis/sakhlis/web/app_site/utils.py changed, reloading.  None
INFO:django.utils.autoreload:/home/alprostov/PycharmProjects/sakhlis/sakhlis/web/app_site/utils.py changed, reloading.
10/Jan/2024 18:49:13   INFO  Watching for file changes with StatReloader  None
10/Jan/2024 18:50:56   INFO  /home/alprostov/PycharmProjects/sakhlis/sakhlis/web/app_site/utils.py changed, reloading.  None
INFO:django.utils.autoreload:/home/alprostov/PycharmProjects/sakhlis/sakhlis/web/app_site/utils.py changed, reloading.
10/Jan/2024 18:50:58   INFO  Watching for file changes with StatReloader  None
10/Jan/2024 18:57:03   INFO  /home/alprostov/PycharmProjects/sakhlis/sakhlis/web/app_site/utils.py changed, reloading.  None
INFO:django.utils.autoreload:/home/alprostov/PycharmProjects/sakhlis/sakhlis/web/app_site/utils.py changed, reloading.
10/Jan/2024 18:57:05   INFO  Watching for file changes with StatReloader  None
10/Jan/2024 19:08:50   INFO  /home/alprostov/PycharmProjects/sakhlis/sakhlis/web/app_site/utils.py changed, reloading.  None
INFO:django.utils.autoreload:/home/alprostov/PycharmProjects/sakhlis/sakhlis/web/app_site/utils.py changed, reloading.
10/Jan/2024 19:08:51   INFO  Watching for file changes with StatReloader  None
10/Jan/2024 19:13:42   INFO  /home/alprostov/PycharmProjects/sakhlis/sakhlis/web/app_site/utils.py changed, reloading.  None
INFO:django.utils.autoreload:/home/alprostov/PycharmProjects/sakhlis/sakhlis/web/app_site/utils.py changed, reloading.
10/Jan/2024 19:13:43   INFO  Watching for file changes with StatReloader  None
10/Jan/2024 19:22:50   INFO  /home/alprostov/PycharmProjects/sakhlis/sakhlis/web/app_site/utils.py changed, reloading.  None
INFO:django.utils.autoreload:/home/alprostov/PycharmProjects/sakhlis/sakhlis/web/app_site/utils.py changed, reloading.
10/Jan/2024 19:22:52   INFO  Watching for file changes with StatReloader  None
10/Jan/2024 19:24:37   INFO  /home/alprostov/PycharmProjects/sakhlis/sakhlis/web/app_site/utils.py changed, reloading.  None
INFO:django.utils.autoreload:/home/alprostov/PycharmProjects/sakhlis/sakhlis/web/app_site/utils.py changed, reloading.
10/Jan/2024 19:24:38   INFO  Watching for file changes with StatReloader  None
10/Jan/2024 19:31:05   INFO  /home/alprostov/PycharmProjects/sakhlis/sakhlis/web/app_site/views.py changed, reloading.  None
INFO:django.utils.autoreload:/home/alprostov/PycharmProjects/sakhlis/sakhlis/web/app_site/views.py changed, reloading.
10/Jan/2024 19:31:06   INFO  Watching for file changes with StatReloader  None
10/Jan/2024 19:31:08   INFO  "GET /list_order?work_status=RCV HTTP/1.1" 200 25401  None
INFO:django.server:"GET /list_order?work_status=RCV HTTP/1.1" 200 25401
10/Jan/2024 19:31:08   WARNING  "GET /static/js/counter.js HTTP/1.1" 404 1798  None
WARNING:django.server:"GET /static/js/counter.js HTTP/1.1" 404 1798
WARNING:root:===========================================================
WARNING:root:ВРЕМЯ:     2024-01-10 19:31:10.153867
WARNING:root:ОШИБКА:        string indices must be integers, not 'dict'
WARNING:root:ТРЭЙСБЭК:     Traceback (most recent call last):
  File "/home/alprostov/PycharmProjects/sakhlis/sakhlis/web/app_site/exeptions.py", line 35, in dispatch
    response = super().dispatch(request, *args, **kwargs)
               ^^^^^^^^^^^^^^^^^^^^^^^^^^^^^^^^^^^^^^^^^^
  File "/home/alprostov/PycharmProjects/sakhlis/venv3/lib/python3.11/site-packages/django/contrib/auth/mixins.py", line 73, in dispatch
    return super().dispatch(request, *args, **kwargs)
           ^^^^^^^^^^^^^^^^^^^^^^^^^^^^^^^^^^^^^^^^^^
  File "/home/alprostov/PycharmProjects/sakhlis/venv3/lib/python3.11/site-packages/django/views/generic/base.py", line 143, in dispatch
    return handler(request, *args, **kwargs)
           ^^^^^^^^^^^^^^^^^^^^^^^^^^^^^^^^^
  File "/home/alprostov/PycharmProjects/sakhlis/venv3/lib/python3.11/site-packages/django/views/generic/base.py", line 226, in get
    context = self.get_context_data(**kwargs)
              ^^^^^^^^^^^^^^^^^^^^^^^^^^^^^^^
  File "/home/alprostov/PycharmProjects/sakhlis/sakhlis/web/app_site/views.py", line 165, in get_context_data
    context['d']=instans_graf.make_graf_pie()
                 ^^^^^^^^^^^^^^^^^^^^^^^^^^^^
  File "/home/alprostov/PycharmProjects/sakhlis/sakhlis/web/app_site/utils.py", line 178, in make_graf_pie
    labels, data=self.get_data_for_graph()
                 ^^^^^^^^^^^^^^^^^^^^^^^^^
  File "/home/alprostov/PycharmProjects/sakhlis/sakhlis/web/app_site/utils.py", line 172, in get_data_for_graph
    labels.append(_[self.name_X])
                  ~^^^^^^^^^^^^^
TypeError: string indices must be integers, not 'dict'

WARNING:root:============================================================
10/Jan/2024 19:31:10   WARNING  Bad Request: /stat/  None
WARNING:django.request:Bad Request: /stat/
10/Jan/2024 19:31:10   WARNING  "GET /stat/ HTTP/1.1" 400 100  None
WARNING:django.server:"GET /stat/ HTTP/1.1" 400 100
10/Jan/2024 19:31:39   INFO  /home/alprostov/PycharmProjects/sakhlis/sakhlis/web/app_site/views.py changed, reloading.  None
INFO:django.utils.autoreload:/home/alprostov/PycharmProjects/sakhlis/sakhlis/web/app_site/views.py changed, reloading.
10/Jan/2024 19:31:41   INFO  Watching for file changes with StatReloader  None
10/Jan/2024 19:31:43   ERROR  Internal Server Error: /stat/  (<class 'TypeError'>, TypeError("string indices must be integers, not 'dict'"), <traceback object at 0x7ffbc0325bc0>)
Traceback (most recent call last):
  File "/home/alprostov/PycharmProjects/sakhlis/venv3/lib/python3.11/site-packages/django/core/handlers/exception.py", line 55, in inner
    response = get_response(request)
               ^^^^^^^^^^^^^^^^^^^^^
  File "/home/alprostov/PycharmProjects/sakhlis/venv3/lib/python3.11/site-packages/django/core/handlers/base.py", line 197, in _get_response
    response = wrapped_callback(request, *callback_args, **callback_kwargs)
               ^^^^^^^^^^^^^^^^^^^^^^^^^^^^^^^^^^^^^^^^^^^^^^^^^^^^^^^^^^^^
  File "/home/alprostov/PycharmProjects/sakhlis/venv3/lib/python3.11/site-packages/django/views/generic/base.py", line 104, in view
    return self.dispatch(request, *args, **kwargs)
           ^^^^^^^^^^^^^^^^^^^^^^^^^^^^^^^^^^^^^^^
  File "/home/alprostov/PycharmProjects/sakhlis/venv3/lib/python3.11/site-packages/django/contrib/auth/mixins.py", line 73, in dispatch
    return super().dispatch(request, *args, **kwargs)
           ^^^^^^^^^^^^^^^^^^^^^^^^^^^^^^^^^^^^^^^^^^
  File "/home/alprostov/PycharmProjects/sakhlis/venv3/lib/python3.11/site-packages/django/views/generic/base.py", line 143, in dispatch
    return handler(request, *args, **kwargs)
           ^^^^^^^^^^^^^^^^^^^^^^^^^^^^^^^^^
  File "/home/alprostov/PycharmProjects/sakhlis/venv3/lib/python3.11/site-packages/django/views/generic/base.py", line 226, in get
    context = self.get_context_data(**kwargs)
              ^^^^^^^^^^^^^^^^^^^^^^^^^^^^^^^
  File "/home/alprostov/PycharmProjects/sakhlis/sakhlis/web/app_site/views.py", line 165, in get_context_data
    context['d']=instans_graf.make_graf_pie()
                 ^^^^^^^^^^^^^^^^^^^^^^^^^^^^
  File "/home/alprostov/PycharmProjects/sakhlis/sakhlis/web/app_site/utils.py", line 178, in make_graf_pie
    labels, data=self.get_data_for_graph()
                 ^^^^^^^^^^^^^^^^^^^^^^^^^
  File "/home/alprostov/PycharmProjects/sakhlis/sakhlis/web/app_site/utils.py", line 172, in get_data_for_graph
    labels.append(_[self.name_X])
                  ~^^^^^^^^^^^^^
TypeError: string indices must be integers, not 'dict'
ERROR:django.request:Internal Server Error: /stat/
Traceback (most recent call last):
  File "/home/alprostov/PycharmProjects/sakhlis/venv3/lib/python3.11/site-packages/django/core/handlers/exception.py", line 55, in inner
    response = get_response(request)
               ^^^^^^^^^^^^^^^^^^^^^
  File "/home/alprostov/PycharmProjects/sakhlis/venv3/lib/python3.11/site-packages/django/core/handlers/base.py", line 197, in _get_response
    response = wrapped_callback(request, *callback_args, **callback_kwargs)
               ^^^^^^^^^^^^^^^^^^^^^^^^^^^^^^^^^^^^^^^^^^^^^^^^^^^^^^^^^^^^
  File "/home/alprostov/PycharmProjects/sakhlis/venv3/lib/python3.11/site-packages/django/views/generic/base.py", line 104, in view
    return self.dispatch(request, *args, **kwargs)
           ^^^^^^^^^^^^^^^^^^^^^^^^^^^^^^^^^^^^^^^
  File "/home/alprostov/PycharmProjects/sakhlis/venv3/lib/python3.11/site-packages/django/contrib/auth/mixins.py", line 73, in dispatch
    return super().dispatch(request, *args, **kwargs)
           ^^^^^^^^^^^^^^^^^^^^^^^^^^^^^^^^^^^^^^^^^^
  File "/home/alprostov/PycharmProjects/sakhlis/venv3/lib/python3.11/site-packages/django/views/generic/base.py", line 143, in dispatch
    return handler(request, *args, **kwargs)
           ^^^^^^^^^^^^^^^^^^^^^^^^^^^^^^^^^
  File "/home/alprostov/PycharmProjects/sakhlis/venv3/lib/python3.11/site-packages/django/views/generic/base.py", line 226, in get
    context = self.get_context_data(**kwargs)
              ^^^^^^^^^^^^^^^^^^^^^^^^^^^^^^^
  File "/home/alprostov/PycharmProjects/sakhlis/sakhlis/web/app_site/views.py", line 165, in get_context_data
    context['d']=instans_graf.make_graf_pie()
                 ^^^^^^^^^^^^^^^^^^^^^^^^^^^^
  File "/home/alprostov/PycharmProjects/sakhlis/sakhlis/web/app_site/utils.py", line 178, in make_graf_pie
    labels, data=self.get_data_for_graph()
                 ^^^^^^^^^^^^^^^^^^^^^^^^^
  File "/home/alprostov/PycharmProjects/sakhlis/sakhlis/web/app_site/utils.py", line 172, in get_data_for_graph
    labels.append(_[self.name_X])
                  ~^^^^^^^^^^^^^
TypeError: string indices must be integers, not 'dict'
10/Jan/2024 19:31:43   ERROR  "GET /stat/ HTTP/1.1" 500 112534  None
ERROR:django.server:"GET /stat/ HTTP/1.1" 500 112534
10/Jan/2024 19:32:50   INFO  /home/alprostov/PycharmProjects/sakhlis/sakhlis/web/app_site/utils.py changed, reloading.  None
INFO:django.utils.autoreload:/home/alprostov/PycharmProjects/sakhlis/sakhlis/web/app_site/utils.py changed, reloading.
10/Jan/2024 19:32:52   INFO  Watching for file changes with StatReloader  None
10/Jan/2024 19:32:54   ERROR  Internal Server Error: /stat/  (<class 'TypeError'>, TypeError("string indices must be integers, not 'dict'"), <traceback object at 0x7faea0209040>)
Traceback (most recent call last):
  File "/home/alprostov/PycharmProjects/sakhlis/venv3/lib/python3.11/site-packages/django/core/handlers/exception.py", line 55, in inner
    response = get_response(request)
               ^^^^^^^^^^^^^^^^^^^^^
  File "/home/alprostov/PycharmProjects/sakhlis/venv3/lib/python3.11/site-packages/django/core/handlers/base.py", line 197, in _get_response
    response = wrapped_callback(request, *callback_args, **callback_kwargs)
               ^^^^^^^^^^^^^^^^^^^^^^^^^^^^^^^^^^^^^^^^^^^^^^^^^^^^^^^^^^^^
  File "/home/alprostov/PycharmProjects/sakhlis/venv3/lib/python3.11/site-packages/django/views/generic/base.py", line 104, in view
    return self.dispatch(request, *args, **kwargs)
           ^^^^^^^^^^^^^^^^^^^^^^^^^^^^^^^^^^^^^^^
  File "/home/alprostov/PycharmProjects/sakhlis/venv3/lib/python3.11/site-packages/django/contrib/auth/mixins.py", line 73, in dispatch
    return super().dispatch(request, *args, **kwargs)
           ^^^^^^^^^^^^^^^^^^^^^^^^^^^^^^^^^^^^^^^^^^
  File "/home/alprostov/PycharmProjects/sakhlis/venv3/lib/python3.11/site-packages/django/views/generic/base.py", line 143, in dispatch
    return handler(request, *args, **kwargs)
           ^^^^^^^^^^^^^^^^^^^^^^^^^^^^^^^^^
  File "/home/alprostov/PycharmProjects/sakhlis/venv3/lib/python3.11/site-packages/django/views/generic/base.py", line 226, in get
    context = self.get_context_data(**kwargs)
              ^^^^^^^^^^^^^^^^^^^^^^^^^^^^^^^
  File "/home/alprostov/PycharmProjects/sakhlis/sakhlis/web/app_site/views.py", line 165, in get_context_data
    context['d']=instans_graf.make_graf_pie()
                 ^^^^^^^^^^^^^^^^^^^^^^^^^^^^
  File "/home/alprostov/PycharmProjects/sakhlis/sakhlis/web/app_site/utils.py", line 178, in make_graf_pie
    labels, data=self.get_data_for_graph()
                 ^^^^^^^^^^^^^^^^^^^^^^^^^
  File "/home/alprostov/PycharmProjects/sakhlis/sakhlis/web/app_site/utils.py", line 172, in get_data_for_graph
    labels.append(_[self.name_X])
                  ~^^^^^^^^^^^^^
TypeError: string indices must be integers, not 'dict'
ERROR:django.request:Internal Server Error: /stat/
Traceback (most recent call last):
  File "/home/alprostov/PycharmProjects/sakhlis/venv3/lib/python3.11/site-packages/django/core/handlers/exception.py", line 55, in inner
    response = get_response(request)
               ^^^^^^^^^^^^^^^^^^^^^
  File "/home/alprostov/PycharmProjects/sakhlis/venv3/lib/python3.11/site-packages/django/core/handlers/base.py", line 197, in _get_response
    response = wrapped_callback(request, *callback_args, **callback_kwargs)
               ^^^^^^^^^^^^^^^^^^^^^^^^^^^^^^^^^^^^^^^^^^^^^^^^^^^^^^^^^^^^
  File "/home/alprostov/PycharmProjects/sakhlis/venv3/lib/python3.11/site-packages/django/views/generic/base.py", line 104, in view
    return self.dispatch(request, *args, **kwargs)
           ^^^^^^^^^^^^^^^^^^^^^^^^^^^^^^^^^^^^^^^
  File "/home/alprostov/PycharmProjects/sakhlis/venv3/lib/python3.11/site-packages/django/contrib/auth/mixins.py", line 73, in dispatch
    return super().dispatch(request, *args, **kwargs)
           ^^^^^^^^^^^^^^^^^^^^^^^^^^^^^^^^^^^^^^^^^^
  File "/home/alprostov/PycharmProjects/sakhlis/venv3/lib/python3.11/site-packages/django/views/generic/base.py", line 143, in dispatch
    return handler(request, *args, **kwargs)
           ^^^^^^^^^^^^^^^^^^^^^^^^^^^^^^^^^
  File "/home/alprostov/PycharmProjects/sakhlis/venv3/lib/python3.11/site-packages/django/views/generic/base.py", line 226, in get
    context = self.get_context_data(**kwargs)
              ^^^^^^^^^^^^^^^^^^^^^^^^^^^^^^^
  File "/home/alprostov/PycharmProjects/sakhlis/sakhlis/web/app_site/views.py", line 165, in get_context_data
    context['d']=instans_graf.make_graf_pie()
                 ^^^^^^^^^^^^^^^^^^^^^^^^^^^^
  File "/home/alprostov/PycharmProjects/sakhlis/sakhlis/web/app_site/utils.py", line 178, in make_graf_pie
    labels, data=self.get_data_for_graph()
                 ^^^^^^^^^^^^^^^^^^^^^^^^^
  File "/home/alprostov/PycharmProjects/sakhlis/sakhlis/web/app_site/utils.py", line 172, in get_data_for_graph
    labels.append(_[self.name_X])
                  ~^^^^^^^^^^^^^
TypeError: string indices must be integers, not 'dict'
10/Jan/2024 19:32:54   ERROR  "GET /stat/ HTTP/1.1" 500 112533  None
ERROR:django.server:"GET /stat/ HTTP/1.1" 500 112533
10/Jan/2024 19:39:19   INFO  /home/alprostov/PycharmProjects/sakhlis/sakhlis/web/app_site/utils.py changed, reloading.  None
INFO:django.utils.autoreload:/home/alprostov/PycharmProjects/sakhlis/sakhlis/web/app_site/utils.py changed, reloading.
10/Jan/2024 19:39:22   INFO  Watching for file changes with StatReloader  None
10/Jan/2024 19:39:26   INFO  "GET /stat/ HTTP/1.1" 200 61937  None
INFO:django.server:"GET /stat/ HTTP/1.1" 200 61937
10/Jan/2024 19:39:26   WARNING  "GET /static/js/counter.js HTTP/1.1" 404 1798  None
WARNING:django.server:"GET /static/js/counter.js HTTP/1.1" 404 1798
10/Jan/2024 19:42:34   INFO  /home/alprostov/PycharmProjects/sakhlis/sakhlis/web/app_site/views.py changed, reloading.  None
INFO:django.utils.autoreload:/home/alprostov/PycharmProjects/sakhlis/sakhlis/web/app_site/views.py changed, reloading.
10/Jan/2024 19:42:34   INFO  "GET /stat/ HTTP/1.1" 200 61937  None
INFO:django.server:"GET /stat/ HTTP/1.1" 200 61937
10/Jan/2024 19:42:34   WARNING  "GET /static/js/counter.js HTTP/1.1" 404 1798  None
WARNING:django.server:"GET /static/js/counter.js HTTP/1.1" 404 1798
10/Jan/2024 19:42:36   INFO  Watching for file changes with StatReloader  None
10/Jan/2024 19:42:38   INFO  "GET /stat/ HTTP/1.1" 200 107899  None
INFO:django.server:"GET /stat/ HTTP/1.1" 200 107899
10/Jan/2024 19:42:38   WARNING  "GET /static/js/counter.js HTTP/1.1" 404 1798  None
WARNING:django.server:"GET /static/js/counter.js HTTP/1.1" 404 1798
10/Jan/2024 19:43:07   INFO  /home/alprostov/PycharmProjects/sakhlis/sakhlis/web/app_site/views.py changed, reloading.  None
INFO:django.utils.autoreload:/home/alprostov/PycharmProjects/sakhlis/sakhlis/web/app_site/views.py changed, reloading.
10/Jan/2024 19:43:08   INFO  "GET /stat/ HTTP/1.1" 200 107899  None
INFO:django.server:"GET /stat/ HTTP/1.1" 200 107899
10/Jan/2024 19:43:08   WARNING  "GET /static/js/counter.js HTTP/1.1" 404 1798  None
WARNING:django.server:"GET /static/js/counter.js HTTP/1.1" 404 1798
10/Jan/2024 19:43:09   INFO  Watching for file changes with StatReloader  None
10/Jan/2024 19:43:10   ERROR  Internal Server Error: /stat/  (<class 'NameError'>, NameError("name 'labels' is not defined"), <traceback object at 0x7fd30a29d140>)
Traceback (most recent call last):
  File "/home/alprostov/PycharmProjects/sakhlis/venv3/lib/python3.11/site-packages/django/core/handlers/exception.py", line 55, in inner
    response = get_response(request)
               ^^^^^^^^^^^^^^^^^^^^^
  File "/home/alprostov/PycharmProjects/sakhlis/venv3/lib/python3.11/site-packages/django/core/handlers/base.py", line 197, in _get_response
    response = wrapped_callback(request, *callback_args, **callback_kwargs)
               ^^^^^^^^^^^^^^^^^^^^^^^^^^^^^^^^^^^^^^^^^^^^^^^^^^^^^^^^^^^^
  File "/home/alprostov/PycharmProjects/sakhlis/venv3/lib/python3.11/site-packages/django/views/generic/base.py", line 104, in view
    return self.dispatch(request, *args, **kwargs)
           ^^^^^^^^^^^^^^^^^^^^^^^^^^^^^^^^^^^^^^^
  File "/home/alprostov/PycharmProjects/sakhlis/venv3/lib/python3.11/site-packages/django/contrib/auth/mixins.py", line 73, in dispatch
    return super().dispatch(request, *args, **kwargs)
           ^^^^^^^^^^^^^^^^^^^^^^^^^^^^^^^^^^^^^^^^^^
  File "/home/alprostov/PycharmProjects/sakhlis/venv3/lib/python3.11/site-packages/django/views/generic/base.py", line 143, in dispatch
    return handler(request, *args, **kwargs)
           ^^^^^^^^^^^^^^^^^^^^^^^^^^^^^^^^^
  File "/home/alprostov/PycharmProjects/sakhlis/venv3/lib/python3.11/site-packages/django/views/generic/base.py", line 226, in get
    context = self.get_context_data(**kwargs)
              ^^^^^^^^^^^^^^^^^^^^^^^^^^^^^^^
  File "/home/alprostov/PycharmProjects/sakhlis/sakhlis/web/app_site/views.py", line 170, in get_context_data
    instans_graf = Graph(a,'time_in__month','count', MONTH_, labels, sizes, 'Выручка', 'lar')
                                                             ^^^^^^
NameError: name 'labels' is not defined
ERROR:django.request:Internal Server Error: /stat/
Traceback (most recent call last):
  File "/home/alprostov/PycharmProjects/sakhlis/venv3/lib/python3.11/site-packages/django/core/handlers/exception.py", line 55, in inner
    response = get_response(request)
               ^^^^^^^^^^^^^^^^^^^^^
  File "/home/alprostov/PycharmProjects/sakhlis/venv3/lib/python3.11/site-packages/django/core/handlers/base.py", line 197, in _get_response
    response = wrapped_callback(request, *callback_args, **callback_kwargs)
               ^^^^^^^^^^^^^^^^^^^^^^^^^^^^^^^^^^^^^^^^^^^^^^^^^^^^^^^^^^^^
  File "/home/alprostov/PycharmProjects/sakhlis/venv3/lib/python3.11/site-packages/django/views/generic/base.py", line 104, in view
    return self.dispatch(request, *args, **kwargs)
           ^^^^^^^^^^^^^^^^^^^^^^^^^^^^^^^^^^^^^^^
  File "/home/alprostov/PycharmProjects/sakhlis/venv3/lib/python3.11/site-packages/django/contrib/auth/mixins.py", line 73, in dispatch
    return super().dispatch(request, *args, **kwargs)
           ^^^^^^^^^^^^^^^^^^^^^^^^^^^^^^^^^^^^^^^^^^
  File "/home/alprostov/PycharmProjects/sakhlis/venv3/lib/python3.11/site-packages/django/views/generic/base.py", line 143, in dispatch
    return handler(request, *args, **kwargs)
           ^^^^^^^^^^^^^^^^^^^^^^^^^^^^^^^^^
  File "/home/alprostov/PycharmProjects/sakhlis/venv3/lib/python3.11/site-packages/django/views/generic/base.py", line 226, in get
    context = self.get_context_data(**kwargs)
              ^^^^^^^^^^^^^^^^^^^^^^^^^^^^^^^
  File "/home/alprostov/PycharmProjects/sakhlis/sakhlis/web/app_site/views.py", line 170, in get_context_data
    instans_graf = Graph(a,'time_in__month','count', MONTH_, labels, sizes, 'Выручка', 'lar')
                                                             ^^^^^^
NameError: name 'labels' is not defined
10/Jan/2024 19:43:10   ERROR  "GET /stat/ HTTP/1.1" 500 108642  None
ERROR:django.server:"GET /stat/ HTTP/1.1" 500 108642
10/Jan/2024 19:43:33   INFO  /home/alprostov/PycharmProjects/sakhlis/sakhlis/web/app_site/views.py changed, reloading.  None
INFO:django.utils.autoreload:/home/alprostov/PycharmProjects/sakhlis/sakhlis/web/app_site/views.py changed, reloading.
10/Jan/2024 19:43:34   ERROR  Internal Server Error: /stat/  (<class 'NameError'>, NameError("name 'labels' is not defined"), <traceback object at 0x7fd309ff2500>)
Traceback (most recent call last):
  File "/home/alprostov/PycharmProjects/sakhlis/venv3/lib/python3.11/site-packages/django/core/handlers/exception.py", line 55, in inner
    response = get_response(request)
               ^^^^^^^^^^^^^^^^^^^^^
  File "/home/alprostov/PycharmProjects/sakhlis/venv3/lib/python3.11/site-packages/django/core/handlers/base.py", line 197, in _get_response
    response = wrapped_callback(request, *callback_args, **callback_kwargs)
               ^^^^^^^^^^^^^^^^^^^^^^^^^^^^^^^^^^^^^^^^^^^^^^^^^^^^^^^^^^^^
  File "/home/alprostov/PycharmProjects/sakhlis/venv3/lib/python3.11/site-packages/django/views/generic/base.py", line 104, in view
    return self.dispatch(request, *args, **kwargs)
           ^^^^^^^^^^^^^^^^^^^^^^^^^^^^^^^^^^^^^^^
  File "/home/alprostov/PycharmProjects/sakhlis/venv3/lib/python3.11/site-packages/django/contrib/auth/mixins.py", line 73, in dispatch
    return super().dispatch(request, *args, **kwargs)
           ^^^^^^^^^^^^^^^^^^^^^^^^^^^^^^^^^^^^^^^^^^
  File "/home/alprostov/PycharmProjects/sakhlis/venv3/lib/python3.11/site-packages/django/views/generic/base.py", line 143, in dispatch
    return handler(request, *args, **kwargs)
           ^^^^^^^^^^^^^^^^^^^^^^^^^^^^^^^^^
  File "/home/alprostov/PycharmProjects/sakhlis/venv3/lib/python3.11/site-packages/django/views/generic/base.py", line 226, in get
    context = self.get_context_data(**kwargs)
              ^^^^^^^^^^^^^^^^^^^^^^^^^^^^^^^
  File "/home/alprostov/PycharmProjects/sakhlis/sakhlis/web/app_site/views.py", line 170, in get_context_data
    instans_graf = Graph(a,'time_in__month','count', MONTH_, 'Выручка', 'lar')
                                                             ^^^^
NameError: name 'labels' is not defined
ERROR:django.request:Internal Server Error: /stat/
Traceback (most recent call last):
  File "/home/alprostov/PycharmProjects/sakhlis/venv3/lib/python3.11/site-packages/django/core/handlers/exception.py", line 55, in inner
    response = get_response(request)
               ^^^^^^^^^^^^^^^^^^^^^
  File "/home/alprostov/PycharmProjects/sakhlis/venv3/lib/python3.11/site-packages/django/core/handlers/base.py", line 197, in _get_response
    response = wrapped_callback(request, *callback_args, **callback_kwargs)
               ^^^^^^^^^^^^^^^^^^^^^^^^^^^^^^^^^^^^^^^^^^^^^^^^^^^^^^^^^^^^
  File "/home/alprostov/PycharmProjects/sakhlis/venv3/lib/python3.11/site-packages/django/views/generic/base.py", line 104, in view
    return self.dispatch(request, *args, **kwargs)
           ^^^^^^^^^^^^^^^^^^^^^^^^^^^^^^^^^^^^^^^
  File "/home/alprostov/PycharmProjects/sakhlis/venv3/lib/python3.11/site-packages/django/contrib/auth/mixins.py", line 73, in dispatch
    return super().dispatch(request, *args, **kwargs)
           ^^^^^^^^^^^^^^^^^^^^^^^^^^^^^^^^^^^^^^^^^^
  File "/home/alprostov/PycharmProjects/sakhlis/venv3/lib/python3.11/site-packages/django/views/generic/base.py", line 143, in dispatch
    return handler(request, *args, **kwargs)
           ^^^^^^^^^^^^^^^^^^^^^^^^^^^^^^^^^
  File "/home/alprostov/PycharmProjects/sakhlis/venv3/lib/python3.11/site-packages/django/views/generic/base.py", line 226, in get
    context = self.get_context_data(**kwargs)
              ^^^^^^^^^^^^^^^^^^^^^^^^^^^^^^^
  File "/home/alprostov/PycharmProjects/sakhlis/sakhlis/web/app_site/views.py", line 170, in get_context_data
    instans_graf = Graph(a,'time_in__month','count', MONTH_, 'Выручка', 'lar')
                                                             ^^^^
NameError: name 'labels' is not defined
10/Jan/2024 19:43:34   ERROR  "GET /stat/ HTTP/1.1" 500 108611  None
ERROR:django.server:"GET /stat/ HTTP/1.1" 500 108611
10/Jan/2024 19:43:35   INFO  Watching for file changes with StatReloader  None
10/Jan/2024 19:43:36   INFO  "GET /stat/ HTTP/1.1" 200 127931  None
INFO:django.server:"GET /stat/ HTTP/1.1" 200 127931
10/Jan/2024 19:43:36   WARNING  "GET /static/js/counter.js HTTP/1.1" 404 1798  None
WARNING:django.server:"GET /static/js/counter.js HTTP/1.1" 404 1798
10/Jan/2024 19:44:05   INFO  /home/alprostov/PycharmProjects/sakhlis/sakhlis/web/app_site/views.py changed, reloading.  None
INFO:django.utils.autoreload:/home/alprostov/PycharmProjects/sakhlis/sakhlis/web/app_site/views.py changed, reloading.
10/Jan/2024 19:44:06   INFO  "GET /stat/ HTTP/1.1" 200 127932  None
INFO:django.server:"GET /stat/ HTTP/1.1" 200 127932
10/Jan/2024 19:44:06   WARNING  "GET /static/js/counter.js HTTP/1.1" 404 1798  None
WARNING:django.server:"GET /static/js/counter.js HTTP/1.1" 404 1798
10/Jan/2024 19:44:08   INFO  Watching for file changes with StatReloader  None
10/Jan/2024 19:44:09   INFO  "GET /stat/ HTTP/1.1" 200 149871  None
INFO:django.server:"GET /stat/ HTTP/1.1" 200 149871
10/Jan/2024 19:44:09   WARNING  "GET /static/js/counter.js HTTP/1.1" 404 1798  None
WARNING:django.server:"GET /static/js/counter.js HTTP/1.1" 404 1798
10/Jan/2024 19:44:37   INFO  /home/alprostov/PycharmProjects/sakhlis/sakhlis/web/app_site/views.py changed, reloading.  None
INFO:django.utils.autoreload:/home/alprostov/PycharmProjects/sakhlis/sakhlis/web/app_site/views.py changed, reloading.
10/Jan/2024 19:44:39   INFO  Watching for file changes with StatReloader  None
10/Jan/2024 19:44:43   ERROR  Internal Server Error: /stat/  (<class 'TypeError'>, TypeError("string indices must be integers, not 'datetime.date'"), <traceback object at 0x7f2b68300d80>)
Traceback (most recent call last):
  File "/home/alprostov/PycharmProjects/sakhlis/venv3/lib/python3.11/site-packages/django/core/handlers/exception.py", line 55, in inner
    response = get_response(request)
               ^^^^^^^^^^^^^^^^^^^^^
  File "/home/alprostov/PycharmProjects/sakhlis/venv3/lib/python3.11/site-packages/django/core/handlers/base.py", line 197, in _get_response
    response = wrapped_callback(request, *callback_args, **callback_kwargs)
               ^^^^^^^^^^^^^^^^^^^^^^^^^^^^^^^^^^^^^^^^^^^^^^^^^^^^^^^^^^^^
  File "/home/alprostov/PycharmProjects/sakhlis/venv3/lib/python3.11/site-packages/django/views/generic/base.py", line 104, in view
    return self.dispatch(request, *args, **kwargs)
           ^^^^^^^^^^^^^^^^^^^^^^^^^^^^^^^^^^^^^^^
  File "/home/alprostov/PycharmProjects/sakhlis/venv3/lib/python3.11/site-packages/django/contrib/auth/mixins.py", line 73, in dispatch
    return super().dispatch(request, *args, **kwargs)
           ^^^^^^^^^^^^^^^^^^^^^^^^^^^^^^^^^^^^^^^^^^
  File "/home/alprostov/PycharmProjects/sakhlis/venv3/lib/python3.11/site-packages/django/views/generic/base.py", line 143, in dispatch
    return handler(request, *args, **kwargs)
           ^^^^^^^^^^^^^^^^^^^^^^^^^^^^^^^^^
  File "/home/alprostov/PycharmProjects/sakhlis/venv3/lib/python3.11/site-packages/django/views/generic/base.py", line 226, in get
    context = self.get_context_data(**kwargs)
              ^^^^^^^^^^^^^^^^^^^^^^^^^^^^^^^
  File "/home/alprostov/PycharmProjects/sakhlis/sakhlis/web/app_site/views.py", line 177, in get_context_data
    context['hh'] = instans_graf.make_graf_plot()
                    ^^^^^^^^^^^^^^^^^^^^^^^^^^^^^
  File "/home/alprostov/PycharmProjects/sakhlis/sakhlis/web/app_site/utils.py", line 216, in make_graf_plot
    labels, data = self.get_data_for_graph()
                   ^^^^^^^^^^^^^^^^^^^^^^^^^
  File "/home/alprostov/PycharmProjects/sakhlis/sakhlis/web/app_site/utils.py", line 172, in get_data_for_graph
    labels.append(b + ' ' + self.help_dict[_[self.name_X]])
                            ~~~~~~~~~~~~~~^^^^^^^^^^^^^^^^
TypeError: string indices must be integers, not 'datetime.date'
ERROR:django.request:Internal Server Error: /stat/
Traceback (most recent call last):
  File "/home/alprostov/PycharmProjects/sakhlis/venv3/lib/python3.11/site-packages/django/core/handlers/exception.py", line 55, in inner
    response = get_response(request)
               ^^^^^^^^^^^^^^^^^^^^^
  File "/home/alprostov/PycharmProjects/sakhlis/venv3/lib/python3.11/site-packages/django/core/handlers/base.py", line 197, in _get_response
    response = wrapped_callback(request, *callback_args, **callback_kwargs)
               ^^^^^^^^^^^^^^^^^^^^^^^^^^^^^^^^^^^^^^^^^^^^^^^^^^^^^^^^^^^^
  File "/home/alprostov/PycharmProjects/sakhlis/venv3/lib/python3.11/site-packages/django/views/generic/base.py", line 104, in view
    return self.dispatch(request, *args, **kwargs)
           ^^^^^^^^^^^^^^^^^^^^^^^^^^^^^^^^^^^^^^^
  File "/home/alprostov/PycharmProjects/sakhlis/venv3/lib/python3.11/site-packages/django/contrib/auth/mixins.py", line 73, in dispatch
    return super().dispatch(request, *args, **kwargs)
           ^^^^^^^^^^^^^^^^^^^^^^^^^^^^^^^^^^^^^^^^^^
  File "/home/alprostov/PycharmProjects/sakhlis/venv3/lib/python3.11/site-packages/django/views/generic/base.py", line 143, in dispatch
    return handler(request, *args, **kwargs)
           ^^^^^^^^^^^^^^^^^^^^^^^^^^^^^^^^^
  File "/home/alprostov/PycharmProjects/sakhlis/venv3/lib/python3.11/site-packages/django/views/generic/base.py", line 226, in get
    context = self.get_context_data(**kwargs)
              ^^^^^^^^^^^^^^^^^^^^^^^^^^^^^^^
  File "/home/alprostov/PycharmProjects/sakhlis/sakhlis/web/app_site/views.py", line 177, in get_context_data
    context['hh'] = instans_graf.make_graf_plot()
                    ^^^^^^^^^^^^^^^^^^^^^^^^^^^^^
  File "/home/alprostov/PycharmProjects/sakhlis/sakhlis/web/app_site/utils.py", line 216, in make_graf_plot
    labels, data = self.get_data_for_graph()
                   ^^^^^^^^^^^^^^^^^^^^^^^^^
  File "/home/alprostov/PycharmProjects/sakhlis/sakhlis/web/app_site/utils.py", line 172, in get_data_for_graph
    labels.append(b + ' ' + self.help_dict[_[self.name_X]])
                            ~~~~~~~~~~~~~~^^^^^^^^^^^^^^^^
TypeError: string indices must be integers, not 'datetime.date'
10/Jan/2024 19:44:43   ERROR  "GET /stat/ HTTP/1.1" 500 116788  None
ERROR:django.server:"GET /stat/ HTTP/1.1" 500 116788
10/Jan/2024 19:47:01   INFO  /home/alprostov/PycharmProjects/sakhlis/sakhlis/web/app_site/views.py changed, reloading.  None
INFO:django.utils.autoreload:/home/alprostov/PycharmProjects/sakhlis/sakhlis/web/app_site/views.py changed, reloading.
10/Jan/2024 19:47:03   INFO  Watching for file changes with StatReloader  None
10/Jan/2024 19:49:23   INFO  /home/alprostov/PycharmProjects/sakhlis/sakhlis/web/app_site/views.py changed, reloading.  None
10/Jan/2024 19:49:25   INFO  Watching for file changes with StatReloader  None
10/Jan/2024 19:49:26   ERROR  Internal Server Error: /stat/  (<class 'TypeError'>, TypeError("Graph.__init__() got multiple values for argument 'help_dict'"), <traceback object at 0x7ff7930415c0>)
Traceback (most recent call last):
  File "/home/alprostov/PycharmProjects/sakhlis/venv3/lib/python3.11/site-packages/django/core/handlers/exception.py", line 55, in inner
    response = get_response(request)
               ^^^^^^^^^^^^^^^^^^^^^
  File "/home/alprostov/PycharmProjects/sakhlis/venv3/lib/python3.11/site-packages/django/core/handlers/base.py", line 197, in _get_response
    response = wrapped_callback(request, *callback_args, **callback_kwargs)
               ^^^^^^^^^^^^^^^^^^^^^^^^^^^^^^^^^^^^^^^^^^^^^^^^^^^^^^^^^^^^
  File "/home/alprostov/PycharmProjects/sakhlis/venv3/lib/python3.11/site-packages/django/views/generic/base.py", line 104, in view
    return self.dispatch(request, *args, **kwargs)
           ^^^^^^^^^^^^^^^^^^^^^^^^^^^^^^^^^^^^^^^
  File "/home/alprostov/PycharmProjects/sakhlis/venv3/lib/python3.11/site-packages/django/contrib/auth/mixins.py", line 73, in dispatch
    return super().dispatch(request, *args, **kwargs)
           ^^^^^^^^^^^^^^^^^^^^^^^^^^^^^^^^^^^^^^^^^^
  File "/home/alprostov/PycharmProjects/sakhlis/venv3/lib/python3.11/site-packages/django/views/generic/base.py", line 143, in dispatch
    return handler(request, *args, **kwargs)
           ^^^^^^^^^^^^^^^^^^^^^^^^^^^^^^^^^
  File "/home/alprostov/PycharmProjects/sakhlis/venv3/lib/python3.11/site-packages/django/views/generic/base.py", line 226, in get
    context = self.get_context_data(**kwargs)
              ^^^^^^^^^^^^^^^^^^^^^^^^^^^^^^^
  File "/home/alprostov/PycharmProjects/sakhlis/sakhlis/web/app_site/views.py", line 176, in get_context_data
    instans_graf = Graph(h,'time_in__date','count',  'Динамика за 30 дней.', '', help_dict=None,)
                   ^^^^^^^^^^^^^^^^^^^^^^^^^^^^^^^^^^^^^^^^^^^^^^^^^^^^^^^^^^^^^^^^^^^^^^^^^^^^^^
TypeError: Graph.__init__() got multiple values for argument 'help_dict'
ERROR:django.request:Internal Server Error: /stat/
Traceback (most recent call last):
  File "/home/alprostov/PycharmProjects/sakhlis/venv3/lib/python3.11/site-packages/django/core/handlers/exception.py", line 55, in inner
    response = get_response(request)
               ^^^^^^^^^^^^^^^^^^^^^
  File "/home/alprostov/PycharmProjects/sakhlis/venv3/lib/python3.11/site-packages/django/core/handlers/base.py", line 197, in _get_response
    response = wrapped_callback(request, *callback_args, **callback_kwargs)
               ^^^^^^^^^^^^^^^^^^^^^^^^^^^^^^^^^^^^^^^^^^^^^^^^^^^^^^^^^^^^
  File "/home/alprostov/PycharmProjects/sakhlis/venv3/lib/python3.11/site-packages/django/views/generic/base.py", line 104, in view
    return self.dispatch(request, *args, **kwargs)
           ^^^^^^^^^^^^^^^^^^^^^^^^^^^^^^^^^^^^^^^
  File "/home/alprostov/PycharmProjects/sakhlis/venv3/lib/python3.11/site-packages/django/contrib/auth/mixins.py", line 73, in dispatch
    return super().dispatch(request, *args, **kwargs)
           ^^^^^^^^^^^^^^^^^^^^^^^^^^^^^^^^^^^^^^^^^^
  File "/home/alprostov/PycharmProjects/sakhlis/venv3/lib/python3.11/site-packages/django/views/generic/base.py", line 143, in dispatch
    return handler(request, *args, **kwargs)
           ^^^^^^^^^^^^^^^^^^^^^^^^^^^^^^^^^
  File "/home/alprostov/PycharmProjects/sakhlis/venv3/lib/python3.11/site-packages/django/views/generic/base.py", line 226, in get
    context = self.get_context_data(**kwargs)
              ^^^^^^^^^^^^^^^^^^^^^^^^^^^^^^^
  File "/home/alprostov/PycharmProjects/sakhlis/sakhlis/web/app_site/views.py", line 176, in get_context_data
    instans_graf = Graph(h,'time_in__date','count',  'Динамика за 30 дней.', '', help_dict=None,)
                   ^^^^^^^^^^^^^^^^^^^^^^^^^^^^^^^^^^^^^^^^^^^^^^^^^^^^^^^^^^^^^^^^^^^^^^^^^^^^^^
TypeError: Graph.__init__() got multiple values for argument 'help_dict'
10/Jan/2024 19:49:26   ERROR  "GET /stat/ HTTP/1.1" 500 108632  None
ERROR:django.server:"GET /stat/ HTTP/1.1" 500 108632
10/Jan/2024 19:49:37   INFO  /home/alprostov/PycharmProjects/sakhlis/sakhlis/web/app_site/views.py changed, reloading.  None
INFO:django.utils.autoreload:/home/alprostov/PycharmProjects/sakhlis/sakhlis/web/app_site/views.py changed, reloading.
10/Jan/2024 19:49:47   INFO  Watching for file changes with StatReloader  None
10/Jan/2024 19:49:52   ERROR  Internal Server Error: /stat/  (<class 'TypeError'>, TypeError("Graph.__init__() got multiple values for argument 'help_dict'"), <traceback object at 0x7f1a9d5e8300>)
Traceback (most recent call last):
  File "/home/alprostov/PycharmProjects/sakhlis/venv3/lib/python3.11/site-packages/django/core/handlers/exception.py", line 55, in inner
    response = get_response(request)
               ^^^^^^^^^^^^^^^^^^^^^
  File "/home/alprostov/PycharmProjects/sakhlis/venv3/lib/python3.11/site-packages/django/core/handlers/base.py", line 197, in _get_response
    response = wrapped_callback(request, *callback_args, **callback_kwargs)
               ^^^^^^^^^^^^^^^^^^^^^^^^^^^^^^^^^^^^^^^^^^^^^^^^^^^^^^^^^^^^
  File "/home/alprostov/PycharmProjects/sakhlis/venv3/lib/python3.11/site-packages/django/views/generic/base.py", line 104, in view
    return self.dispatch(request, *args, **kwargs)
           ^^^^^^^^^^^^^^^^^^^^^^^^^^^^^^^^^^^^^^^
  File "/home/alprostov/PycharmProjects/sakhlis/venv3/lib/python3.11/site-packages/django/contrib/auth/mixins.py", line 73, in dispatch
    return super().dispatch(request, *args, **kwargs)
           ^^^^^^^^^^^^^^^^^^^^^^^^^^^^^^^^^^^^^^^^^^
  File "/home/alprostov/PycharmProjects/sakhlis/venv3/lib/python3.11/site-packages/django/views/generic/base.py", line 143, in dispatch
    return handler(request, *args, **kwargs)
           ^^^^^^^^^^^^^^^^^^^^^^^^^^^^^^^^^
  File "/home/alprostov/PycharmProjects/sakhlis/venv3/lib/python3.11/site-packages/django/views/generic/base.py", line 226, in get
    context = self.get_context_data(**kwargs)
              ^^^^^^^^^^^^^^^^^^^^^^^^^^^^^^^
  File "/home/alprostov/PycharmProjects/sakhlis/sakhlis/web/app_site/views.py", line 176, in get_context_data
    instans_graf = Graph(h,'time_in__date','count',  'Динамика за 30 дней.', '', help_dict=None)
                   ^^^^^^^^^^^^^^^^^^^^^^^^^^^^^^^^^^^^^^^^^^^^^^^^^^^^^^^^^^^^^^^^^^^^^^^^^^^^^
TypeError: Graph.__init__() got multiple values for argument 'help_dict'
ERROR:django.request:Internal Server Error: /stat/
Traceback (most recent call last):
  File "/home/alprostov/PycharmProjects/sakhlis/venv3/lib/python3.11/site-packages/django/core/handlers/exception.py", line 55, in inner
    response = get_response(request)
               ^^^^^^^^^^^^^^^^^^^^^
  File "/home/alprostov/PycharmProjects/sakhlis/venv3/lib/python3.11/site-packages/django/core/handlers/base.py", line 197, in _get_response
    response = wrapped_callback(request, *callback_args, **callback_kwargs)
               ^^^^^^^^^^^^^^^^^^^^^^^^^^^^^^^^^^^^^^^^^^^^^^^^^^^^^^^^^^^^
  File "/home/alprostov/PycharmProjects/sakhlis/venv3/lib/python3.11/site-packages/django/views/generic/base.py", line 104, in view
    return self.dispatch(request, *args, **kwargs)
           ^^^^^^^^^^^^^^^^^^^^^^^^^^^^^^^^^^^^^^^
  File "/home/alprostov/PycharmProjects/sakhlis/venv3/lib/python3.11/site-packages/django/contrib/auth/mixins.py", line 73, in dispatch
    return super().dispatch(request, *args, **kwargs)
           ^^^^^^^^^^^^^^^^^^^^^^^^^^^^^^^^^^^^^^^^^^
  File "/home/alprostov/PycharmProjects/sakhlis/venv3/lib/python3.11/site-packages/django/views/generic/base.py", line 143, in dispatch
    return handler(request, *args, **kwargs)
           ^^^^^^^^^^^^^^^^^^^^^^^^^^^^^^^^^
  File "/home/alprostov/PycharmProjects/sakhlis/venv3/lib/python3.11/site-packages/django/views/generic/base.py", line 226, in get
    context = self.get_context_data(**kwargs)
              ^^^^^^^^^^^^^^^^^^^^^^^^^^^^^^^
  File "/home/alprostov/PycharmProjects/sakhlis/sakhlis/web/app_site/views.py", line 176, in get_context_data
    instans_graf = Graph(h,'time_in__date','count',  'Динамика за 30 дней.', '', help_dict=None)
                   ^^^^^^^^^^^^^^^^^^^^^^^^^^^^^^^^^^^^^^^^^^^^^^^^^^^^^^^^^^^^^^^^^^^^^^^^^^^^^
TypeError: Graph.__init__() got multiple values for argument 'help_dict'
10/Jan/2024 19:49:52   ERROR  "GET /stat/ HTTP/1.1" 500 108630  None
ERROR:django.server:"GET /stat/ HTTP/1.1" 500 108630
10/Jan/2024 19:51:23   INFO  /home/alprostov/PycharmProjects/sakhlis/sakhlis/web/app_site/views.py changed, reloading.  None
INFO:django.utils.autoreload:/home/alprostov/PycharmProjects/sakhlis/sakhlis/web/app_site/views.py changed, reloading.
10/Jan/2024 19:51:26   INFO  Watching for file changes with StatReloader  None
10/Jan/2024 19:51:27   INFO  "GET /stat/ HTTP/1.1" 200 192529  None
INFO:django.server:"GET /stat/ HTTP/1.1" 200 192529
10/Jan/2024 19:51:27   WARNING  "GET /static/js/counter.js HTTP/1.1" 404 1798  None
WARNING:django.server:"GET /static/js/counter.js HTTP/1.1" 404 1798
10/Jan/2024 19:51:39   INFO  /home/alprostov/PycharmProjects/sakhlis/sakhlis/web/app_site/views.py changed, reloading.  None
INFO:django.utils.autoreload:/home/alprostov/PycharmProjects/sakhlis/sakhlis/web/app_site/views.py changed, reloading.
10/Jan/2024 19:51:41   INFO  Watching for file changes with StatReloader  None
10/Jan/2024 19:51:51   INFO  /home/alprostov/PycharmProjects/sakhlis/sakhlis/web/app_site/views.py changed, reloading.  None
INFO:django.utils.autoreload:/home/alprostov/PycharmProjects/sakhlis/sakhlis/web/app_site/views.py changed, reloading.
10/Jan/2024 19:51:51   ERROR  Internal Server Error: /stat/  (<class 'TypeError'>, TypeError("string indices must be integers, not 'datetime.date'"), <traceback object at 0x7f769383ec00>)
Traceback (most recent call last):
  File "/home/alprostov/PycharmProjects/sakhlis/venv3/lib/python3.11/site-packages/django/core/handlers/exception.py", line 55, in inner
    response = get_response(request)
               ^^^^^^^^^^^^^^^^^^^^^
  File "/home/alprostov/PycharmProjects/sakhlis/venv3/lib/python3.11/site-packages/django/core/handlers/base.py", line 197, in _get_response
    response = wrapped_callback(request, *callback_args, **callback_kwargs)
               ^^^^^^^^^^^^^^^^^^^^^^^^^^^^^^^^^^^^^^^^^^^^^^^^^^^^^^^^^^^^
  File "/home/alprostov/PycharmProjects/sakhlis/venv3/lib/python3.11/site-packages/django/views/generic/base.py", line 104, in view
    return self.dispatch(request, *args, **kwargs)
           ^^^^^^^^^^^^^^^^^^^^^^^^^^^^^^^^^^^^^^^
  File "/home/alprostov/PycharmProjects/sakhlis/venv3/lib/python3.11/site-packages/django/contrib/auth/mixins.py", line 73, in dispatch
    return super().dispatch(request, *args, **kwargs)
           ^^^^^^^^^^^^^^^^^^^^^^^^^^^^^^^^^^^^^^^^^^
  File "/home/alprostov/PycharmProjects/sakhlis/venv3/lib/python3.11/site-packages/django/views/generic/base.py", line 143, in dispatch
    return handler(request, *args, **kwargs)
           ^^^^^^^^^^^^^^^^^^^^^^^^^^^^^^^^^
  File "/home/alprostov/PycharmProjects/sakhlis/venv3/lib/python3.11/site-packages/django/views/generic/base.py", line 226, in get
    context = self.get_context_data(**kwargs)
              ^^^^^^^^^^^^^^^^^^^^^^^^^^^^^^^
  File "/home/alprostov/PycharmProjects/sakhlis/sakhlis/web/app_site/views.py", line 177, in get_context_data
    context['hh'] = instans_graf.make_graf_plot()
                    ^^^^^^^^^^^^^^^^^^^^^^^^^^^^^
  File "/home/alprostov/PycharmProjects/sakhlis/sakhlis/web/app_site/utils.py", line 216, in make_graf_plot
    labels, data = self.get_data_for_graph()
                   ^^^^^^^^^^^^^^^^^^^^^^^^^
  File "/home/alprostov/PycharmProjects/sakhlis/sakhlis/web/app_site/utils.py", line 172, in get_data_for_graph
    labels.append(b + ' ' + self.help_dict[_[self.name_X]])
                            ~~~~~~~~~~~~~~^^^^^^^^^^^^^^^^
TypeError: string indices must be integers, not 'datetime.date'
ERROR:django.request:Internal Server Error: /stat/
Traceback (most recent call last):
  File "/home/alprostov/PycharmProjects/sakhlis/venv3/lib/python3.11/site-packages/django/core/handlers/exception.py", line 55, in inner
    response = get_response(request)
               ^^^^^^^^^^^^^^^^^^^^^
  File "/home/alprostov/PycharmProjects/sakhlis/venv3/lib/python3.11/site-packages/django/core/handlers/base.py", line 197, in _get_response
    response = wrapped_callback(request, *callback_args, **callback_kwargs)
               ^^^^^^^^^^^^^^^^^^^^^^^^^^^^^^^^^^^^^^^^^^^^^^^^^^^^^^^^^^^^
  File "/home/alprostov/PycharmProjects/sakhlis/venv3/lib/python3.11/site-packages/django/views/generic/base.py", line 104, in view
    return self.dispatch(request, *args, **kwargs)
           ^^^^^^^^^^^^^^^^^^^^^^^^^^^^^^^^^^^^^^^
  File "/home/alprostov/PycharmProjects/sakhlis/venv3/lib/python3.11/site-packages/django/contrib/auth/mixins.py", line 73, in dispatch
    return super().dispatch(request, *args, **kwargs)
           ^^^^^^^^^^^^^^^^^^^^^^^^^^^^^^^^^^^^^^^^^^
  File "/home/alprostov/PycharmProjects/sakhlis/venv3/lib/python3.11/site-packages/django/views/generic/base.py", line 143, in dispatch
    return handler(request, *args, **kwargs)
           ^^^^^^^^^^^^^^^^^^^^^^^^^^^^^^^^^
  File "/home/alprostov/PycharmProjects/sakhlis/venv3/lib/python3.11/site-packages/django/views/generic/base.py", line 226, in get
    context = self.get_context_data(**kwargs)
              ^^^^^^^^^^^^^^^^^^^^^^^^^^^^^^^
  File "/home/alprostov/PycharmProjects/sakhlis/sakhlis/web/app_site/views.py", line 177, in get_context_data
    context['hh'] = instans_graf.make_graf_plot()
                    ^^^^^^^^^^^^^^^^^^^^^^^^^^^^^
  File "/home/alprostov/PycharmProjects/sakhlis/sakhlis/web/app_site/utils.py", line 216, in make_graf_plot
    labels, data = self.get_data_for_graph()
                   ^^^^^^^^^^^^^^^^^^^^^^^^^
  File "/home/alprostov/PycharmProjects/sakhlis/sakhlis/web/app_site/utils.py", line 172, in get_data_for_graph
    labels.append(b + ' ' + self.help_dict[_[self.name_X]])
                            ~~~~~~~~~~~~~~^^^^^^^^^^^^^^^^
TypeError: string indices must be integers, not 'datetime.date'
10/Jan/2024 19:51:51   ERROR  "GET /stat/ HTTP/1.1" 500 116795  None
ERROR:django.server:"GET /stat/ HTTP/1.1" 500 116795
10/Jan/2024 19:51:53   INFO  Watching for file changes with StatReloader  None
10/Jan/2024 19:51:57   INFO  "GET /stat/ HTTP/1.1" 200 192529  None
INFO:django.server:"GET /stat/ HTTP/1.1" 200 192529
10/Jan/2024 19:51:57   WARNING  "GET /static/js/counter.js HTTP/1.1" 404 1798  None
WARNING:django.server:"GET /static/js/counter.js HTTP/1.1" 404 1798
10/Jan/2024 19:52:01   INFO  "GET /stat/ HTTP/1.1" 200 192529  None
INFO:django.server:"GET /stat/ HTTP/1.1" 200 192529
10/Jan/2024 19:52:01   WARNING  "GET /static/js/counter.js HTTP/1.1" 404 1798  None
WARNING:django.server:"GET /static/js/counter.js HTTP/1.1" 404 1798
10/Jan/2024 19:52:02   INFO  "GET /list_order HTTP/1.1" 200 53823  None
INFO:django.server:"GET /list_order HTTP/1.1" 200 53823
10/Jan/2024 19:52:02   WARNING  "GET /static/js/counter.js HTTP/1.1" 404 1798  None
WARNING:django.server:"GET /static/js/counter.js HTTP/1.1" 404 1798
10/Jan/2024 19:52:04   INFO  "GET /stat/ HTTP/1.1" 200 192529  None
INFO:django.server:"GET /stat/ HTTP/1.1" 200 192529
10/Jan/2024 19:52:04   WARNING  "GET /static/js/counter.js HTTP/1.1" 404 1798  None
WARNING:django.server:"GET /static/js/counter.js HTTP/1.1" 404 1798
10/Jan/2024 19:52:05   INFO  "GET /user/51 HTTP/1.1" 200 15689  None
INFO:django.server:"GET /user/51 HTTP/1.1" 200 15689
10/Jan/2024 19:52:05   WARNING  "GET /static/js/counter.js HTTP/1.1" 404 1798  None
WARNING:django.server:"GET /static/js/counter.js HTTP/1.1" 404 1798
10/Jan/2024 19:52:05   INFO  "GET /media/images/20231222_173850.jpg HTTP/1.1" 200 3729289  None
INFO:django.server:"GET /media/images/20231222_173850.jpg HTTP/1.1" 200 3729289
10/Jan/2024 19:52:08   INFO  "GET /stat/ HTTP/1.1" 200 192529  None
INFO:django.server:"GET /stat/ HTTP/1.1" 200 192529
10/Jan/2024 19:52:08   WARNING  "GET /static/js/counter.js HTTP/1.1" 404 1798  None
WARNING:django.server:"GET /static/js/counter.js HTTP/1.1" 404 1798
10/Jan/2024 19:55:32   INFO  /home/alprostov/PycharmProjects/sakhlis/sakhlis/web/app_site/views.py changed, reloading.  None
INFO:django.utils.autoreload:/home/alprostov/PycharmProjects/sakhlis/sakhlis/web/app_site/views.py changed, reloading.
10/Jan/2024 19:55:33   INFO  "GET /stat/ HTTP/1.1" 200 192529  None
INFO:django.server:"GET /stat/ HTTP/1.1" 200 192529
10/Jan/2024 19:55:33   WARNING  "GET /static/js/counter.js HTTP/1.1" 404 1798  None
WARNING:django.server:"GET /static/js/counter.js HTTP/1.1" 404 1798
10/Jan/2024 19:55:34   INFO  Watching for file changes with StatReloader  None
10/Jan/2024 19:55:35   INFO  "GET /stat/ HTTP/1.1" 200 61937  None
INFO:django.server:"GET /stat/ HTTP/1.1" 200 61937
10/Jan/2024 19:55:35   WARNING  "GET /static/js/counter.js HTTP/1.1" 404 1798  None
WARNING:django.server:"GET /static/js/counter.js HTTP/1.1" 404 1798
10/Jan/2024 19:58:25   INFO  /home/alprostov/PycharmProjects/sakhlis/sakhlis/web/app_site/views.py changed, reloading.  None
INFO:django.utils.autoreload:/home/alprostov/PycharmProjects/sakhlis/sakhlis/web/app_site/views.py changed, reloading.
10/Jan/2024 19:58:25   INFO  "GET /stat/ HTTP/1.1" 200 61938  None
INFO:django.server:"GET /stat/ HTTP/1.1" 200 61938
10/Jan/2024 19:58:25   WARNING  "GET /static/js/counter.js HTTP/1.1" 404 1798  None
WARNING:django.server:"GET /static/js/counter.js HTTP/1.1" 404 1798
10/Jan/2024 19:58:27   INFO  Watching for file changes with StatReloader  None
10/Jan/2024 19:58:29   INFO  "GET /stat/ HTTP/1.1" 200 107899  None
INFO:django.server:"GET /stat/ HTTP/1.1" 200 107899
10/Jan/2024 19:58:29   WARNING  "GET /static/js/counter.js HTTP/1.1" 404 1798  None
WARNING:django.server:"GET /static/js/counter.js HTTP/1.1" 404 1798
10/Jan/2024 20:00:08   INFO  /home/alprostov/PycharmProjects/sakhlis/sakhlis/web/app_site/views.py changed, reloading.  None
INFO:django.utils.autoreload:/home/alprostov/PycharmProjects/sakhlis/sakhlis/web/app_site/views.py changed, reloading.
10/Jan/2024 20:00:10   INFO  Watching for file changes with StatReloader  None
10/Jan/2024 20:00:12   INFO  "GET /stat/ HTTP/1.1" 200 127931  None
INFO:django.server:"GET /stat/ HTTP/1.1" 200 127931
10/Jan/2024 20:00:13   WARNING  "GET /static/js/counter.js HTTP/1.1" 404 1798  None
WARNING:django.server:"GET /static/js/counter.js HTTP/1.1" 404 1798
10/Jan/2024 20:08:56   INFO  /home/alprostov/PycharmProjects/sakhlis/sakhlis/web/app_site/views.py changed, reloading.  None
INFO:django.utils.autoreload:/home/alprostov/PycharmProjects/sakhlis/sakhlis/web/app_site/views.py changed, reloading.
10/Jan/2024 20:08:58   INFO  Watching for file changes with StatReloader  None
10/Jan/2024 20:09:02   INFO  "GET /stat/ HTTP/1.1" 200 149871  None
INFO:django.server:"GET /stat/ HTTP/1.1" 200 149871
10/Jan/2024 20:09:02   WARNING  "GET /static/js/counter.js HTTP/1.1" 404 1798  None
WARNING:django.server:"GET /static/js/counter.js HTTP/1.1" 404 1798
10/Jan/2024 20:11:29   INFO  /home/alprostov/PycharmProjects/sakhlis/sakhlis/web/app_site/views.py changed, reloading.  None
INFO:django.utils.autoreload:/home/alprostov/PycharmProjects/sakhlis/sakhlis/web/app_site/views.py changed, reloading.
10/Jan/2024 20:11:32   INFO  Watching for file changes with StatReloader  None
10/Jan/2024 20:11:35   INFO  "GET /stat/ HTTP/1.1" 200 192529  None
INFO:django.server:"GET /stat/ HTTP/1.1" 200 192529
10/Jan/2024 20:11:35   WARNING  "GET /static/js/counter.js HTTP/1.1" 404 1798  None
WARNING:django.server:"GET /static/js/counter.js HTTP/1.1" 404 1798
10/Jan/2024 20:13:25   INFO  /home/alprostov/PycharmProjects/sakhlis/sakhlis/web/app_site/views.py changed, reloading.  None
INFO:django.utils.autoreload:/home/alprostov/PycharmProjects/sakhlis/sakhlis/web/app_site/views.py changed, reloading.
10/Jan/2024 20:13:27   INFO  Watching for file changes with StatReloader  None
10/Jan/2024 20:19:41   INFO  /home/alprostov/PycharmProjects/sakhlis/sakhlis/web/app_site/views.py changed, reloading.  None
INFO:django.utils.autoreload:/home/alprostov/PycharmProjects/sakhlis/sakhlis/web/app_site/views.py changed, reloading.
10/Jan/2024 20:19:43   INFO  Watching for file changes with StatReloader  None
