27/Nov/2024 08:56:51    ERROR    log    Internal Server Error: /list_order   /home/alprostov/PycharmProjects/sakhlis/web/venv/lib/python3.11/site-packages/django/utils/log.py   (<class 'TypeError'>, TypeError("'OrderFilter' object is not subscriptable"), <traceback object at 0x7f556b5d8940>)
Traceback (most recent call last):
  File "/home/alprostov/PycharmProjects/sakhlis/web/venv/lib/python3.11/site-packages/django/core/handlers/exception.py", line 55, in inner
    response = get_response(request)
               ^^^^^^^^^^^^^^^^^^^^^
  File "/home/alprostov/PycharmProjects/sakhlis/web/venv/lib/python3.11/site-packages/django/core/handlers/base.py", line 197, in _get_response
    response = wrapped_callback(request, *callback_args, **callback_kwargs)
               ^^^^^^^^^^^^^^^^^^^^^^^^^^^^^^^^^^^^^^^^^^^^^^^^^^^^^^^^^^^^
  File "/home/alprostov/PycharmProjects/sakhlis/web/venv/lib/python3.11/site-packages/django/views/generic/base.py", line 104, in view
    return self.dispatch(request, *args, **kwargs)
           ^^^^^^^^^^^^^^^^^^^^^^^^^^^^^^^^^^^^^^^
  File "/home/alprostov/PycharmProjects/sakhlis/web/venv/lib/python3.11/site-packages/django/contrib/auth/mixins.py", line 73, in dispatch
    return super().dispatch(request, *args, **kwargs)
           ^^^^^^^^^^^^^^^^^^^^^^^^^^^^^^^^^^^^^^^^^^
  File "/home/alprostov/PycharmProjects/sakhlis/web/venv/lib/python3.11/site-packages/django/views/generic/base.py", line 143, in dispatch
    return handler(request, *args, **kwargs)
           ^^^^^^^^^^^^^^^^^^^^^^^^^^^^^^^^^
  File "/home/alprostov/PycharmProjects/sakhlis/web/venv/lib/python3.11/site-packages/django/views/generic/list.py", line 174, in get
    context = self.get_context_data()
              ^^^^^^^^^^^^^^^^^^^^^^^
  File "/home/alprostov/PycharmProjects/sakhlis/web/app_site/views.py", line 340, in get_context_data
    context['filterset'] = self.filterset[0:10]
                           ~~~~~~~~~~~~~~^^^^^^
TypeError: 'OrderFilter' object is not subscriptable
27/Nov/2024 08:56:51    ERROR    basehttp    "GET /list_order HTTP/1.1" 500 105971   /home/alprostov/PycharmProjects/sakhlis/web/venv/lib/python3.11/site-packages/django/core/servers/basehttp.py   None
27/Nov/2024 08:57:22    ERROR    log    Internal Server Error: /list_order   /home/alprostov/PycharmProjects/sakhlis/web/venv/lib/python3.11/site-packages/django/utils/log.py   (<class 'TypeError'>, TypeError("'OrderFilter' object is not subscriptable"), <traceback object at 0x7fbec0080700>)
Traceback (most recent call last):
  File "/home/alprostov/PycharmProjects/sakhlis/web/venv/lib/python3.11/site-packages/django/core/handlers/exception.py", line 55, in inner
    response = get_response(request)
               ^^^^^^^^^^^^^^^^^^^^^
  File "/home/alprostov/PycharmProjects/sakhlis/web/venv/lib/python3.11/site-packages/django/core/handlers/base.py", line 197, in _get_response
    response = wrapped_callback(request, *callback_args, **callback_kwargs)
               ^^^^^^^^^^^^^^^^^^^^^^^^^^^^^^^^^^^^^^^^^^^^^^^^^^^^^^^^^^^^
  File "/home/alprostov/PycharmProjects/sakhlis/web/venv/lib/python3.11/site-packages/django/views/generic/base.py", line 104, in view
    return self.dispatch(request, *args, **kwargs)
           ^^^^^^^^^^^^^^^^^^^^^^^^^^^^^^^^^^^^^^^
  File "/home/alprostov/PycharmProjects/sakhlis/web/venv/lib/python3.11/site-packages/django/contrib/auth/mixins.py", line 73, in dispatch
    return super().dispatch(request, *args, **kwargs)
           ^^^^^^^^^^^^^^^^^^^^^^^^^^^^^^^^^^^^^^^^^^
  File "/home/alprostov/PycharmProjects/sakhlis/web/venv/lib/python3.11/site-packages/django/views/generic/base.py", line 143, in dispatch
    return handler(request, *args, **kwargs)
           ^^^^^^^^^^^^^^^^^^^^^^^^^^^^^^^^^
  File "/home/alprostov/PycharmProjects/sakhlis/web/venv/lib/python3.11/site-packages/django/views/generic/list.py", line 154, in get
    self.object_list = self.get_queryset()
                       ^^^^^^^^^^^^^^^^^^^
  File "/home/alprostov/PycharmProjects/sakhlis/web/app_site/views.py", line 335, in get_queryset
    self.filterset = OrderFilter(self.request.GET, queryset)[0:10]
                     ~~~~~~~~~~~~~~~~~~~~~~~~~~~~~~~~~~~~~~~^^^^^^
TypeError: 'OrderFilter' object is not subscriptable
27/Nov/2024 08:57:22    ERROR    basehttp    "GET /list_order HTTP/1.1" 500 106134   /home/alprostov/PycharmProjects/sakhlis/web/venv/lib/python3.11/site-packages/django/core/servers/basehttp.py   None
27/Nov/2024 08:57:23    ERROR    log    Internal Server Error: /list_order   /home/alprostov/PycharmProjects/sakhlis/web/venv/lib/python3.11/site-packages/django/utils/log.py   (<class 'TypeError'>, TypeError("'OrderFilter' object is not subscriptable"), <traceback object at 0x7fbec01d4980>)
Traceback (most recent call last):
  File "/home/alprostov/PycharmProjects/sakhlis/web/venv/lib/python3.11/site-packages/django/core/handlers/exception.py", line 55, in inner
    response = get_response(request)
               ^^^^^^^^^^^^^^^^^^^^^
  File "/home/alprostov/PycharmProjects/sakhlis/web/venv/lib/python3.11/site-packages/django/core/handlers/base.py", line 197, in _get_response
    response = wrapped_callback(request, *callback_args, **callback_kwargs)
               ^^^^^^^^^^^^^^^^^^^^^^^^^^^^^^^^^^^^^^^^^^^^^^^^^^^^^^^^^^^^
  File "/home/alprostov/PycharmProjects/sakhlis/web/venv/lib/python3.11/site-packages/django/views/generic/base.py", line 104, in view
    return self.dispatch(request, *args, **kwargs)
           ^^^^^^^^^^^^^^^^^^^^^^^^^^^^^^^^^^^^^^^
  File "/home/alprostov/PycharmProjects/sakhlis/web/venv/lib/python3.11/site-packages/django/contrib/auth/mixins.py", line 73, in dispatch
    return super().dispatch(request, *args, **kwargs)
           ^^^^^^^^^^^^^^^^^^^^^^^^^^^^^^^^^^^^^^^^^^
  File "/home/alprostov/PycharmProjects/sakhlis/web/venv/lib/python3.11/site-packages/django/views/generic/base.py", line 143, in dispatch
    return handler(request, *args, **kwargs)
           ^^^^^^^^^^^^^^^^^^^^^^^^^^^^^^^^^
  File "/home/alprostov/PycharmProjects/sakhlis/web/venv/lib/python3.11/site-packages/django/views/generic/list.py", line 154, in get
    self.object_list = self.get_queryset()
                       ^^^^^^^^^^^^^^^^^^^
  File "/home/alprostov/PycharmProjects/sakhlis/web/app_site/views.py", line 335, in get_queryset
    self.filterset = OrderFilter(self.request.GET, queryset)[0:10]
                     ~~~~~~~~~~~~~~~~~~~~~~~~~~~~~~~~~~~~~~~^^^^^^
TypeError: 'OrderFilter' object is not subscriptable
27/Nov/2024 08:57:23    ERROR    basehttp    "GET /list_order HTTP/1.1" 500 106132   /home/alprostov/PycharmProjects/sakhlis/web/venv/lib/python3.11/site-packages/django/core/servers/basehttp.py   None
27/Nov/2024 08:57:46    WARNING    log    Not Found: /media/masters/unknown_person.jpg   /home/alprostov/PycharmProjects/sakhlis/web/venv/lib/python3.11/site-packages/django/utils/log.py   None
27/Nov/2024 08:57:46    WARNING    basehttp    "GET /media/masters/unknown_person.jpg HTTP/1.1" 404 19523   /home/alprostov/PycharmProjects/sakhlis/web/venv/lib/python3.11/site-packages/django/core/servers/basehttp.py   None
27/Nov/2024 08:59:44    WARNING    log    Not Found: /media/masters/unknown_person.jpg   /home/alprostov/PycharmProjects/sakhlis/web/venv/lib/python3.11/site-packages/django/utils/log.py   None
27/Nov/2024 08:59:44    WARNING    basehttp    "GET /media/masters/unknown_person.jpg HTTP/1.1" 404 19523   /home/alprostov/PycharmProjects/sakhlis/web/venv/lib/python3.11/site-packages/django/core/servers/basehttp.py   None
27/Nov/2024 08:59:45    WARNING    log    Not Found: /media/masters/unknown_person.jpg   /home/alprostov/PycharmProjects/sakhlis/web/venv/lib/python3.11/site-packages/django/utils/log.py   None
27/Nov/2024 08:59:45    WARNING    basehttp    "GET /media/masters/unknown_person.jpg HTTP/1.1" 404 19523   /home/alprostov/PycharmProjects/sakhlis/web/venv/lib/python3.11/site-packages/django/core/servers/basehttp.py   None
27/Nov/2024 09:13:11    WARNING    log    Not Found: /media/masters/unknown_person.jpg   /home/alprostov/PycharmProjects/sakhlis/web/venv/lib/python3.11/site-packages/django/utils/log.py   None
27/Nov/2024 09:13:11    WARNING    basehttp    "GET /media/masters/unknown_person.jpg HTTP/1.1" 404 19523   /home/alprostov/PycharmProjects/sakhlis/web/venv/lib/python3.11/site-packages/django/core/servers/basehttp.py   None
27/Nov/2024 09:13:18    WARNING    log    Not Found: /media/masters/unknown_person.jpg   /home/alprostov/PycharmProjects/sakhlis/web/venv/lib/python3.11/site-packages/django/utils/log.py   None
27/Nov/2024 09:13:18    WARNING    basehttp    "GET /media/masters/unknown_person.jpg HTTP/1.1" 404 19523   /home/alprostov/PycharmProjects/sakhlis/web/venv/lib/python3.11/site-packages/django/core/servers/basehttp.py   None
27/Nov/2024 09:13:19    WARNING    log    Not Found: /media/masters/unknown_person.jpg   /home/alprostov/PycharmProjects/sakhlis/web/venv/lib/python3.11/site-packages/django/utils/log.py   None
27/Nov/2024 09:13:19    WARNING    basehttp    "GET /media/masters/unknown_person.jpg HTTP/1.1" 404 19523   /home/alprostov/PycharmProjects/sakhlis/web/venv/lib/python3.11/site-packages/django/core/servers/basehttp.py   None
27/Nov/2024 09:13:20    WARNING    log    Not Found: /media/masters/unknown_person.jpg   /home/alprostov/PycharmProjects/sakhlis/web/venv/lib/python3.11/site-packages/django/utils/log.py   None
27/Nov/2024 09:13:20    WARNING    basehttp    "GET /media/masters/unknown_person.jpg HTTP/1.1" 404 19523   /home/alprostov/PycharmProjects/sakhlis/web/venv/lib/python3.11/site-packages/django/core/servers/basehttp.py   None
27/Nov/2024 09:13:20    WARNING    log    Not Found: /media/masters/unknown_person.jpg   /home/alprostov/PycharmProjects/sakhlis/web/venv/lib/python3.11/site-packages/django/utils/log.py   None
27/Nov/2024 09:13:20    WARNING    basehttp    "GET /media/masters/unknown_person.jpg HTTP/1.1" 404 19523   /home/alprostov/PycharmProjects/sakhlis/web/venv/lib/python3.11/site-packages/django/core/servers/basehttp.py   None
27/Nov/2024 09:13:20    WARNING    log    Not Found: /media/masters/unknown_person.jpg   /home/alprostov/PycharmProjects/sakhlis/web/venv/lib/python3.11/site-packages/django/utils/log.py   None
27/Nov/2024 09:13:20    WARNING    basehttp    "GET /media/masters/unknown_person.jpg HTTP/1.1" 404 19523   /home/alprostov/PycharmProjects/sakhlis/web/venv/lib/python3.11/site-packages/django/core/servers/basehttp.py   None
27/Nov/2024 09:13:37    WARNING    log    Not Found: /media/masters/unknown_person.jpg   /home/alprostov/PycharmProjects/sakhlis/web/venv/lib/python3.11/site-packages/django/utils/log.py   None
27/Nov/2024 09:13:37    WARNING    basehttp    "GET /media/masters/unknown_person.jpg HTTP/1.1" 404 19523   /home/alprostov/PycharmProjects/sakhlis/web/venv/lib/python3.11/site-packages/django/core/servers/basehttp.py   None
27/Nov/2024 09:31:47    WARNING    log    Not Found: /favicon.ico   /home/alprostov/PycharmProjects/sakhlis/web/venv/lib/python3.11/site-packages/django/utils/log.py   None
27/Nov/2024 09:31:47    WARNING    basehttp    "GET /favicon.ico HTTP/1.1" 404 19223   /home/alprostov/PycharmProjects/sakhlis/web/venv/lib/python3.11/site-packages/django/core/servers/basehttp.py   None
27/Nov/2024 12:19:44    WARNING    log    Not Found: /favicon.ico   /home/alprostov/PycharmProjects/sakhlis/web/venv/lib/python3.11/site-packages/django/utils/log.py   None
27/Nov/2024 12:19:44    WARNING    basehttp    "GET /favicon.ico HTTP/1.1" 404 19223   /home/alprostov/PycharmProjects/sakhlis/web/venv/lib/python3.11/site-packages/django/core/servers/basehttp.py   None
27/Nov/2024 12:20:16    WARNING    log    Not Found: /media/masters/unknown_person.jpg   /home/alprostov/PycharmProjects/sakhlis/web/venv/lib/python3.11/site-packages/django/utils/log.py   None
27/Nov/2024 12:20:16    WARNING    basehttp    "GET /media/masters/unknown_person.jpg HTTP/1.1" 404 19523   /home/alprostov/PycharmProjects/sakhlis/web/venv/lib/python3.11/site-packages/django/core/servers/basehttp.py   None
27/Nov/2024 12:20:23    WARNING    log    Not Found: /media/masters/unknown_person.jpg   /home/alprostov/PycharmProjects/sakhlis/web/venv/lib/python3.11/site-packages/django/utils/log.py   None
27/Nov/2024 12:20:23    WARNING    basehttp    "GET /media/masters/unknown_person.jpg HTTP/1.1" 404 19523   /home/alprostov/PycharmProjects/sakhlis/web/venv/lib/python3.11/site-packages/django/core/servers/basehttp.py   None
27/Nov/2024 12:20:44    WARNING    log    Not Found: /media/masters/unknown_person.jpg   /home/alprostov/PycharmProjects/sakhlis/web/venv/lib/python3.11/site-packages/django/utils/log.py   None
27/Nov/2024 12:20:44    WARNING    basehttp    "GET /media/masters/unknown_person.jpg HTTP/1.1" 404 19523   /home/alprostov/PycharmProjects/sakhlis/web/venv/lib/python3.11/site-packages/django/core/servers/basehttp.py   None
27/Nov/2024 16:25:30    WARNING    log    Not Found: /favicon.ico   /home/alprostov/PycharmProjects/sakhlis/web/venv/lib/python3.11/site-packages/django/utils/log.py   None
27/Nov/2024 16:25:30    WARNING    basehttp    "GET /favicon.ico HTTP/1.1" 404 19223   /home/alprostov/PycharmProjects/sakhlis/web/venv/lib/python3.11/site-packages/django/core/servers/basehttp.py   None
27/Nov/2024 16:25:38    WARNING    log    Not Found: /media/images/appartment/photo_2024-09-16_21-41-10.jpg   /home/alprostov/PycharmProjects/sakhlis/web/venv/lib/python3.11/site-packages/django/utils/log.py   None
27/Nov/2024 16:25:38    WARNING    basehttp    "GET /media/images/appartment/photo_2024-09-16_21-41-10.jpg HTTP/1.1" 404 19630   /home/alprostov/PycharmProjects/sakhlis/web/venv/lib/python3.11/site-packages/django/core/servers/basehttp.py   None
27/Nov/2024 16:25:38    WARNING    log    Not Found: /media/images/appartment/photo_2024-09-12_22-00-08.jpg   /home/alprostov/PycharmProjects/sakhlis/web/venv/lib/python3.11/site-packages/django/utils/log.py   None
27/Nov/2024 16:25:38    WARNING    log    Not Found: /media/images/appartment/photo_2024-09-20_17-39-16.jpg   /home/alprostov/PycharmProjects/sakhlis/web/venv/lib/python3.11/site-packages/django/utils/log.py   None
27/Nov/2024 16:25:38    WARNING    basehttp    "GET /media/images/appartment/photo_2024-09-12_22-00-08.jpg HTTP/1.1" 404 19630   /home/alprostov/PycharmProjects/sakhlis/web/venv/lib/python3.11/site-packages/django/core/servers/basehttp.py   None
27/Nov/2024 16:25:38    WARNING    basehttp    "GET /media/images/appartment/photo_2024-09-20_17-39-16.jpg HTTP/1.1" 404 19630   /home/alprostov/PycharmProjects/sakhlis/web/venv/lib/python3.11/site-packages/django/core/servers/basehttp.py   None
27/Nov/2024 16:25:39    WARNING    log    Not Found: /media/images/appartment/photo_2024-09-12_21-08-19.jpg   /home/alprostov/PycharmProjects/sakhlis/web/venv/lib/python3.11/site-packages/django/utils/log.py   None
27/Nov/2024 16:25:39    WARNING    basehttp    "GET /media/images/appartment/photo_2024-09-12_21-08-19.jpg HTTP/1.1" 404 19630   /home/alprostov/PycharmProjects/sakhlis/web/venv/lib/python3.11/site-packages/django/core/servers/basehttp.py   None
27/Nov/2024 16:25:39    WARNING    log    Not Found: /media/images/appartment/photo_2024-09-22_12-15-37.jpg   /home/alprostov/PycharmProjects/sakhlis/web/venv/lib/python3.11/site-packages/django/utils/log.py   None
27/Nov/2024 16:25:39    WARNING    basehttp    "GET /media/images/appartment/photo_2024-09-22_12-15-37.jpg HTTP/1.1" 404 19630   /home/alprostov/PycharmProjects/sakhlis/web/venv/lib/python3.11/site-packages/django/core/servers/basehttp.py   None
27/Nov/2024 16:25:39    WARNING    log    Not Found: /media/images/appartment/photo_2024-09-12_20-59-28.jpg   /home/alprostov/PycharmProjects/sakhlis/web/venv/lib/python3.11/site-packages/django/utils/log.py   None
27/Nov/2024 16:25:39    WARNING    basehttp    "GET /media/images/appartment/photo_2024-09-12_20-59-28.jpg HTTP/1.1" 404 19630   /home/alprostov/PycharmProjects/sakhlis/web/venv/lib/python3.11/site-packages/django/core/servers/basehttp.py   None
27/Nov/2024 16:25:39    WARNING    log    Not Found: /media/images/appartment/photo_2024-09-16_21-23-19.jpg   /home/alprostov/PycharmProjects/sakhlis/web/venv/lib/python3.11/site-packages/django/utils/log.py   None
27/Nov/2024 16:25:39    WARNING    basehttp    "GET /media/images/appartment/photo_2024-09-16_21-23-19.jpg HTTP/1.1" 404 19630   /home/alprostov/PycharmProjects/sakhlis/web/venv/lib/python3.11/site-packages/django/core/servers/basehttp.py   None
27/Nov/2024 16:25:39    WARNING    log    Not Found: /media/images/appartment/photo_2024-09-20_16-37-55.jpg   /home/alprostov/PycharmProjects/sakhlis/web/venv/lib/python3.11/site-packages/django/utils/log.py   None
27/Nov/2024 16:25:39    WARNING    basehttp    "GET /media/images/appartment/photo_2024-09-20_16-37-55.jpg HTTP/1.1" 404 19630   /home/alprostov/PycharmProjects/sakhlis/web/venv/lib/python3.11/site-packages/django/core/servers/basehttp.py   None
27/Nov/2024 16:25:39    WARNING    log    Not Found: /media/images/appartment/photo_2024-09-13_20-52-44.jpg   /home/alprostov/PycharmProjects/sakhlis/web/venv/lib/python3.11/site-packages/django/utils/log.py   None
27/Nov/2024 16:25:39    WARNING    basehttp    "GET /media/images/appartment/photo_2024-09-13_20-52-44.jpg HTTP/1.1" 404 19630   /home/alprostov/PycharmProjects/sakhlis/web/venv/lib/python3.11/site-packages/django/core/servers/basehttp.py   None
27/Nov/2024 16:25:39    WARNING    log    Not Found: /media/images/appartment/236.jpg   /home/alprostov/PycharmProjects/sakhlis/web/venv/lib/python3.11/site-packages/django/utils/log.py   None
27/Nov/2024 16:25:39    WARNING    basehttp    "GET /media/images/appartment/236.jpg HTTP/1.1" 404 19520   /home/alprostov/PycharmProjects/sakhlis/web/venv/lib/python3.11/site-packages/django/core/servers/basehttp.py   None
27/Nov/2024 16:25:39    WARNING    log    Not Found: /media/images/appartment/photo_2024-09-16_21-48-59.jpg   /home/alprostov/PycharmProjects/sakhlis/web/venv/lib/python3.11/site-packages/django/utils/log.py   None
27/Nov/2024 16:25:39    WARNING    basehttp    "GET /media/images/appartment/photo_2024-09-16_21-48-59.jpg HTTP/1.1" 404 19630   /home/alprostov/PycharmProjects/sakhlis/web/venv/lib/python3.11/site-packages/django/core/servers/basehttp.py   None
27/Nov/2024 16:25:39    WARNING    log    Not Found: /media/images/appartment/photo_2024-09-13_20-50-02.jpg   /home/alprostov/PycharmProjects/sakhlis/web/venv/lib/python3.11/site-packages/django/utils/log.py   None
27/Nov/2024 16:25:39    WARNING    basehttp    "GET /media/images/appartment/photo_2024-09-13_20-50-02.jpg HTTP/1.1" 404 19630   /home/alprostov/PycharmProjects/sakhlis/web/venv/lib/python3.11/site-packages/django/core/servers/basehttp.py   None
27/Nov/2024 16:25:39    WARNING    log    Not Found: /media/images/appartment/2679.jpg   /home/alprostov/PycharmProjects/sakhlis/web/venv/lib/python3.11/site-packages/django/utils/log.py   None
27/Nov/2024 16:25:39    WARNING    basehttp    "GET /media/images/appartment/2679.jpg HTTP/1.1" 404 19525   /home/alprostov/PycharmProjects/sakhlis/web/venv/lib/python3.11/site-packages/django/core/servers/basehttp.py   None
27/Nov/2024 16:25:39    WARNING    log    Not Found: /media/images/appartment/2718.jpg   /home/alprostov/PycharmProjects/sakhlis/web/venv/lib/python3.11/site-packages/django/utils/log.py   None
27/Nov/2024 16:25:39    WARNING    basehttp    "GET /media/images/appartment/2718.jpg HTTP/1.1" 404 19525   /home/alprostov/PycharmProjects/sakhlis/web/venv/lib/python3.11/site-packages/django/core/servers/basehttp.py   None
27/Nov/2024 16:25:39    WARNING    log    Not Found: /media/images/appartment/photo_2024-09-12_21-08-19_jbnLNP4.jpg   /home/alprostov/PycharmProjects/sakhlis/web/venv/lib/python3.11/site-packages/django/utils/log.py   None
27/Nov/2024 16:25:39    WARNING    basehttp    "GET /media/images/appartment/photo_2024-09-12_21-08-19_jbnLNP4.jpg HTTP/1.1" 404 19670   /home/alprostov/PycharmProjects/sakhlis/web/venv/lib/python3.11/site-packages/django/core/servers/basehttp.py   None
27/Nov/2024 16:32:03    WARNING    log    Not Found: /media/images/appartment/photo_2024-09-12_22-00-08.jpg   /home/alprostov/PycharmProjects/sakhlis/web/venv/lib/python3.11/site-packages/django/utils/log.py   None
27/Nov/2024 16:32:03    WARNING    basehttp    "GET /media/images/appartment/photo_2024-09-12_22-00-08.jpg HTTP/1.1" 404 19630   /home/alprostov/PycharmProjects/sakhlis/web/venv/lib/python3.11/site-packages/django/core/servers/basehttp.py   None
27/Nov/2024 16:32:03    WARNING    log    Not Found: /media/images/appartment/photo_2024-09-16_21-41-10.jpg   /home/alprostov/PycharmProjects/sakhlis/web/venv/lib/python3.11/site-packages/django/utils/log.py   None
27/Nov/2024 16:32:03    WARNING    log    Not Found: /media/images/appartment/photo_2024-09-12_21-08-19.jpg   /home/alprostov/PycharmProjects/sakhlis/web/venv/lib/python3.11/site-packages/django/utils/log.py   None
27/Nov/2024 16:32:03    WARNING    basehttp    "GET /media/images/appartment/photo_2024-09-16_21-41-10.jpg HTTP/1.1" 404 19630   /home/alprostov/PycharmProjects/sakhlis/web/venv/lib/python3.11/site-packages/django/core/servers/basehttp.py   None
27/Nov/2024 16:32:03    WARNING    basehttp    "GET /media/images/appartment/photo_2024-09-12_21-08-19.jpg HTTP/1.1" 404 19630   /home/alprostov/PycharmProjects/sakhlis/web/venv/lib/python3.11/site-packages/django/core/servers/basehttp.py   None
27/Nov/2024 16:32:03    WARNING    log    Not Found: /media/images/appartment/photo_2024-09-20_17-39-16.jpg   /home/alprostov/PycharmProjects/sakhlis/web/venv/lib/python3.11/site-packages/django/utils/log.py   None
27/Nov/2024 16:32:03    WARNING    basehttp    "GET /media/images/appartment/photo_2024-09-20_17-39-16.jpg HTTP/1.1" 404 19630   /home/alprostov/PycharmProjects/sakhlis/web/venv/lib/python3.11/site-packages/django/core/servers/basehttp.py   None
27/Nov/2024 16:32:03    WARNING    log    Not Found: /media/images/appartment/photo_2024-09-12_20-59-28.jpg   /home/alprostov/PycharmProjects/sakhlis/web/venv/lib/python3.11/site-packages/django/utils/log.py   None
27/Nov/2024 16:32:03    WARNING    basehttp    "GET /media/images/appartment/photo_2024-09-12_20-59-28.jpg HTTP/1.1" 404 19630   /home/alprostov/PycharmProjects/sakhlis/web/venv/lib/python3.11/site-packages/django/core/servers/basehttp.py   None
27/Nov/2024 16:32:03    WARNING    log    Not Found: /media/images/appartment/photo_2024-09-22_12-15-37.jpg   /home/alprostov/PycharmProjects/sakhlis/web/venv/lib/python3.11/site-packages/django/utils/log.py   None
27/Nov/2024 16:32:03    WARNING    basehttp    "GET /media/images/appartment/photo_2024-09-22_12-15-37.jpg HTTP/1.1" 404 19630   /home/alprostov/PycharmProjects/sakhlis/web/venv/lib/python3.11/site-packages/django/core/servers/basehttp.py   None
27/Nov/2024 16:32:03    WARNING    log    Not Found: /media/images/appartment/photo_2024-09-13_20-52-44.jpg   /home/alprostov/PycharmProjects/sakhlis/web/venv/lib/python3.11/site-packages/django/utils/log.py   None
27/Nov/2024 16:32:03    WARNING    basehttp    "GET /media/images/appartment/photo_2024-09-13_20-52-44.jpg HTTP/1.1" 404 19630   /home/alprostov/PycharmProjects/sakhlis/web/venv/lib/python3.11/site-packages/django/core/servers/basehttp.py   None
27/Nov/2024 16:32:03    WARNING    log    Not Found: /media/images/appartment/photo_2024-09-16_21-23-19.jpg   /home/alprostov/PycharmProjects/sakhlis/web/venv/lib/python3.11/site-packages/django/utils/log.py   None
27/Nov/2024 16:32:03    WARNING    basehttp    "GET /media/images/appartment/photo_2024-09-16_21-23-19.jpg HTTP/1.1" 404 19630   /home/alprostov/PycharmProjects/sakhlis/web/venv/lib/python3.11/site-packages/django/core/servers/basehttp.py   None
27/Nov/2024 16:32:03    WARNING    log    Not Found: /media/images/appartment/236.jpg   /home/alprostov/PycharmProjects/sakhlis/web/venv/lib/python3.11/site-packages/django/utils/log.py   None
27/Nov/2024 16:32:03    WARNING    log    Not Found: /media/images/appartment/photo_2024-09-16_21-48-59.jpg   /home/alprostov/PycharmProjects/sakhlis/web/venv/lib/python3.11/site-packages/django/utils/log.py   None
27/Nov/2024 16:32:03    WARNING    basehttp    "GET /media/images/appartment/236.jpg HTTP/1.1" 404 19520   /home/alprostov/PycharmProjects/sakhlis/web/venv/lib/python3.11/site-packages/django/core/servers/basehttp.py   None
27/Nov/2024 16:32:03    WARNING    basehttp    "GET /media/images/appartment/photo_2024-09-16_21-48-59.jpg HTTP/1.1" 404 19630   /home/alprostov/PycharmProjects/sakhlis/web/venv/lib/python3.11/site-packages/django/core/servers/basehttp.py   None
27/Nov/2024 16:32:03    WARNING    log    Not Found: /media/images/appartment/photo_2024-09-20_16-37-55.jpg   /home/alprostov/PycharmProjects/sakhlis/web/venv/lib/python3.11/site-packages/django/utils/log.py   None
27/Nov/2024 16:32:03    WARNING    basehttp    "GET /media/images/appartment/photo_2024-09-20_16-37-55.jpg HTTP/1.1" 404 19630   /home/alprostov/PycharmProjects/sakhlis/web/venv/lib/python3.11/site-packages/django/core/servers/basehttp.py   None
27/Nov/2024 16:32:03    WARNING    log    Not Found: /media/images/appartment/photo_2024-09-13_20-50-02.jpg   /home/alprostov/PycharmProjects/sakhlis/web/venv/lib/python3.11/site-packages/django/utils/log.py   None
27/Nov/2024 16:32:03    WARNING    basehttp    "GET /media/images/appartment/photo_2024-09-13_20-50-02.jpg HTTP/1.1" 404 19630   /home/alprostov/PycharmProjects/sakhlis/web/venv/lib/python3.11/site-packages/django/core/servers/basehttp.py   None
27/Nov/2024 16:32:03    WARNING    log    Not Found: /media/images/appartment/2718.jpg   /home/alprostov/PycharmProjects/sakhlis/web/venv/lib/python3.11/site-packages/django/utils/log.py   None
27/Nov/2024 16:32:03    WARNING    basehttp    "GET /media/images/appartment/2718.jpg HTTP/1.1" 404 19525   /home/alprostov/PycharmProjects/sakhlis/web/venv/lib/python3.11/site-packages/django/core/servers/basehttp.py   None
27/Nov/2024 16:32:03    WARNING    log    Not Found: /media/images/appartment/2679.jpg   /home/alprostov/PycharmProjects/sakhlis/web/venv/lib/python3.11/site-packages/django/utils/log.py   None
27/Nov/2024 16:32:03    WARNING    basehttp    "GET /media/images/appartment/2679.jpg HTTP/1.1" 404 19525   /home/alprostov/PycharmProjects/sakhlis/web/venv/lib/python3.11/site-packages/django/core/servers/basehttp.py   None
27/Nov/2024 16:32:03    WARNING    log    Not Found: /media/images/appartment/photo_2024-09-12_21-08-19_jbnLNP4.jpg   /home/alprostov/PycharmProjects/sakhlis/web/venv/lib/python3.11/site-packages/django/utils/log.py   None
27/Nov/2024 16:32:03    WARNING    basehttp    "GET /media/images/appartment/photo_2024-09-12_21-08-19_jbnLNP4.jpg HTTP/1.1" 404 19670   /home/alprostov/PycharmProjects/sakhlis/web/venv/lib/python3.11/site-packages/django/core/servers/basehttp.py   None
28/Nov/2024 17:31:44    WARNING    log    Not Found: /favicon.ico   /home/alprostov/PycharmProjects/sakhlis/web/venv/lib/python3.11/site-packages/django/utils/log.py   None
28/Nov/2024 17:31:44    WARNING    basehttp    "GET /favicon.ico HTTP/1.1" 404 19223   /home/alprostov/PycharmProjects/sakhlis/web/venv/lib/python3.11/site-packages/django/core/servers/basehttp.py   None
28/Nov/2024 17:41:34    WARNING    basehttp    "GET /static/js/bootstrap.min.js.map HTTP/1.1" 404 1828   /home/alprostov/PycharmProjects/sakhlis/web/venv/lib/python3.11/site-packages/django/core/servers/basehttp.py   None
28/Nov/2024 17:41:34    WARNING    basehttp    "GET /static/css/bootstrap.min.css.map HTTP/1.1" 404 1834   /home/alprostov/PycharmProjects/sakhlis/web/venv/lib/python3.11/site-packages/django/core/servers/basehttp.py   None
28/Nov/2024 20:46:11    WARNING    log    Not Found: /favicon.ico   /home/alprostov/PycharmProjects/sakhlis/web/venv/lib/python3.11/site-packages/django/utils/log.py   None
28/Nov/2024 20:46:11    WARNING    basehttp    "GET /favicon.ico HTTP/1.1" 404 19402   /home/alprostov/PycharmProjects/sakhlis/web/venv/lib/python3.11/site-packages/django/core/servers/basehttp.py   None
28/Nov/2024 21:21:07    WARNING    log    Not Found: /favicon.ico   /home/alprostov/PycharmProjects/sakhlis/web/venv/lib/python3.11/site-packages/django/utils/log.py   None
28/Nov/2024 21:21:07    WARNING    basehttp    "GET /favicon.ico HTTP/1.1" 404 19402   /home/alprostov/PycharmProjects/sakhlis/web/venv/lib/python3.11/site-packages/django/core/servers/basehttp.py   None
29/Nov/2024 18:06:45    WARNING    log    Not Found: /favicon.ico   /home/alprostov/PycharmProjects/sakhlis/web/venv/lib/python3.11/site-packages/django/utils/log.py   None
29/Nov/2024 18:06:45    WARNING    basehttp    "GET /favicon.ico HTTP/1.1" 404 19572   /home/alprostov/PycharmProjects/sakhlis/web/venv/lib/python3.11/site-packages/django/core/servers/basehttp.py   None
29/Nov/2024 18:07:12    ERROR    log    Internal Server Error: /corporate   /home/alprostov/PycharmProjects/sakhlis/web/venv/lib/python3.11/site-packages/django/utils/log.py   (<class 'django.template.exceptions.TemplateDoesNotExist'>, TemplateDoesNotExist('cbusiness.html'), <traceback object at 0x7fe30497a1c0>)
Traceback (most recent call last):
  File "/home/alprostov/PycharmProjects/sakhlis/web/venv/lib/python3.11/site-packages/django/core/handlers/exception.py", line 55, in inner
    response = get_response(request)
               ^^^^^^^^^^^^^^^^^^^^^
  File "/home/alprostov/PycharmProjects/sakhlis/web/venv/lib/python3.11/site-packages/django/core/handlers/base.py", line 220, in _get_response
    response = response.render()
               ^^^^^^^^^^^^^^^^^
  File "/home/alprostov/PycharmProjects/sakhlis/web/venv/lib/python3.11/site-packages/django/template/response.py", line 111, in render
    self.content = self.rendered_content
                   ^^^^^^^^^^^^^^^^^^^^^
  File "/home/alprostov/PycharmProjects/sakhlis/web/venv/lib/python3.11/site-packages/django/template/response.py", line 87, in rendered_content
    template = self.resolve_template(self.template_name)
               ^^^^^^^^^^^^^^^^^^^^^^^^^^^^^^^^^^^^^^^^^
  File "/home/alprostov/PycharmProjects/sakhlis/web/venv/lib/python3.11/site-packages/django/template/response.py", line 69, in resolve_template
    return select_template(template, using=self.using)
           ^^^^^^^^^^^^^^^^^^^^^^^^^^^^^^^^^^^^^^^^^^^
  File "/home/alprostov/PycharmProjects/sakhlis/web/venv/lib/python3.11/site-packages/django/template/loader.py", line 47, in select_template
    raise TemplateDoesNotExist(", ".join(template_name_list), chain=chain)
django.template.exceptions.TemplateDoesNotExist: cbusiness.html
29/Nov/2024 18:07:12    ERROR    basehttp    "GET /corporate HTTP/1.1" 500 97608   /home/alprostov/PycharmProjects/sakhlis/web/venv/lib/python3.11/site-packages/django/core/servers/basehttp.py   None
29/Nov/2024 18:07:13    ERROR    log    Internal Server Error: /corporate   /home/alprostov/PycharmProjects/sakhlis/web/venv/lib/python3.11/site-packages/django/utils/log.py   (<class 'django.template.exceptions.TemplateDoesNotExist'>, TemplateDoesNotExist('cbusiness.html'), <traceback object at 0x7fe2fdbb9a00>)
Traceback (most recent call last):
  File "/home/alprostov/PycharmProjects/sakhlis/web/venv/lib/python3.11/site-packages/django/core/handlers/exception.py", line 55, in inner
    response = get_response(request)
               ^^^^^^^^^^^^^^^^^^^^^
  File "/home/alprostov/PycharmProjects/sakhlis/web/venv/lib/python3.11/site-packages/django/core/handlers/base.py", line 220, in _get_response
    response = response.render()
               ^^^^^^^^^^^^^^^^^
  File "/home/alprostov/PycharmProjects/sakhlis/web/venv/lib/python3.11/site-packages/django/template/response.py", line 111, in render
    self.content = self.rendered_content
                   ^^^^^^^^^^^^^^^^^^^^^
  File "/home/alprostov/PycharmProjects/sakhlis/web/venv/lib/python3.11/site-packages/django/template/response.py", line 87, in rendered_content
    template = self.resolve_template(self.template_name)
               ^^^^^^^^^^^^^^^^^^^^^^^^^^^^^^^^^^^^^^^^^
  File "/home/alprostov/PycharmProjects/sakhlis/web/venv/lib/python3.11/site-packages/django/template/response.py", line 69, in resolve_template
    return select_template(template, using=self.using)
           ^^^^^^^^^^^^^^^^^^^^^^^^^^^^^^^^^^^^^^^^^^^
  File "/home/alprostov/PycharmProjects/sakhlis/web/venv/lib/python3.11/site-packages/django/template/loader.py", line 47, in select_template
    raise TemplateDoesNotExist(", ".join(template_name_list), chain=chain)
django.template.exceptions.TemplateDoesNotExist: cbusiness.html
29/Nov/2024 18:07:13    ERROR    basehttp    "GET /corporate HTTP/1.1" 500 97608   /home/alprostov/PycharmProjects/sakhlis/web/venv/lib/python3.11/site-packages/django/core/servers/basehttp.py   None
29/Nov/2024 18:07:13    ERROR    log    Internal Server Error: /corporate   /home/alprostov/PycharmProjects/sakhlis/web/venv/lib/python3.11/site-packages/django/utils/log.py   (<class 'django.template.exceptions.TemplateDoesNotExist'>, TemplateDoesNotExist('cbusiness.html'), <traceback object at 0x7fe2fd135a40>)
Traceback (most recent call last):
  File "/home/alprostov/PycharmProjects/sakhlis/web/venv/lib/python3.11/site-packages/django/core/handlers/exception.py", line 55, in inner
    response = get_response(request)
               ^^^^^^^^^^^^^^^^^^^^^
  File "/home/alprostov/PycharmProjects/sakhlis/web/venv/lib/python3.11/site-packages/django/core/handlers/base.py", line 220, in _get_response
    response = response.render()
               ^^^^^^^^^^^^^^^^^
  File "/home/alprostov/PycharmProjects/sakhlis/web/venv/lib/python3.11/site-packages/django/template/response.py", line 111, in render
    self.content = self.rendered_content
                   ^^^^^^^^^^^^^^^^^^^^^
  File "/home/alprostov/PycharmProjects/sakhlis/web/venv/lib/python3.11/site-packages/django/template/response.py", line 87, in rendered_content
    template = self.resolve_template(self.template_name)
               ^^^^^^^^^^^^^^^^^^^^^^^^^^^^^^^^^^^^^^^^^
  File "/home/alprostov/PycharmProjects/sakhlis/web/venv/lib/python3.11/site-packages/django/template/response.py", line 69, in resolve_template
    return select_template(template, using=self.using)
           ^^^^^^^^^^^^^^^^^^^^^^^^^^^^^^^^^^^^^^^^^^^
  File "/home/alprostov/PycharmProjects/sakhlis/web/venv/lib/python3.11/site-packages/django/template/loader.py", line 47, in select_template
    raise TemplateDoesNotExist(", ".join(template_name_list), chain=chain)
django.template.exceptions.TemplateDoesNotExist: cbusiness.html
29/Nov/2024 18:07:13    ERROR    basehttp    "GET /corporate HTTP/1.1" 500 97608   /home/alprostov/PycharmProjects/sakhlis/web/venv/lib/python3.11/site-packages/django/core/servers/basehttp.py   None
29/Nov/2024 18:07:14    ERROR    log    Internal Server Error: /corporate   /home/alprostov/PycharmProjects/sakhlis/web/venv/lib/python3.11/site-packages/django/utils/log.py   (<class 'django.template.exceptions.TemplateDoesNotExist'>, TemplateDoesNotExist('cbusiness.html'), <traceback object at 0x7fe2fd1b8540>)
Traceback (most recent call last):
  File "/home/alprostov/PycharmProjects/sakhlis/web/venv/lib/python3.11/site-packages/django/core/handlers/exception.py", line 55, in inner
    response = get_response(request)
               ^^^^^^^^^^^^^^^^^^^^^
  File "/home/alprostov/PycharmProjects/sakhlis/web/venv/lib/python3.11/site-packages/django/core/handlers/base.py", line 220, in _get_response
    response = response.render()
               ^^^^^^^^^^^^^^^^^
  File "/home/alprostov/PycharmProjects/sakhlis/web/venv/lib/python3.11/site-packages/django/template/response.py", line 111, in render
    self.content = self.rendered_content
                   ^^^^^^^^^^^^^^^^^^^^^
  File "/home/alprostov/PycharmProjects/sakhlis/web/venv/lib/python3.11/site-packages/django/template/response.py", line 87, in rendered_content
    template = self.resolve_template(self.template_name)
               ^^^^^^^^^^^^^^^^^^^^^^^^^^^^^^^^^^^^^^^^^
  File "/home/alprostov/PycharmProjects/sakhlis/web/venv/lib/python3.11/site-packages/django/template/response.py", line 69, in resolve_template
    return select_template(template, using=self.using)
           ^^^^^^^^^^^^^^^^^^^^^^^^^^^^^^^^^^^^^^^^^^^
  File "/home/alprostov/PycharmProjects/sakhlis/web/venv/lib/python3.11/site-packages/django/template/loader.py", line 47, in select_template
    raise TemplateDoesNotExist(", ".join(template_name_list), chain=chain)
django.template.exceptions.TemplateDoesNotExist: cbusiness.html
29/Nov/2024 18:07:14    ERROR    basehttp    "GET /corporate HTTP/1.1" 500 97608   /home/alprostov/PycharmProjects/sakhlis/web/venv/lib/python3.11/site-packages/django/core/servers/basehttp.py   None
29/Nov/2024 18:07:14    ERROR    log    Internal Server Error: /corporate   /home/alprostov/PycharmProjects/sakhlis/web/venv/lib/python3.11/site-packages/django/utils/log.py   (<class 'django.template.exceptions.TemplateDoesNotExist'>, TemplateDoesNotExist('cbusiness.html'), <traceback object at 0x7fe2fd02a840>)
Traceback (most recent call last):
  File "/home/alprostov/PycharmProjects/sakhlis/web/venv/lib/python3.11/site-packages/django/core/handlers/exception.py", line 55, in inner
    response = get_response(request)
               ^^^^^^^^^^^^^^^^^^^^^
  File "/home/alprostov/PycharmProjects/sakhlis/web/venv/lib/python3.11/site-packages/django/core/handlers/base.py", line 220, in _get_response
    response = response.render()
               ^^^^^^^^^^^^^^^^^
  File "/home/alprostov/PycharmProjects/sakhlis/web/venv/lib/python3.11/site-packages/django/template/response.py", line 111, in render
    self.content = self.rendered_content
                   ^^^^^^^^^^^^^^^^^^^^^
  File "/home/alprostov/PycharmProjects/sakhlis/web/venv/lib/python3.11/site-packages/django/template/response.py", line 87, in rendered_content
    template = self.resolve_template(self.template_name)
               ^^^^^^^^^^^^^^^^^^^^^^^^^^^^^^^^^^^^^^^^^
  File "/home/alprostov/PycharmProjects/sakhlis/web/venv/lib/python3.11/site-packages/django/template/response.py", line 69, in resolve_template
    return select_template(template, using=self.using)
           ^^^^^^^^^^^^^^^^^^^^^^^^^^^^^^^^^^^^^^^^^^^
  File "/home/alprostov/PycharmProjects/sakhlis/web/venv/lib/python3.11/site-packages/django/template/loader.py", line 47, in select_template
    raise TemplateDoesNotExist(", ".join(template_name_list), chain=chain)
django.template.exceptions.TemplateDoesNotExist: cbusiness.html
29/Nov/2024 18:07:14    ERROR    basehttp    "GET /corporate HTTP/1.1" 500 97608   /home/alprostov/PycharmProjects/sakhlis/web/venv/lib/python3.11/site-packages/django/core/servers/basehttp.py   None
29/Nov/2024 20:50:25    ERROR    log    Internal Server Error: /   /home/alprostov/PycharmProjects/sakhlis/web/venv/lib/python3.11/site-packages/django/utils/log.py   (<class 'django.template.exceptions.TemplateSyntaxError'>, TemplateSyntaxError("Invalid block tag on line 37: 'static'. Did you forget to register or load this tag?"), <traceback object at 0x7fcffe724a00>)
Traceback (most recent call last):
  File "/home/alprostov/PycharmProjects/sakhlis/web/venv/lib/python3.11/site-packages/django/template/base.py", line 505, in parse
    compile_func = self.tags[command]
                   ~~~~~~~~~^^^^^^^^^
KeyError: 'static'

During handling of the above exception, another exception occurred:

Traceback (most recent call last):
  File "/home/alprostov/PycharmProjects/sakhlis/web/venv/lib/python3.11/site-packages/django/core/handlers/exception.py", line 55, in inner
    response = get_response(request)
               ^^^^^^^^^^^^^^^^^^^^^
  File "/home/alprostov/PycharmProjects/sakhlis/web/venv/lib/python3.11/site-packages/django/core/handlers/base.py", line 220, in _get_response
    response = response.render()
               ^^^^^^^^^^^^^^^^^
  File "/home/alprostov/PycharmProjects/sakhlis/web/venv/lib/python3.11/site-packages/django/template/response.py", line 111, in render
    self.content = self.rendered_content
                   ^^^^^^^^^^^^^^^^^^^^^
  File "/home/alprostov/PycharmProjects/sakhlis/web/venv/lib/python3.11/site-packages/django/template/response.py", line 89, in rendered_content
    return template.render(context, self._request)
           ^^^^^^^^^^^^^^^^^^^^^^^^^^^^^^^^^^^^^^^
  File "/home/alprostov/PycharmProjects/sakhlis/web/venv/lib/python3.11/site-packages/django/template/backends/django.py", line 61, in render
    return self.template.render(context)
           ^^^^^^^^^^^^^^^^^^^^^^^^^^^^^
  File "/home/alprostov/PycharmProjects/sakhlis/web/venv/lib/python3.11/site-packages/django/template/base.py", line 175, in render
    return self._render(context)
           ^^^^^^^^^^^^^^^^^^^^^
  File "/home/alprostov/PycharmProjects/sakhlis/web/venv/lib/python3.11/site-packages/django/test/utils.py", line 112, in instrumented_test_render
    return self.nodelist.render(context)
           ^^^^^^^^^^^^^^^^^^^^^^^^^^^^^
  File "/home/alprostov/PycharmProjects/sakhlis/web/venv/lib/python3.11/site-packages/django/template/base.py", line 1005, in render
    return SafeString("".join([node.render_annotated(context) for node in self]))
                              ^^^^^^^^^^^^^^^^^^^^^^^^^^^^^^^^^^^^^^^^^^^^^^^^^
  File "/home/alprostov/PycharmProjects/sakhlis/web/venv/lib/python3.11/site-packages/django/template/base.py", line 1005, in <listcomp>
    return SafeString("".join([node.render_annotated(context) for node in self]))
                               ^^^^^^^^^^^^^^^^^^^^^^^^^^^^^^
  File "/home/alprostov/PycharmProjects/sakhlis/web/venv/lib/python3.11/site-packages/django/template/base.py", line 966, in render_annotated
    return self.render(context)
           ^^^^^^^^^^^^^^^^^^^^
  File "/home/alprostov/PycharmProjects/sakhlis/web/venv/lib/python3.11/site-packages/slippers/templatetags/slippers.py", line 102, in render
    template = context.template.engine.get_template(self.template_path)
               ^^^^^^^^^^^^^^^^^^^^^^^^^^^^^^^^^^^^^^^^^^^^^^^^^^^^^^^^
  File "/home/alprostov/PycharmProjects/sakhlis/web/venv/lib/python3.11/site-packages/django/template/engine.py", line 175, in get_template
    template, origin = self.find_template(template_name)
                       ^^^^^^^^^^^^^^^^^^^^^^^^^^^^^^^^^
  File "/home/alprostov/PycharmProjects/sakhlis/web/venv/lib/python3.11/site-packages/django/template/engine.py", line 157, in find_template
    template = loader.get_template(name, skip=skip)
               ^^^^^^^^^^^^^^^^^^^^^^^^^^^^^^^^^^^^
  File "/home/alprostov/PycharmProjects/sakhlis/web/venv/lib/python3.11/site-packages/django/template/loaders/cached.py", line 57, in get_template
    template = super().get_template(template_name, skip)
               ^^^^^^^^^^^^^^^^^^^^^^^^^^^^^^^^^^^^^^^^^
  File "/home/alprostov/PycharmProjects/sakhlis/web/venv/lib/python3.11/site-packages/django/template/loaders/base.py", line 28, in get_template
    return Template(
           ^^^^^^^^^
  File "/home/alprostov/PycharmProjects/sakhlis/web/venv/lib/python3.11/site-packages/django/template/base.py", line 154, in __init__
    self.nodelist = self.compile_nodelist()
                    ^^^^^^^^^^^^^^^^^^^^^^^
  File "/home/alprostov/PycharmProjects/sakhlis/web/venv/lib/python3.11/site-packages/django/template/base.py", line 200, in compile_nodelist
    return parser.parse()
           ^^^^^^^^^^^^^^
  File "/home/alprostov/PycharmProjects/sakhlis/web/venv/lib/python3.11/site-packages/django/template/base.py", line 507, in parse
    self.invalid_block_tag(token, command, parse_until)
  File "/home/alprostov/PycharmProjects/sakhlis/web/venv/lib/python3.11/site-packages/django/template/base.py", line 568, in invalid_block_tag
    raise self.error(
django.template.exceptions.TemplateSyntaxError: Invalid block tag on line 37: 'static'. Did you forget to register or load this tag?
29/Nov/2024 20:50:25    ERROR    basehttp    "GET / HTTP/1.1" 500 181728   /home/alprostov/PycharmProjects/sakhlis/web/venv/lib/python3.11/site-packages/django/core/servers/basehttp.py   None
30/Nov/2024 07:13:30    WARNING    log    Not Found: /favicon.ico   /home/alprostov/PycharmProjects/sakhlis/web/venv/lib/python3.11/site-packages/django/utils/log.py   None
30/Nov/2024 07:13:30    WARNING    basehttp    "GET /favicon.ico HTTP/1.1" 404 19572   /home/alprostov/PycharmProjects/sakhlis/web/venv/lib/python3.11/site-packages/django/core/servers/basehttp.py   None
30/Nov/2024 12:13:13    WARNING    log    Not Found: /favicon.ico   /home/alprostov/PycharmProjects/sakhlis/web/venv/lib/python3.11/site-packages/django/utils/log.py   None
30/Nov/2024 12:13:13    WARNING    basehttp    "GET /favicon.ico HTTP/1.1" 404 19572   /home/alprostov/PycharmProjects/sakhlis/web/venv/lib/python3.11/site-packages/django/core/servers/basehttp.py   None
30/Nov/2024 12:24:50    ERROR    log    Internal Server Error: /createorder   /home/alprostov/PycharmProjects/sakhlis/web/venv/lib/python3.11/site-packages/django/utils/log.py   (<class 'TypeError'>, TypeError('Object of type set is not JSON serializable'), <traceback object at 0x7fc7e95182c0>)
Traceback (most recent call last):
  File "/home/alprostov/PycharmProjects/sakhlis/web/venv/lib/python3.11/site-packages/django/core/handlers/exception.py", line 55, in inner
    response = get_response(request)
               ^^^^^^^^^^^^^^^^^^^^^
  File "/home/alprostov/PycharmProjects/sakhlis/web/venv/lib/python3.11/site-packages/django/core/handlers/base.py", line 197, in _get_response
    response = wrapped_callback(request, *callback_args, **callback_kwargs)
               ^^^^^^^^^^^^^^^^^^^^^^^^^^^^^^^^^^^^^^^^^^^^^^^^^^^^^^^^^^^^
  File "/home/alprostov/PycharmProjects/sakhlis/web/venv/lib/python3.11/site-packages/django/views/generic/base.py", line 104, in view
    return self.dispatch(request, *args, **kwargs)
           ^^^^^^^^^^^^^^^^^^^^^^^^^^^^^^^^^^^^^^^
  File "/home/alprostov/PycharmProjects/sakhlis/web/venv/lib/python3.11/site-packages/django/views/generic/base.py", line 143, in dispatch
    return handler(request, *args, **kwargs)
           ^^^^^^^^^^^^^^^^^^^^^^^^^^^^^^^^^
  File "/home/alprostov/PycharmProjects/sakhlis/web/venv/lib/python3.11/site-packages/django/views/generic/edit.py", line 184, in post
    return super().post(request, *args, **kwargs)
           ^^^^^^^^^^^^^^^^^^^^^^^^^^^^^^^^^^^^^^
  File "/home/alprostov/PycharmProjects/sakhlis/web/venv/lib/python3.11/site-packages/django/views/generic/edit.py", line 153, in post
    return self.form_valid(form)
           ^^^^^^^^^^^^^^^^^^^^^
  File "/home/alprostov/PycharmProjects/sakhlis/web/app_site/views.py", line 250, in form_valid
    return JsonResponse({'message': {form.instance.pk},
           ^^^^^^^^^^^^^^^^^^^^^^^^^^^^^^^^^^^^^^^^^^^^
  File "/home/alprostov/PycharmProjects/sakhlis/web/venv/lib/python3.11/site-packages/django/http/response.py", line 748, in __init__
    data = json.dumps(data, cls=encoder, **json_dumps_params)
           ^^^^^^^^^^^^^^^^^^^^^^^^^^^^^^^^^^^^^^^^^^^^^^^^^^
  File "/usr/lib/python3.11/json/__init__.py", line 238, in dumps
    **kw).encode(obj)
          ^^^^^^^^^^^
  File "/usr/lib/python3.11/json/encoder.py", line 200, in encode
    chunks = self.iterencode(o, _one_shot=True)
             ^^^^^^^^^^^^^^^^^^^^^^^^^^^^^^^^^^
  File "/usr/lib/python3.11/json/encoder.py", line 258, in iterencode
    return _iterencode(o, 0)
           ^^^^^^^^^^^^^^^^^
  File "/home/alprostov/PycharmProjects/sakhlis/web/venv/lib/python3.11/site-packages/django/core/serializers/json.py", line 106, in default
    return super().default(o)
           ^^^^^^^^^^^^^^^^^^
  File "/usr/lib/python3.11/json/encoder.py", line 180, in default
    raise TypeError(f'Object of type {o.__class__.__name__} '
TypeError: Object of type set is not JSON serializable
30/Nov/2024 12:24:50    ERROR    basehttp    "POST /createorder HTTP/1.1" 500 133417   /home/alprostov/PycharmProjects/sakhlis/web/venv/lib/python3.11/site-packages/django/core/servers/basehttp.py   None
30/Nov/2024 12:25:45    ERROR    log    Internal Server Error: /createorder   /home/alprostov/PycharmProjects/sakhlis/web/venv/lib/python3.11/site-packages/django/utils/log.py   (<class 'TypeError'>, TypeError('Object of type set is not JSON serializable'), <traceback object at 0x7fc7e8b61c00>)
Traceback (most recent call last):
  File "/home/alprostov/PycharmProjects/sakhlis/web/venv/lib/python3.11/site-packages/django/core/handlers/exception.py", line 55, in inner
    response = get_response(request)
               ^^^^^^^^^^^^^^^^^^^^^
  File "/home/alprostov/PycharmProjects/sakhlis/web/venv/lib/python3.11/site-packages/django/core/handlers/base.py", line 197, in _get_response
    response = wrapped_callback(request, *callback_args, **callback_kwargs)
               ^^^^^^^^^^^^^^^^^^^^^^^^^^^^^^^^^^^^^^^^^^^^^^^^^^^^^^^^^^^^
  File "/home/alprostov/PycharmProjects/sakhlis/web/venv/lib/python3.11/site-packages/django/views/generic/base.py", line 104, in view
    return self.dispatch(request, *args, **kwargs)
           ^^^^^^^^^^^^^^^^^^^^^^^^^^^^^^^^^^^^^^^
  File "/home/alprostov/PycharmProjects/sakhlis/web/venv/lib/python3.11/site-packages/django/views/generic/base.py", line 143, in dispatch
    return handler(request, *args, **kwargs)
           ^^^^^^^^^^^^^^^^^^^^^^^^^^^^^^^^^
  File "/home/alprostov/PycharmProjects/sakhlis/web/venv/lib/python3.11/site-packages/django/views/generic/edit.py", line 184, in post
    return super().post(request, *args, **kwargs)
           ^^^^^^^^^^^^^^^^^^^^^^^^^^^^^^^^^^^^^^
  File "/home/alprostov/PycharmProjects/sakhlis/web/venv/lib/python3.11/site-packages/django/views/generic/edit.py", line 153, in post
    return self.form_valid(form)
           ^^^^^^^^^^^^^^^^^^^^^
  File "/home/alprostov/PycharmProjects/sakhlis/web/app_site/views.py", line 250, in form_valid
    return JsonResponse({'message': {form.instance.pk},
           ^^^^^^^^^^^^^^^^^^^^^^^^^^^^^^^^^^^^^^^^^^^^
  File "/home/alprostov/PycharmProjects/sakhlis/web/venv/lib/python3.11/site-packages/django/http/response.py", line 748, in __init__
    data = json.dumps(data, cls=encoder, **json_dumps_params)
           ^^^^^^^^^^^^^^^^^^^^^^^^^^^^^^^^^^^^^^^^^^^^^^^^^^
  File "/usr/lib/python3.11/json/__init__.py", line 238, in dumps
    **kw).encode(obj)
          ^^^^^^^^^^^
  File "/usr/lib/python3.11/json/encoder.py", line 200, in encode
    chunks = self.iterencode(o, _one_shot=True)
             ^^^^^^^^^^^^^^^^^^^^^^^^^^^^^^^^^^
  File "/usr/lib/python3.11/json/encoder.py", line 258, in iterencode
    return _iterencode(o, 0)
           ^^^^^^^^^^^^^^^^^
  File "/home/alprostov/PycharmProjects/sakhlis/web/venv/lib/python3.11/site-packages/django/core/serializers/json.py", line 106, in default
    return super().default(o)
           ^^^^^^^^^^^^^^^^^^
  File "/usr/lib/python3.11/json/encoder.py", line 180, in default
    raise TypeError(f'Object of type {o.__class__.__name__} '
TypeError: Object of type set is not JSON serializable
30/Nov/2024 12:25:45    ERROR    basehttp    "POST /createorder HTTP/1.1" 500 133411   /home/alprostov/PycharmProjects/sakhlis/web/venv/lib/python3.11/site-packages/django/core/servers/basehttp.py   None
30/Nov/2024 13:06:03    WARNING    log    Not Found: /favicon.ico   /home/alprostov/PycharmProjects/sakhlis/web/venv/lib/python3.11/site-packages/django/utils/log.py   None
30/Nov/2024 13:06:03    WARNING    basehttp    "GET /favicon.ico HTTP/1.1" 404 19573   /home/alprostov/PycharmProjects/sakhlis/web/venv/lib/python3.11/site-packages/django/core/servers/basehttp.py   None
30/Nov/2024 13:58:12    WARNING    basehttp    "GET /static/images/5_png HTTP/1.1" 404 1795   /home/alprostov/PycharmProjects/sakhlis/web/venv/lib/python3.11/site-packages/django/core/servers/basehttp.py   None
30/Nov/2024 13:58:12    WARNING    basehttp    "GET /static/images/5_png HTTP/1.1" 404 1795   /home/alprostov/PycharmProjects/sakhlis/web/venv/lib/python3.11/site-packages/django/core/servers/basehttp.py   None
30/Nov/2024 13:58:13    WARNING    basehttp    "GET /static/images/5_png HTTP/1.1" 404 1795   /home/alprostov/PycharmProjects/sakhlis/web/venv/lib/python3.11/site-packages/django/core/servers/basehttp.py   None
30/Nov/2024 13:58:13    WARNING    basehttp    "GET /static/images/5_png HTTP/1.1" 404 1795   /home/alprostov/PycharmProjects/sakhlis/web/venv/lib/python3.11/site-packages/django/core/servers/basehttp.py   None
30/Nov/2024 13:58:22    WARNING    basehttp    "GET /static/images/5_png HTTP/1.1" 404 1795   /home/alprostov/PycharmProjects/sakhlis/web/venv/lib/python3.11/site-packages/django/core/servers/basehttp.py   None
30/Nov/2024 13:58:22    WARNING    basehttp    "GET /static/images/5_png HTTP/1.1" 404 1795   /home/alprostov/PycharmProjects/sakhlis/web/venv/lib/python3.11/site-packages/django/core/servers/basehttp.py   None
30/Nov/2024 13:59:02    WARNING    basehttp    "GET /static/images/5_png HTTP/1.1" 404 1795   /home/alprostov/PycharmProjects/sakhlis/web/venv/lib/python3.11/site-packages/django/core/servers/basehttp.py   None
30/Nov/2024 13:59:06    WARNING    basehttp    "GET /static/images/5_png HTTP/1.1" 404 1795   /home/alprostov/PycharmProjects/sakhlis/web/venv/lib/python3.11/site-packages/django/core/servers/basehttp.py   None
30/Nov/2024 14:14:53    WARNING    log    Not Found: /favicon.ico   /home/alprostov/PycharmProjects/sakhlis/web/venv/lib/python3.11/site-packages/django/utils/log.py   None
30/Nov/2024 14:14:53    WARNING    basehttp    "GET /favicon.ico HTTP/1.1" 404 19572   /home/alprostov/PycharmProjects/sakhlis/web/venv/lib/python3.11/site-packages/django/core/servers/basehttp.py   None
30/Nov/2024 15:11:01    WARNING    log    Not Found: /favicon.ico   /home/alprostov/PycharmProjects/sakhlis/web/venv/lib/python3.11/site-packages/django/utils/log.py   None
30/Nov/2024 15:11:01    WARNING    basehttp    "GET /favicon.ico HTTP/1.1" 404 19572   /home/alprostov/PycharmProjects/sakhlis/web/venv/lib/python3.11/site-packages/django/core/servers/basehttp.py   None
02/Dec/2024 18:06:31    WARNING    log    Not Found: /favicon.ico   /home/alprostov/PycharmProjects/sakhlis/web/venv/lib/python3.11/site-packages/django/utils/log.py   None
02/Dec/2024 18:06:31    WARNING    basehttp    "GET /favicon.ico HTTP/1.1" 404 19746   /home/alprostov/PycharmProjects/sakhlis/web/venv/lib/python3.11/site-packages/django/core/servers/basehttp.py   None
02/Dec/2024 18:13:10    WARNING    log    Forbidden (CSRF token missing.): /sendoffer   /home/alprostov/PycharmProjects/sakhlis/web/venv/lib/python3.11/site-packages/django/utils/log.py   None
02/Dec/2024 18:13:10    WARNING    basehttp    "POST /sendoffer HTTP/1.1" 403 11807   /home/alprostov/PycharmProjects/sakhlis/web/venv/lib/python3.11/site-packages/django/core/servers/basehttp.py   None
02/Dec/2024 18:13:54    WARNING    log    Forbidden (CSRF token missing.): /sendoffer   /home/alprostov/PycharmProjects/sakhlis/web/venv/lib/python3.11/site-packages/django/utils/log.py   None
02/Dec/2024 18:13:54    WARNING    basehttp    "POST /sendoffer HTTP/1.1" 403 11807   /home/alprostov/PycharmProjects/sakhlis/web/venv/lib/python3.11/site-packages/django/core/servers/basehttp.py   None
02/Dec/2024 18:13:58    WARNING    log    Forbidden (CSRF token missing.): /sendoffer   /home/alprostov/PycharmProjects/sakhlis/web/venv/lib/python3.11/site-packages/django/utils/log.py   None
02/Dec/2024 18:13:58    WARNING    basehttp    "POST /sendoffer HTTP/1.1" 403 11807   /home/alprostov/PycharmProjects/sakhlis/web/venv/lib/python3.11/site-packages/django/core/servers/basehttp.py   None
02/Dec/2024 18:14:06    ERROR    log    Internal Server Error: /sendoffer   /home/alprostov/PycharmProjects/sakhlis/web/venv/lib/python3.11/site-packages/django/utils/log.py   (<class 'ValueError'>, ValueError("The view app_site.views.view didn't return an HttpResponse object. It returned None instead."), <traceback object at 0x7f7065db82c0>)
Traceback (most recent call last):
  File "/home/alprostov/PycharmProjects/sakhlis/web/venv/lib/python3.11/site-packages/django/core/handlers/exception.py", line 55, in inner
    response = get_response(request)
               ^^^^^^^^^^^^^^^^^^^^^
  File "/home/alprostov/PycharmProjects/sakhlis/web/venv/lib/python3.11/site-packages/django/core/handlers/base.py", line 204, in _get_response
    self.check_response(response, callback)
  File "/home/alprostov/PycharmProjects/sakhlis/web/venv/lib/python3.11/site-packages/django/core/handlers/base.py", line 332, in check_response
    raise ValueError(
ValueError: The view app_site.views.view didn't return an HttpResponse object. It returned None instead.
02/Dec/2024 18:14:06    ERROR    basehttp    "POST /sendoffer HTTP/1.1" 500 82628   /home/alprostov/PycharmProjects/sakhlis/web/venv/lib/python3.11/site-packages/django/core/servers/basehttp.py   None
02/Dec/2024 18:15:07    ERROR    log    Internal Server Error: /sendoffer   /home/alprostov/PycharmProjects/sakhlis/web/venv/lib/python3.11/site-packages/django/utils/log.py   (<class 'ValueError'>, ValueError("The view app_site.views.view didn't return an HttpResponse object. It returned None instead."), <traceback object at 0x7fd9d40c5c40>)
Traceback (most recent call last):
  File "/home/alprostov/PycharmProjects/sakhlis/web/venv/lib/python3.11/site-packages/django/core/handlers/exception.py", line 55, in inner
    response = get_response(request)
               ^^^^^^^^^^^^^^^^^^^^^
  File "/home/alprostov/PycharmProjects/sakhlis/web/venv/lib/python3.11/site-packages/django/core/handlers/base.py", line 204, in _get_response
    self.check_response(response, callback)
  File "/home/alprostov/PycharmProjects/sakhlis/web/venv/lib/python3.11/site-packages/django/core/handlers/base.py", line 332, in check_response
    raise ValueError(
ValueError: The view app_site.views.view didn't return an HttpResponse object. It returned None instead.
02/Dec/2024 18:15:07    ERROR    basehttp    "POST /sendoffer HTTP/1.1" 500 82634   /home/alprostov/PycharmProjects/sakhlis/web/venv/lib/python3.11/site-packages/django/core/servers/basehttp.py   None
02/Dec/2024 18:15:26    ERROR    log    Internal Server Error: /sendoffer   /home/alprostov/PycharmProjects/sakhlis/web/venv/lib/python3.11/site-packages/django/utils/log.py   (<class 'KeyError'>, KeyError('formset'), <traceback object at 0x7f1e91d8ae80>)
Traceback (most recent call last):
  File "/home/alprostov/PycharmProjects/sakhlis/web/venv/lib/python3.11/site-packages/django/core/handlers/exception.py", line 55, in inner
    response = get_response(request)
               ^^^^^^^^^^^^^^^^^^^^^
  File "/home/alprostov/PycharmProjects/sakhlis/web/venv/lib/python3.11/site-packages/django/core/handlers/base.py", line 197, in _get_response
    response = wrapped_callback(request, *callback_args, **callback_kwargs)
               ^^^^^^^^^^^^^^^^^^^^^^^^^^^^^^^^^^^^^^^^^^^^^^^^^^^^^^^^^^^^
  File "/home/alprostov/PycharmProjects/sakhlis/web/venv/lib/python3.11/site-packages/django/views/generic/base.py", line 104, in view
    return self.dispatch(request, *args, **kwargs)
           ^^^^^^^^^^^^^^^^^^^^^^^^^^^^^^^^^^^^^^^
  File "/home/alprostov/PycharmProjects/sakhlis/web/venv/lib/python3.11/site-packages/django/views/generic/base.py", line 143, in dispatch
    return handler(request, *args, **kwargs)
           ^^^^^^^^^^^^^^^^^^^^^^^^^^^^^^^^^
  File "/home/alprostov/PycharmProjects/sakhlis/web/app_site/views.py", line 439, in post
    print(kwargs['formset'])
          ~~~~~~^^^^^^^^^^^
KeyError: 'formset'
02/Dec/2024 18:15:26    ERROR    basehttp    "POST /sendoffer HTTP/1.1" 500 91175   /home/alprostov/PycharmProjects/sakhlis/web/venv/lib/python3.11/site-packages/django/core/servers/basehttp.py   None
02/Dec/2024 18:16:21    ERROR    log    Internal Server Error: /sendoffer   /home/alprostov/PycharmProjects/sakhlis/web/venv/lib/python3.11/site-packages/django/utils/log.py   (<class 'ValueError'>, ValueError("The view app_site.views.view didn't return an HttpResponse object. It returned None instead."), <traceback object at 0x7f333d7e1200>)
Traceback (most recent call last):
  File "/home/alprostov/PycharmProjects/sakhlis/web/venv/lib/python3.11/site-packages/django/core/handlers/exception.py", line 55, in inner
    response = get_response(request)
               ^^^^^^^^^^^^^^^^^^^^^
  File "/home/alprostov/PycharmProjects/sakhlis/web/venv/lib/python3.11/site-packages/django/core/handlers/base.py", line 204, in _get_response
    self.check_response(response, callback)
  File "/home/alprostov/PycharmProjects/sakhlis/web/venv/lib/python3.11/site-packages/django/core/handlers/base.py", line 332, in check_response
    raise ValueError(
ValueError: The view app_site.views.view didn't return an HttpResponse object. It returned None instead.
02/Dec/2024 18:16:21    ERROR    basehttp    "POST /sendoffer HTTP/1.1" 500 82633   /home/alprostov/PycharmProjects/sakhlis/web/venv/lib/python3.11/site-packages/django/core/servers/basehttp.py   None
02/Dec/2024 18:16:59    ERROR    log    Internal Server Error: /sendoffer   /home/alprostov/PycharmProjects/sakhlis/web/venv/lib/python3.11/site-packages/django/utils/log.py   (<class 'ValueError'>, ValueError("The view app_site.views.view didn't return an HttpResponse object. It returned None instead."), <traceback object at 0x7f72eb558980>)
Traceback (most recent call last):
  File "/home/alprostov/PycharmProjects/sakhlis/web/venv/lib/python3.11/site-packages/django/core/handlers/exception.py", line 55, in inner
    response = get_response(request)
               ^^^^^^^^^^^^^^^^^^^^^
  File "/home/alprostov/PycharmProjects/sakhlis/web/venv/lib/python3.11/site-packages/django/core/handlers/base.py", line 204, in _get_response
    self.check_response(response, callback)
  File "/home/alprostov/PycharmProjects/sakhlis/web/venv/lib/python3.11/site-packages/django/core/handlers/base.py", line 332, in check_response
    raise ValueError(
ValueError: The view app_site.views.view didn't return an HttpResponse object. It returned None instead.
02/Dec/2024 18:17:00    ERROR    basehttp    "POST /sendoffer HTTP/1.1" 500 82633   /home/alprostov/PycharmProjects/sakhlis/web/venv/lib/python3.11/site-packages/django/core/servers/basehttp.py   None
02/Dec/2024 18:26:20    ERROR    log    Internal Server Error: /sendoffer   /home/alprostov/PycharmProjects/sakhlis/web/venv/lib/python3.11/site-packages/django/utils/log.py   (<class 'KeyError'>, KeyError('pk'), <traceback object at 0x7f03c0b2d100>)
Traceback (most recent call last):
  File "/home/alprostov/PycharmProjects/sakhlis/web/venv/lib/python3.11/site-packages/django/core/handlers/exception.py", line 55, in inner
    response = get_response(request)
               ^^^^^^^^^^^^^^^^^^^^^
  File "/home/alprostov/PycharmProjects/sakhlis/web/venv/lib/python3.11/site-packages/django/core/handlers/base.py", line 197, in _get_response
    response = wrapped_callback(request, *callback_args, **callback_kwargs)
               ^^^^^^^^^^^^^^^^^^^^^^^^^^^^^^^^^^^^^^^^^^^^^^^^^^^^^^^^^^^^
  File "/home/alprostov/PycharmProjects/sakhlis/web/venv/lib/python3.11/site-packages/django/views/generic/base.py", line 104, in view
    return self.dispatch(request, *args, **kwargs)
           ^^^^^^^^^^^^^^^^^^^^^^^^^^^^^^^^^^^^^^^
  File "/home/alprostov/PycharmProjects/sakhlis/web/venv/lib/python3.11/site-packages/django/views/generic/base.py", line 143, in dispatch
    return handler(request, *args, **kwargs)
           ^^^^^^^^^^^^^^^^^^^^^^^^^^^^^^^^^
  File "/home/alprostov/PycharmProjects/sakhlis/web/app_site/views.py", line 440, in post
    send_email(self.request.POST['email'],
  File "/home/alprostov/PycharmProjects/sakhlis/web/venv/lib/python3.11/site-packages/celery/local.py", line 188, in __call__
    return self._get_current_object()(*a, **kw)
           ^^^^^^^^^^^^^^^^^^^^^^^^^^^^^^^^^^^^
  File "/home/alprostov/PycharmProjects/sakhlis/web/venv/lib/python3.11/site-packages/celery/app/task.py", line 392, in __call__
    return self.run(*args, **kwargs)
           ^^^^^^^^^^^^^^^^^^^^^^^^^
  File "/home/alprostov/PycharmProjects/sakhlis/web/app_site/tasks.py", line 36, in send_email
    user_ = User.objects.get(pk=context_['pk'])
                                ~~~~~~~~^^^^^^
KeyError: 'pk'
02/Dec/2024 18:26:20    ERROR    basehttp    "POST /sendoffer HTTP/1.1" 500 103836   /home/alprostov/PycharmProjects/sakhlis/web/venv/lib/python3.11/site-packages/django/core/servers/basehttp.py   None
02/Dec/2024 18:29:09    ERROR    log    Internal Server Error: /sendoffer   /home/alprostov/PycharmProjects/sakhlis/web/venv/lib/python3.11/site-packages/django/utils/log.py   (<class 'NameError'>, NameError("name 'user_' is not defined"), <traceback object at 0x7f81a451ec00>)
Traceback (most recent call last):
  File "/home/alprostov/PycharmProjects/sakhlis/web/venv/lib/python3.11/site-packages/django/core/handlers/exception.py", line 55, in inner
    response = get_response(request)
               ^^^^^^^^^^^^^^^^^^^^^
  File "/home/alprostov/PycharmProjects/sakhlis/web/venv/lib/python3.11/site-packages/django/core/handlers/base.py", line 197, in _get_response
    response = wrapped_callback(request, *callback_args, **callback_kwargs)
               ^^^^^^^^^^^^^^^^^^^^^^^^^^^^^^^^^^^^^^^^^^^^^^^^^^^^^^^^^^^^
  File "/home/alprostov/PycharmProjects/sakhlis/web/venv/lib/python3.11/site-packages/django/views/generic/base.py", line 104, in view
    return self.dispatch(request, *args, **kwargs)
           ^^^^^^^^^^^^^^^^^^^^^^^^^^^^^^^^^^^^^^^
  File "/home/alprostov/PycharmProjects/sakhlis/web/venv/lib/python3.11/site-packages/django/views/generic/base.py", line 143, in dispatch
    return handler(request, *args, **kwargs)
           ^^^^^^^^^^^^^^^^^^^^^^^^^^^^^^^^^
  File "/home/alprostov/PycharmProjects/sakhlis/web/app_site/views.py", line 440, in post
    send_email(self.request.POST['email'],
  File "/home/alprostov/PycharmProjects/sakhlis/web/venv/lib/python3.11/site-packages/celery/local.py", line 188, in __call__
    return self._get_current_object()(*a, **kw)
           ^^^^^^^^^^^^^^^^^^^^^^^^^^^^^^^^^^^^
  File "/home/alprostov/PycharmProjects/sakhlis/web/venv/lib/python3.11/site-packages/celery/app/task.py", line 392, in __call__
    return self.run(*args, **kwargs)
           ^^^^^^^^^^^^^^^^^^^^^^^^^
  File "/home/alprostov/PycharmProjects/sakhlis/web/app_site/tasks.py", line 37, in send_email
    token=UserProfile.objects.get(user=user_).customer_name
                                       ^^^^^
NameError: name 'user_' is not defined
02/Dec/2024 18:29:09    ERROR    basehttp    "POST /sendoffer HTTP/1.1" 500 103946   /home/alprostov/PycharmProjects/sakhlis/web/venv/lib/python3.11/site-packages/django/core/servers/basehttp.py   None
02/Dec/2024 18:29:33    ERROR    log    Internal Server Error: /sendoffer   /home/alprostov/PycharmProjects/sakhlis/web/venv/lib/python3.11/site-packages/django/utils/log.py   (<class 'NameError'>, NameError("name 'user_' is not defined"), <traceback object at 0x7f819cdba580>)
Traceback (most recent call last):
  File "/home/alprostov/PycharmProjects/sakhlis/web/venv/lib/python3.11/site-packages/django/core/handlers/exception.py", line 55, in inner
    response = get_response(request)
               ^^^^^^^^^^^^^^^^^^^^^
  File "/home/alprostov/PycharmProjects/sakhlis/web/venv/lib/python3.11/site-packages/django/core/handlers/base.py", line 197, in _get_response
    response = wrapped_callback(request, *callback_args, **callback_kwargs)
               ^^^^^^^^^^^^^^^^^^^^^^^^^^^^^^^^^^^^^^^^^^^^^^^^^^^^^^^^^^^^
  File "/home/alprostov/PycharmProjects/sakhlis/web/venv/lib/python3.11/site-packages/django/views/generic/base.py", line 104, in view
    return self.dispatch(request, *args, **kwargs)
           ^^^^^^^^^^^^^^^^^^^^^^^^^^^^^^^^^^^^^^^
  File "/home/alprostov/PycharmProjects/sakhlis/web/venv/lib/python3.11/site-packages/django/views/generic/base.py", line 143, in dispatch
    return handler(request, *args, **kwargs)
           ^^^^^^^^^^^^^^^^^^^^^^^^^^^^^^^^^
  File "/home/alprostov/PycharmProjects/sakhlis/web/app_site/views.py", line 440, in post
    send_email(self.request.POST['email'],
  File "/home/alprostov/PycharmProjects/sakhlis/web/venv/lib/python3.11/site-packages/celery/local.py", line 188, in __call__
    return self._get_current_object()(*a, **kw)
           ^^^^^^^^^^^^^^^^^^^^^^^^^^^^^^^^^^^^
  File "/home/alprostov/PycharmProjects/sakhlis/web/venv/lib/python3.11/site-packages/celery/app/task.py", line 392, in __call__
    return self.run(*args, **kwargs)
           ^^^^^^^^^^^^^^^^^^^^^^^^^
  File "/home/alprostov/PycharmProjects/sakhlis/web/app_site/tasks.py", line 37, in send_email
    token=UserProfile.objects.get(user=user_).customer_name
                                       ^^^^^
NameError: name 'user_' is not defined
02/Dec/2024 18:29:33    ERROR    basehttp    "POST /sendoffer HTTP/1.1" 500 103948   /home/alprostov/PycharmProjects/sakhlis/web/venv/lib/python3.11/site-packages/django/core/servers/basehttp.py   None
02/Dec/2024 18:30:51    ERROR    log    Internal Server Error: /sendoffer   /home/alprostov/PycharmProjects/sakhlis/web/venv/lib/python3.11/site-packages/django/utils/log.py   (<class 'ValueError'>, ValueError("The view app_site.views.view didn't return an HttpResponse object. It returned None instead."), <traceback object at 0x7f4867d282c0>)
Traceback (most recent call last):
  File "/home/alprostov/PycharmProjects/sakhlis/web/venv/lib/python3.11/site-packages/django/core/handlers/exception.py", line 55, in inner
    response = get_response(request)
               ^^^^^^^^^^^^^^^^^^^^^
  File "/home/alprostov/PycharmProjects/sakhlis/web/venv/lib/python3.11/site-packages/django/core/handlers/base.py", line 204, in _get_response
    self.check_response(response, callback)
  File "/home/alprostov/PycharmProjects/sakhlis/web/venv/lib/python3.11/site-packages/django/core/handlers/base.py", line 332, in check_response
    raise ValueError(
ValueError: The view app_site.views.view didn't return an HttpResponse object. It returned None instead.
02/Dec/2024 18:30:51    ERROR    basehttp    "POST /sendoffer HTTP/1.1" 500 82675   /home/alprostov/PycharmProjects/sakhlis/web/venv/lib/python3.11/site-packages/django/core/servers/basehttp.py   None
02/Dec/2024 18:32:38    ERROR    log    Internal Server Error: /sendoffer   /home/alprostov/PycharmProjects/sakhlis/web/venv/lib/python3.11/site-packages/django/utils/log.py   (<class 'ValueError'>, ValueError("The view app_site.views.view didn't return an HttpResponse object. It returned None instead."), <traceback object at 0x7f1f75de7c40>)
Traceback (most recent call last):
  File "/home/alprostov/PycharmProjects/sakhlis/web/venv/lib/python3.11/site-packages/django/core/handlers/exception.py", line 55, in inner
    response = get_response(request)
               ^^^^^^^^^^^^^^^^^^^^^
  File "/home/alprostov/PycharmProjects/sakhlis/web/venv/lib/python3.11/site-packages/django/core/handlers/base.py", line 204, in _get_response
    self.check_response(response, callback)
  File "/home/alprostov/PycharmProjects/sakhlis/web/venv/lib/python3.11/site-packages/django/core/handlers/base.py", line 332, in check_response
    raise ValueError(
ValueError: The view app_site.views.view didn't return an HttpResponse object. It returned None instead.
02/Dec/2024 18:32:38    ERROR    basehttp    "POST /sendoffer HTTP/1.1" 500 82677   /home/alprostov/PycharmProjects/sakhlis/web/venv/lib/python3.11/site-packages/django/core/servers/basehttp.py   None
02/Dec/2024 18:33:19    ERROR    log    Internal Server Error: /sendoffer   /home/alprostov/PycharmProjects/sakhlis/web/venv/lib/python3.11/site-packages/django/utils/log.py   (<class 'ValueError'>, ValueError("The view app_site.views.view didn't return an HttpResponse object. It returned None instead."), <traceback object at 0x7f1f67549180>)
Traceback (most recent call last):
  File "/home/alprostov/PycharmProjects/sakhlis/web/venv/lib/python3.11/site-packages/django/core/handlers/exception.py", line 55, in inner
    response = get_response(request)
               ^^^^^^^^^^^^^^^^^^^^^
  File "/home/alprostov/PycharmProjects/sakhlis/web/venv/lib/python3.11/site-packages/django/core/handlers/base.py", line 204, in _get_response
    self.check_response(response, callback)
  File "/home/alprostov/PycharmProjects/sakhlis/web/venv/lib/python3.11/site-packages/django/core/handlers/base.py", line 332, in check_response
    raise ValueError(
ValueError: The view app_site.views.view didn't return an HttpResponse object. It returned None instead.
02/Dec/2024 18:33:19    ERROR    basehttp    "POST /sendoffer HTTP/1.1" 500 82675   /home/alprostov/PycharmProjects/sakhlis/web/venv/lib/python3.11/site-packages/django/core/servers/basehttp.py   None
02/Dec/2024 18:35:05    ERROR    log    Internal Server Error: /sendoffer   /home/alprostov/PycharmProjects/sakhlis/web/venv/lib/python3.11/site-packages/django/utils/log.py   (<class 'ValueError'>, ValueError("The view app_site.views.view didn't return an HttpResponse object. It returned None instead."), <traceback object at 0x7f07f5aafd00>)
Traceback (most recent call last):
  File "/home/alprostov/PycharmProjects/sakhlis/web/venv/lib/python3.11/site-packages/django/core/handlers/exception.py", line 55, in inner
    response = get_response(request)
               ^^^^^^^^^^^^^^^^^^^^^
  File "/home/alprostov/PycharmProjects/sakhlis/web/venv/lib/python3.11/site-packages/django/core/handlers/base.py", line 204, in _get_response
    self.check_response(response, callback)
  File "/home/alprostov/PycharmProjects/sakhlis/web/venv/lib/python3.11/site-packages/django/core/handlers/base.py", line 332, in check_response
    raise ValueError(
ValueError: The view app_site.views.view didn't return an HttpResponse object. It returned None instead.
02/Dec/2024 18:35:05    ERROR    basehttp    "POST /sendoffer HTTP/1.1" 500 82690   /home/alprostov/PycharmProjects/sakhlis/web/venv/lib/python3.11/site-packages/django/core/servers/basehttp.py   None
02/Dec/2024 18:37:17    ERROR    log    Internal Server Error: /sendoffer   /home/alprostov/PycharmProjects/sakhlis/web/venv/lib/python3.11/site-packages/django/utils/log.py   (<class 'socket.gaierror'>, gaierror(-3, 'Temporary failure in name resolution'), <traceback object at 0x7f5b611c3380>)
Traceback (most recent call last):
  File "/home/alprostov/PycharmProjects/sakhlis/web/venv/lib/python3.11/site-packages/django/core/handlers/exception.py", line 55, in inner
    response = get_response(request)
               ^^^^^^^^^^^^^^^^^^^^^
  File "/home/alprostov/PycharmProjects/sakhlis/web/venv/lib/python3.11/site-packages/django/core/handlers/base.py", line 197, in _get_response
    response = wrapped_callback(request, *callback_args, **callback_kwargs)
               ^^^^^^^^^^^^^^^^^^^^^^^^^^^^^^^^^^^^^^^^^^^^^^^^^^^^^^^^^^^^
  File "/home/alprostov/PycharmProjects/sakhlis/web/venv/lib/python3.11/site-packages/django/views/generic/base.py", line 104, in view
    return self.dispatch(request, *args, **kwargs)
           ^^^^^^^^^^^^^^^^^^^^^^^^^^^^^^^^^^^^^^^
  File "/home/alprostov/PycharmProjects/sakhlis/web/venv/lib/python3.11/site-packages/django/views/generic/base.py", line 143, in dispatch
    return handler(request, *args, **kwargs)
           ^^^^^^^^^^^^^^^^^^^^^^^^^^^^^^^^^
  File "/home/alprostov/PycharmProjects/sakhlis/web/app_site/views.py", line 440, in post
    send_email(self.request.POST['email'],
  File "/home/alprostov/PycharmProjects/sakhlis/web/venv/lib/python3.11/site-packages/celery/local.py", line 188, in __call__
    return self._get_current_object()(*a, **kw)
           ^^^^^^^^^^^^^^^^^^^^^^^^^^^^^^^^^^^^
  File "/home/alprostov/PycharmProjects/sakhlis/web/venv/lib/python3.11/site-packages/celery/app/task.py", line 392, in __call__
    return self.run(*args, **kwargs)
           ^^^^^^^^^^^^^^^^^^^^^^^^^
  File "/home/alprostov/PycharmProjects/sakhlis/web/app_site/tasks.py", line 49, in send_email
    msg.send()  # send email
    ^^^^^^^^^^
  File "/home/alprostov/PycharmProjects/sakhlis/web/venv/lib/python3.11/site-packages/django/core/mail/message.py", line 298, in send
    return self.get_connection(fail_silently).send_messages([self])
           ^^^^^^^^^^^^^^^^^^^^^^^^^^^^^^^^^^^^^^^^^^^^^^^^^^^^^^^^
  File "/home/alprostov/PycharmProjects/sakhlis/web/venv/lib/python3.11/site-packages/django/core/mail/backends/smtp.py", line 127, in send_messages
    new_conn_created = self.open()
                       ^^^^^^^^^^^
  File "/home/alprostov/PycharmProjects/sakhlis/web/venv/lib/python3.11/site-packages/django/core/mail/backends/smtp.py", line 85, in open
    self.connection = self.connection_class(
                      ^^^^^^^^^^^^^^^^^^^^^^
  File "/usr/lib/python3.11/smtplib.py", line 255, in __init__
    (code, msg) = self.connect(host, port)
                  ^^^^^^^^^^^^^^^^^^^^^^^^
  File "/usr/lib/python3.11/smtplib.py", line 341, in connect
    self.sock = self._get_socket(host, port, self.timeout)
                ^^^^^^^^^^^^^^^^^^^^^^^^^^^^^^^^^^^^^^^^^^
  File "/usr/lib/python3.11/smtplib.py", line 312, in _get_socket
    return socket.create_connection((host, port), timeout,
           ^^^^^^^^^^^^^^^^^^^^^^^^^^^^^^^^^^^^^^^^^^^^^^^
  File "/usr/lib/python3.11/socket.py", line 839, in create_connection
    for res in getaddrinfo(host, port, 0, SOCK_STREAM):
               ^^^^^^^^^^^^^^^^^^^^^^^^^^^^^^^^^^^^^^^
  File "/usr/lib/python3.11/socket.py", line 974, in getaddrinfo
    for res in _socket.getaddrinfo(host, port, family, type, proto, flags):
               ^^^^^^^^^^^^^^^^^^^^^^^^^^^^^^^^^^^^^^^^^^^^^^^^^^^^^^^^^^^
socket.gaierror: [Errno -3] Temporary failure in name resolution
02/Dec/2024 18:37:17    ERROR    basehttp    "POST /sendoffer HTTP/1.1" 500 142612   /home/alprostov/PycharmProjects/sakhlis/web/venv/lib/python3.11/site-packages/django/core/servers/basehttp.py   None
02/Dec/2024 18:38:14    ERROR    log    Internal Server Error: /sendoffer   /home/alprostov/PycharmProjects/sakhlis/web/venv/lib/python3.11/site-packages/django/utils/log.py   (<class 'ValueError'>, ValueError("The view app_site.views.view didn't return an HttpResponse object. It returned None instead."), <traceback object at 0x7f5b67bc9cc0>)
Traceback (most recent call last):
  File "/home/alprostov/PycharmProjects/sakhlis/web/venv/lib/python3.11/site-packages/django/core/handlers/exception.py", line 55, in inner
    response = get_response(request)
               ^^^^^^^^^^^^^^^^^^^^^
  File "/home/alprostov/PycharmProjects/sakhlis/web/venv/lib/python3.11/site-packages/django/core/handlers/base.py", line 204, in _get_response
    self.check_response(response, callback)
  File "/home/alprostov/PycharmProjects/sakhlis/web/venv/lib/python3.11/site-packages/django/core/handlers/base.py", line 332, in check_response
    raise ValueError(
ValueError: The view app_site.views.view didn't return an HttpResponse object. It returned None instead.
02/Dec/2024 18:38:14    ERROR    basehttp    "POST /sendoffer HTTP/1.1" 500 82690   /home/alprostov/PycharmProjects/sakhlis/web/venv/lib/python3.11/site-packages/django/core/servers/basehttp.py   None
02/Dec/2024 18:46:43    WARNING    log    Not Found: /favicon.ico   /home/alprostov/PycharmProjects/sakhlis/web/venv/lib/python3.11/site-packages/django/utils/log.py   None
02/Dec/2024 18:46:43    WARNING    basehttp    "GET /favicon.ico HTTP/1.1" 404 19746   /home/alprostov/PycharmProjects/sakhlis/web/venv/lib/python3.11/site-packages/django/core/servers/basehttp.py   None
02/Dec/2024 18:46:52    ERROR    log    Internal Server Error: /sendoffer   /home/alprostov/PycharmProjects/sakhlis/web/venv/lib/python3.11/site-packages/django/utils/log.py   (<class 'ValueError'>, ValueError("The view app_site.views.view didn't return an HttpResponse object. It returned None instead."), <traceback object at 0x7f5b606c66c0>)
Traceback (most recent call last):
  File "/home/alprostov/PycharmProjects/sakhlis/web/venv/lib/python3.11/site-packages/django/core/handlers/exception.py", line 55, in inner
    response = get_response(request)
               ^^^^^^^^^^^^^^^^^^^^^
  File "/home/alprostov/PycharmProjects/sakhlis/web/venv/lib/python3.11/site-packages/django/core/handlers/base.py", line 204, in _get_response
    self.check_response(response, callback)
  File "/home/alprostov/PycharmProjects/sakhlis/web/venv/lib/python3.11/site-packages/django/core/handlers/base.py", line 332, in check_response
    raise ValueError(
ValueError: The view app_site.views.view didn't return an HttpResponse object. It returned None instead.
02/Dec/2024 18:46:52    ERROR    basehttp    "POST /sendoffer HTTP/1.1" 500 82675   /home/alprostov/PycharmProjects/sakhlis/web/venv/lib/python3.11/site-packages/django/core/servers/basehttp.py   None
02/Dec/2024 19:07:19    ERROR    log    Internal Server Error: /sendoffer   /home/alprostov/PycharmProjects/sakhlis/web/venv/lib/python3.11/site-packages/django/utils/log.py   (<class 'ValueError'>, ValueError("The view app_site.views.view didn't return an HttpResponse object. It returned None instead."), <traceback object at 0x7fa4c03e3ac0>)
Traceback (most recent call last):
  File "/home/alprostov/PycharmProjects/sakhlis/web/venv/lib/python3.11/site-packages/django/core/handlers/exception.py", line 55, in inner
    response = get_response(request)
               ^^^^^^^^^^^^^^^^^^^^^
  File "/home/alprostov/PycharmProjects/sakhlis/web/venv/lib/python3.11/site-packages/django/core/handlers/base.py", line 204, in _get_response
    self.check_response(response, callback)
  File "/home/alprostov/PycharmProjects/sakhlis/web/venv/lib/python3.11/site-packages/django/core/handlers/base.py", line 332, in check_response
    raise ValueError(
ValueError: The view app_site.views.view didn't return an HttpResponse object. It returned None instead.
02/Dec/2024 19:07:19    ERROR    basehttp    "POST /sendoffer HTTP/1.1" 500 82676   /home/alprostov/PycharmProjects/sakhlis/web/venv/lib/python3.11/site-packages/django/core/servers/basehttp.py   None
