27/Nov/2024 08:56:51    ERROR    log    Internal Server Error: /list_order   /home/alprostov/PycharmProjects/sakhlis/web/venv/lib/python3.11/site-packages/django/utils/log.py   (<class 'TypeError'>, TypeError("'OrderFilter' object is not subscriptable"), <traceback object at 0x7f556b5d8940>)
Traceback (most recent call last):
  File "/home/alprostov/PycharmProjects/sakhlis/web/venv/lib/python3.11/site-packages/django/core/handlers/exception.py", line 55, in inner
    response = get_response(request)
               ^^^^^^^^^^^^^^^^^^^^^
  File "/home/alprostov/PycharmProjects/sakhlis/web/venv/lib/python3.11/site-packages/django/core/handlers/base.py", line 197, in _get_response
    response = wrapped_callback(request, *callback_args, **callback_kwargs)
               ^^^^^^^^^^^^^^^^^^^^^^^^^^^^^^^^^^^^^^^^^^^^^^^^^^^^^^^^^^^^
  File "/home/alprostov/PycharmProjects/sakhlis/web/venv/lib/python3.11/site-packages/django/views/generic/base.py", line 104, in view
    return self.dispatch(request, *args, **kwargs)
           ^^^^^^^^^^^^^^^^^^^^^^^^^^^^^^^^^^^^^^^
  File "/home/alprostov/PycharmProjects/sakhlis/web/venv/lib/python3.11/site-packages/django/contrib/auth/mixins.py", line 73, in dispatch
    return super().dispatch(request, *args, **kwargs)
           ^^^^^^^^^^^^^^^^^^^^^^^^^^^^^^^^^^^^^^^^^^
  File "/home/alprostov/PycharmProjects/sakhlis/web/venv/lib/python3.11/site-packages/django/views/generic/base.py", line 143, in dispatch
    return handler(request, *args, **kwargs)
           ^^^^^^^^^^^^^^^^^^^^^^^^^^^^^^^^^
  File "/home/alprostov/PycharmProjects/sakhlis/web/venv/lib/python3.11/site-packages/django/views/generic/list.py", line 174, in get
    context = self.get_context_data()
              ^^^^^^^^^^^^^^^^^^^^^^^
  File "/home/alprostov/PycharmProjects/sakhlis/web/app_site/views.py", line 340, in get_context_data
    context['filterset'] = self.filterset[0:10]
                           ~~~~~~~~~~~~~~^^^^^^
TypeError: 'OrderFilter' object is not subscriptable
27/Nov/2024 08:56:51    ERROR    basehttp    "GET /list_order HTTP/1.1" 500 105971   /home/alprostov/PycharmProjects/sakhlis/web/venv/lib/python3.11/site-packages/django/core/servers/basehttp.py   None
27/Nov/2024 08:57:22    ERROR    log    Internal Server Error: /list_order   /home/alprostov/PycharmProjects/sakhlis/web/venv/lib/python3.11/site-packages/django/utils/log.py   (<class 'TypeError'>, TypeError("'OrderFilter' object is not subscriptable"), <traceback object at 0x7fbec0080700>)
Traceback (most recent call last):
  File "/home/alprostov/PycharmProjects/sakhlis/web/venv/lib/python3.11/site-packages/django/core/handlers/exception.py", line 55, in inner
    response = get_response(request)
               ^^^^^^^^^^^^^^^^^^^^^
  File "/home/alprostov/PycharmProjects/sakhlis/web/venv/lib/python3.11/site-packages/django/core/handlers/base.py", line 197, in _get_response
    response = wrapped_callback(request, *callback_args, **callback_kwargs)
               ^^^^^^^^^^^^^^^^^^^^^^^^^^^^^^^^^^^^^^^^^^^^^^^^^^^^^^^^^^^^
  File "/home/alprostov/PycharmProjects/sakhlis/web/venv/lib/python3.11/site-packages/django/views/generic/base.py", line 104, in view
    return self.dispatch(request, *args, **kwargs)
           ^^^^^^^^^^^^^^^^^^^^^^^^^^^^^^^^^^^^^^^
  File "/home/alprostov/PycharmProjects/sakhlis/web/venv/lib/python3.11/site-packages/django/contrib/auth/mixins.py", line 73, in dispatch
    return super().dispatch(request, *args, **kwargs)
           ^^^^^^^^^^^^^^^^^^^^^^^^^^^^^^^^^^^^^^^^^^
  File "/home/alprostov/PycharmProjects/sakhlis/web/venv/lib/python3.11/site-packages/django/views/generic/base.py", line 143, in dispatch
    return handler(request, *args, **kwargs)
           ^^^^^^^^^^^^^^^^^^^^^^^^^^^^^^^^^
  File "/home/alprostov/PycharmProjects/sakhlis/web/venv/lib/python3.11/site-packages/django/views/generic/list.py", line 154, in get
    self.object_list = self.get_queryset()
                       ^^^^^^^^^^^^^^^^^^^
  File "/home/alprostov/PycharmProjects/sakhlis/web/app_site/views.py", line 335, in get_queryset
    self.filterset = OrderFilter(self.request.GET, queryset)[0:10]
                     ~~~~~~~~~~~~~~~~~~~~~~~~~~~~~~~~~~~~~~~^^^^^^
TypeError: 'OrderFilter' object is not subscriptable
27/Nov/2024 08:57:22    ERROR    basehttp    "GET /list_order HTTP/1.1" 500 106134   /home/alprostov/PycharmProjects/sakhlis/web/venv/lib/python3.11/site-packages/django/core/servers/basehttp.py   None
27/Nov/2024 08:57:23    ERROR    log    Internal Server Error: /list_order   /home/alprostov/PycharmProjects/sakhlis/web/venv/lib/python3.11/site-packages/django/utils/log.py   (<class 'TypeError'>, TypeError("'OrderFilter' object is not subscriptable"), <traceback object at 0x7fbec01d4980>)
Traceback (most recent call last):
  File "/home/alprostov/PycharmProjects/sakhlis/web/venv/lib/python3.11/site-packages/django/core/handlers/exception.py", line 55, in inner
    response = get_response(request)
               ^^^^^^^^^^^^^^^^^^^^^
  File "/home/alprostov/PycharmProjects/sakhlis/web/venv/lib/python3.11/site-packages/django/core/handlers/base.py", line 197, in _get_response
    response = wrapped_callback(request, *callback_args, **callback_kwargs)
               ^^^^^^^^^^^^^^^^^^^^^^^^^^^^^^^^^^^^^^^^^^^^^^^^^^^^^^^^^^^^
  File "/home/alprostov/PycharmProjects/sakhlis/web/venv/lib/python3.11/site-packages/django/views/generic/base.py", line 104, in view
    return self.dispatch(request, *args, **kwargs)
           ^^^^^^^^^^^^^^^^^^^^^^^^^^^^^^^^^^^^^^^
  File "/home/alprostov/PycharmProjects/sakhlis/web/venv/lib/python3.11/site-packages/django/contrib/auth/mixins.py", line 73, in dispatch
    return super().dispatch(request, *args, **kwargs)
           ^^^^^^^^^^^^^^^^^^^^^^^^^^^^^^^^^^^^^^^^^^
  File "/home/alprostov/PycharmProjects/sakhlis/web/venv/lib/python3.11/site-packages/django/views/generic/base.py", line 143, in dispatch
    return handler(request, *args, **kwargs)
           ^^^^^^^^^^^^^^^^^^^^^^^^^^^^^^^^^
  File "/home/alprostov/PycharmProjects/sakhlis/web/venv/lib/python3.11/site-packages/django/views/generic/list.py", line 154, in get
    self.object_list = self.get_queryset()
                       ^^^^^^^^^^^^^^^^^^^
  File "/home/alprostov/PycharmProjects/sakhlis/web/app_site/views.py", line 335, in get_queryset
    self.filterset = OrderFilter(self.request.GET, queryset)[0:10]
                     ~~~~~~~~~~~~~~~~~~~~~~~~~~~~~~~~~~~~~~~^^^^^^
TypeError: 'OrderFilter' object is not subscriptable
27/Nov/2024 08:57:23    ERROR    basehttp    "GET /list_order HTTP/1.1" 500 106132   /home/alprostov/PycharmProjects/sakhlis/web/venv/lib/python3.11/site-packages/django/core/servers/basehttp.py   None
27/Nov/2024 08:57:46    WARNING    log    Not Found: /media/masters/unknown_person.jpg   /home/alprostov/PycharmProjects/sakhlis/web/venv/lib/python3.11/site-packages/django/utils/log.py   None
27/Nov/2024 08:57:46    WARNING    basehttp    "GET /media/masters/unknown_person.jpg HTTP/1.1" 404 19523   /home/alprostov/PycharmProjects/sakhlis/web/venv/lib/python3.11/site-packages/django/core/servers/basehttp.py   None
27/Nov/2024 08:59:44    WARNING    log    Not Found: /media/masters/unknown_person.jpg   /home/alprostov/PycharmProjects/sakhlis/web/venv/lib/python3.11/site-packages/django/utils/log.py   None
27/Nov/2024 08:59:44    WARNING    basehttp    "GET /media/masters/unknown_person.jpg HTTP/1.1" 404 19523   /home/alprostov/PycharmProjects/sakhlis/web/venv/lib/python3.11/site-packages/django/core/servers/basehttp.py   None
27/Nov/2024 08:59:45    WARNING    log    Not Found: /media/masters/unknown_person.jpg   /home/alprostov/PycharmProjects/sakhlis/web/venv/lib/python3.11/site-packages/django/utils/log.py   None
27/Nov/2024 08:59:45    WARNING    basehttp    "GET /media/masters/unknown_person.jpg HTTP/1.1" 404 19523   /home/alprostov/PycharmProjects/sakhlis/web/venv/lib/python3.11/site-packages/django/core/servers/basehttp.py   None
27/Nov/2024 09:13:11    WARNING    log    Not Found: /media/masters/unknown_person.jpg   /home/alprostov/PycharmProjects/sakhlis/web/venv/lib/python3.11/site-packages/django/utils/log.py   None
27/Nov/2024 09:13:11    WARNING    basehttp    "GET /media/masters/unknown_person.jpg HTTP/1.1" 404 19523   /home/alprostov/PycharmProjects/sakhlis/web/venv/lib/python3.11/site-packages/django/core/servers/basehttp.py   None
27/Nov/2024 09:13:18    WARNING    log    Not Found: /media/masters/unknown_person.jpg   /home/alprostov/PycharmProjects/sakhlis/web/venv/lib/python3.11/site-packages/django/utils/log.py   None
27/Nov/2024 09:13:18    WARNING    basehttp    "GET /media/masters/unknown_person.jpg HTTP/1.1" 404 19523   /home/alprostov/PycharmProjects/sakhlis/web/venv/lib/python3.11/site-packages/django/core/servers/basehttp.py   None
27/Nov/2024 09:13:19    WARNING    log    Not Found: /media/masters/unknown_person.jpg   /home/alprostov/PycharmProjects/sakhlis/web/venv/lib/python3.11/site-packages/django/utils/log.py   None
27/Nov/2024 09:13:19    WARNING    basehttp    "GET /media/masters/unknown_person.jpg HTTP/1.1" 404 19523   /home/alprostov/PycharmProjects/sakhlis/web/venv/lib/python3.11/site-packages/django/core/servers/basehttp.py   None
27/Nov/2024 09:13:20    WARNING    log    Not Found: /media/masters/unknown_person.jpg   /home/alprostov/PycharmProjects/sakhlis/web/venv/lib/python3.11/site-packages/django/utils/log.py   None
27/Nov/2024 09:13:20    WARNING    basehttp    "GET /media/masters/unknown_person.jpg HTTP/1.1" 404 19523   /home/alprostov/PycharmProjects/sakhlis/web/venv/lib/python3.11/site-packages/django/core/servers/basehttp.py   None
27/Nov/2024 09:13:20    WARNING    log    Not Found: /media/masters/unknown_person.jpg   /home/alprostov/PycharmProjects/sakhlis/web/venv/lib/python3.11/site-packages/django/utils/log.py   None
27/Nov/2024 09:13:20    WARNING    basehttp    "GET /media/masters/unknown_person.jpg HTTP/1.1" 404 19523   /home/alprostov/PycharmProjects/sakhlis/web/venv/lib/python3.11/site-packages/django/core/servers/basehttp.py   None
27/Nov/2024 09:13:20    WARNING    log    Not Found: /media/masters/unknown_person.jpg   /home/alprostov/PycharmProjects/sakhlis/web/venv/lib/python3.11/site-packages/django/utils/log.py   None
27/Nov/2024 09:13:20    WARNING    basehttp    "GET /media/masters/unknown_person.jpg HTTP/1.1" 404 19523   /home/alprostov/PycharmProjects/sakhlis/web/venv/lib/python3.11/site-packages/django/core/servers/basehttp.py   None
27/Nov/2024 09:13:37    WARNING    log    Not Found: /media/masters/unknown_person.jpg   /home/alprostov/PycharmProjects/sakhlis/web/venv/lib/python3.11/site-packages/django/utils/log.py   None
27/Nov/2024 09:13:37    WARNING    basehttp    "GET /media/masters/unknown_person.jpg HTTP/1.1" 404 19523   /home/alprostov/PycharmProjects/sakhlis/web/venv/lib/python3.11/site-packages/django/core/servers/basehttp.py   None
27/Nov/2024 09:31:47    WARNING    log    Not Found: /favicon.ico   /home/alprostov/PycharmProjects/sakhlis/web/venv/lib/python3.11/site-packages/django/utils/log.py   None
27/Nov/2024 09:31:47    WARNING    basehttp    "GET /favicon.ico HTTP/1.1" 404 19223   /home/alprostov/PycharmProjects/sakhlis/web/venv/lib/python3.11/site-packages/django/core/servers/basehttp.py   None
27/Nov/2024 12:19:44    WARNING    log    Not Found: /favicon.ico   /home/alprostov/PycharmProjects/sakhlis/web/venv/lib/python3.11/site-packages/django/utils/log.py   None
27/Nov/2024 12:19:44    WARNING    basehttp    "GET /favicon.ico HTTP/1.1" 404 19223   /home/alprostov/PycharmProjects/sakhlis/web/venv/lib/python3.11/site-packages/django/core/servers/basehttp.py   None
27/Nov/2024 12:20:16    WARNING    log    Not Found: /media/masters/unknown_person.jpg   /home/alprostov/PycharmProjects/sakhlis/web/venv/lib/python3.11/site-packages/django/utils/log.py   None
27/Nov/2024 12:20:16    WARNING    basehttp    "GET /media/masters/unknown_person.jpg HTTP/1.1" 404 19523   /home/alprostov/PycharmProjects/sakhlis/web/venv/lib/python3.11/site-packages/django/core/servers/basehttp.py   None
27/Nov/2024 12:20:23    WARNING    log    Not Found: /media/masters/unknown_person.jpg   /home/alprostov/PycharmProjects/sakhlis/web/venv/lib/python3.11/site-packages/django/utils/log.py   None
27/Nov/2024 12:20:23    WARNING    basehttp    "GET /media/masters/unknown_person.jpg HTTP/1.1" 404 19523   /home/alprostov/PycharmProjects/sakhlis/web/venv/lib/python3.11/site-packages/django/core/servers/basehttp.py   None
27/Nov/2024 12:20:44    WARNING    log    Not Found: /media/masters/unknown_person.jpg   /home/alprostov/PycharmProjects/sakhlis/web/venv/lib/python3.11/site-packages/django/utils/log.py   None
27/Nov/2024 12:20:44    WARNING    basehttp    "GET /media/masters/unknown_person.jpg HTTP/1.1" 404 19523   /home/alprostov/PycharmProjects/sakhlis/web/venv/lib/python3.11/site-packages/django/core/servers/basehttp.py   None
27/Nov/2024 16:25:30    WARNING    log    Not Found: /favicon.ico   /home/alprostov/PycharmProjects/sakhlis/web/venv/lib/python3.11/site-packages/django/utils/log.py   None
27/Nov/2024 16:25:30    WARNING    basehttp    "GET /favicon.ico HTTP/1.1" 404 19223   /home/alprostov/PycharmProjects/sakhlis/web/venv/lib/python3.11/site-packages/django/core/servers/basehttp.py   None
27/Nov/2024 16:25:38    WARNING    log    Not Found: /media/images/appartment/photo_2024-09-16_21-41-10.jpg   /home/alprostov/PycharmProjects/sakhlis/web/venv/lib/python3.11/site-packages/django/utils/log.py   None
27/Nov/2024 16:25:38    WARNING    basehttp    "GET /media/images/appartment/photo_2024-09-16_21-41-10.jpg HTTP/1.1" 404 19630   /home/alprostov/PycharmProjects/sakhlis/web/venv/lib/python3.11/site-packages/django/core/servers/basehttp.py   None
27/Nov/2024 16:25:38    WARNING    log    Not Found: /media/images/appartment/photo_2024-09-12_22-00-08.jpg   /home/alprostov/PycharmProjects/sakhlis/web/venv/lib/python3.11/site-packages/django/utils/log.py   None
27/Nov/2024 16:25:38    WARNING    log    Not Found: /media/images/appartment/photo_2024-09-20_17-39-16.jpg   /home/alprostov/PycharmProjects/sakhlis/web/venv/lib/python3.11/site-packages/django/utils/log.py   None
27/Nov/2024 16:25:38    WARNING    basehttp    "GET /media/images/appartment/photo_2024-09-12_22-00-08.jpg HTTP/1.1" 404 19630   /home/alprostov/PycharmProjects/sakhlis/web/venv/lib/python3.11/site-packages/django/core/servers/basehttp.py   None
27/Nov/2024 16:25:38    WARNING    basehttp    "GET /media/images/appartment/photo_2024-09-20_17-39-16.jpg HTTP/1.1" 404 19630   /home/alprostov/PycharmProjects/sakhlis/web/venv/lib/python3.11/site-packages/django/core/servers/basehttp.py   None
27/Nov/2024 16:25:39    WARNING    log    Not Found: /media/images/appartment/photo_2024-09-12_21-08-19.jpg   /home/alprostov/PycharmProjects/sakhlis/web/venv/lib/python3.11/site-packages/django/utils/log.py   None
27/Nov/2024 16:25:39    WARNING    basehttp    "GET /media/images/appartment/photo_2024-09-12_21-08-19.jpg HTTP/1.1" 404 19630   /home/alprostov/PycharmProjects/sakhlis/web/venv/lib/python3.11/site-packages/django/core/servers/basehttp.py   None
27/Nov/2024 16:25:39    WARNING    log    Not Found: /media/images/appartment/photo_2024-09-22_12-15-37.jpg   /home/alprostov/PycharmProjects/sakhlis/web/venv/lib/python3.11/site-packages/django/utils/log.py   None
27/Nov/2024 16:25:39    WARNING    basehttp    "GET /media/images/appartment/photo_2024-09-22_12-15-37.jpg HTTP/1.1" 404 19630   /home/alprostov/PycharmProjects/sakhlis/web/venv/lib/python3.11/site-packages/django/core/servers/basehttp.py   None
27/Nov/2024 16:25:39    WARNING    log    Not Found: /media/images/appartment/photo_2024-09-12_20-59-28.jpg   /home/alprostov/PycharmProjects/sakhlis/web/venv/lib/python3.11/site-packages/django/utils/log.py   None
27/Nov/2024 16:25:39    WARNING    basehttp    "GET /media/images/appartment/photo_2024-09-12_20-59-28.jpg HTTP/1.1" 404 19630   /home/alprostov/PycharmProjects/sakhlis/web/venv/lib/python3.11/site-packages/django/core/servers/basehttp.py   None
27/Nov/2024 16:25:39    WARNING    log    Not Found: /media/images/appartment/photo_2024-09-16_21-23-19.jpg   /home/alprostov/PycharmProjects/sakhlis/web/venv/lib/python3.11/site-packages/django/utils/log.py   None
27/Nov/2024 16:25:39    WARNING    basehttp    "GET /media/images/appartment/photo_2024-09-16_21-23-19.jpg HTTP/1.1" 404 19630   /home/alprostov/PycharmProjects/sakhlis/web/venv/lib/python3.11/site-packages/django/core/servers/basehttp.py   None
27/Nov/2024 16:25:39    WARNING    log    Not Found: /media/images/appartment/photo_2024-09-20_16-37-55.jpg   /home/alprostov/PycharmProjects/sakhlis/web/venv/lib/python3.11/site-packages/django/utils/log.py   None
27/Nov/2024 16:25:39    WARNING    basehttp    "GET /media/images/appartment/photo_2024-09-20_16-37-55.jpg HTTP/1.1" 404 19630   /home/alprostov/PycharmProjects/sakhlis/web/venv/lib/python3.11/site-packages/django/core/servers/basehttp.py   None
27/Nov/2024 16:25:39    WARNING    log    Not Found: /media/images/appartment/photo_2024-09-13_20-52-44.jpg   /home/alprostov/PycharmProjects/sakhlis/web/venv/lib/python3.11/site-packages/django/utils/log.py   None
27/Nov/2024 16:25:39    WARNING    basehttp    "GET /media/images/appartment/photo_2024-09-13_20-52-44.jpg HTTP/1.1" 404 19630   /home/alprostov/PycharmProjects/sakhlis/web/venv/lib/python3.11/site-packages/django/core/servers/basehttp.py   None
27/Nov/2024 16:25:39    WARNING    log    Not Found: /media/images/appartment/236.jpg   /home/alprostov/PycharmProjects/sakhlis/web/venv/lib/python3.11/site-packages/django/utils/log.py   None
27/Nov/2024 16:25:39    WARNING    basehttp    "GET /media/images/appartment/236.jpg HTTP/1.1" 404 19520   /home/alprostov/PycharmProjects/sakhlis/web/venv/lib/python3.11/site-packages/django/core/servers/basehttp.py   None
27/Nov/2024 16:25:39    WARNING    log    Not Found: /media/images/appartment/photo_2024-09-16_21-48-59.jpg   /home/alprostov/PycharmProjects/sakhlis/web/venv/lib/python3.11/site-packages/django/utils/log.py   None
27/Nov/2024 16:25:39    WARNING    basehttp    "GET /media/images/appartment/photo_2024-09-16_21-48-59.jpg HTTP/1.1" 404 19630   /home/alprostov/PycharmProjects/sakhlis/web/venv/lib/python3.11/site-packages/django/core/servers/basehttp.py   None
27/Nov/2024 16:25:39    WARNING    log    Not Found: /media/images/appartment/photo_2024-09-13_20-50-02.jpg   /home/alprostov/PycharmProjects/sakhlis/web/venv/lib/python3.11/site-packages/django/utils/log.py   None
27/Nov/2024 16:25:39    WARNING    basehttp    "GET /media/images/appartment/photo_2024-09-13_20-50-02.jpg HTTP/1.1" 404 19630   /home/alprostov/PycharmProjects/sakhlis/web/venv/lib/python3.11/site-packages/django/core/servers/basehttp.py   None
27/Nov/2024 16:25:39    WARNING    log    Not Found: /media/images/appartment/2679.jpg   /home/alprostov/PycharmProjects/sakhlis/web/venv/lib/python3.11/site-packages/django/utils/log.py   None
27/Nov/2024 16:25:39    WARNING    basehttp    "GET /media/images/appartment/2679.jpg HTTP/1.1" 404 19525   /home/alprostov/PycharmProjects/sakhlis/web/venv/lib/python3.11/site-packages/django/core/servers/basehttp.py   None
27/Nov/2024 16:25:39    WARNING    log    Not Found: /media/images/appartment/2718.jpg   /home/alprostov/PycharmProjects/sakhlis/web/venv/lib/python3.11/site-packages/django/utils/log.py   None
27/Nov/2024 16:25:39    WARNING    basehttp    "GET /media/images/appartment/2718.jpg HTTP/1.1" 404 19525   /home/alprostov/PycharmProjects/sakhlis/web/venv/lib/python3.11/site-packages/django/core/servers/basehttp.py   None
27/Nov/2024 16:25:39    WARNING    log    Not Found: /media/images/appartment/photo_2024-09-12_21-08-19_jbnLNP4.jpg   /home/alprostov/PycharmProjects/sakhlis/web/venv/lib/python3.11/site-packages/django/utils/log.py   None
27/Nov/2024 16:25:39    WARNING    basehttp    "GET /media/images/appartment/photo_2024-09-12_21-08-19_jbnLNP4.jpg HTTP/1.1" 404 19670   /home/alprostov/PycharmProjects/sakhlis/web/venv/lib/python3.11/site-packages/django/core/servers/basehttp.py   None
27/Nov/2024 16:32:03    WARNING    log    Not Found: /media/images/appartment/photo_2024-09-12_22-00-08.jpg   /home/alprostov/PycharmProjects/sakhlis/web/venv/lib/python3.11/site-packages/django/utils/log.py   None
27/Nov/2024 16:32:03    WARNING    basehttp    "GET /media/images/appartment/photo_2024-09-12_22-00-08.jpg HTTP/1.1" 404 19630   /home/alprostov/PycharmProjects/sakhlis/web/venv/lib/python3.11/site-packages/django/core/servers/basehttp.py   None
27/Nov/2024 16:32:03    WARNING    log    Not Found: /media/images/appartment/photo_2024-09-16_21-41-10.jpg   /home/alprostov/PycharmProjects/sakhlis/web/venv/lib/python3.11/site-packages/django/utils/log.py   None
27/Nov/2024 16:32:03    WARNING    log    Not Found: /media/images/appartment/photo_2024-09-12_21-08-19.jpg   /home/alprostov/PycharmProjects/sakhlis/web/venv/lib/python3.11/site-packages/django/utils/log.py   None
27/Nov/2024 16:32:03    WARNING    basehttp    "GET /media/images/appartment/photo_2024-09-16_21-41-10.jpg HTTP/1.1" 404 19630   /home/alprostov/PycharmProjects/sakhlis/web/venv/lib/python3.11/site-packages/django/core/servers/basehttp.py   None
27/Nov/2024 16:32:03    WARNING    basehttp    "GET /media/images/appartment/photo_2024-09-12_21-08-19.jpg HTTP/1.1" 404 19630   /home/alprostov/PycharmProjects/sakhlis/web/venv/lib/python3.11/site-packages/django/core/servers/basehttp.py   None
27/Nov/2024 16:32:03    WARNING    log    Not Found: /media/images/appartment/photo_2024-09-20_17-39-16.jpg   /home/alprostov/PycharmProjects/sakhlis/web/venv/lib/python3.11/site-packages/django/utils/log.py   None
27/Nov/2024 16:32:03    WARNING    basehttp    "GET /media/images/appartment/photo_2024-09-20_17-39-16.jpg HTTP/1.1" 404 19630   /home/alprostov/PycharmProjects/sakhlis/web/venv/lib/python3.11/site-packages/django/core/servers/basehttp.py   None
27/Nov/2024 16:32:03    WARNING    log    Not Found: /media/images/appartment/photo_2024-09-12_20-59-28.jpg   /home/alprostov/PycharmProjects/sakhlis/web/venv/lib/python3.11/site-packages/django/utils/log.py   None
27/Nov/2024 16:32:03    WARNING    basehttp    "GET /media/images/appartment/photo_2024-09-12_20-59-28.jpg HTTP/1.1" 404 19630   /home/alprostov/PycharmProjects/sakhlis/web/venv/lib/python3.11/site-packages/django/core/servers/basehttp.py   None
27/Nov/2024 16:32:03    WARNING    log    Not Found: /media/images/appartment/photo_2024-09-22_12-15-37.jpg   /home/alprostov/PycharmProjects/sakhlis/web/venv/lib/python3.11/site-packages/django/utils/log.py   None
27/Nov/2024 16:32:03    WARNING    basehttp    "GET /media/images/appartment/photo_2024-09-22_12-15-37.jpg HTTP/1.1" 404 19630   /home/alprostov/PycharmProjects/sakhlis/web/venv/lib/python3.11/site-packages/django/core/servers/basehttp.py   None
27/Nov/2024 16:32:03    WARNING    log    Not Found: /media/images/appartment/photo_2024-09-13_20-52-44.jpg   /home/alprostov/PycharmProjects/sakhlis/web/venv/lib/python3.11/site-packages/django/utils/log.py   None
27/Nov/2024 16:32:03    WARNING    basehttp    "GET /media/images/appartment/photo_2024-09-13_20-52-44.jpg HTTP/1.1" 404 19630   /home/alprostov/PycharmProjects/sakhlis/web/venv/lib/python3.11/site-packages/django/core/servers/basehttp.py   None
27/Nov/2024 16:32:03    WARNING    log    Not Found: /media/images/appartment/photo_2024-09-16_21-23-19.jpg   /home/alprostov/PycharmProjects/sakhlis/web/venv/lib/python3.11/site-packages/django/utils/log.py   None
27/Nov/2024 16:32:03    WARNING    basehttp    "GET /media/images/appartment/photo_2024-09-16_21-23-19.jpg HTTP/1.1" 404 19630   /home/alprostov/PycharmProjects/sakhlis/web/venv/lib/python3.11/site-packages/django/core/servers/basehttp.py   None
27/Nov/2024 16:32:03    WARNING    log    Not Found: /media/images/appartment/236.jpg   /home/alprostov/PycharmProjects/sakhlis/web/venv/lib/python3.11/site-packages/django/utils/log.py   None
27/Nov/2024 16:32:03    WARNING    log    Not Found: /media/images/appartment/photo_2024-09-16_21-48-59.jpg   /home/alprostov/PycharmProjects/sakhlis/web/venv/lib/python3.11/site-packages/django/utils/log.py   None
27/Nov/2024 16:32:03    WARNING    basehttp    "GET /media/images/appartment/236.jpg HTTP/1.1" 404 19520   /home/alprostov/PycharmProjects/sakhlis/web/venv/lib/python3.11/site-packages/django/core/servers/basehttp.py   None
27/Nov/2024 16:32:03    WARNING    basehttp    "GET /media/images/appartment/photo_2024-09-16_21-48-59.jpg HTTP/1.1" 404 19630   /home/alprostov/PycharmProjects/sakhlis/web/venv/lib/python3.11/site-packages/django/core/servers/basehttp.py   None
27/Nov/2024 16:32:03    WARNING    log    Not Found: /media/images/appartment/photo_2024-09-20_16-37-55.jpg   /home/alprostov/PycharmProjects/sakhlis/web/venv/lib/python3.11/site-packages/django/utils/log.py   None
27/Nov/2024 16:32:03    WARNING    basehttp    "GET /media/images/appartment/photo_2024-09-20_16-37-55.jpg HTTP/1.1" 404 19630   /home/alprostov/PycharmProjects/sakhlis/web/venv/lib/python3.11/site-packages/django/core/servers/basehttp.py   None
27/Nov/2024 16:32:03    WARNING    log    Not Found: /media/images/appartment/photo_2024-09-13_20-50-02.jpg   /home/alprostov/PycharmProjects/sakhlis/web/venv/lib/python3.11/site-packages/django/utils/log.py   None
27/Nov/2024 16:32:03    WARNING    basehttp    "GET /media/images/appartment/photo_2024-09-13_20-50-02.jpg HTTP/1.1" 404 19630   /home/alprostov/PycharmProjects/sakhlis/web/venv/lib/python3.11/site-packages/django/core/servers/basehttp.py   None
27/Nov/2024 16:32:03    WARNING    log    Not Found: /media/images/appartment/2718.jpg   /home/alprostov/PycharmProjects/sakhlis/web/venv/lib/python3.11/site-packages/django/utils/log.py   None
27/Nov/2024 16:32:03    WARNING    basehttp    "GET /media/images/appartment/2718.jpg HTTP/1.1" 404 19525   /home/alprostov/PycharmProjects/sakhlis/web/venv/lib/python3.11/site-packages/django/core/servers/basehttp.py   None
27/Nov/2024 16:32:03    WARNING    log    Not Found: /media/images/appartment/2679.jpg   /home/alprostov/PycharmProjects/sakhlis/web/venv/lib/python3.11/site-packages/django/utils/log.py   None
27/Nov/2024 16:32:03    WARNING    basehttp    "GET /media/images/appartment/2679.jpg HTTP/1.1" 404 19525   /home/alprostov/PycharmProjects/sakhlis/web/venv/lib/python3.11/site-packages/django/core/servers/basehttp.py   None
27/Nov/2024 16:32:03    WARNING    log    Not Found: /media/images/appartment/photo_2024-09-12_21-08-19_jbnLNP4.jpg   /home/alprostov/PycharmProjects/sakhlis/web/venv/lib/python3.11/site-packages/django/utils/log.py   None
27/Nov/2024 16:32:03    WARNING    basehttp    "GET /media/images/appartment/photo_2024-09-12_21-08-19_jbnLNP4.jpg HTTP/1.1" 404 19670   /home/alprostov/PycharmProjects/sakhlis/web/venv/lib/python3.11/site-packages/django/core/servers/basehttp.py   None
28/Nov/2024 17:31:44    WARNING    log    Not Found: /favicon.ico   /home/alprostov/PycharmProjects/sakhlis/web/venv/lib/python3.11/site-packages/django/utils/log.py   None
28/Nov/2024 17:31:44    WARNING    basehttp    "GET /favicon.ico HTTP/1.1" 404 19223   /home/alprostov/PycharmProjects/sakhlis/web/venv/lib/python3.11/site-packages/django/core/servers/basehttp.py   None
28/Nov/2024 17:41:34    WARNING    basehttp    "GET /static/js/bootstrap.min.js.map HTTP/1.1" 404 1828   /home/alprostov/PycharmProjects/sakhlis/web/venv/lib/python3.11/site-packages/django/core/servers/basehttp.py   None
28/Nov/2024 17:41:34    WARNING    basehttp    "GET /static/css/bootstrap.min.css.map HTTP/1.1" 404 1834   /home/alprostov/PycharmProjects/sakhlis/web/venv/lib/python3.11/site-packages/django/core/servers/basehttp.py   None
28/Nov/2024 20:46:11    WARNING    log    Not Found: /favicon.ico   /home/alprostov/PycharmProjects/sakhlis/web/venv/lib/python3.11/site-packages/django/utils/log.py   None
28/Nov/2024 20:46:11    WARNING    basehttp    "GET /favicon.ico HTTP/1.1" 404 19402   /home/alprostov/PycharmProjects/sakhlis/web/venv/lib/python3.11/site-packages/django/core/servers/basehttp.py   None
28/Nov/2024 21:21:07    WARNING    log    Not Found: /favicon.ico   /home/alprostov/PycharmProjects/sakhlis/web/venv/lib/python3.11/site-packages/django/utils/log.py   None
28/Nov/2024 21:21:07    WARNING    basehttp    "GET /favicon.ico HTTP/1.1" 404 19402   /home/alprostov/PycharmProjects/sakhlis/web/venv/lib/python3.11/site-packages/django/core/servers/basehttp.py   None
29/Nov/2024 18:06:45    WARNING    log    Not Found: /favicon.ico   /home/alprostov/PycharmProjects/sakhlis/web/venv/lib/python3.11/site-packages/django/utils/log.py   None
29/Nov/2024 18:06:45    WARNING    basehttp    "GET /favicon.ico HTTP/1.1" 404 19572   /home/alprostov/PycharmProjects/sakhlis/web/venv/lib/python3.11/site-packages/django/core/servers/basehttp.py   None
29/Nov/2024 18:07:12    ERROR    log    Internal Server Error: /corporate   /home/alprostov/PycharmProjects/sakhlis/web/venv/lib/python3.11/site-packages/django/utils/log.py   (<class 'django.template.exceptions.TemplateDoesNotExist'>, TemplateDoesNotExist('cbusiness.html'), <traceback object at 0x7fe30497a1c0>)
Traceback (most recent call last):
  File "/home/alprostov/PycharmProjects/sakhlis/web/venv/lib/python3.11/site-packages/django/core/handlers/exception.py", line 55, in inner
    response = get_response(request)
               ^^^^^^^^^^^^^^^^^^^^^
  File "/home/alprostov/PycharmProjects/sakhlis/web/venv/lib/python3.11/site-packages/django/core/handlers/base.py", line 220, in _get_response
    response = response.render()
               ^^^^^^^^^^^^^^^^^
  File "/home/alprostov/PycharmProjects/sakhlis/web/venv/lib/python3.11/site-packages/django/template/response.py", line 111, in render
    self.content = self.rendered_content
                   ^^^^^^^^^^^^^^^^^^^^^
  File "/home/alprostov/PycharmProjects/sakhlis/web/venv/lib/python3.11/site-packages/django/template/response.py", line 87, in rendered_content
    template = self.resolve_template(self.template_name)
               ^^^^^^^^^^^^^^^^^^^^^^^^^^^^^^^^^^^^^^^^^
  File "/home/alprostov/PycharmProjects/sakhlis/web/venv/lib/python3.11/site-packages/django/template/response.py", line 69, in resolve_template
    return select_template(template, using=self.using)
           ^^^^^^^^^^^^^^^^^^^^^^^^^^^^^^^^^^^^^^^^^^^
  File "/home/alprostov/PycharmProjects/sakhlis/web/venv/lib/python3.11/site-packages/django/template/loader.py", line 47, in select_template
    raise TemplateDoesNotExist(", ".join(template_name_list), chain=chain)
django.template.exceptions.TemplateDoesNotExist: cbusiness.html
29/Nov/2024 18:07:12    ERROR    basehttp    "GET /corporate HTTP/1.1" 500 97608   /home/alprostov/PycharmProjects/sakhlis/web/venv/lib/python3.11/site-packages/django/core/servers/basehttp.py   None
29/Nov/2024 18:07:13    ERROR    log    Internal Server Error: /corporate   /home/alprostov/PycharmProjects/sakhlis/web/venv/lib/python3.11/site-packages/django/utils/log.py   (<class 'django.template.exceptions.TemplateDoesNotExist'>, TemplateDoesNotExist('cbusiness.html'), <traceback object at 0x7fe2fdbb9a00>)
Traceback (most recent call last):
  File "/home/alprostov/PycharmProjects/sakhlis/web/venv/lib/python3.11/site-packages/django/core/handlers/exception.py", line 55, in inner
    response = get_response(request)
               ^^^^^^^^^^^^^^^^^^^^^
  File "/home/alprostov/PycharmProjects/sakhlis/web/venv/lib/python3.11/site-packages/django/core/handlers/base.py", line 220, in _get_response
    response = response.render()
               ^^^^^^^^^^^^^^^^^
  File "/home/alprostov/PycharmProjects/sakhlis/web/venv/lib/python3.11/site-packages/django/template/response.py", line 111, in render
    self.content = self.rendered_content
                   ^^^^^^^^^^^^^^^^^^^^^
  File "/home/alprostov/PycharmProjects/sakhlis/web/venv/lib/python3.11/site-packages/django/template/response.py", line 87, in rendered_content
    template = self.resolve_template(self.template_name)
               ^^^^^^^^^^^^^^^^^^^^^^^^^^^^^^^^^^^^^^^^^
  File "/home/alprostov/PycharmProjects/sakhlis/web/venv/lib/python3.11/site-packages/django/template/response.py", line 69, in resolve_template
    return select_template(template, using=self.using)
           ^^^^^^^^^^^^^^^^^^^^^^^^^^^^^^^^^^^^^^^^^^^
  File "/home/alprostov/PycharmProjects/sakhlis/web/venv/lib/python3.11/site-packages/django/template/loader.py", line 47, in select_template
    raise TemplateDoesNotExist(", ".join(template_name_list), chain=chain)
django.template.exceptions.TemplateDoesNotExist: cbusiness.html
29/Nov/2024 18:07:13    ERROR    basehttp    "GET /corporate HTTP/1.1" 500 97608   /home/alprostov/PycharmProjects/sakhlis/web/venv/lib/python3.11/site-packages/django/core/servers/basehttp.py   None
29/Nov/2024 18:07:13    ERROR    log    Internal Server Error: /corporate   /home/alprostov/PycharmProjects/sakhlis/web/venv/lib/python3.11/site-packages/django/utils/log.py   (<class 'django.template.exceptions.TemplateDoesNotExist'>, TemplateDoesNotExist('cbusiness.html'), <traceback object at 0x7fe2fd135a40>)
Traceback (most recent call last):
  File "/home/alprostov/PycharmProjects/sakhlis/web/venv/lib/python3.11/site-packages/django/core/handlers/exception.py", line 55, in inner
    response = get_response(request)
               ^^^^^^^^^^^^^^^^^^^^^
  File "/home/alprostov/PycharmProjects/sakhlis/web/venv/lib/python3.11/site-packages/django/core/handlers/base.py", line 220, in _get_response
    response = response.render()
               ^^^^^^^^^^^^^^^^^
  File "/home/alprostov/PycharmProjects/sakhlis/web/venv/lib/python3.11/site-packages/django/template/response.py", line 111, in render
    self.content = self.rendered_content
                   ^^^^^^^^^^^^^^^^^^^^^
  File "/home/alprostov/PycharmProjects/sakhlis/web/venv/lib/python3.11/site-packages/django/template/response.py", line 87, in rendered_content
    template = self.resolve_template(self.template_name)
               ^^^^^^^^^^^^^^^^^^^^^^^^^^^^^^^^^^^^^^^^^
  File "/home/alprostov/PycharmProjects/sakhlis/web/venv/lib/python3.11/site-packages/django/template/response.py", line 69, in resolve_template
    return select_template(template, using=self.using)
           ^^^^^^^^^^^^^^^^^^^^^^^^^^^^^^^^^^^^^^^^^^^
  File "/home/alprostov/PycharmProjects/sakhlis/web/venv/lib/python3.11/site-packages/django/template/loader.py", line 47, in select_template
    raise TemplateDoesNotExist(", ".join(template_name_list), chain=chain)
django.template.exceptions.TemplateDoesNotExist: cbusiness.html
29/Nov/2024 18:07:13    ERROR    basehttp    "GET /corporate HTTP/1.1" 500 97608   /home/alprostov/PycharmProjects/sakhlis/web/venv/lib/python3.11/site-packages/django/core/servers/basehttp.py   None
29/Nov/2024 18:07:14    ERROR    log    Internal Server Error: /corporate   /home/alprostov/PycharmProjects/sakhlis/web/venv/lib/python3.11/site-packages/django/utils/log.py   (<class 'django.template.exceptions.TemplateDoesNotExist'>, TemplateDoesNotExist('cbusiness.html'), <traceback object at 0x7fe2fd1b8540>)
Traceback (most recent call last):
  File "/home/alprostov/PycharmProjects/sakhlis/web/venv/lib/python3.11/site-packages/django/core/handlers/exception.py", line 55, in inner
    response = get_response(request)
               ^^^^^^^^^^^^^^^^^^^^^
  File "/home/alprostov/PycharmProjects/sakhlis/web/venv/lib/python3.11/site-packages/django/core/handlers/base.py", line 220, in _get_response
    response = response.render()
               ^^^^^^^^^^^^^^^^^
  File "/home/alprostov/PycharmProjects/sakhlis/web/venv/lib/python3.11/site-packages/django/template/response.py", line 111, in render
    self.content = self.rendered_content
                   ^^^^^^^^^^^^^^^^^^^^^
  File "/home/alprostov/PycharmProjects/sakhlis/web/venv/lib/python3.11/site-packages/django/template/response.py", line 87, in rendered_content
    template = self.resolve_template(self.template_name)
               ^^^^^^^^^^^^^^^^^^^^^^^^^^^^^^^^^^^^^^^^^
  File "/home/alprostov/PycharmProjects/sakhlis/web/venv/lib/python3.11/site-packages/django/template/response.py", line 69, in resolve_template
    return select_template(template, using=self.using)
           ^^^^^^^^^^^^^^^^^^^^^^^^^^^^^^^^^^^^^^^^^^^
  File "/home/alprostov/PycharmProjects/sakhlis/web/venv/lib/python3.11/site-packages/django/template/loader.py", line 47, in select_template
    raise TemplateDoesNotExist(", ".join(template_name_list), chain=chain)
django.template.exceptions.TemplateDoesNotExist: cbusiness.html
29/Nov/2024 18:07:14    ERROR    basehttp    "GET /corporate HTTP/1.1" 500 97608   /home/alprostov/PycharmProjects/sakhlis/web/venv/lib/python3.11/site-packages/django/core/servers/basehttp.py   None
29/Nov/2024 18:07:14    ERROR    log    Internal Server Error: /corporate   /home/alprostov/PycharmProjects/sakhlis/web/venv/lib/python3.11/site-packages/django/utils/log.py   (<class 'django.template.exceptions.TemplateDoesNotExist'>, TemplateDoesNotExist('cbusiness.html'), <traceback object at 0x7fe2fd02a840>)
Traceback (most recent call last):
  File "/home/alprostov/PycharmProjects/sakhlis/web/venv/lib/python3.11/site-packages/django/core/handlers/exception.py", line 55, in inner
    response = get_response(request)
               ^^^^^^^^^^^^^^^^^^^^^
  File "/home/alprostov/PycharmProjects/sakhlis/web/venv/lib/python3.11/site-packages/django/core/handlers/base.py", line 220, in _get_response
    response = response.render()
               ^^^^^^^^^^^^^^^^^
  File "/home/alprostov/PycharmProjects/sakhlis/web/venv/lib/python3.11/site-packages/django/template/response.py", line 111, in render
    self.content = self.rendered_content
                   ^^^^^^^^^^^^^^^^^^^^^
  File "/home/alprostov/PycharmProjects/sakhlis/web/venv/lib/python3.11/site-packages/django/template/response.py", line 87, in rendered_content
    template = self.resolve_template(self.template_name)
               ^^^^^^^^^^^^^^^^^^^^^^^^^^^^^^^^^^^^^^^^^
  File "/home/alprostov/PycharmProjects/sakhlis/web/venv/lib/python3.11/site-packages/django/template/response.py", line 69, in resolve_template
    return select_template(template, using=self.using)
           ^^^^^^^^^^^^^^^^^^^^^^^^^^^^^^^^^^^^^^^^^^^
  File "/home/alprostov/PycharmProjects/sakhlis/web/venv/lib/python3.11/site-packages/django/template/loader.py", line 47, in select_template
    raise TemplateDoesNotExist(", ".join(template_name_list), chain=chain)
django.template.exceptions.TemplateDoesNotExist: cbusiness.html
29/Nov/2024 18:07:14    ERROR    basehttp    "GET /corporate HTTP/1.1" 500 97608   /home/alprostov/PycharmProjects/sakhlis/web/venv/lib/python3.11/site-packages/django/core/servers/basehttp.py   None
29/Nov/2024 20:50:25    ERROR    log    Internal Server Error: /   /home/alprostov/PycharmProjects/sakhlis/web/venv/lib/python3.11/site-packages/django/utils/log.py   (<class 'django.template.exceptions.TemplateSyntaxError'>, TemplateSyntaxError("Invalid block tag on line 37: 'static'. Did you forget to register or load this tag?"), <traceback object at 0x7fcffe724a00>)
Traceback (most recent call last):
  File "/home/alprostov/PycharmProjects/sakhlis/web/venv/lib/python3.11/site-packages/django/template/base.py", line 505, in parse
    compile_func = self.tags[command]
                   ~~~~~~~~~^^^^^^^^^
KeyError: 'static'

During handling of the above exception, another exception occurred:

Traceback (most recent call last):
  File "/home/alprostov/PycharmProjects/sakhlis/web/venv/lib/python3.11/site-packages/django/core/handlers/exception.py", line 55, in inner
    response = get_response(request)
               ^^^^^^^^^^^^^^^^^^^^^
  File "/home/alprostov/PycharmProjects/sakhlis/web/venv/lib/python3.11/site-packages/django/core/handlers/base.py", line 220, in _get_response
    response = response.render()
               ^^^^^^^^^^^^^^^^^
  File "/home/alprostov/PycharmProjects/sakhlis/web/venv/lib/python3.11/site-packages/django/template/response.py", line 111, in render
    self.content = self.rendered_content
                   ^^^^^^^^^^^^^^^^^^^^^
  File "/home/alprostov/PycharmProjects/sakhlis/web/venv/lib/python3.11/site-packages/django/template/response.py", line 89, in rendered_content
    return template.render(context, self._request)
           ^^^^^^^^^^^^^^^^^^^^^^^^^^^^^^^^^^^^^^^
  File "/home/alprostov/PycharmProjects/sakhlis/web/venv/lib/python3.11/site-packages/django/template/backends/django.py", line 61, in render
    return self.template.render(context)
           ^^^^^^^^^^^^^^^^^^^^^^^^^^^^^
  File "/home/alprostov/PycharmProjects/sakhlis/web/venv/lib/python3.11/site-packages/django/template/base.py", line 175, in render
    return self._render(context)
           ^^^^^^^^^^^^^^^^^^^^^
  File "/home/alprostov/PycharmProjects/sakhlis/web/venv/lib/python3.11/site-packages/django/test/utils.py", line 112, in instrumented_test_render
    return self.nodelist.render(context)
           ^^^^^^^^^^^^^^^^^^^^^^^^^^^^^
  File "/home/alprostov/PycharmProjects/sakhlis/web/venv/lib/python3.11/site-packages/django/template/base.py", line 1005, in render
    return SafeString("".join([node.render_annotated(context) for node in self]))
                              ^^^^^^^^^^^^^^^^^^^^^^^^^^^^^^^^^^^^^^^^^^^^^^^^^
  File "/home/alprostov/PycharmProjects/sakhlis/web/venv/lib/python3.11/site-packages/django/template/base.py", line 1005, in <listcomp>
    return SafeString("".join([node.render_annotated(context) for node in self]))
                               ^^^^^^^^^^^^^^^^^^^^^^^^^^^^^^
  File "/home/alprostov/PycharmProjects/sakhlis/web/venv/lib/python3.11/site-packages/django/template/base.py", line 966, in render_annotated
    return self.render(context)
           ^^^^^^^^^^^^^^^^^^^^
  File "/home/alprostov/PycharmProjects/sakhlis/web/venv/lib/python3.11/site-packages/slippers/templatetags/slippers.py", line 102, in render
    template = context.template.engine.get_template(self.template_path)
               ^^^^^^^^^^^^^^^^^^^^^^^^^^^^^^^^^^^^^^^^^^^^^^^^^^^^^^^^
  File "/home/alprostov/PycharmProjects/sakhlis/web/venv/lib/python3.11/site-packages/django/template/engine.py", line 175, in get_template
    template, origin = self.find_template(template_name)
                       ^^^^^^^^^^^^^^^^^^^^^^^^^^^^^^^^^
  File "/home/alprostov/PycharmProjects/sakhlis/web/venv/lib/python3.11/site-packages/django/template/engine.py", line 157, in find_template
    template = loader.get_template(name, skip=skip)
               ^^^^^^^^^^^^^^^^^^^^^^^^^^^^^^^^^^^^
  File "/home/alprostov/PycharmProjects/sakhlis/web/venv/lib/python3.11/site-packages/django/template/loaders/cached.py", line 57, in get_template
    template = super().get_template(template_name, skip)
               ^^^^^^^^^^^^^^^^^^^^^^^^^^^^^^^^^^^^^^^^^
  File "/home/alprostov/PycharmProjects/sakhlis/web/venv/lib/python3.11/site-packages/django/template/loaders/base.py", line 28, in get_template
    return Template(
           ^^^^^^^^^
  File "/home/alprostov/PycharmProjects/sakhlis/web/venv/lib/python3.11/site-packages/django/template/base.py", line 154, in __init__
    self.nodelist = self.compile_nodelist()
                    ^^^^^^^^^^^^^^^^^^^^^^^
  File "/home/alprostov/PycharmProjects/sakhlis/web/venv/lib/python3.11/site-packages/django/template/base.py", line 200, in compile_nodelist
    return parser.parse()
           ^^^^^^^^^^^^^^
  File "/home/alprostov/PycharmProjects/sakhlis/web/venv/lib/python3.11/site-packages/django/template/base.py", line 507, in parse
    self.invalid_block_tag(token, command, parse_until)
  File "/home/alprostov/PycharmProjects/sakhlis/web/venv/lib/python3.11/site-packages/django/template/base.py", line 568, in invalid_block_tag
    raise self.error(
django.template.exceptions.TemplateSyntaxError: Invalid block tag on line 37: 'static'. Did you forget to register or load this tag?
29/Nov/2024 20:50:25    ERROR    basehttp    "GET / HTTP/1.1" 500 181728   /home/alprostov/PycharmProjects/sakhlis/web/venv/lib/python3.11/site-packages/django/core/servers/basehttp.py   None
30/Nov/2024 07:13:30    WARNING    log    Not Found: /favicon.ico   /home/alprostov/PycharmProjects/sakhlis/web/venv/lib/python3.11/site-packages/django/utils/log.py   None
30/Nov/2024 07:13:30    WARNING    basehttp    "GET /favicon.ico HTTP/1.1" 404 19572   /home/alprostov/PycharmProjects/sakhlis/web/venv/lib/python3.11/site-packages/django/core/servers/basehttp.py   None
30/Nov/2024 12:13:13    WARNING    log    Not Found: /favicon.ico   /home/alprostov/PycharmProjects/sakhlis/web/venv/lib/python3.11/site-packages/django/utils/log.py   None
30/Nov/2024 12:13:13    WARNING    basehttp    "GET /favicon.ico HTTP/1.1" 404 19572   /home/alprostov/PycharmProjects/sakhlis/web/venv/lib/python3.11/site-packages/django/core/servers/basehttp.py   None
30/Nov/2024 12:24:50    ERROR    log    Internal Server Error: /createorder   /home/alprostov/PycharmProjects/sakhlis/web/venv/lib/python3.11/site-packages/django/utils/log.py   (<class 'TypeError'>, TypeError('Object of type set is not JSON serializable'), <traceback object at 0x7fc7e95182c0>)
Traceback (most recent call last):
  File "/home/alprostov/PycharmProjects/sakhlis/web/venv/lib/python3.11/site-packages/django/core/handlers/exception.py", line 55, in inner
    response = get_response(request)
               ^^^^^^^^^^^^^^^^^^^^^
  File "/home/alprostov/PycharmProjects/sakhlis/web/venv/lib/python3.11/site-packages/django/core/handlers/base.py", line 197, in _get_response
    response = wrapped_callback(request, *callback_args, **callback_kwargs)
               ^^^^^^^^^^^^^^^^^^^^^^^^^^^^^^^^^^^^^^^^^^^^^^^^^^^^^^^^^^^^
  File "/home/alprostov/PycharmProjects/sakhlis/web/venv/lib/python3.11/site-packages/django/views/generic/base.py", line 104, in view
    return self.dispatch(request, *args, **kwargs)
           ^^^^^^^^^^^^^^^^^^^^^^^^^^^^^^^^^^^^^^^
  File "/home/alprostov/PycharmProjects/sakhlis/web/venv/lib/python3.11/site-packages/django/views/generic/base.py", line 143, in dispatch
    return handler(request, *args, **kwargs)
           ^^^^^^^^^^^^^^^^^^^^^^^^^^^^^^^^^
  File "/home/alprostov/PycharmProjects/sakhlis/web/venv/lib/python3.11/site-packages/django/views/generic/edit.py", line 184, in post
    return super().post(request, *args, **kwargs)
           ^^^^^^^^^^^^^^^^^^^^^^^^^^^^^^^^^^^^^^
  File "/home/alprostov/PycharmProjects/sakhlis/web/venv/lib/python3.11/site-packages/django/views/generic/edit.py", line 153, in post
    return self.form_valid(form)
           ^^^^^^^^^^^^^^^^^^^^^
  File "/home/alprostov/PycharmProjects/sakhlis/web/app_site/views.py", line 250, in form_valid
    return JsonResponse({'message': {form.instance.pk},
           ^^^^^^^^^^^^^^^^^^^^^^^^^^^^^^^^^^^^^^^^^^^^
  File "/home/alprostov/PycharmProjects/sakhlis/web/venv/lib/python3.11/site-packages/django/http/response.py", line 748, in __init__
    data = json.dumps(data, cls=encoder, **json_dumps_params)
           ^^^^^^^^^^^^^^^^^^^^^^^^^^^^^^^^^^^^^^^^^^^^^^^^^^
  File "/usr/lib/python3.11/json/__init__.py", line 238, in dumps
    **kw).encode(obj)
          ^^^^^^^^^^^
  File "/usr/lib/python3.11/json/encoder.py", line 200, in encode
    chunks = self.iterencode(o, _one_shot=True)
             ^^^^^^^^^^^^^^^^^^^^^^^^^^^^^^^^^^
  File "/usr/lib/python3.11/json/encoder.py", line 258, in iterencode
    return _iterencode(o, 0)
           ^^^^^^^^^^^^^^^^^
  File "/home/alprostov/PycharmProjects/sakhlis/web/venv/lib/python3.11/site-packages/django/core/serializers/json.py", line 106, in default
    return super().default(o)
           ^^^^^^^^^^^^^^^^^^
  File "/usr/lib/python3.11/json/encoder.py", line 180, in default
    raise TypeError(f'Object of type {o.__class__.__name__} '
TypeError: Object of type set is not JSON serializable
30/Nov/2024 12:24:50    ERROR    basehttp    "POST /createorder HTTP/1.1" 500 133417   /home/alprostov/PycharmProjects/sakhlis/web/venv/lib/python3.11/site-packages/django/core/servers/basehttp.py   None
30/Nov/2024 12:25:45    ERROR    log    Internal Server Error: /createorder   /home/alprostov/PycharmProjects/sakhlis/web/venv/lib/python3.11/site-packages/django/utils/log.py   (<class 'TypeError'>, TypeError('Object of type set is not JSON serializable'), <traceback object at 0x7fc7e8b61c00>)
Traceback (most recent call last):
  File "/home/alprostov/PycharmProjects/sakhlis/web/venv/lib/python3.11/site-packages/django/core/handlers/exception.py", line 55, in inner
    response = get_response(request)
               ^^^^^^^^^^^^^^^^^^^^^
  File "/home/alprostov/PycharmProjects/sakhlis/web/venv/lib/python3.11/site-packages/django/core/handlers/base.py", line 197, in _get_response
    response = wrapped_callback(request, *callback_args, **callback_kwargs)
               ^^^^^^^^^^^^^^^^^^^^^^^^^^^^^^^^^^^^^^^^^^^^^^^^^^^^^^^^^^^^
  File "/home/alprostov/PycharmProjects/sakhlis/web/venv/lib/python3.11/site-packages/django/views/generic/base.py", line 104, in view
    return self.dispatch(request, *args, **kwargs)
           ^^^^^^^^^^^^^^^^^^^^^^^^^^^^^^^^^^^^^^^
  File "/home/alprostov/PycharmProjects/sakhlis/web/venv/lib/python3.11/site-packages/django/views/generic/base.py", line 143, in dispatch
    return handler(request, *args, **kwargs)
           ^^^^^^^^^^^^^^^^^^^^^^^^^^^^^^^^^
  File "/home/alprostov/PycharmProjects/sakhlis/web/venv/lib/python3.11/site-packages/django/views/generic/edit.py", line 184, in post
    return super().post(request, *args, **kwargs)
           ^^^^^^^^^^^^^^^^^^^^^^^^^^^^^^^^^^^^^^
  File "/home/alprostov/PycharmProjects/sakhlis/web/venv/lib/python3.11/site-packages/django/views/generic/edit.py", line 153, in post
    return self.form_valid(form)
           ^^^^^^^^^^^^^^^^^^^^^
  File "/home/alprostov/PycharmProjects/sakhlis/web/app_site/views.py", line 250, in form_valid
    return JsonResponse({'message': {form.instance.pk},
           ^^^^^^^^^^^^^^^^^^^^^^^^^^^^^^^^^^^^^^^^^^^^
  File "/home/alprostov/PycharmProjects/sakhlis/web/venv/lib/python3.11/site-packages/django/http/response.py", line 748, in __init__
    data = json.dumps(data, cls=encoder, **json_dumps_params)
           ^^^^^^^^^^^^^^^^^^^^^^^^^^^^^^^^^^^^^^^^^^^^^^^^^^
  File "/usr/lib/python3.11/json/__init__.py", line 238, in dumps
    **kw).encode(obj)
          ^^^^^^^^^^^
  File "/usr/lib/python3.11/json/encoder.py", line 200, in encode
    chunks = self.iterencode(o, _one_shot=True)
             ^^^^^^^^^^^^^^^^^^^^^^^^^^^^^^^^^^
  File "/usr/lib/python3.11/json/encoder.py", line 258, in iterencode
    return _iterencode(o, 0)
           ^^^^^^^^^^^^^^^^^
  File "/home/alprostov/PycharmProjects/sakhlis/web/venv/lib/python3.11/site-packages/django/core/serializers/json.py", line 106, in default
    return super().default(o)
           ^^^^^^^^^^^^^^^^^^
  File "/usr/lib/python3.11/json/encoder.py", line 180, in default
    raise TypeError(f'Object of type {o.__class__.__name__} '
TypeError: Object of type set is not JSON serializable
30/Nov/2024 12:25:45    ERROR    basehttp    "POST /createorder HTTP/1.1" 500 133411   /home/alprostov/PycharmProjects/sakhlis/web/venv/lib/python3.11/site-packages/django/core/servers/basehttp.py   None
30/Nov/2024 13:06:03    WARNING    log    Not Found: /favicon.ico   /home/alprostov/PycharmProjects/sakhlis/web/venv/lib/python3.11/site-packages/django/utils/log.py   None
30/Nov/2024 13:06:03    WARNING    basehttp    "GET /favicon.ico HTTP/1.1" 404 19573   /home/alprostov/PycharmProjects/sakhlis/web/venv/lib/python3.11/site-packages/django/core/servers/basehttp.py   None
30/Nov/2024 13:58:12    WARNING    basehttp    "GET /static/images/5_png HTTP/1.1" 404 1795   /home/alprostov/PycharmProjects/sakhlis/web/venv/lib/python3.11/site-packages/django/core/servers/basehttp.py   None
30/Nov/2024 13:58:12    WARNING    basehttp    "GET /static/images/5_png HTTP/1.1" 404 1795   /home/alprostov/PycharmProjects/sakhlis/web/venv/lib/python3.11/site-packages/django/core/servers/basehttp.py   None
30/Nov/2024 13:58:13    WARNING    basehttp    "GET /static/images/5_png HTTP/1.1" 404 1795   /home/alprostov/PycharmProjects/sakhlis/web/venv/lib/python3.11/site-packages/django/core/servers/basehttp.py   None
30/Nov/2024 13:58:13    WARNING    basehttp    "GET /static/images/5_png HTTP/1.1" 404 1795   /home/alprostov/PycharmProjects/sakhlis/web/venv/lib/python3.11/site-packages/django/core/servers/basehttp.py   None
30/Nov/2024 13:58:22    WARNING    basehttp    "GET /static/images/5_png HTTP/1.1" 404 1795   /home/alprostov/PycharmProjects/sakhlis/web/venv/lib/python3.11/site-packages/django/core/servers/basehttp.py   None
30/Nov/2024 13:58:22    WARNING    basehttp    "GET /static/images/5_png HTTP/1.1" 404 1795   /home/alprostov/PycharmProjects/sakhlis/web/venv/lib/python3.11/site-packages/django/core/servers/basehttp.py   None
30/Nov/2024 13:59:02    WARNING    basehttp    "GET /static/images/5_png HTTP/1.1" 404 1795   /home/alprostov/PycharmProjects/sakhlis/web/venv/lib/python3.11/site-packages/django/core/servers/basehttp.py   None
30/Nov/2024 13:59:06    WARNING    basehttp    "GET /static/images/5_png HTTP/1.1" 404 1795   /home/alprostov/PycharmProjects/sakhlis/web/venv/lib/python3.11/site-packages/django/core/servers/basehttp.py   None
30/Nov/2024 14:14:53    WARNING    log    Not Found: /favicon.ico   /home/alprostov/PycharmProjects/sakhlis/web/venv/lib/python3.11/site-packages/django/utils/log.py   None
30/Nov/2024 14:14:53    WARNING    basehttp    "GET /favicon.ico HTTP/1.1" 404 19572   /home/alprostov/PycharmProjects/sakhlis/web/venv/lib/python3.11/site-packages/django/core/servers/basehttp.py   None
30/Nov/2024 15:11:01    WARNING    log    Not Found: /favicon.ico   /home/alprostov/PycharmProjects/sakhlis/web/venv/lib/python3.11/site-packages/django/utils/log.py   None
30/Nov/2024 15:11:01    WARNING    basehttp    "GET /favicon.ico HTTP/1.1" 404 19572   /home/alprostov/PycharmProjects/sakhlis/web/venv/lib/python3.11/site-packages/django/core/servers/basehttp.py   None
02/Dec/2024 18:06:31    WARNING    log    Not Found: /favicon.ico   /home/alprostov/PycharmProjects/sakhlis/web/venv/lib/python3.11/site-packages/django/utils/log.py   None
02/Dec/2024 18:06:31    WARNING    basehttp    "GET /favicon.ico HTTP/1.1" 404 19746   /home/alprostov/PycharmProjects/sakhlis/web/venv/lib/python3.11/site-packages/django/core/servers/basehttp.py   None
02/Dec/2024 18:13:10    WARNING    log    Forbidden (CSRF token missing.): /sendoffer   /home/alprostov/PycharmProjects/sakhlis/web/venv/lib/python3.11/site-packages/django/utils/log.py   None
02/Dec/2024 18:13:10    WARNING    basehttp    "POST /sendoffer HTTP/1.1" 403 11807   /home/alprostov/PycharmProjects/sakhlis/web/venv/lib/python3.11/site-packages/django/core/servers/basehttp.py   None
02/Dec/2024 18:13:54    WARNING    log    Forbidden (CSRF token missing.): /sendoffer   /home/alprostov/PycharmProjects/sakhlis/web/venv/lib/python3.11/site-packages/django/utils/log.py   None
02/Dec/2024 18:13:54    WARNING    basehttp    "POST /sendoffer HTTP/1.1" 403 11807   /home/alprostov/PycharmProjects/sakhlis/web/venv/lib/python3.11/site-packages/django/core/servers/basehttp.py   None
02/Dec/2024 18:13:58    WARNING    log    Forbidden (CSRF token missing.): /sendoffer   /home/alprostov/PycharmProjects/sakhlis/web/venv/lib/python3.11/site-packages/django/utils/log.py   None
02/Dec/2024 18:13:58    WARNING    basehttp    "POST /sendoffer HTTP/1.1" 403 11807   /home/alprostov/PycharmProjects/sakhlis/web/venv/lib/python3.11/site-packages/django/core/servers/basehttp.py   None
02/Dec/2024 18:14:06    ERROR    log    Internal Server Error: /sendoffer   /home/alprostov/PycharmProjects/sakhlis/web/venv/lib/python3.11/site-packages/django/utils/log.py   (<class 'ValueError'>, ValueError("The view app_site.views.view didn't return an HttpResponse object. It returned None instead."), <traceback object at 0x7f7065db82c0>)
Traceback (most recent call last):
  File "/home/alprostov/PycharmProjects/sakhlis/web/venv/lib/python3.11/site-packages/django/core/handlers/exception.py", line 55, in inner
    response = get_response(request)
               ^^^^^^^^^^^^^^^^^^^^^
  File "/home/alprostov/PycharmProjects/sakhlis/web/venv/lib/python3.11/site-packages/django/core/handlers/base.py", line 204, in _get_response
    self.check_response(response, callback)
  File "/home/alprostov/PycharmProjects/sakhlis/web/venv/lib/python3.11/site-packages/django/core/handlers/base.py", line 332, in check_response
    raise ValueError(
ValueError: The view app_site.views.view didn't return an HttpResponse object. It returned None instead.
02/Dec/2024 18:14:06    ERROR    basehttp    "POST /sendoffer HTTP/1.1" 500 82628   /home/alprostov/PycharmProjects/sakhlis/web/venv/lib/python3.11/site-packages/django/core/servers/basehttp.py   None
02/Dec/2024 18:15:07    ERROR    log    Internal Server Error: /sendoffer   /home/alprostov/PycharmProjects/sakhlis/web/venv/lib/python3.11/site-packages/django/utils/log.py   (<class 'ValueError'>, ValueError("The view app_site.views.view didn't return an HttpResponse object. It returned None instead."), <traceback object at 0x7fd9d40c5c40>)
Traceback (most recent call last):
  File "/home/alprostov/PycharmProjects/sakhlis/web/venv/lib/python3.11/site-packages/django/core/handlers/exception.py", line 55, in inner
    response = get_response(request)
               ^^^^^^^^^^^^^^^^^^^^^
  File "/home/alprostov/PycharmProjects/sakhlis/web/venv/lib/python3.11/site-packages/django/core/handlers/base.py", line 204, in _get_response
    self.check_response(response, callback)
  File "/home/alprostov/PycharmProjects/sakhlis/web/venv/lib/python3.11/site-packages/django/core/handlers/base.py", line 332, in check_response
    raise ValueError(
ValueError: The view app_site.views.view didn't return an HttpResponse object. It returned None instead.
02/Dec/2024 18:15:07    ERROR    basehttp    "POST /sendoffer HTTP/1.1" 500 82634   /home/alprostov/PycharmProjects/sakhlis/web/venv/lib/python3.11/site-packages/django/core/servers/basehttp.py   None
02/Dec/2024 18:15:26    ERROR    log    Internal Server Error: /sendoffer   /home/alprostov/PycharmProjects/sakhlis/web/venv/lib/python3.11/site-packages/django/utils/log.py   (<class 'KeyError'>, KeyError('formset'), <traceback object at 0x7f1e91d8ae80>)
Traceback (most recent call last):
  File "/home/alprostov/PycharmProjects/sakhlis/web/venv/lib/python3.11/site-packages/django/core/handlers/exception.py", line 55, in inner
    response = get_response(request)
               ^^^^^^^^^^^^^^^^^^^^^
  File "/home/alprostov/PycharmProjects/sakhlis/web/venv/lib/python3.11/site-packages/django/core/handlers/base.py", line 197, in _get_response
    response = wrapped_callback(request, *callback_args, **callback_kwargs)
               ^^^^^^^^^^^^^^^^^^^^^^^^^^^^^^^^^^^^^^^^^^^^^^^^^^^^^^^^^^^^
  File "/home/alprostov/PycharmProjects/sakhlis/web/venv/lib/python3.11/site-packages/django/views/generic/base.py", line 104, in view
    return self.dispatch(request, *args, **kwargs)
           ^^^^^^^^^^^^^^^^^^^^^^^^^^^^^^^^^^^^^^^
  File "/home/alprostov/PycharmProjects/sakhlis/web/venv/lib/python3.11/site-packages/django/views/generic/base.py", line 143, in dispatch
    return handler(request, *args, **kwargs)
           ^^^^^^^^^^^^^^^^^^^^^^^^^^^^^^^^^
  File "/home/alprostov/PycharmProjects/sakhlis/web/app_site/views.py", line 439, in post
    print(kwargs['formset'])
          ~~~~~~^^^^^^^^^^^
KeyError: 'formset'
02/Dec/2024 18:15:26    ERROR    basehttp    "POST /sendoffer HTTP/1.1" 500 91175   /home/alprostov/PycharmProjects/sakhlis/web/venv/lib/python3.11/site-packages/django/core/servers/basehttp.py   None
02/Dec/2024 18:16:21    ERROR    log    Internal Server Error: /sendoffer   /home/alprostov/PycharmProjects/sakhlis/web/venv/lib/python3.11/site-packages/django/utils/log.py   (<class 'ValueError'>, ValueError("The view app_site.views.view didn't return an HttpResponse object. It returned None instead."), <traceback object at 0x7f333d7e1200>)
Traceback (most recent call last):
  File "/home/alprostov/PycharmProjects/sakhlis/web/venv/lib/python3.11/site-packages/django/core/handlers/exception.py", line 55, in inner
    response = get_response(request)
               ^^^^^^^^^^^^^^^^^^^^^
  File "/home/alprostov/PycharmProjects/sakhlis/web/venv/lib/python3.11/site-packages/django/core/handlers/base.py", line 204, in _get_response
    self.check_response(response, callback)
  File "/home/alprostov/PycharmProjects/sakhlis/web/venv/lib/python3.11/site-packages/django/core/handlers/base.py", line 332, in check_response
    raise ValueError(
ValueError: The view app_site.views.view didn't return an HttpResponse object. It returned None instead.
02/Dec/2024 18:16:21    ERROR    basehttp    "POST /sendoffer HTTP/1.1" 500 82633   /home/alprostov/PycharmProjects/sakhlis/web/venv/lib/python3.11/site-packages/django/core/servers/basehttp.py   None
02/Dec/2024 18:16:59    ERROR    log    Internal Server Error: /sendoffer   /home/alprostov/PycharmProjects/sakhlis/web/venv/lib/python3.11/site-packages/django/utils/log.py   (<class 'ValueError'>, ValueError("The view app_site.views.view didn't return an HttpResponse object. It returned None instead."), <traceback object at 0x7f72eb558980>)
Traceback (most recent call last):
  File "/home/alprostov/PycharmProjects/sakhlis/web/venv/lib/python3.11/site-packages/django/core/handlers/exception.py", line 55, in inner
    response = get_response(request)
               ^^^^^^^^^^^^^^^^^^^^^
  File "/home/alprostov/PycharmProjects/sakhlis/web/venv/lib/python3.11/site-packages/django/core/handlers/base.py", line 204, in _get_response
    self.check_response(response, callback)
  File "/home/alprostov/PycharmProjects/sakhlis/web/venv/lib/python3.11/site-packages/django/core/handlers/base.py", line 332, in check_response
    raise ValueError(
ValueError: The view app_site.views.view didn't return an HttpResponse object. It returned None instead.
02/Dec/2024 18:17:00    ERROR    basehttp    "POST /sendoffer HTTP/1.1" 500 82633   /home/alprostov/PycharmProjects/sakhlis/web/venv/lib/python3.11/site-packages/django/core/servers/basehttp.py   None
02/Dec/2024 18:26:20    ERROR    log    Internal Server Error: /sendoffer   /home/alprostov/PycharmProjects/sakhlis/web/venv/lib/python3.11/site-packages/django/utils/log.py   (<class 'KeyError'>, KeyError('pk'), <traceback object at 0x7f03c0b2d100>)
Traceback (most recent call last):
  File "/home/alprostov/PycharmProjects/sakhlis/web/venv/lib/python3.11/site-packages/django/core/handlers/exception.py", line 55, in inner
    response = get_response(request)
               ^^^^^^^^^^^^^^^^^^^^^
  File "/home/alprostov/PycharmProjects/sakhlis/web/venv/lib/python3.11/site-packages/django/core/handlers/base.py", line 197, in _get_response
    response = wrapped_callback(request, *callback_args, **callback_kwargs)
               ^^^^^^^^^^^^^^^^^^^^^^^^^^^^^^^^^^^^^^^^^^^^^^^^^^^^^^^^^^^^
  File "/home/alprostov/PycharmProjects/sakhlis/web/venv/lib/python3.11/site-packages/django/views/generic/base.py", line 104, in view
    return self.dispatch(request, *args, **kwargs)
           ^^^^^^^^^^^^^^^^^^^^^^^^^^^^^^^^^^^^^^^
  File "/home/alprostov/PycharmProjects/sakhlis/web/venv/lib/python3.11/site-packages/django/views/generic/base.py", line 143, in dispatch
    return handler(request, *args, **kwargs)
           ^^^^^^^^^^^^^^^^^^^^^^^^^^^^^^^^^
  File "/home/alprostov/PycharmProjects/sakhlis/web/app_site/views.py", line 440, in post
    send_email(self.request.POST['email'],
  File "/home/alprostov/PycharmProjects/sakhlis/web/venv/lib/python3.11/site-packages/celery/local.py", line 188, in __call__
    return self._get_current_object()(*a, **kw)
           ^^^^^^^^^^^^^^^^^^^^^^^^^^^^^^^^^^^^
  File "/home/alprostov/PycharmProjects/sakhlis/web/venv/lib/python3.11/site-packages/celery/app/task.py", line 392, in __call__
    return self.run(*args, **kwargs)
           ^^^^^^^^^^^^^^^^^^^^^^^^^
  File "/home/alprostov/PycharmProjects/sakhlis/web/app_site/tasks.py", line 36, in send_email
    user_ = User.objects.get(pk=context_['pk'])
                                ~~~~~~~~^^^^^^
KeyError: 'pk'
02/Dec/2024 18:26:20    ERROR    basehttp    "POST /sendoffer HTTP/1.1" 500 103836   /home/alprostov/PycharmProjects/sakhlis/web/venv/lib/python3.11/site-packages/django/core/servers/basehttp.py   None
02/Dec/2024 18:29:09    ERROR    log    Internal Server Error: /sendoffer   /home/alprostov/PycharmProjects/sakhlis/web/venv/lib/python3.11/site-packages/django/utils/log.py   (<class 'NameError'>, NameError("name 'user_' is not defined"), <traceback object at 0x7f81a451ec00>)
Traceback (most recent call last):
  File "/home/alprostov/PycharmProjects/sakhlis/web/venv/lib/python3.11/site-packages/django/core/handlers/exception.py", line 55, in inner
    response = get_response(request)
               ^^^^^^^^^^^^^^^^^^^^^
  File "/home/alprostov/PycharmProjects/sakhlis/web/venv/lib/python3.11/site-packages/django/core/handlers/base.py", line 197, in _get_response
    response = wrapped_callback(request, *callback_args, **callback_kwargs)
               ^^^^^^^^^^^^^^^^^^^^^^^^^^^^^^^^^^^^^^^^^^^^^^^^^^^^^^^^^^^^
  File "/home/alprostov/PycharmProjects/sakhlis/web/venv/lib/python3.11/site-packages/django/views/generic/base.py", line 104, in view
    return self.dispatch(request, *args, **kwargs)
           ^^^^^^^^^^^^^^^^^^^^^^^^^^^^^^^^^^^^^^^
  File "/home/alprostov/PycharmProjects/sakhlis/web/venv/lib/python3.11/site-packages/django/views/generic/base.py", line 143, in dispatch
    return handler(request, *args, **kwargs)
           ^^^^^^^^^^^^^^^^^^^^^^^^^^^^^^^^^
  File "/home/alprostov/PycharmProjects/sakhlis/web/app_site/views.py", line 440, in post
    send_email(self.request.POST['email'],
  File "/home/alprostov/PycharmProjects/sakhlis/web/venv/lib/python3.11/site-packages/celery/local.py", line 188, in __call__
    return self._get_current_object()(*a, **kw)
           ^^^^^^^^^^^^^^^^^^^^^^^^^^^^^^^^^^^^
  File "/home/alprostov/PycharmProjects/sakhlis/web/venv/lib/python3.11/site-packages/celery/app/task.py", line 392, in __call__
    return self.run(*args, **kwargs)
           ^^^^^^^^^^^^^^^^^^^^^^^^^
  File "/home/alprostov/PycharmProjects/sakhlis/web/app_site/tasks.py", line 37, in send_email
    token=UserProfile.objects.get(user=user_).customer_name
                                       ^^^^^
NameError: name 'user_' is not defined
02/Dec/2024 18:29:09    ERROR    basehttp    "POST /sendoffer HTTP/1.1" 500 103946   /home/alprostov/PycharmProjects/sakhlis/web/venv/lib/python3.11/site-packages/django/core/servers/basehttp.py   None
02/Dec/2024 18:29:33    ERROR    log    Internal Server Error: /sendoffer   /home/alprostov/PycharmProjects/sakhlis/web/venv/lib/python3.11/site-packages/django/utils/log.py   (<class 'NameError'>, NameError("name 'user_' is not defined"), <traceback object at 0x7f819cdba580>)
Traceback (most recent call last):
  File "/home/alprostov/PycharmProjects/sakhlis/web/venv/lib/python3.11/site-packages/django/core/handlers/exception.py", line 55, in inner
    response = get_response(request)
               ^^^^^^^^^^^^^^^^^^^^^
  File "/home/alprostov/PycharmProjects/sakhlis/web/venv/lib/python3.11/site-packages/django/core/handlers/base.py", line 197, in _get_response
    response = wrapped_callback(request, *callback_args, **callback_kwargs)
               ^^^^^^^^^^^^^^^^^^^^^^^^^^^^^^^^^^^^^^^^^^^^^^^^^^^^^^^^^^^^
  File "/home/alprostov/PycharmProjects/sakhlis/web/venv/lib/python3.11/site-packages/django/views/generic/base.py", line 104, in view
    return self.dispatch(request, *args, **kwargs)
           ^^^^^^^^^^^^^^^^^^^^^^^^^^^^^^^^^^^^^^^
  File "/home/alprostov/PycharmProjects/sakhlis/web/venv/lib/python3.11/site-packages/django/views/generic/base.py", line 143, in dispatch
    return handler(request, *args, **kwargs)
           ^^^^^^^^^^^^^^^^^^^^^^^^^^^^^^^^^
  File "/home/alprostov/PycharmProjects/sakhlis/web/app_site/views.py", line 440, in post
    send_email(self.request.POST['email'],
  File "/home/alprostov/PycharmProjects/sakhlis/web/venv/lib/python3.11/site-packages/celery/local.py", line 188, in __call__
    return self._get_current_object()(*a, **kw)
           ^^^^^^^^^^^^^^^^^^^^^^^^^^^^^^^^^^^^
  File "/home/alprostov/PycharmProjects/sakhlis/web/venv/lib/python3.11/site-packages/celery/app/task.py", line 392, in __call__
    return self.run(*args, **kwargs)
           ^^^^^^^^^^^^^^^^^^^^^^^^^
  File "/home/alprostov/PycharmProjects/sakhlis/web/app_site/tasks.py", line 37, in send_email
    token=UserProfile.objects.get(user=user_).customer_name
                                       ^^^^^
NameError: name 'user_' is not defined
02/Dec/2024 18:29:33    ERROR    basehttp    "POST /sendoffer HTTP/1.1" 500 103948   /home/alprostov/PycharmProjects/sakhlis/web/venv/lib/python3.11/site-packages/django/core/servers/basehttp.py   None
02/Dec/2024 18:30:51    ERROR    log    Internal Server Error: /sendoffer   /home/alprostov/PycharmProjects/sakhlis/web/venv/lib/python3.11/site-packages/django/utils/log.py   (<class 'ValueError'>, ValueError("The view app_site.views.view didn't return an HttpResponse object. It returned None instead."), <traceback object at 0x7f4867d282c0>)
Traceback (most recent call last):
  File "/home/alprostov/PycharmProjects/sakhlis/web/venv/lib/python3.11/site-packages/django/core/handlers/exception.py", line 55, in inner
    response = get_response(request)
               ^^^^^^^^^^^^^^^^^^^^^
  File "/home/alprostov/PycharmProjects/sakhlis/web/venv/lib/python3.11/site-packages/django/core/handlers/base.py", line 204, in _get_response
    self.check_response(response, callback)
  File "/home/alprostov/PycharmProjects/sakhlis/web/venv/lib/python3.11/site-packages/django/core/handlers/base.py", line 332, in check_response
    raise ValueError(
ValueError: The view app_site.views.view didn't return an HttpResponse object. It returned None instead.
02/Dec/2024 18:30:51    ERROR    basehttp    "POST /sendoffer HTTP/1.1" 500 82675   /home/alprostov/PycharmProjects/sakhlis/web/venv/lib/python3.11/site-packages/django/core/servers/basehttp.py   None
02/Dec/2024 18:32:38    ERROR    log    Internal Server Error: /sendoffer   /home/alprostov/PycharmProjects/sakhlis/web/venv/lib/python3.11/site-packages/django/utils/log.py   (<class 'ValueError'>, ValueError("The view app_site.views.view didn't return an HttpResponse object. It returned None instead."), <traceback object at 0x7f1f75de7c40>)
Traceback (most recent call last):
  File "/home/alprostov/PycharmProjects/sakhlis/web/venv/lib/python3.11/site-packages/django/core/handlers/exception.py", line 55, in inner
    response = get_response(request)
               ^^^^^^^^^^^^^^^^^^^^^
  File "/home/alprostov/PycharmProjects/sakhlis/web/venv/lib/python3.11/site-packages/django/core/handlers/base.py", line 204, in _get_response
    self.check_response(response, callback)
  File "/home/alprostov/PycharmProjects/sakhlis/web/venv/lib/python3.11/site-packages/django/core/handlers/base.py", line 332, in check_response
    raise ValueError(
ValueError: The view app_site.views.view didn't return an HttpResponse object. It returned None instead.
02/Dec/2024 18:32:38    ERROR    basehttp    "POST /sendoffer HTTP/1.1" 500 82677   /home/alprostov/PycharmProjects/sakhlis/web/venv/lib/python3.11/site-packages/django/core/servers/basehttp.py   None
02/Dec/2024 18:33:19    ERROR    log    Internal Server Error: /sendoffer   /home/alprostov/PycharmProjects/sakhlis/web/venv/lib/python3.11/site-packages/django/utils/log.py   (<class 'ValueError'>, ValueError("The view app_site.views.view didn't return an HttpResponse object. It returned None instead."), <traceback object at 0x7f1f67549180>)
Traceback (most recent call last):
  File "/home/alprostov/PycharmProjects/sakhlis/web/venv/lib/python3.11/site-packages/django/core/handlers/exception.py", line 55, in inner
    response = get_response(request)
               ^^^^^^^^^^^^^^^^^^^^^
  File "/home/alprostov/PycharmProjects/sakhlis/web/venv/lib/python3.11/site-packages/django/core/handlers/base.py", line 204, in _get_response
    self.check_response(response, callback)
  File "/home/alprostov/PycharmProjects/sakhlis/web/venv/lib/python3.11/site-packages/django/core/handlers/base.py", line 332, in check_response
    raise ValueError(
ValueError: The view app_site.views.view didn't return an HttpResponse object. It returned None instead.
02/Dec/2024 18:33:19    ERROR    basehttp    "POST /sendoffer HTTP/1.1" 500 82675   /home/alprostov/PycharmProjects/sakhlis/web/venv/lib/python3.11/site-packages/django/core/servers/basehttp.py   None
02/Dec/2024 18:35:05    ERROR    log    Internal Server Error: /sendoffer   /home/alprostov/PycharmProjects/sakhlis/web/venv/lib/python3.11/site-packages/django/utils/log.py   (<class 'ValueError'>, ValueError("The view app_site.views.view didn't return an HttpResponse object. It returned None instead."), <traceback object at 0x7f07f5aafd00>)
Traceback (most recent call last):
  File "/home/alprostov/PycharmProjects/sakhlis/web/venv/lib/python3.11/site-packages/django/core/handlers/exception.py", line 55, in inner
    response = get_response(request)
               ^^^^^^^^^^^^^^^^^^^^^
  File "/home/alprostov/PycharmProjects/sakhlis/web/venv/lib/python3.11/site-packages/django/core/handlers/base.py", line 204, in _get_response
    self.check_response(response, callback)
  File "/home/alprostov/PycharmProjects/sakhlis/web/venv/lib/python3.11/site-packages/django/core/handlers/base.py", line 332, in check_response
    raise ValueError(
ValueError: The view app_site.views.view didn't return an HttpResponse object. It returned None instead.
02/Dec/2024 18:35:05    ERROR    basehttp    "POST /sendoffer HTTP/1.1" 500 82690   /home/alprostov/PycharmProjects/sakhlis/web/venv/lib/python3.11/site-packages/django/core/servers/basehttp.py   None
02/Dec/2024 18:37:17    ERROR    log    Internal Server Error: /sendoffer   /home/alprostov/PycharmProjects/sakhlis/web/venv/lib/python3.11/site-packages/django/utils/log.py   (<class 'socket.gaierror'>, gaierror(-3, 'Temporary failure in name resolution'), <traceback object at 0x7f5b611c3380>)
Traceback (most recent call last):
  File "/home/alprostov/PycharmProjects/sakhlis/web/venv/lib/python3.11/site-packages/django/core/handlers/exception.py", line 55, in inner
    response = get_response(request)
               ^^^^^^^^^^^^^^^^^^^^^
  File "/home/alprostov/PycharmProjects/sakhlis/web/venv/lib/python3.11/site-packages/django/core/handlers/base.py", line 197, in _get_response
    response = wrapped_callback(request, *callback_args, **callback_kwargs)
               ^^^^^^^^^^^^^^^^^^^^^^^^^^^^^^^^^^^^^^^^^^^^^^^^^^^^^^^^^^^^
  File "/home/alprostov/PycharmProjects/sakhlis/web/venv/lib/python3.11/site-packages/django/views/generic/base.py", line 104, in view
    return self.dispatch(request, *args, **kwargs)
           ^^^^^^^^^^^^^^^^^^^^^^^^^^^^^^^^^^^^^^^
  File "/home/alprostov/PycharmProjects/sakhlis/web/venv/lib/python3.11/site-packages/django/views/generic/base.py", line 143, in dispatch
    return handler(request, *args, **kwargs)
           ^^^^^^^^^^^^^^^^^^^^^^^^^^^^^^^^^
  File "/home/alprostov/PycharmProjects/sakhlis/web/app_site/views.py", line 440, in post
    send_email(self.request.POST['email'],
  File "/home/alprostov/PycharmProjects/sakhlis/web/venv/lib/python3.11/site-packages/celery/local.py", line 188, in __call__
    return self._get_current_object()(*a, **kw)
           ^^^^^^^^^^^^^^^^^^^^^^^^^^^^^^^^^^^^
  File "/home/alprostov/PycharmProjects/sakhlis/web/venv/lib/python3.11/site-packages/celery/app/task.py", line 392, in __call__
    return self.run(*args, **kwargs)
           ^^^^^^^^^^^^^^^^^^^^^^^^^
  File "/home/alprostov/PycharmProjects/sakhlis/web/app_site/tasks.py", line 49, in send_email
    msg.send()  # send email
    ^^^^^^^^^^
  File "/home/alprostov/PycharmProjects/sakhlis/web/venv/lib/python3.11/site-packages/django/core/mail/message.py", line 298, in send
    return self.get_connection(fail_silently).send_messages([self])
           ^^^^^^^^^^^^^^^^^^^^^^^^^^^^^^^^^^^^^^^^^^^^^^^^^^^^^^^^
  File "/home/alprostov/PycharmProjects/sakhlis/web/venv/lib/python3.11/site-packages/django/core/mail/backends/smtp.py", line 127, in send_messages
    new_conn_created = self.open()
                       ^^^^^^^^^^^
  File "/home/alprostov/PycharmProjects/sakhlis/web/venv/lib/python3.11/site-packages/django/core/mail/backends/smtp.py", line 85, in open
    self.connection = self.connection_class(
                      ^^^^^^^^^^^^^^^^^^^^^^
  File "/usr/lib/python3.11/smtplib.py", line 255, in __init__
    (code, msg) = self.connect(host, port)
                  ^^^^^^^^^^^^^^^^^^^^^^^^
  File "/usr/lib/python3.11/smtplib.py", line 341, in connect
    self.sock = self._get_socket(host, port, self.timeout)
                ^^^^^^^^^^^^^^^^^^^^^^^^^^^^^^^^^^^^^^^^^^
  File "/usr/lib/python3.11/smtplib.py", line 312, in _get_socket
    return socket.create_connection((host, port), timeout,
           ^^^^^^^^^^^^^^^^^^^^^^^^^^^^^^^^^^^^^^^^^^^^^^^
  File "/usr/lib/python3.11/socket.py", line 839, in create_connection
    for res in getaddrinfo(host, port, 0, SOCK_STREAM):
               ^^^^^^^^^^^^^^^^^^^^^^^^^^^^^^^^^^^^^^^
  File "/usr/lib/python3.11/socket.py", line 974, in getaddrinfo
    for res in _socket.getaddrinfo(host, port, family, type, proto, flags):
               ^^^^^^^^^^^^^^^^^^^^^^^^^^^^^^^^^^^^^^^^^^^^^^^^^^^^^^^^^^^
socket.gaierror: [Errno -3] Temporary failure in name resolution
02/Dec/2024 18:37:17    ERROR    basehttp    "POST /sendoffer HTTP/1.1" 500 142612   /home/alprostov/PycharmProjects/sakhlis/web/venv/lib/python3.11/site-packages/django/core/servers/basehttp.py   None
02/Dec/2024 18:38:14    ERROR    log    Internal Server Error: /sendoffer   /home/alprostov/PycharmProjects/sakhlis/web/venv/lib/python3.11/site-packages/django/utils/log.py   (<class 'ValueError'>, ValueError("The view app_site.views.view didn't return an HttpResponse object. It returned None instead."), <traceback object at 0x7f5b67bc9cc0>)
Traceback (most recent call last):
  File "/home/alprostov/PycharmProjects/sakhlis/web/venv/lib/python3.11/site-packages/django/core/handlers/exception.py", line 55, in inner
    response = get_response(request)
               ^^^^^^^^^^^^^^^^^^^^^
  File "/home/alprostov/PycharmProjects/sakhlis/web/venv/lib/python3.11/site-packages/django/core/handlers/base.py", line 204, in _get_response
    self.check_response(response, callback)
  File "/home/alprostov/PycharmProjects/sakhlis/web/venv/lib/python3.11/site-packages/django/core/handlers/base.py", line 332, in check_response
    raise ValueError(
ValueError: The view app_site.views.view didn't return an HttpResponse object. It returned None instead.
02/Dec/2024 18:38:14    ERROR    basehttp    "POST /sendoffer HTTP/1.1" 500 82690   /home/alprostov/PycharmProjects/sakhlis/web/venv/lib/python3.11/site-packages/django/core/servers/basehttp.py   None
02/Dec/2024 18:46:43    WARNING    log    Not Found: /favicon.ico   /home/alprostov/PycharmProjects/sakhlis/web/venv/lib/python3.11/site-packages/django/utils/log.py   None
02/Dec/2024 18:46:43    WARNING    basehttp    "GET /favicon.ico HTTP/1.1" 404 19746   /home/alprostov/PycharmProjects/sakhlis/web/venv/lib/python3.11/site-packages/django/core/servers/basehttp.py   None
02/Dec/2024 18:46:52    ERROR    log    Internal Server Error: /sendoffer   /home/alprostov/PycharmProjects/sakhlis/web/venv/lib/python3.11/site-packages/django/utils/log.py   (<class 'ValueError'>, ValueError("The view app_site.views.view didn't return an HttpResponse object. It returned None instead."), <traceback object at 0x7f5b606c66c0>)
Traceback (most recent call last):
  File "/home/alprostov/PycharmProjects/sakhlis/web/venv/lib/python3.11/site-packages/django/core/handlers/exception.py", line 55, in inner
    response = get_response(request)
               ^^^^^^^^^^^^^^^^^^^^^
  File "/home/alprostov/PycharmProjects/sakhlis/web/venv/lib/python3.11/site-packages/django/core/handlers/base.py", line 204, in _get_response
    self.check_response(response, callback)
  File "/home/alprostov/PycharmProjects/sakhlis/web/venv/lib/python3.11/site-packages/django/core/handlers/base.py", line 332, in check_response
    raise ValueError(
ValueError: The view app_site.views.view didn't return an HttpResponse object. It returned None instead.
02/Dec/2024 18:46:52    ERROR    basehttp    "POST /sendoffer HTTP/1.1" 500 82675   /home/alprostov/PycharmProjects/sakhlis/web/venv/lib/python3.11/site-packages/django/core/servers/basehttp.py   None
02/Dec/2024 19:07:19    ERROR    log    Internal Server Error: /sendoffer   /home/alprostov/PycharmProjects/sakhlis/web/venv/lib/python3.11/site-packages/django/utils/log.py   (<class 'ValueError'>, ValueError("The view app_site.views.view didn't return an HttpResponse object. It returned None instead."), <traceback object at 0x7fa4c03e3ac0>)
Traceback (most recent call last):
  File "/home/alprostov/PycharmProjects/sakhlis/web/venv/lib/python3.11/site-packages/django/core/handlers/exception.py", line 55, in inner
    response = get_response(request)
               ^^^^^^^^^^^^^^^^^^^^^
  File "/home/alprostov/PycharmProjects/sakhlis/web/venv/lib/python3.11/site-packages/django/core/handlers/base.py", line 204, in _get_response
    self.check_response(response, callback)
  File "/home/alprostov/PycharmProjects/sakhlis/web/venv/lib/python3.11/site-packages/django/core/handlers/base.py", line 332, in check_response
    raise ValueError(
ValueError: The view app_site.views.view didn't return an HttpResponse object. It returned None instead.
02/Dec/2024 19:07:19    ERROR    basehttp    "POST /sendoffer HTTP/1.1" 500 82676   /home/alprostov/PycharmProjects/sakhlis/web/venv/lib/python3.11/site-packages/django/core/servers/basehttp.py   None
03/Dec/2024 07:10:26    WARNING    log    Not Found: /favicon.ico   /home/alprostov/PycharmProjects/sakhlis/web/venv/lib/python3.11/site-packages/django/utils/log.py   None
03/Dec/2024 07:10:26    WARNING    basehttp    "GET /favicon.ico HTTP/1.1" 404 19746   /home/alprostov/PycharmProjects/sakhlis/web/venv/lib/python3.11/site-packages/django/core/servers/basehttp.py   None
03/Dec/2024 07:10:38    ERROR    log    Internal Server Error: /sendoffer   /home/alprostov/PycharmProjects/sakhlis/web/venv/lib/python3.11/site-packages/django/utils/log.py   (<class 'ValueError'>, ValueError("The view app_site.views.view didn't return an HttpResponse object. It returned None instead."), <traceback object at 0x7fdec8906b00>)
Traceback (most recent call last):
  File "/home/alprostov/PycharmProjects/sakhlis/web/venv/lib/python3.11/site-packages/django/core/handlers/exception.py", line 55, in inner
    response = get_response(request)
               ^^^^^^^^^^^^^^^^^^^^^
  File "/home/alprostov/PycharmProjects/sakhlis/web/venv/lib/python3.11/site-packages/django/core/handlers/base.py", line 204, in _get_response
    self.check_response(response, callback)
  File "/home/alprostov/PycharmProjects/sakhlis/web/venv/lib/python3.11/site-packages/django/core/handlers/base.py", line 332, in check_response
    raise ValueError(
ValueError: The view app_site.views.view didn't return an HttpResponse object. It returned None instead.
03/Dec/2024 07:10:38    ERROR    basehttp    "POST /sendoffer HTTP/1.1" 500 82675   /home/alprostov/PycharmProjects/sakhlis/web/venv/lib/python3.11/site-packages/django/core/servers/basehttp.py   None
03/Dec/2024 14:59:49    WARNING    log    Not Found: /favicon.ico   /home/alprostov/PycharmProjects/sakhlis/web/venv/lib/python3.11/site-packages/django/utils/log.py   None
03/Dec/2024 14:59:49    WARNING    basehttp    "GET /favicon.ico HTTP/1.1" 404 19746   /home/alprostov/PycharmProjects/sakhlis/web/venv/lib/python3.11/site-packages/django/core/servers/basehttp.py   None
03/Dec/2024 14:59:57    ERROR    log    Internal Server Error: /sendoffer   /home/alprostov/PycharmProjects/sakhlis/web/venv/lib/python3.11/site-packages/django/utils/log.py   (<class 'ValueError'>, ValueError("The view app_site.views.view didn't return an HttpResponse object. It returned None instead."), <traceback object at 0x7f355cf36fc0>)
Traceback (most recent call last):
  File "/home/alprostov/PycharmProjects/sakhlis/web/venv/lib/python3.11/site-packages/django/core/handlers/exception.py", line 55, in inner
    response = get_response(request)
               ^^^^^^^^^^^^^^^^^^^^^
  File "/home/alprostov/PycharmProjects/sakhlis/web/venv/lib/python3.11/site-packages/django/core/handlers/base.py", line 204, in _get_response
    self.check_response(response, callback)
  File "/home/alprostov/PycharmProjects/sakhlis/web/venv/lib/python3.11/site-packages/django/core/handlers/base.py", line 332, in check_response
    raise ValueError(
ValueError: The view app_site.views.view didn't return an HttpResponse object. It returned None instead.
03/Dec/2024 14:59:57    ERROR    basehttp    "POST /sendoffer HTTP/1.1" 500 82675   /home/alprostov/PycharmProjects/sakhlis/web/venv/lib/python3.11/site-packages/django/core/servers/basehttp.py   None
03/Dec/2024 15:00:31    ERROR    log    Internal Server Error: /sendoffer   /home/alprostov/PycharmProjects/sakhlis/web/venv/lib/python3.11/site-packages/django/utils/log.py   (<class 'ValueError'>, ValueError("The view app_site.views.view didn't return an HttpResponse object. It returned None instead."), <traceback object at 0x7f355d9733c0>)
Traceback (most recent call last):
  File "/home/alprostov/PycharmProjects/sakhlis/web/venv/lib/python3.11/site-packages/django/core/handlers/exception.py", line 55, in inner
    response = get_response(request)
               ^^^^^^^^^^^^^^^^^^^^^
  File "/home/alprostov/PycharmProjects/sakhlis/web/venv/lib/python3.11/site-packages/django/core/handlers/base.py", line 204, in _get_response
    self.check_response(response, callback)
  File "/home/alprostov/PycharmProjects/sakhlis/web/venv/lib/python3.11/site-packages/django/core/handlers/base.py", line 332, in check_response
    raise ValueError(
ValueError: The view app_site.views.view didn't return an HttpResponse object. It returned None instead.
03/Dec/2024 15:00:31    ERROR    basehttp    "POST /sendoffer HTTP/1.1" 500 82675   /home/alprostov/PycharmProjects/sakhlis/web/venv/lib/python3.11/site-packages/django/core/servers/basehttp.py   None
03/Dec/2024 15:12:32    ERROR    log    Internal Server Error: /sendoffer   /home/alprostov/PycharmProjects/sakhlis/web/venv/lib/python3.11/site-packages/django/utils/log.py   (<class 'ValueError'>, ValueError("The view app_site.views.view didn't return an HttpResponse object. It returned None instead."), <traceback object at 0x7efcc3bc9e40>)
Traceback (most recent call last):
  File "/home/alprostov/PycharmProjects/sakhlis/web/venv/lib/python3.11/site-packages/django/core/handlers/exception.py", line 55, in inner
    response = get_response(request)
               ^^^^^^^^^^^^^^^^^^^^^
  File "/home/alprostov/PycharmProjects/sakhlis/web/venv/lib/python3.11/site-packages/django/core/handlers/base.py", line 204, in _get_response
    self.check_response(response, callback)
  File "/home/alprostov/PycharmProjects/sakhlis/web/venv/lib/python3.11/site-packages/django/core/handlers/base.py", line 332, in check_response
    raise ValueError(
ValueError: The view app_site.views.view didn't return an HttpResponse object. It returned None instead.
03/Dec/2024 15:12:32    ERROR    basehttp    "POST /sendoffer HTTP/1.1" 500 82676   /home/alprostov/PycharmProjects/sakhlis/web/venv/lib/python3.11/site-packages/django/core/servers/basehttp.py   None
03/Dec/2024 15:12:46    ERROR    log    Internal Server Error: /sendoffer   /home/alprostov/PycharmProjects/sakhlis/web/venv/lib/python3.11/site-packages/django/utils/log.py   (<class 'ValueError'>, ValueError("The view app_site.views.view didn't return an HttpResponse object. It returned None instead."), <traceback object at 0x7efcc2d28ec0>)
Traceback (most recent call last):
  File "/home/alprostov/PycharmProjects/sakhlis/web/venv/lib/python3.11/site-packages/django/core/handlers/exception.py", line 55, in inner
    response = get_response(request)
               ^^^^^^^^^^^^^^^^^^^^^
  File "/home/alprostov/PycharmProjects/sakhlis/web/venv/lib/python3.11/site-packages/django/core/handlers/base.py", line 204, in _get_response
    self.check_response(response, callback)
  File "/home/alprostov/PycharmProjects/sakhlis/web/venv/lib/python3.11/site-packages/django/core/handlers/base.py", line 332, in check_response
    raise ValueError(
ValueError: The view app_site.views.view didn't return an HttpResponse object. It returned None instead.
03/Dec/2024 15:12:46    ERROR    basehttp    "POST /sendoffer HTTP/1.1" 500 82666   /home/alprostov/PycharmProjects/sakhlis/web/venv/lib/python3.11/site-packages/django/core/servers/basehttp.py   None
03/Dec/2024 15:18:55    ERROR    log    Internal Server Error: /sendoffer   /home/alprostov/PycharmProjects/sakhlis/web/venv/lib/python3.11/site-packages/django/utils/log.py   (<class 'ValueError'>, ValueError("The view app_site.views.view didn't return an HttpResponse object. It returned None instead."), <traceback object at 0x7fc65bbb5dc0>)
Traceback (most recent call last):
  File "/home/alprostov/PycharmProjects/sakhlis/web/venv/lib/python3.11/site-packages/django/core/handlers/exception.py", line 55, in inner
    response = get_response(request)
               ^^^^^^^^^^^^^^^^^^^^^
  File "/home/alprostov/PycharmProjects/sakhlis/web/venv/lib/python3.11/site-packages/django/core/handlers/base.py", line 204, in _get_response
    self.check_response(response, callback)
  File "/home/alprostov/PycharmProjects/sakhlis/web/venv/lib/python3.11/site-packages/django/core/handlers/base.py", line 332, in check_response
    raise ValueError(
ValueError: The view app_site.views.view didn't return an HttpResponse object. It returned None instead.
03/Dec/2024 15:18:55    ERROR    basehttp    "POST /sendoffer HTTP/1.1" 500 82674   /home/alprostov/PycharmProjects/sakhlis/web/venv/lib/python3.11/site-packages/django/core/servers/basehttp.py   None
03/Dec/2024 16:02:56    WARNING    log    Not Found: /favicon.ico   /home/alprostov/PycharmProjects/sakhlis/web/venv/lib/python3.11/site-packages/django/utils/log.py   None
03/Dec/2024 16:02:56    WARNING    basehttp    "GET /favicon.ico HTTP/1.1" 404 19746   /home/alprostov/PycharmProjects/sakhlis/web/venv/lib/python3.11/site-packages/django/core/servers/basehttp.py   None
03/Dec/2024 16:03:01    ERROR    log    Internal Server Error: /sendoffer   /home/alprostov/PycharmProjects/sakhlis/web/venv/lib/python3.11/site-packages/django/utils/log.py   (<class 'ValueError'>, ValueError("The view app_site.views.view didn't return an HttpResponse object. It returned None instead."), <traceback object at 0x7f0c6751c940>)
Traceback (most recent call last):
  File "/home/alprostov/PycharmProjects/sakhlis/web/venv/lib/python3.11/site-packages/django/core/handlers/exception.py", line 55, in inner
    response = get_response(request)
               ^^^^^^^^^^^^^^^^^^^^^
  File "/home/alprostov/PycharmProjects/sakhlis/web/venv/lib/python3.11/site-packages/django/core/handlers/base.py", line 204, in _get_response
    self.check_response(response, callback)
  File "/home/alprostov/PycharmProjects/sakhlis/web/venv/lib/python3.11/site-packages/django/core/handlers/base.py", line 332, in check_response
    raise ValueError(
ValueError: The view app_site.views.view didn't return an HttpResponse object. It returned None instead.
03/Dec/2024 16:03:01    ERROR    basehttp    "POST /sendoffer HTTP/1.1" 500 82675   /home/alprostov/PycharmProjects/sakhlis/web/venv/lib/python3.11/site-packages/django/core/servers/basehttp.py   None
03/Dec/2024 16:15:17    WARNING    log    Not Found: /favicon.ico   /home/alprostov/PycharmProjects/sakhlis/web/venv/lib/python3.11/site-packages/django/utils/log.py   None
03/Dec/2024 16:15:17    WARNING    basehttp    "GET /favicon.ico HTTP/1.1" 404 19746   /home/alprostov/PycharmProjects/sakhlis/web/venv/lib/python3.11/site-packages/django/core/servers/basehttp.py   None
08/Dec/2024 14:38:25    WARNING    log    Not Found: /favicon.ico   /home/alprostov/PycharmProjects/sakhlis/web/venv/lib/python3.11/site-packages/django/utils/log.py   None
08/Dec/2024 14:38:25    WARNING    basehttp    "GET /favicon.ico HTTP/1.1" 404 19746   /home/alprostov/PycharmProjects/sakhlis/web/venv/lib/python3.11/site-packages/django/core/servers/basehttp.py   None
08/Dec/2024 14:38:45    WARNING    log    Not Found: /media/masters/unknown_person.jpg   /home/alprostov/PycharmProjects/sakhlis/web/venv/lib/python3.11/site-packages/django/utils/log.py   None
08/Dec/2024 14:38:45    WARNING    basehttp    "GET /media/masters/unknown_person.jpg HTTP/1.1" 404 20046   /home/alprostov/PycharmProjects/sakhlis/web/venv/lib/python3.11/site-packages/django/core/servers/basehttp.py   None
08/Dec/2024 14:38:50    WARNING    log    Not Found: /media/masters/unknown_person.jpg   /home/alprostov/PycharmProjects/sakhlis/web/venv/lib/python3.11/site-packages/django/utils/log.py   None
08/Dec/2024 14:38:50    WARNING    basehttp    "GET /media/masters/unknown_person.jpg HTTP/1.1" 404 20046   /home/alprostov/PycharmProjects/sakhlis/web/venv/lib/python3.11/site-packages/django/core/servers/basehttp.py   None
08/Dec/2024 14:38:57    ERROR    log    Internal Server Error: /list_order   /home/alprostov/PycharmProjects/sakhlis/web/venv/lib/python3.11/site-packages/django/utils/log.py   (<class 'TypeError'>, TypeError('Cannot filter a query once a slice has been taken.'), <traceback object at 0x7fe02c025080>)
Traceback (most recent call last):
  File "/home/alprostov/PycharmProjects/sakhlis/web/venv/lib/python3.11/site-packages/django/core/handlers/exception.py", line 55, in inner
    response = get_response(request)
               ^^^^^^^^^^^^^^^^^^^^^
  File "/home/alprostov/PycharmProjects/sakhlis/web/venv/lib/python3.11/site-packages/django/core/handlers/base.py", line 197, in _get_response
    response = wrapped_callback(request, *callback_args, **callback_kwargs)
               ^^^^^^^^^^^^^^^^^^^^^^^^^^^^^^^^^^^^^^^^^^^^^^^^^^^^^^^^^^^^
  File "/home/alprostov/PycharmProjects/sakhlis/web/venv/lib/python3.11/site-packages/django/views/generic/base.py", line 104, in view
    return self.dispatch(request, *args, **kwargs)
           ^^^^^^^^^^^^^^^^^^^^^^^^^^^^^^^^^^^^^^^
  File "/home/alprostov/PycharmProjects/sakhlis/web/venv/lib/python3.11/site-packages/django/contrib/auth/mixins.py", line 73, in dispatch
    return super().dispatch(request, *args, **kwargs)
           ^^^^^^^^^^^^^^^^^^^^^^^^^^^^^^^^^^^^^^^^^^
  File "/home/alprostov/PycharmProjects/sakhlis/web/venv/lib/python3.11/site-packages/django/views/generic/base.py", line 143, in dispatch
    return handler(request, *args, **kwargs)
           ^^^^^^^^^^^^^^^^^^^^^^^^^^^^^^^^^
  File "/home/alprostov/PycharmProjects/sakhlis/web/venv/lib/python3.11/site-packages/django/views/generic/list.py", line 154, in get
    self.object_list = self.get_queryset()
                       ^^^^^^^^^^^^^^^^^^^
  File "/home/alprostov/PycharmProjects/sakhlis/web/app_site/views.py", line 330, in get_queryset
    return self.filterset.qs
           ^^^^^^^^^^^^^^^^^
  File "/home/alprostov/PycharmProjects/sakhlis/web/venv/lib/python3.11/site-packages/django_filters/filterset.py", line 230, in qs
    qs = self.filter_queryset(qs)
         ^^^^^^^^^^^^^^^^^^^^^^^^
  File "/home/alprostov/PycharmProjects/sakhlis/web/venv/lib/python3.11/site-packages/django_filters/filterset.py", line 213, in filter_queryset
    queryset = self.filters[name].filter(queryset, value)
               ^^^^^^^^^^^^^^^^^^^^^^^^^^^^^^^^^^^^^^^^^^
  File "/home/alprostov/PycharmProjects/sakhlis/web/venv/lib/python3.11/site-packages/django_filters/filters.py", line 158, in filter
    qs = self.get_method(qs)(**{lookup: value})
         ^^^^^^^^^^^^^^^^^^^^^^^^^^^^^^^^^^^^^^
  File "/home/alprostov/PycharmProjects/sakhlis/web/venv/lib/python3.11/site-packages/django/db/models/query.py", line 1436, in filter
    return self._filter_or_exclude(False, args, kwargs)
           ^^^^^^^^^^^^^^^^^^^^^^^^^^^^^^^^^^^^^^^^^^^^
  File "/home/alprostov/PycharmProjects/sakhlis/web/venv/lib/python3.11/site-packages/django/db/models/query.py", line 1448, in _filter_or_exclude
    raise TypeError("Cannot filter a query once a slice has been taken.")
TypeError: Cannot filter a query once a slice has been taken.
08/Dec/2024 14:38:57    ERROR    basehttp    "GET /list_order?time_in_sence=2024-10-08&time_in_until=&order_status=&repairer_id= HTTP/1.1" 500 158647   /home/alprostov/PycharmProjects/sakhlis/web/venv/lib/python3.11/site-packages/django/core/servers/basehttp.py   None
08/Dec/2024 14:40:48    WARNING    log    Not Found: /media/masters/unknown_person.jpg   /home/alprostov/PycharmProjects/sakhlis/web/venv/lib/python3.11/site-packages/django/utils/log.py   None
08/Dec/2024 14:40:48    WARNING    basehttp    "GET /media/masters/unknown_person.jpg HTTP/1.1" 404 20046   /home/alprostov/PycharmProjects/sakhlis/web/venv/lib/python3.11/site-packages/django/core/servers/basehttp.py   None
08/Dec/2024 14:41:10    WARNING    log    Not Found: /media/masters/unknown_person.jpg   /home/alprostov/PycharmProjects/sakhlis/web/venv/lib/python3.11/site-packages/django/utils/log.py   None
08/Dec/2024 14:41:10    WARNING    basehttp    "GET /media/masters/unknown_person.jpg HTTP/1.1" 404 20046   /home/alprostov/PycharmProjects/sakhlis/web/venv/lib/python3.11/site-packages/django/core/servers/basehttp.py   None
08/Dec/2024 14:41:22    WARNING    log    Not Found: /media/masters/unknown_person.jpg   /home/alprostov/PycharmProjects/sakhlis/web/venv/lib/python3.11/site-packages/django/utils/log.py   None
08/Dec/2024 14:41:22    WARNING    basehttp    "GET /media/masters/unknown_person.jpg HTTP/1.1" 404 20046   /home/alprostov/PycharmProjects/sakhlis/web/venv/lib/python3.11/site-packages/django/core/servers/basehttp.py   None
08/Dec/2024 14:41:23    WARNING    log    Not Found: /media/masters/unknown_person.jpg   /home/alprostov/PycharmProjects/sakhlis/web/venv/lib/python3.11/site-packages/django/utils/log.py   None
08/Dec/2024 14:41:23    WARNING    basehttp    "GET /media/masters/unknown_person.jpg HTTP/1.1" 404 20046   /home/alprostov/PycharmProjects/sakhlis/web/venv/lib/python3.11/site-packages/django/core/servers/basehttp.py   None
08/Dec/2024 14:41:24    WARNING    log    Not Found: /media/masters/unknown_person.jpg   /home/alprostov/PycharmProjects/sakhlis/web/venv/lib/python3.11/site-packages/django/utils/log.py   None
08/Dec/2024 14:41:24    WARNING    basehttp    "GET /media/masters/unknown_person.jpg HTTP/1.1" 404 20046   /home/alprostov/PycharmProjects/sakhlis/web/venv/lib/python3.11/site-packages/django/core/servers/basehttp.py   None
08/Dec/2024 14:41:44    WARNING    log    Not Found: /media/masters/unknown_person.jpg   /home/alprostov/PycharmProjects/sakhlis/web/venv/lib/python3.11/site-packages/django/utils/log.py   None
08/Dec/2024 14:41:44    WARNING    basehttp    "GET /media/masters/unknown_person.jpg HTTP/1.1" 404 20046   /home/alprostov/PycharmProjects/sakhlis/web/venv/lib/python3.11/site-packages/django/core/servers/basehttp.py   None
08/Dec/2024 14:41:44    WARNING    log    Not Found: /media/masters/unknown_person.jpg   /home/alprostov/PycharmProjects/sakhlis/web/venv/lib/python3.11/site-packages/django/utils/log.py   None
08/Dec/2024 14:41:44    WARNING    basehttp    "GET /media/masters/unknown_person.jpg HTTP/1.1" 404 20046   /home/alprostov/PycharmProjects/sakhlis/web/venv/lib/python3.11/site-packages/django/core/servers/basehttp.py   None
08/Dec/2024 14:41:54    WARNING    log    Not Found: /media/   /home/alprostov/PycharmProjects/sakhlis/web/venv/lib/python3.11/site-packages/django/utils/log.py   None
08/Dec/2024 14:41:54    WARNING    basehttp    "GET /media/ HTTP/1.1" 404 19884   /home/alprostov/PycharmProjects/sakhlis/web/venv/lib/python3.11/site-packages/django/core/servers/basehttp.py   None
08/Dec/2024 18:25:58    WARNING    log    Not Found: /media/masters/unknown_person.jpg   /home/alprostov/PycharmProjects/sakhlis/web/venv/lib/python3.11/site-packages/django/utils/log.py   None
08/Dec/2024 18:25:58    WARNING    basehttp    "GET /media/masters/unknown_person.jpg HTTP/1.1" 404 20046   /home/alprostov/PycharmProjects/sakhlis/web/venv/lib/python3.11/site-packages/django/core/servers/basehttp.py   None
08/Dec/2024 18:25:59    WARNING    log    Not Found: /favicon.ico   /home/alprostov/PycharmProjects/sakhlis/web/venv/lib/python3.11/site-packages/django/utils/log.py   None
08/Dec/2024 18:25:59    WARNING    basehttp    "GET /favicon.ico HTTP/1.1" 404 19746   /home/alprostov/PycharmProjects/sakhlis/web/venv/lib/python3.11/site-packages/django/core/servers/basehttp.py   None
08/Dec/2024 18:26:07    WARNING    log    Not Found: /media/masters/unknown_person.jpg   /home/alprostov/PycharmProjects/sakhlis/web/venv/lib/python3.11/site-packages/django/utils/log.py   None
08/Dec/2024 18:26:07    WARNING    basehttp    "GET /media/masters/unknown_person.jpg HTTP/1.1" 404 20046   /home/alprostov/PycharmProjects/sakhlis/web/venv/lib/python3.11/site-packages/django/core/servers/basehttp.py   None
08/Dec/2024 18:28:02    WARNING    log    Not Found: /media/masters/unknown_person.jpg   /home/alprostov/PycharmProjects/sakhlis/web/venv/lib/python3.11/site-packages/django/utils/log.py   None
08/Dec/2024 18:28:02    WARNING    basehttp    "GET /media/masters/unknown_person.jpg HTTP/1.1" 404 20046   /home/alprostov/PycharmProjects/sakhlis/web/venv/lib/python3.11/site-packages/django/core/servers/basehttp.py   None
08/Dec/2024 18:30:09    WARNING    log    Not Found: /media/masters/unknown_person.jpg   /home/alprostov/PycharmProjects/sakhlis/web/venv/lib/python3.11/site-packages/django/utils/log.py   None
08/Dec/2024 18:30:09    WARNING    basehttp    "GET /media/masters/unknown_person.jpg HTTP/1.1" 404 20046   /home/alprostov/PycharmProjects/sakhlis/web/venv/lib/python3.11/site-packages/django/core/servers/basehttp.py   None
08/Dec/2024 18:30:18    WARNING    log    Not Found: /media/masters/unknown_person.jpg   /home/alprostov/PycharmProjects/sakhlis/web/venv/lib/python3.11/site-packages/django/utils/log.py   None
08/Dec/2024 18:30:18    WARNING    basehttp    "GET /media/masters/unknown_person.jpg HTTP/1.1" 404 20046   /home/alprostov/PycharmProjects/sakhlis/web/venv/lib/python3.11/site-packages/django/core/servers/basehttp.py   None
08/Dec/2024 18:30:53    WARNING    log    Not Found: /media/masters/unknown_person.jpg   /home/alprostov/PycharmProjects/sakhlis/web/venv/lib/python3.11/site-packages/django/utils/log.py   None
08/Dec/2024 18:30:53    WARNING    basehttp    "GET /media/masters/unknown_person.jpg HTTP/1.1" 404 20046   /home/alprostov/PycharmProjects/sakhlis/web/venv/lib/python3.11/site-packages/django/core/servers/basehttp.py   None
08/Dec/2024 18:31:01    WARNING    log    Not Found: /media/masters/unknown_person.jpg   /home/alprostov/PycharmProjects/sakhlis/web/venv/lib/python3.11/site-packages/django/utils/log.py   None
08/Dec/2024 18:31:01    WARNING    basehttp    "GET /media/masters/unknown_person.jpg HTTP/1.1" 404 20046   /home/alprostov/PycharmProjects/sakhlis/web/venv/lib/python3.11/site-packages/django/core/servers/basehttp.py   None
08/Dec/2024 18:35:12    WARNING    log    Not Found: /media/masters/unknown_person.jpg   /home/alprostov/PycharmProjects/sakhlis/web/venv/lib/python3.11/site-packages/django/utils/log.py   None
08/Dec/2024 18:35:12    WARNING    basehttp    "GET /media/masters/unknown_person.jpg HTTP/1.1" 404 20046   /home/alprostov/PycharmProjects/sakhlis/web/venv/lib/python3.11/site-packages/django/core/servers/basehttp.py   None
08/Dec/2024 18:36:56    WARNING    log    Not Found: /media/masters/unknown_person.jpg   /home/alprostov/PycharmProjects/sakhlis/web/venv/lib/python3.11/site-packages/django/utils/log.py   None
08/Dec/2024 18:36:56    WARNING    basehttp    "GET /media/masters/unknown_person.jpg HTTP/1.1" 404 20046   /home/alprostov/PycharmProjects/sakhlis/web/venv/lib/python3.11/site-packages/django/core/servers/basehttp.py   None
08/Dec/2024 18:46:27    WARNING    log    Not Found: /media/masters/unknown_person.jpg   /home/alprostov/PycharmProjects/sakhlis/web/venv/lib/python3.11/site-packages/django/utils/log.py   None
08/Dec/2024 18:46:27    WARNING    basehttp    "GET /media/masters/unknown_person.jpg HTTP/1.1" 404 20046   /home/alprostov/PycharmProjects/sakhlis/web/venv/lib/python3.11/site-packages/django/core/servers/basehttp.py   None
10/Dec/2024 11:43:07    WARNING    log    Not Found: /favicon.ico   /home/alprostov/PycharmProjects/sakhlis/web/venv/lib/python3.11/site-packages/django/utils/log.py   None
10/Dec/2024 11:43:07    WARNING    basehttp    "GET /favicon.ico HTTP/1.1" 404 19746   /home/alprostov/PycharmProjects/sakhlis/web/venv/lib/python3.11/site-packages/django/core/servers/basehttp.py   None
10/Dec/2024 11:43:13    WARNING    log    Not Found: /media/masters/unknown_person.jpg   /home/alprostov/PycharmProjects/sakhlis/web/venv/lib/python3.11/site-packages/django/utils/log.py   None
10/Dec/2024 11:43:13    WARNING    basehttp    "GET /media/masters/unknown_person.jpg HTTP/1.1" 404 20046   /home/alprostov/PycharmProjects/sakhlis/web/venv/lib/python3.11/site-packages/django/core/servers/basehttp.py   None
10/Dec/2024 11:43:14    WARNING    log    Not Found: /media/masters/unknown_person.jpg   /home/alprostov/PycharmProjects/sakhlis/web/venv/lib/python3.11/site-packages/django/utils/log.py   None
10/Dec/2024 11:43:14    WARNING    basehttp    "GET /media/masters/unknown_person.jpg HTTP/1.1" 404 20046   /home/alprostov/PycharmProjects/sakhlis/web/venv/lib/python3.11/site-packages/django/core/servers/basehttp.py   None
10/Dec/2024 11:43:19    WARNING    log    Not Found: /media/masters/unknown_person.jpg   /home/alprostov/PycharmProjects/sakhlis/web/venv/lib/python3.11/site-packages/django/utils/log.py   None
10/Dec/2024 11:43:19    WARNING    basehttp    "GET /media/masters/unknown_person.jpg HTTP/1.1" 404 20046   /home/alprostov/PycharmProjects/sakhlis/web/venv/lib/python3.11/site-packages/django/core/servers/basehttp.py   None
10/Dec/2024 11:43:20    WARNING    log    Not Found: /media/masters/unknown_person.jpg   /home/alprostov/PycharmProjects/sakhlis/web/venv/lib/python3.11/site-packages/django/utils/log.py   None
10/Dec/2024 11:43:20    WARNING    basehttp    "GET /media/masters/unknown_person.jpg HTTP/1.1" 404 20046   /home/alprostov/PycharmProjects/sakhlis/web/venv/lib/python3.11/site-packages/django/core/servers/basehttp.py   None
10/Dec/2024 11:43:21    WARNING    log    Not Found: /media/masters/unknown_person.jpg   /home/alprostov/PycharmProjects/sakhlis/web/venv/lib/python3.11/site-packages/django/utils/log.py   None
10/Dec/2024 11:43:21    WARNING    basehttp    "GET /media/masters/unknown_person.jpg HTTP/1.1" 404 20046   /home/alprostov/PycharmProjects/sakhlis/web/venv/lib/python3.11/site-packages/django/core/servers/basehttp.py   None
10/Dec/2024 11:43:25    WARNING    log    Not Found: /media/masters/unknown_person.jpg   /home/alprostov/PycharmProjects/sakhlis/web/venv/lib/python3.11/site-packages/django/utils/log.py   None
10/Dec/2024 11:43:25    WARNING    basehttp    "GET /media/masters/unknown_person.jpg HTTP/1.1" 404 20046   /home/alprostov/PycharmProjects/sakhlis/web/venv/lib/python3.11/site-packages/django/core/servers/basehttp.py   None
10/Dec/2024 11:43:25    WARNING    log    Not Found: /media/masters/unknown_person.jpg   /home/alprostov/PycharmProjects/sakhlis/web/venv/lib/python3.11/site-packages/django/utils/log.py   None
10/Dec/2024 11:43:25    WARNING    basehttp    "GET /media/masters/unknown_person.jpg HTTP/1.1" 404 20046   /home/alprostov/PycharmProjects/sakhlis/web/venv/lib/python3.11/site-packages/django/core/servers/basehttp.py   None
10/Dec/2024 11:43:29    WARNING    log    Not Found: /media/masters/unknown_person.jpg   /home/alprostov/PycharmProjects/sakhlis/web/venv/lib/python3.11/site-packages/django/utils/log.py   None
10/Dec/2024 11:43:29    WARNING    basehttp    "GET /media/masters/unknown_person.jpg HTTP/1.1" 404 20046   /home/alprostov/PycharmProjects/sakhlis/web/venv/lib/python3.11/site-packages/django/core/servers/basehttp.py   None
10/Dec/2024 11:43:29    WARNING    log    Not Found: /media/masters/unknown_person.jpg   /home/alprostov/PycharmProjects/sakhlis/web/venv/lib/python3.11/site-packages/django/utils/log.py   None
10/Dec/2024 11:43:29    WARNING    basehttp    "GET /media/masters/unknown_person.jpg HTTP/1.1" 404 20046   /home/alprostov/PycharmProjects/sakhlis/web/venv/lib/python3.11/site-packages/django/core/servers/basehttp.py   None
10/Dec/2024 11:43:32    WARNING    log    Not Found: /media/masters/unknown_person.jpg   /home/alprostov/PycharmProjects/sakhlis/web/venv/lib/python3.11/site-packages/django/utils/log.py   None
10/Dec/2024 11:43:32    WARNING    basehttp    "GET /media/masters/unknown_person.jpg HTTP/1.1" 404 20046   /home/alprostov/PycharmProjects/sakhlis/web/venv/lib/python3.11/site-packages/django/core/servers/basehttp.py   None
10/Dec/2024 11:43:32    WARNING    log    Not Found: /media/masters/unknown_person.jpg   /home/alprostov/PycharmProjects/sakhlis/web/venv/lib/python3.11/site-packages/django/utils/log.py   None
10/Dec/2024 11:43:32    WARNING    basehttp    "GET /media/masters/unknown_person.jpg HTTP/1.1" 404 20046   /home/alprostov/PycharmProjects/sakhlis/web/venv/lib/python3.11/site-packages/django/core/servers/basehttp.py   None
10/Dec/2024 11:43:36    WARNING    log    Not Found: /media/masters/unknown_person.jpg   /home/alprostov/PycharmProjects/sakhlis/web/venv/lib/python3.11/site-packages/django/utils/log.py   None
10/Dec/2024 11:43:36    WARNING    basehttp    "GET /media/masters/unknown_person.jpg HTTP/1.1" 404 20046   /home/alprostov/PycharmProjects/sakhlis/web/venv/lib/python3.11/site-packages/django/core/servers/basehttp.py   None
10/Dec/2024 11:43:36    WARNING    log    Not Found: /media/masters/unknown_person.jpg   /home/alprostov/PycharmProjects/sakhlis/web/venv/lib/python3.11/site-packages/django/utils/log.py   None
10/Dec/2024 11:43:36    WARNING    basehttp    "GET /media/masters/unknown_person.jpg HTTP/1.1" 404 20046   /home/alprostov/PycharmProjects/sakhlis/web/venv/lib/python3.11/site-packages/django/core/servers/basehttp.py   None
10/Dec/2024 11:43:53    WARNING    log    Not Found: /media/masters/unknown_person.jpg   /home/alprostov/PycharmProjects/sakhlis/web/venv/lib/python3.11/site-packages/django/utils/log.py   None
10/Dec/2024 11:43:53    WARNING    basehttp    "GET /media/masters/unknown_person.jpg HTTP/1.1" 404 20046   /home/alprostov/PycharmProjects/sakhlis/web/venv/lib/python3.11/site-packages/django/core/servers/basehttp.py   None
10/Dec/2024 11:44:06    WARNING    log    Not Found: /media/masters/unknown_person.jpg   /home/alprostov/PycharmProjects/sakhlis/web/venv/lib/python3.11/site-packages/django/utils/log.py   None
10/Dec/2024 11:44:06    WARNING    basehttp    "GET /media/masters/unknown_person.jpg HTTP/1.1" 404 20046   /home/alprostov/PycharmProjects/sakhlis/web/venv/lib/python3.11/site-packages/django/core/servers/basehttp.py   None
10/Dec/2024 11:44:06    WARNING    log    Not Found: /media/masters/unknown_person.jpg   /home/alprostov/PycharmProjects/sakhlis/web/venv/lib/python3.11/site-packages/django/utils/log.py   None
10/Dec/2024 11:44:06    WARNING    basehttp    "GET /media/masters/unknown_person.jpg HTTP/1.1" 404 20046   /home/alprostov/PycharmProjects/sakhlis/web/venv/lib/python3.11/site-packages/django/core/servers/basehttp.py   None
10/Dec/2024 11:44:08    WARNING    log    Not Found: /media/   /home/alprostov/PycharmProjects/sakhlis/web/venv/lib/python3.11/site-packages/django/utils/log.py   None
10/Dec/2024 11:44:08    WARNING    basehttp    "GET /media/ HTTP/1.1" 404 19884   /home/alprostov/PycharmProjects/sakhlis/web/venv/lib/python3.11/site-packages/django/core/servers/basehttp.py   None
10/Dec/2024 11:44:14    WARNING    log    Not Found: /media/undefined   /home/alprostov/PycharmProjects/sakhlis/web/venv/lib/python3.11/site-packages/django/utils/log.py   None
10/Dec/2024 11:44:14    WARNING    basehttp    "GET /media/undefined HTTP/1.1" 404 19961   /home/alprostov/PycharmProjects/sakhlis/web/venv/lib/python3.11/site-packages/django/core/servers/basehttp.py   None
10/Dec/2024 11:44:18    WARNING    log    Not Found: /media/   /home/alprostov/PycharmProjects/sakhlis/web/venv/lib/python3.11/site-packages/django/utils/log.py   None
10/Dec/2024 11:44:18    WARNING    basehttp    "GET /media/ HTTP/1.1" 404 19884   /home/alprostov/PycharmProjects/sakhlis/web/venv/lib/python3.11/site-packages/django/core/servers/basehttp.py   None
10/Dec/2024 11:44:23    WARNING    log    Not Found: /media/masters/unknown_person.jpg   /home/alprostov/PycharmProjects/sakhlis/web/venv/lib/python3.11/site-packages/django/utils/log.py   None
10/Dec/2024 11:44:23    WARNING    basehttp    "GET /media/masters/unknown_person.jpg HTTP/1.1" 404 20046   /home/alprostov/PycharmProjects/sakhlis/web/venv/lib/python3.11/site-packages/django/core/servers/basehttp.py   None
10/Dec/2024 11:49:20    WARNING    log    Not Found: /admin/app_site/clients/1/change/   /home/alprostov/PycharmProjects/sakhlis/web/venv/lib/python3.11/site-packages/django/utils/log.py   None
10/Dec/2024 11:49:20    WARNING    basehttp    "GET /admin/app_site/clients/1/change/ HTTP/1.1" 404 15445   /home/alprostov/PycharmProjects/sakhlis/web/venv/lib/python3.11/site-packages/django/core/servers/basehttp.py   None
10/Dec/2024 18:28:38    WARNING    log    Not Found: /media/masters/unknown_person.jpg   /home/alprostov/PycharmProjects/sakhlis/web/venv/lib/python3.11/site-packages/django/utils/log.py   None
10/Dec/2024 18:28:38    WARNING    basehttp    "GET /media/masters/unknown_person.jpg HTTP/1.1" 404 20046   /home/alprostov/PycharmProjects/sakhlis/web/venv/lib/python3.11/site-packages/django/core/servers/basehttp.py   None
10/Dec/2024 18:28:38    WARNING    log    Not Found: /media/masters/unknown_person.jpg   /home/alprostov/PycharmProjects/sakhlis/web/venv/lib/python3.11/site-packages/django/utils/log.py   None
10/Dec/2024 18:28:38    WARNING    basehttp    "GET /media/masters/unknown_person.jpg HTTP/1.1" 404 20046   /home/alprostov/PycharmProjects/sakhlis/web/venv/lib/python3.11/site-packages/django/core/servers/basehttp.py   None
10/Dec/2024 18:28:38    WARNING    log    Not Found: /favicon.ico   /home/alprostov/PycharmProjects/sakhlis/web/venv/lib/python3.11/site-packages/django/utils/log.py   None
10/Dec/2024 18:28:38    WARNING    basehttp    "GET /favicon.ico HTTP/1.1" 404 19746   /home/alprostov/PycharmProjects/sakhlis/web/venv/lib/python3.11/site-packages/django/core/servers/basehttp.py   None
10/Dec/2024 18:31:19    WARNING    log    Not Found: /admin/djcelery   /home/alprostov/PycharmProjects/sakhlis/web/venv/lib/python3.11/site-packages/django/utils/log.py   None
10/Dec/2024 18:31:19    WARNING    basehttp    "GET /admin/djcelery HTTP/1.1" 404 15371   /home/alprostov/PycharmProjects/sakhlis/web/venv/lib/python3.11/site-packages/django/core/servers/basehttp.py   None
14/Dec/2024 21:11:10    WARNING    log    Not Found: /favicon.ico   /home/alprostov/PycharmProjects/sakhlis/web/venv/lib/python3.11/site-packages/django/utils/log.py   None
14/Dec/2024 21:11:10    WARNING    basehttp    "GET /favicon.ico HTTP/1.1" 404 19898   /home/alprostov/PycharmProjects/sakhlis/web/venv/lib/python3.11/site-packages/django/core/servers/basehttp.py   None
14/Dec/2024 21:11:16    ERROR    log    Internal Server Error: /mails   /home/alprostov/PycharmProjects/sakhlis/web/venv/lib/python3.11/site-packages/django/utils/log.py   (<class 'TypeError'>, TypeError('aaa() takes 0 positional arguments but 1 was given'), <traceback object at 0x7f0c27b88300>)
Traceback (most recent call last):
  File "/home/alprostov/PycharmProjects/sakhlis/web/venv/lib/python3.11/site-packages/django/core/handlers/exception.py", line 55, in inner
    response = get_response(request)
               ^^^^^^^^^^^^^^^^^^^^^
  File "/home/alprostov/PycharmProjects/sakhlis/web/venv/lib/python3.11/site-packages/django/core/handlers/base.py", line 197, in _get_response
    response = wrapped_callback(request, *callback_args, **callback_kwargs)
               ^^^^^^^^^^^^^^^^^^^^^^^^^^^^^^^^^^^^^^^^^^^^^^^^^^^^^^^^^^^^
TypeError: aaa() takes 0 positional arguments but 1 was given
14/Dec/2024 21:11:16    ERROR    basehttp    "GET /mails HTTP/1.1" 500 76618   /home/alprostov/PycharmProjects/sakhlis/web/venv/lib/python3.11/site-packages/django/core/servers/basehttp.py   None
14/Dec/2024 21:11:45    ERROR    log    Internal Server Error: /mails   /home/alprostov/PycharmProjects/sakhlis/web/venv/lib/python3.11/site-packages/django/utils/log.py   (<class 'ImportError'>, ImportError("Missing optional dependency 'openpyxl'.  Use pip or conda to install openpyxl."), <traceback object at 0x7f6d59ee44c0>)
Traceback (most recent call last):
  File "/home/alprostov/PycharmProjects/sakhlis/web/venv/lib/python3.11/site-packages/pandas/compat/_optional.py", line 135, in import_optional_dependency
    module = importlib.import_module(name)
             ^^^^^^^^^^^^^^^^^^^^^^^^^^^^^
  File "/usr/lib/python3.11/importlib/__init__.py", line 126, in import_module
    return _bootstrap._gcd_import(name[level:], package, level)
           ^^^^^^^^^^^^^^^^^^^^^^^^^^^^^^^^^^^^^^^^^^^^^^^^^^^^
  File "<frozen importlib._bootstrap>", line 1204, in _gcd_import
  File "<frozen importlib._bootstrap>", line 1176, in _find_and_load
  File "<frozen importlib._bootstrap>", line 1140, in _find_and_load_unlocked
ModuleNotFoundError: No module named 'openpyxl'

During handling of the above exception, another exception occurred:

Traceback (most recent call last):
  File "/home/alprostov/PycharmProjects/sakhlis/web/venv/lib/python3.11/site-packages/django/core/handlers/exception.py", line 55, in inner
    response = get_response(request)
               ^^^^^^^^^^^^^^^^^^^^^
  File "/home/alprostov/PycharmProjects/sakhlis/web/venv/lib/python3.11/site-packages/django/core/handlers/base.py", line 197, in _get_response
    response = wrapped_callback(request, *callback_args, **callback_kwargs)
               ^^^^^^^^^^^^^^^^^^^^^^^^^^^^^^^^^^^^^^^^^^^^^^^^^^^^^^^^^^^^
  File "/home/alprostov/PycharmProjects/sakhlis/web/app_site/views.py", line 688, in aaa
    excel_data = pd.read_excel('emails.xlsx')
                 ^^^^^^^^^^^^^^^^^^^^^^^^^^^^
  File "/home/alprostov/PycharmProjects/sakhlis/web/venv/lib/python3.11/site-packages/pandas/io/excel/_base.py", line 495, in read_excel
    io = ExcelFile(
         ^^^^^^^^^^
  File "/home/alprostov/PycharmProjects/sakhlis/web/venv/lib/python3.11/site-packages/pandas/io/excel/_base.py", line 1567, in __init__
    self._reader = self._engines[engine](
                   ^^^^^^^^^^^^^^^^^^^^^^
  File "/home/alprostov/PycharmProjects/sakhlis/web/venv/lib/python3.11/site-packages/pandas/io/excel/_openpyxl.py", line 552, in __init__
    import_optional_dependency("openpyxl")
  File "/home/alprostov/PycharmProjects/sakhlis/web/venv/lib/python3.11/site-packages/pandas/compat/_optional.py", line 138, in import_optional_dependency
    raise ImportError(msg)
ImportError: Missing optional dependency 'openpyxl'.  Use pip or conda to install openpyxl.
14/Dec/2024 21:11:45    ERROR    basehttp    "GET /mails HTTP/1.1" 500 117738   /home/alprostov/PycharmProjects/sakhlis/web/venv/lib/python3.11/site-packages/django/core/servers/basehttp.py   None
14/Dec/2024 21:11:49    ERROR    log    Internal Server Error: /mails   /home/alprostov/PycharmProjects/sakhlis/web/venv/lib/python3.11/site-packages/django/utils/log.py   (<class 'ImportError'>, ImportError("Missing optional dependency 'openpyxl'.  Use pip or conda to install openpyxl."), <traceback object at 0x7f6d63db5d40>)
Traceback (most recent call last):
  File "/home/alprostov/PycharmProjects/sakhlis/web/venv/lib/python3.11/site-packages/pandas/compat/_optional.py", line 135, in import_optional_dependency
    module = importlib.import_module(name)
             ^^^^^^^^^^^^^^^^^^^^^^^^^^^^^
  File "/usr/lib/python3.11/importlib/__init__.py", line 126, in import_module
    return _bootstrap._gcd_import(name[level:], package, level)
           ^^^^^^^^^^^^^^^^^^^^^^^^^^^^^^^^^^^^^^^^^^^^^^^^^^^^
  File "<frozen importlib._bootstrap>", line 1204, in _gcd_import
  File "<frozen importlib._bootstrap>", line 1176, in _find_and_load
  File "<frozen importlib._bootstrap>", line 1140, in _find_and_load_unlocked
ModuleNotFoundError: No module named 'openpyxl'

During handling of the above exception, another exception occurred:

Traceback (most recent call last):
  File "/home/alprostov/PycharmProjects/sakhlis/web/venv/lib/python3.11/site-packages/django/core/handlers/exception.py", line 55, in inner
    response = get_response(request)
               ^^^^^^^^^^^^^^^^^^^^^
  File "/home/alprostov/PycharmProjects/sakhlis/web/venv/lib/python3.11/site-packages/django/core/handlers/base.py", line 197, in _get_response
    response = wrapped_callback(request, *callback_args, **callback_kwargs)
               ^^^^^^^^^^^^^^^^^^^^^^^^^^^^^^^^^^^^^^^^^^^^^^^^^^^^^^^^^^^^
  File "/home/alprostov/PycharmProjects/sakhlis/web/app_site/views.py", line 688, in aaa
    excel_data = pd.read_excel('emails.xlsx')
                 ^^^^^^^^^^^^^^^^^^^^^^^^^^^^
  File "/home/alprostov/PycharmProjects/sakhlis/web/venv/lib/python3.11/site-packages/pandas/io/excel/_base.py", line 495, in read_excel
    io = ExcelFile(
         ^^^^^^^^^^
  File "/home/alprostov/PycharmProjects/sakhlis/web/venv/lib/python3.11/site-packages/pandas/io/excel/_base.py", line 1567, in __init__
    self._reader = self._engines[engine](
                   ^^^^^^^^^^^^^^^^^^^^^^
  File "/home/alprostov/PycharmProjects/sakhlis/web/venv/lib/python3.11/site-packages/pandas/io/excel/_openpyxl.py", line 552, in __init__
    import_optional_dependency("openpyxl")
  File "/home/alprostov/PycharmProjects/sakhlis/web/venv/lib/python3.11/site-packages/pandas/compat/_optional.py", line 138, in import_optional_dependency
    raise ImportError(msg)
ImportError: Missing optional dependency 'openpyxl'.  Use pip or conda to install openpyxl.
14/Dec/2024 21:11:49    ERROR    basehttp    "GET /mails HTTP/1.1" 500 117736   /home/alprostov/PycharmProjects/sakhlis/web/venv/lib/python3.11/site-packages/django/core/servers/basehttp.py   None
14/Dec/2024 21:12:36    ERROR    log    Internal Server Error: /mails   /home/alprostov/PycharmProjects/sakhlis/web/venv/lib/python3.11/site-packages/django/utils/log.py   (<class 'ValueError'>, ValueError("The view app_site.views.aaa didn't return an HttpResponse object. It returned None instead."), <traceback object at 0x7f0eb40c4140>)
Traceback (most recent call last):
  File "/home/alprostov/PycharmProjects/sakhlis/web/venv/lib/python3.11/site-packages/django/core/handlers/exception.py", line 55, in inner
    response = get_response(request)
               ^^^^^^^^^^^^^^^^^^^^^
  File "/home/alprostov/PycharmProjects/sakhlis/web/venv/lib/python3.11/site-packages/django/core/handlers/base.py", line 204, in _get_response
    self.check_response(response, callback)
  File "/home/alprostov/PycharmProjects/sakhlis/web/venv/lib/python3.11/site-packages/django/core/handlers/base.py", line 332, in check_response
    raise ValueError(
ValueError: The view app_site.views.aaa didn't return an HttpResponse object. It returned None instead.
14/Dec/2024 21:12:36    ERROR    basehttp    "GET /mails HTTP/1.1" 500 81388   /home/alprostov/PycharmProjects/sakhlis/web/venv/lib/python3.11/site-packages/django/core/servers/basehttp.py   None
14/Dec/2024 21:13:05    ERROR    log    Internal Server Error: /mails   /home/alprostov/PycharmProjects/sakhlis/web/venv/lib/python3.11/site-packages/django/utils/log.py   (<class 'KeyError'>, KeyError(0), <traceback object at 0x7f21570670c0>)
Traceback (most recent call last):
  File "/home/alprostov/PycharmProjects/sakhlis/web/venv/lib/python3.11/site-packages/pandas/core/indexes/base.py", line 3805, in get_loc
    return self._engine.get_loc(casted_key)
           ^^^^^^^^^^^^^^^^^^^^^^^^^^^^^^^^
  File "index.pyx", line 167, in pandas._libs.index.IndexEngine.get_loc
  File "index.pyx", line 196, in pandas._libs.index.IndexEngine.get_loc
  File "pandas/_libs/hashtable_class_helper.pxi", line 7081, in pandas._libs.hashtable.PyObjectHashTable.get_item
  File "pandas/_libs/hashtable_class_helper.pxi", line 7089, in pandas._libs.hashtable.PyObjectHashTable.get_item
KeyError: 0

The above exception was the direct cause of the following exception:

Traceback (most recent call last):
  File "/home/alprostov/PycharmProjects/sakhlis/web/venv/lib/python3.11/site-packages/django/core/handlers/exception.py", line 55, in inner
    response = get_response(request)
               ^^^^^^^^^^^^^^^^^^^^^
  File "/home/alprostov/PycharmProjects/sakhlis/web/venv/lib/python3.11/site-packages/django/core/handlers/base.py", line 197, in _get_response
    response = wrapped_callback(request, *callback_args, **callback_kwargs)
               ^^^^^^^^^^^^^^^^^^^^^^^^^^^^^^^^^^^^^^^^^^^^^^^^^^^^^^^^^^^^
  File "/home/alprostov/PycharmProjects/sakhlis/web/app_site/views.py", line 692, in aaa
    print("The content of the file is:\n", data[0])
                                           ~~~~^^^
  File "/home/alprostov/PycharmProjects/sakhlis/web/venv/lib/python3.11/site-packages/pandas/core/frame.py", line 4102, in __getitem__
    indexer = self.columns.get_loc(key)
              ^^^^^^^^^^^^^^^^^^^^^^^^^
  File "/home/alprostov/PycharmProjects/sakhlis/web/venv/lib/python3.11/site-packages/pandas/core/indexes/base.py", line 3812, in get_loc
    raise KeyError(key) from err
KeyError: 0
14/Dec/2024 21:13:05    ERROR    basehttp    "GET /mails HTTP/1.1" 500 97555   /home/alprostov/PycharmProjects/sakhlis/web/venv/lib/python3.11/site-packages/django/core/servers/basehttp.py   None
14/Dec/2024 21:13:56    ERROR    log    Internal Server Error: /mails   /home/alprostov/PycharmProjects/sakhlis/web/venv/lib/python3.11/site-packages/django/utils/log.py   (<class 'ValueError'>, ValueError("The view app_site.views.aaa didn't return an HttpResponse object. It returned None instead."), <traceback object at 0x7f8707d13840>)
Traceback (most recent call last):
  File "/home/alprostov/PycharmProjects/sakhlis/web/venv/lib/python3.11/site-packages/django/core/handlers/exception.py", line 55, in inner
    response = get_response(request)
               ^^^^^^^^^^^^^^^^^^^^^
  File "/home/alprostov/PycharmProjects/sakhlis/web/venv/lib/python3.11/site-packages/django/core/handlers/base.py", line 204, in _get_response
    self.check_response(response, callback)
  File "/home/alprostov/PycharmProjects/sakhlis/web/venv/lib/python3.11/site-packages/django/core/handlers/base.py", line 332, in check_response
    raise ValueError(
ValueError: The view app_site.views.aaa didn't return an HttpResponse object. It returned None instead.
14/Dec/2024 21:13:56    ERROR    basehttp    "GET /mails HTTP/1.1" 500 81390   /home/alprostov/PycharmProjects/sakhlis/web/venv/lib/python3.11/site-packages/django/core/servers/basehttp.py   None
14/Dec/2024 21:14:18    ERROR    log    Internal Server Error: /mails   /home/alprostov/PycharmProjects/sakhlis/web/venv/lib/python3.11/site-packages/django/utils/log.py   (<class 'ValueError'>, ValueError("The view app_site.views.aaa didn't return an HttpResponse object. It returned None instead."), <traceback object at 0x7fa10ffc2280>)
Traceback (most recent call last):
  File "/home/alprostov/PycharmProjects/sakhlis/web/venv/lib/python3.11/site-packages/django/core/handlers/exception.py", line 55, in inner
    response = get_response(request)
               ^^^^^^^^^^^^^^^^^^^^^
  File "/home/alprostov/PycharmProjects/sakhlis/web/venv/lib/python3.11/site-packages/django/core/handlers/base.py", line 204, in _get_response
    self.check_response(response, callback)
  File "/home/alprostov/PycharmProjects/sakhlis/web/venv/lib/python3.11/site-packages/django/core/handlers/base.py", line 332, in check_response
    raise ValueError(
ValueError: The view app_site.views.aaa didn't return an HttpResponse object. It returned None instead.
14/Dec/2024 21:14:18    ERROR    basehttp    "GET /mails HTTP/1.1" 500 81388   /home/alprostov/PycharmProjects/sakhlis/web/venv/lib/python3.11/site-packages/django/core/servers/basehttp.py   None
14/Dec/2024 21:14:34    ERROR    log    Internal Server Error: /mails   /home/alprostov/PycharmProjects/sakhlis/web/venv/lib/python3.11/site-packages/django/utils/log.py   (<class 'ValueError'>, ValueError("The view app_site.views.aaa didn't return an HttpResponse object. It returned None instead."), <traceback object at 0x7f171e190a80>)
Traceback (most recent call last):
  File "/home/alprostov/PycharmProjects/sakhlis/web/venv/lib/python3.11/site-packages/django/core/handlers/exception.py", line 55, in inner
    response = get_response(request)
               ^^^^^^^^^^^^^^^^^^^^^
  File "/home/alprostov/PycharmProjects/sakhlis/web/venv/lib/python3.11/site-packages/django/core/handlers/base.py", line 204, in _get_response
    self.check_response(response, callback)
  File "/home/alprostov/PycharmProjects/sakhlis/web/venv/lib/python3.11/site-packages/django/core/handlers/base.py", line 332, in check_response
    raise ValueError(
ValueError: The view app_site.views.aaa didn't return an HttpResponse object. It returned None instead.
14/Dec/2024 21:14:34    ERROR    basehttp    "GET /mails HTTP/1.1" 500 81389   /home/alprostov/PycharmProjects/sakhlis/web/venv/lib/python3.11/site-packages/django/core/servers/basehttp.py   None
14/Dec/2024 21:15:53    ERROR    log    Internal Server Error: /mails   /home/alprostov/PycharmProjects/sakhlis/web/venv/lib/python3.11/site-packages/django/utils/log.py   (<class 'ValueError'>, ValueError("The view app_site.views.aaa didn't return an HttpResponse object. It returned None instead."), <traceback object at 0x7f3ec53c3f40>)
Traceback (most recent call last):
  File "/home/alprostov/PycharmProjects/sakhlis/web/venv/lib/python3.11/site-packages/django/core/handlers/exception.py", line 55, in inner
    response = get_response(request)
               ^^^^^^^^^^^^^^^^^^^^^
  File "/home/alprostov/PycharmProjects/sakhlis/web/venv/lib/python3.11/site-packages/django/core/handlers/base.py", line 204, in _get_response
    self.check_response(response, callback)
  File "/home/alprostov/PycharmProjects/sakhlis/web/venv/lib/python3.11/site-packages/django/core/handlers/base.py", line 332, in check_response
    raise ValueError(
ValueError: The view app_site.views.aaa didn't return an HttpResponse object. It returned None instead.
14/Dec/2024 21:15:53    ERROR    basehttp    "GET /mails HTTP/1.1" 500 81390   /home/alprostov/PycharmProjects/sakhlis/web/venv/lib/python3.11/site-packages/django/core/servers/basehttp.py   None
14/Dec/2024 21:18:37    ERROR    log    Internal Server Error: /mails   /home/alprostov/PycharmProjects/sakhlis/web/venv/lib/python3.11/site-packages/django/utils/log.py   (<class 'TypeError'>, TypeError("Client() got unexpected keyword arguments: 'email'"), <traceback object at 0x7ff1d85100c0>)
Traceback (most recent call last):
  File "/home/alprostov/PycharmProjects/sakhlis/web/venv/lib/python3.11/site-packages/django/core/handlers/exception.py", line 55, in inner
    response = get_response(request)
               ^^^^^^^^^^^^^^^^^^^^^
  File "/home/alprostov/PycharmProjects/sakhlis/web/venv/lib/python3.11/site-packages/django/core/handlers/base.py", line 197, in _get_response
    response = wrapped_callback(request, *callback_args, **callback_kwargs)
               ^^^^^^^^^^^^^^^^^^^^^^^^^^^^^^^^^^^^^^^^^^^^^^^^^^^^^^^^^^^^
  File "/home/alprostov/PycharmProjects/sakhlis/web/app_site/views.py", line 695, in aaa
    b=Client(email=i)
      ^^^^^^^^^^^^^^^
  File "/home/alprostov/PycharmProjects/sakhlis/web/venv/lib/python3.11/site-packages/django/db/models/base.py", line 567, in __init__
    raise TypeError(
TypeError: Client() got unexpected keyword arguments: 'email'
14/Dec/2024 21:18:37    ERROR    basehttp    "GET /mails HTTP/1.1" 500 88653   /home/alprostov/PycharmProjects/sakhlis/web/venv/lib/python3.11/site-packages/django/core/servers/basehttp.py   None
14/Dec/2024 21:21:13    ERROR    log    Internal Server Error: /mails   /home/alprostov/PycharmProjects/sakhlis/web/venv/lib/python3.11/site-packages/django/utils/log.py   (<class 'ValueError'>, ValueError("The view app_site.views.aaa didn't return an HttpResponse object. It returned None instead."), <traceback object at 0x7f61edde6d00>)
Traceback (most recent call last):
  File "/home/alprostov/PycharmProjects/sakhlis/web/venv/lib/python3.11/site-packages/django/core/handlers/exception.py", line 55, in inner
    response = get_response(request)
               ^^^^^^^^^^^^^^^^^^^^^
  File "/home/alprostov/PycharmProjects/sakhlis/web/venv/lib/python3.11/site-packages/django/core/handlers/base.py", line 204, in _get_response
    self.check_response(response, callback)
  File "/home/alprostov/PycharmProjects/sakhlis/web/venv/lib/python3.11/site-packages/django/core/handlers/base.py", line 332, in check_response
    raise ValueError(
ValueError: The view app_site.views.aaa didn't return an HttpResponse object. It returned None instead.
14/Dec/2024 21:21:13    ERROR    basehttp    "GET /mails HTTP/1.1" 500 81529   /home/alprostov/PycharmProjects/sakhlis/web/venv/lib/python3.11/site-packages/django/core/servers/basehttp.py   None
14/Dec/2024 21:22:56    ERROR    log    Internal Server Error: /mails   /home/alprostov/PycharmProjects/sakhlis/web/venv/lib/python3.11/site-packages/django/utils/log.py   (<class 'ValueError'>, ValueError("The view app_site.views.aaa didn't return an HttpResponse object. It returned None instead."), <traceback object at 0x7fb1d3fb9400>)
Traceback (most recent call last):
  File "/home/alprostov/PycharmProjects/sakhlis/web/venv/lib/python3.11/site-packages/django/core/handlers/exception.py", line 55, in inner
    response = get_response(request)
               ^^^^^^^^^^^^^^^^^^^^^
  File "/home/alprostov/PycharmProjects/sakhlis/web/venv/lib/python3.11/site-packages/django/core/handlers/base.py", line 204, in _get_response
    self.check_response(response, callback)
  File "/home/alprostov/PycharmProjects/sakhlis/web/venv/lib/python3.11/site-packages/django/core/handlers/base.py", line 332, in check_response
    raise ValueError(
ValueError: The view app_site.views.aaa didn't return an HttpResponse object. It returned None instead.
14/Dec/2024 21:22:56    ERROR    basehttp    "GET /mails HTTP/1.1" 500 81529   /home/alprostov/PycharmProjects/sakhlis/web/venv/lib/python3.11/site-packages/django/core/servers/basehttp.py   None
14/Dec/2024 21:26:32    ERROR    log    Internal Server Error: /mails   /home/alprostov/PycharmProjects/sakhlis/web/venv/lib/python3.11/site-packages/django/utils/log.py   (<class 'ValueError'>, ValueError("The view app_site.views.aaa didn't return an HttpResponse object. It returned None instead."), <traceback object at 0x7f787030f440>)
Traceback (most recent call last):
  File "/home/alprostov/PycharmProjects/sakhlis/web/venv/lib/python3.11/site-packages/django/core/handlers/exception.py", line 55, in inner
    response = get_response(request)
               ^^^^^^^^^^^^^^^^^^^^^
  File "/home/alprostov/PycharmProjects/sakhlis/web/venv/lib/python3.11/site-packages/django/core/handlers/base.py", line 204, in _get_response
    self.check_response(response, callback)
  File "/home/alprostov/PycharmProjects/sakhlis/web/venv/lib/python3.11/site-packages/django/core/handlers/base.py", line 332, in check_response
    raise ValueError(
ValueError: The view app_site.views.aaa didn't return an HttpResponse object. It returned None instead.
14/Dec/2024 21:26:32    ERROR    basehttp    "GET /mails HTTP/1.1" 500 81529   /home/alprostov/PycharmProjects/sakhlis/web/venv/lib/python3.11/site-packages/django/core/servers/basehttp.py   None
14/Dec/2024 21:28:16    ERROR    log    Internal Server Error: /mails   /home/alprostov/PycharmProjects/sakhlis/web/venv/lib/python3.11/site-packages/django/utils/log.py   (<class 'TypeError'>, TypeError("Field.__init__() got an unexpected keyword argument '_ST'"), <traceback object at 0x7fd9d7b70a40>)
Traceback (most recent call last):
  File "/home/alprostov/PycharmProjects/sakhlis/web/venv/lib/python3.11/site-packages/django/core/handlers/exception.py", line 55, in inner
    response = get_response(request)
               ^^^^^^^^^^^^^^^^^^^^^
  File "/home/alprostov/PycharmProjects/sakhlis/web/venv/lib/python3.11/site-packages/django/core/handlers/base.py", line 197, in _get_response
    response = wrapped_callback(request, *callback_args, **callback_kwargs)
               ^^^^^^^^^^^^^^^^^^^^^^^^^^^^^^^^^^^^^^^^^^^^^^^^^^^^^^^^^^^^
  File "/home/alprostov/PycharmProjects/sakhlis/web/app_site/views.py", line 695, in aaa
    b=models.EmailField(_ST=i)
      ^^^^^^^^^^^^^^^^^^^^^^^^
  File "/home/alprostov/PycharmProjects/sakhlis/web/venv/lib/python3.11/site-packages/django/db/models/fields/__init__.py", line 1852, in __init__
    super().__init__(*args, **kwargs)
  File "/home/alprostov/PycharmProjects/sakhlis/web/venv/lib/python3.11/site-packages/django/db/models/fields/__init__.py", line 1139, in __init__
    super().__init__(*args, **kwargs)
TypeError: Field.__init__() got an unexpected keyword argument '_ST'
14/Dec/2024 21:28:16    ERROR    basehttp    "GET /mails HTTP/1.1" 500 91651   /home/alprostov/PycharmProjects/sakhlis/web/venv/lib/python3.11/site-packages/django/core/servers/basehttp.py   None
14/Dec/2024 21:28:19    ERROR    log    Internal Server Error: /mails   /home/alprostov/PycharmProjects/sakhlis/web/venv/lib/python3.11/site-packages/django/utils/log.py   (<class 'TypeError'>, TypeError("Field.__init__() got an unexpected keyword argument '_ST'"), <traceback object at 0x7fd9d7618f80>)
Traceback (most recent call last):
  File "/home/alprostov/PycharmProjects/sakhlis/web/venv/lib/python3.11/site-packages/django/core/handlers/exception.py", line 55, in inner
    response = get_response(request)
               ^^^^^^^^^^^^^^^^^^^^^
  File "/home/alprostov/PycharmProjects/sakhlis/web/venv/lib/python3.11/site-packages/django/core/handlers/base.py", line 197, in _get_response
    response = wrapped_callback(request, *callback_args, **callback_kwargs)
               ^^^^^^^^^^^^^^^^^^^^^^^^^^^^^^^^^^^^^^^^^^^^^^^^^^^^^^^^^^^^
  File "/home/alprostov/PycharmProjects/sakhlis/web/app_site/views.py", line 695, in aaa
    b=models.EmailField(_ST=i)
      ^^^^^^^^^^^^^^^^^^^^^^^^
  File "/home/alprostov/PycharmProjects/sakhlis/web/venv/lib/python3.11/site-packages/django/db/models/fields/__init__.py", line 1852, in __init__
    super().__init__(*args, **kwargs)
  File "/home/alprostov/PycharmProjects/sakhlis/web/venv/lib/python3.11/site-packages/django/db/models/fields/__init__.py", line 1139, in __init__
    super().__init__(*args, **kwargs)
TypeError: Field.__init__() got an unexpected keyword argument '_ST'
14/Dec/2024 21:28:19    ERROR    basehttp    "GET /mails HTTP/1.1" 500 91649   /home/alprostov/PycharmProjects/sakhlis/web/venv/lib/python3.11/site-packages/django/core/servers/basehttp.py   None
14/Dec/2024 21:29:50    ERROR    log    Internal Server Error: /mails   /home/alprostov/PycharmProjects/sakhlis/web/venv/lib/python3.11/site-packages/django/utils/log.py   (<class 'TypeError'>, TypeError("Client() got unexpected keyword arguments: 'email'"), <traceback object at 0x7f5779363f00>)
Traceback (most recent call last):
  File "/home/alprostov/PycharmProjects/sakhlis/web/venv/lib/python3.11/site-packages/django/core/handlers/exception.py", line 55, in inner
    response = get_response(request)
               ^^^^^^^^^^^^^^^^^^^^^
  File "/home/alprostov/PycharmProjects/sakhlis/web/venv/lib/python3.11/site-packages/django/core/handlers/base.py", line 197, in _get_response
    response = wrapped_callback(request, *callback_args, **callback_kwargs)
               ^^^^^^^^^^^^^^^^^^^^^^^^^^^^^^^^^^^^^^^^^^^^^^^^^^^^^^^^^^^^
  File "/home/alprostov/PycharmProjects/sakhlis/web/app_site/views.py", line 695, in aaa
    b=Client(email=i,flag=False)
      ^^^^^^^^^^^^^^^^^^^^^^^^^^
  File "/home/alprostov/PycharmProjects/sakhlis/web/venv/lib/python3.11/site-packages/django/db/models/base.py", line 567, in __init__
    raise TypeError(
TypeError: Client() got unexpected keyword arguments: 'email'
14/Dec/2024 21:29:50    ERROR    basehttp    "GET /mails HTTP/1.1" 500 88838   /home/alprostov/PycharmProjects/sakhlis/web/venv/lib/python3.11/site-packages/django/core/servers/basehttp.py   None
14/Dec/2024 21:30:29    ERROR    log    Internal Server Error: /mails   /home/alprostov/PycharmProjects/sakhlis/web/venv/lib/python3.11/site-packages/django/utils/log.py   (<class 'TypeError'>, TypeError("Client() got unexpected keyword arguments: 'email'"), <traceback object at 0x7f9a0230be40>)
Traceback (most recent call last):
  File "/home/alprostov/PycharmProjects/sakhlis/web/venv/lib/python3.11/site-packages/django/core/handlers/exception.py", line 55, in inner
    response = get_response(request)
               ^^^^^^^^^^^^^^^^^^^^^
  File "/home/alprostov/PycharmProjects/sakhlis/web/venv/lib/python3.11/site-packages/django/core/handlers/base.py", line 197, in _get_response
    response = wrapped_callback(request, *callback_args, **callback_kwargs)
               ^^^^^^^^^^^^^^^^^^^^^^^^^^^^^^^^^^^^^^^^^^^^^^^^^^^^^^^^^^^^
  File "/home/alprostov/PycharmProjects/sakhlis/web/app_site/views.py", line 695, in aaa
    b=Client(email=i,flag=False)
      ^^^^^^^^^^^^^^^^^^^^^^^^^^
  File "/home/alprostov/PycharmProjects/sakhlis/web/venv/lib/python3.11/site-packages/django/db/models/base.py", line 567, in __init__
    raise TypeError(
TypeError: Client() got unexpected keyword arguments: 'email'
14/Dec/2024 21:30:29    ERROR    basehttp    "GET /mails HTTP/1.1" 500 88837   /home/alprostov/PycharmProjects/sakhlis/web/venv/lib/python3.11/site-packages/django/core/servers/basehttp.py   None
14/Dec/2024 21:38:31    WARNING    log    Not Found: /favicon.ico   /home/alprostov/PycharmProjects/sakhlis/web/venv/lib/python3.11/site-packages/django/utils/log.py   None
14/Dec/2024 21:38:31    WARNING    basehttp    "GET /favicon.ico HTTP/1.1" 404 19899   /home/alprostov/PycharmProjects/sakhlis/web/venv/lib/python3.11/site-packages/django/core/servers/basehttp.py   None
14/Dec/2024 21:42:48    WARNING    log    Not Found: /aaa   /home/alprostov/PycharmProjects/sakhlis/web/venv/lib/python3.11/site-packages/django/utils/log.py   None
14/Dec/2024 21:42:48    WARNING    basehttp    "GET /aaa HTTP/1.1" 404 19866   /home/alprostov/PycharmProjects/sakhlis/web/venv/lib/python3.11/site-packages/django/core/servers/basehttp.py   None
14/Dec/2024 21:43:07    ERROR    log    Internal Server Error: /mails   /home/alprostov/PycharmProjects/sakhlis/web/venv/lib/python3.11/site-packages/django/utils/log.py   (<class 'ValueError'>, ValueError("The view app_site.views.aaa didn't return an HttpResponse object. It returned None instead."), <traceback object at 0x7f4345d74d00>)
Traceback (most recent call last):
  File "/home/alprostov/PycharmProjects/sakhlis/web/venv/lib/python3.11/site-packages/django/core/handlers/exception.py", line 55, in inner
    response = get_response(request)
               ^^^^^^^^^^^^^^^^^^^^^
  File "/home/alprostov/PycharmProjects/sakhlis/web/venv/lib/python3.11/site-packages/django/core/handlers/base.py", line 204, in _get_response
    self.check_response(response, callback)
  File "/home/alprostov/PycharmProjects/sakhlis/web/venv/lib/python3.11/site-packages/django/core/handlers/base.py", line 332, in check_response
    raise ValueError(
ValueError: The view app_site.views.aaa didn't return an HttpResponse object. It returned None instead.
14/Dec/2024 21:43:07    ERROR    basehttp    "GET /mails HTTP/1.1" 500 81387   /home/alprostov/PycharmProjects/sakhlis/web/venv/lib/python3.11/site-packages/django/core/servers/basehttp.py   None
14/Dec/2024 21:51:04    ERROR    log    Internal Server Error: /mails   /home/alprostov/PycharmProjects/sakhlis/web/venv/lib/python3.11/site-packages/django/utils/log.py   (<class 'ValueError'>, ValueError("The view app_site.views.aaa didn't return an HttpResponse object. It returned None instead."), <traceback object at 0x7f0577fa0c40>)
Traceback (most recent call last):
  File "/home/alprostov/PycharmProjects/sakhlis/web/venv/lib/python3.11/site-packages/django/core/handlers/exception.py", line 55, in inner
    response = get_response(request)
               ^^^^^^^^^^^^^^^^^^^^^
  File "/home/alprostov/PycharmProjects/sakhlis/web/venv/lib/python3.11/site-packages/django/core/handlers/base.py", line 204, in _get_response
    self.check_response(response, callback)
  File "/home/alprostov/PycharmProjects/sakhlis/web/venv/lib/python3.11/site-packages/django/core/handlers/base.py", line 332, in check_response
    raise ValueError(
ValueError: The view app_site.views.aaa didn't return an HttpResponse object. It returned None instead.
14/Dec/2024 21:51:39    ERROR    basehttp    "GET /mails HTTP/1.1" 500 81582   /home/alprostov/PycharmProjects/sakhlis/web/venv/lib/python3.11/site-packages/django/core/servers/basehttp.py   None
14/Dec/2024 21:55:13    WARNING    log    Not Found: /media/masters/unknown_person.jpg   /home/alprostov/PycharmProjects/sakhlis/web/venv/lib/python3.11/site-packages/django/utils/log.py   None
14/Dec/2024 21:55:13    WARNING    basehttp    "GET /media/masters/unknown_person.jpg HTTP/1.1" 404 20198   /home/alprostov/PycharmProjects/sakhlis/web/venv/lib/python3.11/site-packages/django/core/servers/basehttp.py   None
15/Dec/2024 18:27:18    WARNING    log    Not Found: /media/masters/unknown_person.jpg   /home/alprostov/PycharmProjects/sakhlis/web/venv/lib/python3.11/site-packages/django/utils/log.py   None
15/Dec/2024 18:27:18    WARNING    basehttp    "GET /media/masters/unknown_person.jpg HTTP/1.1" 404 20198   /home/alprostov/PycharmProjects/sakhlis/web/venv/lib/python3.11/site-packages/django/core/servers/basehttp.py   None
15/Dec/2024 18:28:33    WARNING    log    Not Found: /media/masters/unknown_person.jpg   /home/alprostov/PycharmProjects/sakhlis/web/venv/lib/python3.11/site-packages/django/utils/log.py   None
15/Dec/2024 18:28:33    WARNING    basehttp    "GET /media/masters/unknown_person.jpg HTTP/1.1" 404 20198   /home/alprostov/PycharmProjects/sakhlis/web/venv/lib/python3.11/site-packages/django/core/servers/basehttp.py   None
15/Dec/2024 18:28:33    WARNING    log    Not Found: /media/masters/unknown_person.jpg   /home/alprostov/PycharmProjects/sakhlis/web/venv/lib/python3.11/site-packages/django/utils/log.py   None
15/Dec/2024 18:28:33    WARNING    basehttp    "GET /media/masters/unknown_person.jpg HTTP/1.1" 404 20198   /home/alprostov/PycharmProjects/sakhlis/web/venv/lib/python3.11/site-packages/django/core/servers/basehttp.py   None
15/Dec/2024 18:28:33    WARNING    log    Not Found: /favicon.ico   /home/alprostov/PycharmProjects/sakhlis/web/venv/lib/python3.11/site-packages/django/utils/log.py   None
15/Dec/2024 18:28:33    WARNING    basehttp    "GET /favicon.ico HTTP/1.1" 404 19898   /home/alprostov/PycharmProjects/sakhlis/web/venv/lib/python3.11/site-packages/django/core/servers/basehttp.py   None
15/Dec/2024 18:28:42    WARNING    log    Not Found: /media/masters/unknown_person.jpg   /home/alprostov/PycharmProjects/sakhlis/web/venv/lib/python3.11/site-packages/django/utils/log.py   None
15/Dec/2024 18:28:42    WARNING    basehttp    "GET /media/masters/unknown_person.jpg HTTP/1.1" 404 20198   /home/alprostov/PycharmProjects/sakhlis/web/venv/lib/python3.11/site-packages/django/core/servers/basehttp.py   None
15/Dec/2024 18:31:07    WARNING    log    Not Found: /media/masters/unknown_person.jpg   /home/alprostov/PycharmProjects/sakhlis/web/venv/lib/python3.11/site-packages/django/utils/log.py   None
15/Dec/2024 18:31:07    WARNING    basehttp    "GET /media/masters/unknown_person.jpg HTTP/1.1" 404 20198   /home/alprostov/PycharmProjects/sakhlis/web/venv/lib/python3.11/site-packages/django/core/servers/basehttp.py   None
15/Dec/2024 18:34:37    WARNING    log    Not Found: /media/masters/unknown_person.jpg   /home/alprostov/PycharmProjects/sakhlis/web/venv/lib/python3.11/site-packages/django/utils/log.py   None
15/Dec/2024 18:34:37    WARNING    basehttp    "GET /media/masters/unknown_person.jpg HTTP/1.1" 404 20198   /home/alprostov/PycharmProjects/sakhlis/web/venv/lib/python3.11/site-packages/django/core/servers/basehttp.py   None
15/Dec/2024 18:34:48    WARNING    log    Not Found: /media/masters/unknown_person.jpg   /home/alprostov/PycharmProjects/sakhlis/web/venv/lib/python3.11/site-packages/django/utils/log.py   None
15/Dec/2024 18:34:48    WARNING    basehttp    "GET /media/masters/unknown_person.jpg HTTP/1.1" 404 20198   /home/alprostov/PycharmProjects/sakhlis/web/venv/lib/python3.11/site-packages/django/core/servers/basehttp.py   None
15/Dec/2024 18:34:58    WARNING    log    Not Found: /media/masters/unknown_person.jpg   /home/alprostov/PycharmProjects/sakhlis/web/venv/lib/python3.11/site-packages/django/utils/log.py   None
15/Dec/2024 18:34:58    WARNING    basehttp    "GET /media/masters/unknown_person.jpg HTTP/1.1" 404 20198   /home/alprostov/PycharmProjects/sakhlis/web/venv/lib/python3.11/site-packages/django/core/servers/basehttp.py   None
15/Dec/2024 18:35:22    WARNING    log    Not Found: /media/masters/unknown_person.jpg   /home/alprostov/PycharmProjects/sakhlis/web/venv/lib/python3.11/site-packages/django/utils/log.py   None
15/Dec/2024 18:35:22    WARNING    basehttp    "GET /media/masters/unknown_person.jpg HTTP/1.1" 404 20198   /home/alprostov/PycharmProjects/sakhlis/web/venv/lib/python3.11/site-packages/django/core/servers/basehttp.py   None
15/Dec/2024 18:35:35    WARNING    log    Not Found: /media/masters/unknown_person.jpg   /home/alprostov/PycharmProjects/sakhlis/web/venv/lib/python3.11/site-packages/django/utils/log.py   None
15/Dec/2024 18:35:35    WARNING    basehttp    "GET /media/masters/unknown_person.jpg HTTP/1.1" 404 20198   /home/alprostov/PycharmProjects/sakhlis/web/venv/lib/python3.11/site-packages/django/core/servers/basehttp.py   None
15/Dec/2024 18:46:24    WARNING    log    Not Found: /media/masters/unknown_person.jpg   /home/alprostov/PycharmProjects/sakhlis/web/venv/lib/python3.11/site-packages/django/utils/log.py   None
15/Dec/2024 18:46:24    WARNING    basehttp    "GET /media/masters/unknown_person.jpg HTTP/1.1" 404 20198   /home/alprostov/PycharmProjects/sakhlis/web/venv/lib/python3.11/site-packages/django/core/servers/basehttp.py   None
15/Dec/2024 18:46:24    WARNING    log    Not Found: /media/masters/unknown_person.jpg   /home/alprostov/PycharmProjects/sakhlis/web/venv/lib/python3.11/site-packages/django/utils/log.py   None
15/Dec/2024 18:46:24    WARNING    basehttp    "GET /media/masters/unknown_person.jpg HTTP/1.1" 404 20198   /home/alprostov/PycharmProjects/sakhlis/web/venv/lib/python3.11/site-packages/django/core/servers/basehttp.py   None
15/Dec/2024 21:40:13    WARNING    log    Not Found: /media/masters/unknown_person.jpg   /home/alprostov/PycharmProjects/sakhlis/web/venv/lib/python3.11/site-packages/django/utils/log.py   None
15/Dec/2024 21:40:13    WARNING    basehttp    "GET /media/masters/unknown_person.jpg HTTP/1.1" 404 20198   /home/alprostov/PycharmProjects/sakhlis/web/venv/lib/python3.11/site-packages/django/core/servers/basehttp.py   None
15/Dec/2024 21:40:13    WARNING    log    Not Found: /media/masters/unknown_person.jpg   /home/alprostov/PycharmProjects/sakhlis/web/venv/lib/python3.11/site-packages/django/utils/log.py   None
15/Dec/2024 21:40:13    WARNING    basehttp    "GET /media/masters/unknown_person.jpg HTTP/1.1" 404 20198   /home/alprostov/PycharmProjects/sakhlis/web/venv/lib/python3.11/site-packages/django/core/servers/basehttp.py   None
15/Dec/2024 21:40:17    WARNING    log    Not Found: /media/masters/unknown_person.jpg   /home/alprostov/PycharmProjects/sakhlis/web/venv/lib/python3.11/site-packages/django/utils/log.py   None
15/Dec/2024 21:40:17    WARNING    basehttp    "GET /media/masters/unknown_person.jpg HTTP/1.1" 404 20198   /home/alprostov/PycharmProjects/sakhlis/web/venv/lib/python3.11/site-packages/django/core/servers/basehttp.py   None
15/Dec/2024 21:40:17    WARNING    log    Not Found: /media/masters/unknown_person.jpg   /home/alprostov/PycharmProjects/sakhlis/web/venv/lib/python3.11/site-packages/django/utils/log.py   None
15/Dec/2024 21:40:17    WARNING    basehttp    "GET /media/masters/unknown_person.jpg HTTP/1.1" 404 20198   /home/alprostov/PycharmProjects/sakhlis/web/venv/lib/python3.11/site-packages/django/core/servers/basehttp.py   None
15/Dec/2024 21:40:20    WARNING    log    Not Found: /media/masters/unknown_person.jpg   /home/alprostov/PycharmProjects/sakhlis/web/venv/lib/python3.11/site-packages/django/utils/log.py   None
15/Dec/2024 21:40:20    WARNING    basehttp    "GET /media/masters/unknown_person.jpg HTTP/1.1" 404 20198   /home/alprostov/PycharmProjects/sakhlis/web/venv/lib/python3.11/site-packages/django/core/servers/basehttp.py   None
15/Dec/2024 21:40:20    WARNING    log    Not Found: /media/masters/unknown_person.jpg   /home/alprostov/PycharmProjects/sakhlis/web/venv/lib/python3.11/site-packages/django/utils/log.py   None
15/Dec/2024 21:40:20    WARNING    basehttp    "GET /media/masters/unknown_person.jpg HTTP/1.1" 404 20198   /home/alprostov/PycharmProjects/sakhlis/web/venv/lib/python3.11/site-packages/django/core/servers/basehttp.py   None
15/Dec/2024 21:40:22    WARNING    log    Not Found: /media/masters/unknown_person.jpg   /home/alprostov/PycharmProjects/sakhlis/web/venv/lib/python3.11/site-packages/django/utils/log.py   None
15/Dec/2024 21:40:22    WARNING    basehttp    "GET /media/masters/unknown_person.jpg HTTP/1.1" 404 20198   /home/alprostov/PycharmProjects/sakhlis/web/venv/lib/python3.11/site-packages/django/core/servers/basehttp.py   None
15/Dec/2024 21:40:22    WARNING    log    Not Found: /media/masters/unknown_person.jpg   /home/alprostov/PycharmProjects/sakhlis/web/venv/lib/python3.11/site-packages/django/utils/log.py   None
15/Dec/2024 21:40:22    WARNING    basehttp    "GET /media/masters/unknown_person.jpg HTTP/1.1" 404 20198   /home/alprostov/PycharmProjects/sakhlis/web/venv/lib/python3.11/site-packages/django/core/servers/basehttp.py   None
15/Dec/2024 21:40:25    WARNING    log    Not Found: /media/masters/unknown_person.jpg   /home/alprostov/PycharmProjects/sakhlis/web/venv/lib/python3.11/site-packages/django/utils/log.py   None
15/Dec/2024 21:40:25    WARNING    basehttp    "GET /media/masters/unknown_person.jpg HTTP/1.1" 404 20198   /home/alprostov/PycharmProjects/sakhlis/web/venv/lib/python3.11/site-packages/django/core/servers/basehttp.py   None
15/Dec/2024 21:40:25    WARNING    log    Not Found: /media/masters/unknown_person.jpg   /home/alprostov/PycharmProjects/sakhlis/web/venv/lib/python3.11/site-packages/django/utils/log.py   None
15/Dec/2024 21:40:25    WARNING    basehttp    "GET /media/masters/unknown_person.jpg HTTP/1.1" 404 20198   /home/alprostov/PycharmProjects/sakhlis/web/venv/lib/python3.11/site-packages/django/core/servers/basehttp.py   None
15/Dec/2024 21:40:27    WARNING    log    Not Found: /media/masters/unknown_person.jpg   /home/alprostov/PycharmProjects/sakhlis/web/venv/lib/python3.11/site-packages/django/utils/log.py   None
15/Dec/2024 21:40:27    WARNING    basehttp    "GET /media/masters/unknown_person.jpg HTTP/1.1" 404 20198   /home/alprostov/PycharmProjects/sakhlis/web/venv/lib/python3.11/site-packages/django/core/servers/basehttp.py   None
15/Dec/2024 21:40:28    WARNING    log    Not Found: /media/masters/unknown_person.jpg   /home/alprostov/PycharmProjects/sakhlis/web/venv/lib/python3.11/site-packages/django/utils/log.py   None
15/Dec/2024 21:40:28    WARNING    basehttp    "GET /media/masters/unknown_person.jpg HTTP/1.1" 404 20198   /home/alprostov/PycharmProjects/sakhlis/web/venv/lib/python3.11/site-packages/django/core/servers/basehttp.py   None
15/Dec/2024 21:40:30    WARNING    log    Not Found: /media/masters/unknown_person.jpg   /home/alprostov/PycharmProjects/sakhlis/web/venv/lib/python3.11/site-packages/django/utils/log.py   None
15/Dec/2024 21:40:30    WARNING    basehttp    "GET /media/masters/unknown_person.jpg HTTP/1.1" 404 20198   /home/alprostov/PycharmProjects/sakhlis/web/venv/lib/python3.11/site-packages/django/core/servers/basehttp.py   None
15/Dec/2024 21:40:30    WARNING    log    Not Found: /media/masters/unknown_person.jpg   /home/alprostov/PycharmProjects/sakhlis/web/venv/lib/python3.11/site-packages/django/utils/log.py   None
15/Dec/2024 21:40:30    WARNING    basehttp    "GET /media/masters/unknown_person.jpg HTTP/1.1" 404 20198   /home/alprostov/PycharmProjects/sakhlis/web/venv/lib/python3.11/site-packages/django/core/servers/basehttp.py   None
15/Dec/2024 21:40:32    WARNING    log    Not Found: /media/masters/unknown_person.jpg   /home/alprostov/PycharmProjects/sakhlis/web/venv/lib/python3.11/site-packages/django/utils/log.py   None
15/Dec/2024 21:40:32    WARNING    basehttp    "GET /media/masters/unknown_person.jpg HTTP/1.1" 404 20198   /home/alprostov/PycharmProjects/sakhlis/web/venv/lib/python3.11/site-packages/django/core/servers/basehttp.py   None
15/Dec/2024 21:40:32    WARNING    log    Not Found: /media/masters/unknown_person.jpg   /home/alprostov/PycharmProjects/sakhlis/web/venv/lib/python3.11/site-packages/django/utils/log.py   None
15/Dec/2024 21:40:32    WARNING    basehttp    "GET /media/masters/unknown_person.jpg HTTP/1.1" 404 20198   /home/alprostov/PycharmProjects/sakhlis/web/venv/lib/python3.11/site-packages/django/core/servers/basehttp.py   None
15/Dec/2024 21:40:35    WARNING    log    Not Found: /media/masters/unknown_person.jpg   /home/alprostov/PycharmProjects/sakhlis/web/venv/lib/python3.11/site-packages/django/utils/log.py   None
15/Dec/2024 21:40:35    WARNING    basehttp    "GET /media/masters/unknown_person.jpg HTTP/1.1" 404 20198   /home/alprostov/PycharmProjects/sakhlis/web/venv/lib/python3.11/site-packages/django/core/servers/basehttp.py   None
15/Dec/2024 21:40:35    WARNING    log    Not Found: /media/masters/unknown_person.jpg   /home/alprostov/PycharmProjects/sakhlis/web/venv/lib/python3.11/site-packages/django/utils/log.py   None
15/Dec/2024 21:40:35    WARNING    basehttp    "GET /media/masters/unknown_person.jpg HTTP/1.1" 404 20198   /home/alprostov/PycharmProjects/sakhlis/web/venv/lib/python3.11/site-packages/django/core/servers/basehttp.py   None
15/Dec/2024 21:40:38    WARNING    log    Not Found: /media/masters/unknown_person.jpg   /home/alprostov/PycharmProjects/sakhlis/web/venv/lib/python3.11/site-packages/django/utils/log.py   None
15/Dec/2024 21:40:38    WARNING    basehttp    "GET /media/masters/unknown_person.jpg HTTP/1.1" 404 20198   /home/alprostov/PycharmProjects/sakhlis/web/venv/lib/python3.11/site-packages/django/core/servers/basehttp.py   None
15/Dec/2024 21:40:38    WARNING    log    Not Found: /media/masters/unknown_person.jpg   /home/alprostov/PycharmProjects/sakhlis/web/venv/lib/python3.11/site-packages/django/utils/log.py   None
15/Dec/2024 21:40:38    WARNING    basehttp    "GET /media/masters/unknown_person.jpg HTTP/1.1" 404 20198   /home/alprostov/PycharmProjects/sakhlis/web/venv/lib/python3.11/site-packages/django/core/servers/basehttp.py   None
15/Dec/2024 21:40:41    WARNING    log    Not Found: /media/masters/unknown_person.jpg   /home/alprostov/PycharmProjects/sakhlis/web/venv/lib/python3.11/site-packages/django/utils/log.py   None
15/Dec/2024 21:40:41    WARNING    basehttp    "GET /media/masters/unknown_person.jpg HTTP/1.1" 404 20198   /home/alprostov/PycharmProjects/sakhlis/web/venv/lib/python3.11/site-packages/django/core/servers/basehttp.py   None
15/Dec/2024 21:40:41    WARNING    log    Not Found: /media/masters/unknown_person.jpg   /home/alprostov/PycharmProjects/sakhlis/web/venv/lib/python3.11/site-packages/django/utils/log.py   None
15/Dec/2024 21:40:41    WARNING    basehttp    "GET /media/masters/unknown_person.jpg HTTP/1.1" 404 20198   /home/alprostov/PycharmProjects/sakhlis/web/venv/lib/python3.11/site-packages/django/core/servers/basehttp.py   None
15/Dec/2024 21:40:44    WARNING    log    Not Found: /media/masters/unknown_person.jpg   /home/alprostov/PycharmProjects/sakhlis/web/venv/lib/python3.11/site-packages/django/utils/log.py   None
15/Dec/2024 21:40:44    WARNING    basehttp    "GET /media/masters/unknown_person.jpg HTTP/1.1" 404 20198   /home/alprostov/PycharmProjects/sakhlis/web/venv/lib/python3.11/site-packages/django/core/servers/basehttp.py   None
15/Dec/2024 21:40:44    WARNING    log    Not Found: /media/masters/unknown_person.jpg   /home/alprostov/PycharmProjects/sakhlis/web/venv/lib/python3.11/site-packages/django/utils/log.py   None
15/Dec/2024 21:40:44    WARNING    basehttp    "GET /media/masters/unknown_person.jpg HTTP/1.1" 404 20198   /home/alprostov/PycharmProjects/sakhlis/web/venv/lib/python3.11/site-packages/django/core/servers/basehttp.py   None
15/Dec/2024 21:40:46    WARNING    log    Not Found: /media/masters/unknown_person.jpg   /home/alprostov/PycharmProjects/sakhlis/web/venv/lib/python3.11/site-packages/django/utils/log.py   None
15/Dec/2024 21:40:46    WARNING    basehttp    "GET /media/masters/unknown_person.jpg HTTP/1.1" 404 20198   /home/alprostov/PycharmProjects/sakhlis/web/venv/lib/python3.11/site-packages/django/core/servers/basehttp.py   None
15/Dec/2024 21:40:46    WARNING    log    Not Found: /media/masters/unknown_person.jpg   /home/alprostov/PycharmProjects/sakhlis/web/venv/lib/python3.11/site-packages/django/utils/log.py   None
15/Dec/2024 21:40:46    WARNING    basehttp    "GET /media/masters/unknown_person.jpg HTTP/1.1" 404 20198   /home/alprostov/PycharmProjects/sakhlis/web/venv/lib/python3.11/site-packages/django/core/servers/basehttp.py   None
15/Dec/2024 21:40:49    WARNING    log    Not Found: /media/masters/unknown_person.jpg   /home/alprostov/PycharmProjects/sakhlis/web/venv/lib/python3.11/site-packages/django/utils/log.py   None
15/Dec/2024 21:40:49    WARNING    basehttp    "GET /media/masters/unknown_person.jpg HTTP/1.1" 404 20198   /home/alprostov/PycharmProjects/sakhlis/web/venv/lib/python3.11/site-packages/django/core/servers/basehttp.py   None
15/Dec/2024 21:40:49    WARNING    log    Not Found: /media/masters/unknown_person.jpg   /home/alprostov/PycharmProjects/sakhlis/web/venv/lib/python3.11/site-packages/django/utils/log.py   None
15/Dec/2024 21:40:49    WARNING    basehttp    "GET /media/masters/unknown_person.jpg HTTP/1.1" 404 20198   /home/alprostov/PycharmProjects/sakhlis/web/venv/lib/python3.11/site-packages/django/core/servers/basehttp.py   None
15/Dec/2024 21:40:51    WARNING    log    Not Found: /media/masters/unknown_person.jpg   /home/alprostov/PycharmProjects/sakhlis/web/venv/lib/python3.11/site-packages/django/utils/log.py   None
15/Dec/2024 21:40:51    WARNING    basehttp    "GET /media/masters/unknown_person.jpg HTTP/1.1" 404 20198   /home/alprostov/PycharmProjects/sakhlis/web/venv/lib/python3.11/site-packages/django/core/servers/basehttp.py   None
15/Dec/2024 21:40:51    WARNING    log    Not Found: /media/masters/unknown_person.jpg   /home/alprostov/PycharmProjects/sakhlis/web/venv/lib/python3.11/site-packages/django/utils/log.py   None
15/Dec/2024 21:40:51    WARNING    basehttp    "GET /media/masters/unknown_person.jpg HTTP/1.1" 404 20198   /home/alprostov/PycharmProjects/sakhlis/web/venv/lib/python3.11/site-packages/django/core/servers/basehttp.py   None
15/Dec/2024 21:40:54    WARNING    log    Not Found: /media/masters/unknown_person.jpg   /home/alprostov/PycharmProjects/sakhlis/web/venv/lib/python3.11/site-packages/django/utils/log.py   None
15/Dec/2024 21:40:54    WARNING    basehttp    "GET /media/masters/unknown_person.jpg HTTP/1.1" 404 20198   /home/alprostov/PycharmProjects/sakhlis/web/venv/lib/python3.11/site-packages/django/core/servers/basehttp.py   None
15/Dec/2024 21:40:55    WARNING    log    Not Found: /media/masters/unknown_person.jpg   /home/alprostov/PycharmProjects/sakhlis/web/venv/lib/python3.11/site-packages/django/utils/log.py   None
15/Dec/2024 21:40:55    WARNING    basehttp    "GET /media/masters/unknown_person.jpg HTTP/1.1" 404 20198   /home/alprostov/PycharmProjects/sakhlis/web/venv/lib/python3.11/site-packages/django/core/servers/basehttp.py   None
15/Dec/2024 21:40:57    WARNING    log    Not Found: /media/masters/unknown_person.jpg   /home/alprostov/PycharmProjects/sakhlis/web/venv/lib/python3.11/site-packages/django/utils/log.py   None
15/Dec/2024 21:40:57    WARNING    basehttp    "GET /media/masters/unknown_person.jpg HTTP/1.1" 404 20198   /home/alprostov/PycharmProjects/sakhlis/web/venv/lib/python3.11/site-packages/django/core/servers/basehttp.py   None
15/Dec/2024 21:40:57    WARNING    log    Not Found: /media/masters/unknown_person.jpg   /home/alprostov/PycharmProjects/sakhlis/web/venv/lib/python3.11/site-packages/django/utils/log.py   None
15/Dec/2024 21:40:57    WARNING    basehttp    "GET /media/masters/unknown_person.jpg HTTP/1.1" 404 20198   /home/alprostov/PycharmProjects/sakhlis/web/venv/lib/python3.11/site-packages/django/core/servers/basehttp.py   None
15/Dec/2024 21:40:59    WARNING    log    Not Found: /media/masters/unknown_person.jpg   /home/alprostov/PycharmProjects/sakhlis/web/venv/lib/python3.11/site-packages/django/utils/log.py   None
15/Dec/2024 21:40:59    WARNING    basehttp    "GET /media/masters/unknown_person.jpg HTTP/1.1" 404 20198   /home/alprostov/PycharmProjects/sakhlis/web/venv/lib/python3.11/site-packages/django/core/servers/basehttp.py   None
15/Dec/2024 21:41:00    WARNING    log    Not Found: /media/masters/unknown_person.jpg   /home/alprostov/PycharmProjects/sakhlis/web/venv/lib/python3.11/site-packages/django/utils/log.py   None
15/Dec/2024 21:41:00    WARNING    basehttp    "GET /media/masters/unknown_person.jpg HTTP/1.1" 404 20198   /home/alprostov/PycharmProjects/sakhlis/web/venv/lib/python3.11/site-packages/django/core/servers/basehttp.py   None
15/Dec/2024 21:41:02    WARNING    log    Not Found: /media/masters/unknown_person.jpg   /home/alprostov/PycharmProjects/sakhlis/web/venv/lib/python3.11/site-packages/django/utils/log.py   None
15/Dec/2024 21:41:02    WARNING    basehttp    "GET /media/masters/unknown_person.jpg HTTP/1.1" 404 20198   /home/alprostov/PycharmProjects/sakhlis/web/venv/lib/python3.11/site-packages/django/core/servers/basehttp.py   None
15/Dec/2024 21:41:02    WARNING    log    Not Found: /media/masters/unknown_person.jpg   /home/alprostov/PycharmProjects/sakhlis/web/venv/lib/python3.11/site-packages/django/utils/log.py   None
15/Dec/2024 21:41:02    WARNING    basehttp    "GET /media/masters/unknown_person.jpg HTTP/1.1" 404 20198   /home/alprostov/PycharmProjects/sakhlis/web/venv/lib/python3.11/site-packages/django/core/servers/basehttp.py   None
15/Dec/2024 21:41:05    WARNING    log    Not Found: /media/masters/unknown_person.jpg   /home/alprostov/PycharmProjects/sakhlis/web/venv/lib/python3.11/site-packages/django/utils/log.py   None
15/Dec/2024 21:41:05    WARNING    basehttp    "GET /media/masters/unknown_person.jpg HTTP/1.1" 404 20198   /home/alprostov/PycharmProjects/sakhlis/web/venv/lib/python3.11/site-packages/django/core/servers/basehttp.py   None
15/Dec/2024 21:41:05    WARNING    log    Not Found: /media/masters/unknown_person.jpg   /home/alprostov/PycharmProjects/sakhlis/web/venv/lib/python3.11/site-packages/django/utils/log.py   None
15/Dec/2024 21:41:05    WARNING    basehttp    "GET /media/masters/unknown_person.jpg HTTP/1.1" 404 20198   /home/alprostov/PycharmProjects/sakhlis/web/venv/lib/python3.11/site-packages/django/core/servers/basehttp.py   None
15/Dec/2024 21:41:08    WARNING    log    Not Found: /media/masters/unknown_person.jpg   /home/alprostov/PycharmProjects/sakhlis/web/venv/lib/python3.11/site-packages/django/utils/log.py   None
15/Dec/2024 21:41:08    WARNING    basehttp    "GET /media/masters/unknown_person.jpg HTTP/1.1" 404 20198   /home/alprostov/PycharmProjects/sakhlis/web/venv/lib/python3.11/site-packages/django/core/servers/basehttp.py   None
15/Dec/2024 21:41:08    WARNING    log    Not Found: /media/masters/unknown_person.jpg   /home/alprostov/PycharmProjects/sakhlis/web/venv/lib/python3.11/site-packages/django/utils/log.py   None
15/Dec/2024 21:41:08    WARNING    basehttp    "GET /media/masters/unknown_person.jpg HTTP/1.1" 404 20198   /home/alprostov/PycharmProjects/sakhlis/web/venv/lib/python3.11/site-packages/django/core/servers/basehttp.py   None
15/Dec/2024 21:41:10    WARNING    log    Not Found: /media/masters/unknown_person.jpg   /home/alprostov/PycharmProjects/sakhlis/web/venv/lib/python3.11/site-packages/django/utils/log.py   None
15/Dec/2024 21:41:10    WARNING    basehttp    "GET /media/masters/unknown_person.jpg HTTP/1.1" 404 20198   /home/alprostov/PycharmProjects/sakhlis/web/venv/lib/python3.11/site-packages/django/core/servers/basehttp.py   None
15/Dec/2024 21:41:10    WARNING    log    Not Found: /media/masters/unknown_person.jpg   /home/alprostov/PycharmProjects/sakhlis/web/venv/lib/python3.11/site-packages/django/utils/log.py   None
15/Dec/2024 21:41:10    WARNING    basehttp    "GET /media/masters/unknown_person.jpg HTTP/1.1" 404 20198   /home/alprostov/PycharmProjects/sakhlis/web/venv/lib/python3.11/site-packages/django/core/servers/basehttp.py   None
15/Dec/2024 21:41:13    WARNING    log    Not Found: /media/masters/unknown_person.jpg   /home/alprostov/PycharmProjects/sakhlis/web/venv/lib/python3.11/site-packages/django/utils/log.py   None
15/Dec/2024 21:41:13    WARNING    basehttp    "GET /media/masters/unknown_person.jpg HTTP/1.1" 404 20198   /home/alprostov/PycharmProjects/sakhlis/web/venv/lib/python3.11/site-packages/django/core/servers/basehttp.py   None
15/Dec/2024 21:41:13    WARNING    log    Not Found: /media/masters/unknown_person.jpg   /home/alprostov/PycharmProjects/sakhlis/web/venv/lib/python3.11/site-packages/django/utils/log.py   None
15/Dec/2024 21:41:13    WARNING    basehttp    "GET /media/masters/unknown_person.jpg HTTP/1.1" 404 20198   /home/alprostov/PycharmProjects/sakhlis/web/venv/lib/python3.11/site-packages/django/core/servers/basehttp.py   None
15/Dec/2024 21:41:15    WARNING    log    Not Found: /media/masters/unknown_person.jpg   /home/alprostov/PycharmProjects/sakhlis/web/venv/lib/python3.11/site-packages/django/utils/log.py   None
15/Dec/2024 21:41:15    WARNING    basehttp    "GET /media/masters/unknown_person.jpg HTTP/1.1" 404 20198   /home/alprostov/PycharmProjects/sakhlis/web/venv/lib/python3.11/site-packages/django/core/servers/basehttp.py   None
15/Dec/2024 21:41:15    WARNING    log    Not Found: /media/masters/unknown_person.jpg   /home/alprostov/PycharmProjects/sakhlis/web/venv/lib/python3.11/site-packages/django/utils/log.py   None
15/Dec/2024 21:41:15    WARNING    basehttp    "GET /media/masters/unknown_person.jpg HTTP/1.1" 404 20198   /home/alprostov/PycharmProjects/sakhlis/web/venv/lib/python3.11/site-packages/django/core/servers/basehttp.py   None
15/Dec/2024 21:41:18    WARNING    log    Not Found: /media/masters/unknown_person.jpg   /home/alprostov/PycharmProjects/sakhlis/web/venv/lib/python3.11/site-packages/django/utils/log.py   None
15/Dec/2024 21:41:18    WARNING    basehttp    "GET /media/masters/unknown_person.jpg HTTP/1.1" 404 20198   /home/alprostov/PycharmProjects/sakhlis/web/venv/lib/python3.11/site-packages/django/core/servers/basehttp.py   None
15/Dec/2024 21:41:18    WARNING    log    Not Found: /media/masters/unknown_person.jpg   /home/alprostov/PycharmProjects/sakhlis/web/venv/lib/python3.11/site-packages/django/utils/log.py   None
15/Dec/2024 21:41:18    WARNING    basehttp    "GET /media/masters/unknown_person.jpg HTTP/1.1" 404 20198   /home/alprostov/PycharmProjects/sakhlis/web/venv/lib/python3.11/site-packages/django/core/servers/basehttp.py   None
15/Dec/2024 21:41:20    WARNING    log    Not Found: /media/masters/unknown_person.jpg   /home/alprostov/PycharmProjects/sakhlis/web/venv/lib/python3.11/site-packages/django/utils/log.py   None
15/Dec/2024 21:41:20    WARNING    basehttp    "GET /media/masters/unknown_person.jpg HTTP/1.1" 404 20198   /home/alprostov/PycharmProjects/sakhlis/web/venv/lib/python3.11/site-packages/django/core/servers/basehttp.py   None
15/Dec/2024 21:41:20    WARNING    log    Not Found: /media/masters/unknown_person.jpg   /home/alprostov/PycharmProjects/sakhlis/web/venv/lib/python3.11/site-packages/django/utils/log.py   None
15/Dec/2024 21:41:20    WARNING    basehttp    "GET /media/masters/unknown_person.jpg HTTP/1.1" 404 20198   /home/alprostov/PycharmProjects/sakhlis/web/venv/lib/python3.11/site-packages/django/core/servers/basehttp.py   None
15/Dec/2024 21:41:23    WARNING    log    Not Found: /media/masters/unknown_person.jpg   /home/alprostov/PycharmProjects/sakhlis/web/venv/lib/python3.11/site-packages/django/utils/log.py   None
15/Dec/2024 21:41:23    WARNING    basehttp    "GET /media/masters/unknown_person.jpg HTTP/1.1" 404 20198   /home/alprostov/PycharmProjects/sakhlis/web/venv/lib/python3.11/site-packages/django/core/servers/basehttp.py   None
15/Dec/2024 21:41:23    WARNING    log    Not Found: /media/masters/unknown_person.jpg   /home/alprostov/PycharmProjects/sakhlis/web/venv/lib/python3.11/site-packages/django/utils/log.py   None
15/Dec/2024 21:41:23    WARNING    basehttp    "GET /media/masters/unknown_person.jpg HTTP/1.1" 404 20198   /home/alprostov/PycharmProjects/sakhlis/web/venv/lib/python3.11/site-packages/django/core/servers/basehttp.py   None
15/Dec/2024 21:41:26    WARNING    log    Not Found: /media/masters/unknown_person.jpg   /home/alprostov/PycharmProjects/sakhlis/web/venv/lib/python3.11/site-packages/django/utils/log.py   None
15/Dec/2024 21:41:26    WARNING    basehttp    "GET /media/masters/unknown_person.jpg HTTP/1.1" 404 20198   /home/alprostov/PycharmProjects/sakhlis/web/venv/lib/python3.11/site-packages/django/core/servers/basehttp.py   None
15/Dec/2024 21:41:26    WARNING    log    Not Found: /media/masters/unknown_person.jpg   /home/alprostov/PycharmProjects/sakhlis/web/venv/lib/python3.11/site-packages/django/utils/log.py   None
15/Dec/2024 21:41:26    WARNING    basehttp    "GET /media/masters/unknown_person.jpg HTTP/1.1" 404 20198   /home/alprostov/PycharmProjects/sakhlis/web/venv/lib/python3.11/site-packages/django/core/servers/basehttp.py   None
15/Dec/2024 21:41:28    WARNING    log    Not Found: /media/masters/unknown_person.jpg   /home/alprostov/PycharmProjects/sakhlis/web/venv/lib/python3.11/site-packages/django/utils/log.py   None
15/Dec/2024 21:41:28    WARNING    basehttp    "GET /media/masters/unknown_person.jpg HTTP/1.1" 404 20198   /home/alprostov/PycharmProjects/sakhlis/web/venv/lib/python3.11/site-packages/django/core/servers/basehttp.py   None
15/Dec/2024 21:41:28    WARNING    log    Not Found: /media/masters/unknown_person.jpg   /home/alprostov/PycharmProjects/sakhlis/web/venv/lib/python3.11/site-packages/django/utils/log.py   None
15/Dec/2024 21:41:28    WARNING    basehttp    "GET /media/masters/unknown_person.jpg HTTP/1.1" 404 20198   /home/alprostov/PycharmProjects/sakhlis/web/venv/lib/python3.11/site-packages/django/core/servers/basehttp.py   None
15/Dec/2024 21:41:31    WARNING    log    Not Found: /media/masters/unknown_person.jpg   /home/alprostov/PycharmProjects/sakhlis/web/venv/lib/python3.11/site-packages/django/utils/log.py   None
15/Dec/2024 21:41:31    WARNING    basehttp    "GET /media/masters/unknown_person.jpg HTTP/1.1" 404 20198   /home/alprostov/PycharmProjects/sakhlis/web/venv/lib/python3.11/site-packages/django/core/servers/basehttp.py   None
15/Dec/2024 21:41:31    WARNING    log    Not Found: /media/masters/unknown_person.jpg   /home/alprostov/PycharmProjects/sakhlis/web/venv/lib/python3.11/site-packages/django/utils/log.py   None
15/Dec/2024 21:41:31    WARNING    basehttp    "GET /media/masters/unknown_person.jpg HTTP/1.1" 404 20198   /home/alprostov/PycharmProjects/sakhlis/web/venv/lib/python3.11/site-packages/django/core/servers/basehttp.py   None
15/Dec/2024 21:41:33    WARNING    log    Not Found: /media/masters/unknown_person.jpg   /home/alprostov/PycharmProjects/sakhlis/web/venv/lib/python3.11/site-packages/django/utils/log.py   None
15/Dec/2024 21:41:33    WARNING    basehttp    "GET /media/masters/unknown_person.jpg HTTP/1.1" 404 20198   /home/alprostov/PycharmProjects/sakhlis/web/venv/lib/python3.11/site-packages/django/core/servers/basehttp.py   None
15/Dec/2024 21:41:33    WARNING    log    Not Found: /media/masters/unknown_person.jpg   /home/alprostov/PycharmProjects/sakhlis/web/venv/lib/python3.11/site-packages/django/utils/log.py   None
15/Dec/2024 21:41:33    WARNING    basehttp    "GET /media/masters/unknown_person.jpg HTTP/1.1" 404 20198   /home/alprostov/PycharmProjects/sakhlis/web/venv/lib/python3.11/site-packages/django/core/servers/basehttp.py   None
15/Dec/2024 21:41:36    WARNING    log    Not Found: /media/masters/unknown_person.jpg   /home/alprostov/PycharmProjects/sakhlis/web/venv/lib/python3.11/site-packages/django/utils/log.py   None
15/Dec/2024 21:41:36    WARNING    basehttp    "GET /media/masters/unknown_person.jpg HTTP/1.1" 404 20198   /home/alprostov/PycharmProjects/sakhlis/web/venv/lib/python3.11/site-packages/django/core/servers/basehttp.py   None
15/Dec/2024 21:41:36    WARNING    log    Not Found: /media/masters/unknown_person.jpg   /home/alprostov/PycharmProjects/sakhlis/web/venv/lib/python3.11/site-packages/django/utils/log.py   None
15/Dec/2024 21:41:36    WARNING    basehttp    "GET /media/masters/unknown_person.jpg HTTP/1.1" 404 20198   /home/alprostov/PycharmProjects/sakhlis/web/venv/lib/python3.11/site-packages/django/core/servers/basehttp.py   None
15/Dec/2024 21:41:39    WARNING    log    Not Found: /media/masters/unknown_person.jpg   /home/alprostov/PycharmProjects/sakhlis/web/venv/lib/python3.11/site-packages/django/utils/log.py   None
15/Dec/2024 21:41:39    WARNING    basehttp    "GET /media/masters/unknown_person.jpg HTTP/1.1" 404 20198   /home/alprostov/PycharmProjects/sakhlis/web/venv/lib/python3.11/site-packages/django/core/servers/basehttp.py   None
15/Dec/2024 21:41:39    WARNING    log    Not Found: /media/masters/unknown_person.jpg   /home/alprostov/PycharmProjects/sakhlis/web/venv/lib/python3.11/site-packages/django/utils/log.py   None
15/Dec/2024 21:41:39    WARNING    basehttp    "GET /media/masters/unknown_person.jpg HTTP/1.1" 404 20198   /home/alprostov/PycharmProjects/sakhlis/web/venv/lib/python3.11/site-packages/django/core/servers/basehttp.py   None
19/Dec/2024 20:10:43    WARNING    log    Not Found: /favicon.ico   /home/alprostov/PycharmProjects/sakhlis/web/venv/lib/python3.11/site-packages/django/utils/log.py   None
19/Dec/2024 20:10:43    WARNING    basehttp    "GET /favicon.ico HTTP/1.1" 404 19851   /home/alprostov/PycharmProjects/sakhlis/web/venv/lib/python3.11/site-packages/django/core/servers/basehttp.py   None
