WARNING:django.request:Not Found: /favicon.ico
WARNING:django.request:Not Found: /favicon.ico
WARNING:django.request:Not Found: /favicon.ico
WARNING:django.request:Not Found: /favicon.ico
WARNING:django.request:Not Found: /favicon.ico
WARNING:django.request:Not Found: /favicon.ico
ERROR:django.request:Internal Server Error: /
Traceback (most recent call last):
  File "/home/alprostov/.local/share/virtualenvs/web-mek5ITq2/lib64/python3.11/site-packages/django/template/backends/django.py", line 61, in render
    return self.template.render(context)
           ^^^^^^^^^^^^^^^^^^^^^^^^^^^^^
  File "/home/alprostov/.local/share/virtualenvs/web-mek5ITq2/lib64/python3.11/site-packages/django/template/base.py", line 175, in render
    return self._render(context)
           ^^^^^^^^^^^^^^^^^^^^^
  File "/home/alprostov/.local/share/virtualenvs/web-mek5ITq2/lib64/python3.11/site-packages/django/test/utils.py", line 112, in instrumented_test_render
    return self.nodelist.render(context)
           ^^^^^^^^^^^^^^^^^^^^^^^^^^^^^
  File "/home/alprostov/.local/share/virtualenvs/web-mek5ITq2/lib64/python3.11/site-packages/django/template/base.py", line 1005, in render
    return SafeString("".join([node.render_annotated(context) for node in self]))
                              ^^^^^^^^^^^^^^^^^^^^^^^^^^^^^^^^^^^^^^^^^^^^^^^^^
  File "/home/alprostov/.local/share/virtualenvs/web-mek5ITq2/lib64/python3.11/site-packages/django/template/base.py", line 1005, in <listcomp>
    return SafeString("".join([node.render_annotated(context) for node in self]))
                               ^^^^^^^^^^^^^^^^^^^^^^^^^^^^^^
  File "/home/alprostov/.local/share/virtualenvs/web-mek5ITq2/lib64/python3.11/site-packages/django/template/base.py", line 966, in render_annotated
    return self.render(context)
           ^^^^^^^^^^^^^^^^^^^^
  File "/home/alprostov/.local/share/virtualenvs/web-mek5ITq2/lib64/python3.11/site-packages/slippers/templatetags/slippers.py", line 102, in render
    template = context.template.engine.get_template(self.template_path)
               ^^^^^^^^^^^^^^^^^^^^^^^^^^^^^^^^^^^^^^^^^^^^^^^^^^^^^^^^
  File "/home/alprostov/.local/share/virtualenvs/web-mek5ITq2/lib64/python3.11/site-packages/django/template/engine.py", line 175, in get_template
    template, origin = self.find_template(template_name)
                       ^^^^^^^^^^^^^^^^^^^^^^^^^^^^^^^^^
  File "/home/alprostov/.local/share/virtualenvs/web-mek5ITq2/lib64/python3.11/site-packages/django/template/engine.py", line 161, in find_template
    raise TemplateDoesNotExist(name, tried=tried)
django.template.exceptions.TemplateDoesNotExist:  partials/form_for_order.html

The above exception was the direct cause of the following exception:

Traceback (most recent call last):
  File "/home/alprostov/.local/share/virtualenvs/web-mek5ITq2/lib64/python3.11/site-packages/django/core/handlers/exception.py", line 55, in inner
    response = get_response(request)
               ^^^^^^^^^^^^^^^^^^^^^
  File "/home/alprostov/.local/share/virtualenvs/web-mek5ITq2/lib64/python3.11/site-packages/django/core/handlers/base.py", line 220, in _get_response
    response = response.render()
               ^^^^^^^^^^^^^^^^^
  File "/home/alprostov/.local/share/virtualenvs/web-mek5ITq2/lib64/python3.11/site-packages/django/template/response.py", line 111, in render
    self.content = self.rendered_content
                   ^^^^^^^^^^^^^^^^^^^^^
  File "/home/alprostov/.local/share/virtualenvs/web-mek5ITq2/lib64/python3.11/site-packages/django/template/response.py", line 89, in rendered_content
    return template.render(context, self._request)
           ^^^^^^^^^^^^^^^^^^^^^^^^^^^^^^^^^^^^^^^
  File "/home/alprostov/.local/share/virtualenvs/web-mek5ITq2/lib64/python3.11/site-packages/django/template/backends/django.py", line 63, in render
    reraise(exc, self.backend)
  File "/home/alprostov/.local/share/virtualenvs/web-mek5ITq2/lib64/python3.11/site-packages/django/template/backends/django.py", line 84, in reraise
    raise new from exc
django.template.exceptions.TemplateDoesNotExist:  partials/form_for_order.html
ERROR:django.request:Internal Server Error: /
Traceback (most recent call last):
  File "/home/alprostov/.local/share/virtualenvs/web-mek5ITq2/lib64/python3.11/site-packages/django/template/backends/django.py", line 61, in render
    return self.template.render(context)
           ^^^^^^^^^^^^^^^^^^^^^^^^^^^^^
  File "/home/alprostov/.local/share/virtualenvs/web-mek5ITq2/lib64/python3.11/site-packages/django/template/base.py", line 175, in render
    return self._render(context)
           ^^^^^^^^^^^^^^^^^^^^^
  File "/home/alprostov/.local/share/virtualenvs/web-mek5ITq2/lib64/python3.11/site-packages/django/test/utils.py", line 112, in instrumented_test_render
    return self.nodelist.render(context)
           ^^^^^^^^^^^^^^^^^^^^^^^^^^^^^
  File "/home/alprostov/.local/share/virtualenvs/web-mek5ITq2/lib64/python3.11/site-packages/django/template/base.py", line 1005, in render
    return SafeString("".join([node.render_annotated(context) for node in self]))
                              ^^^^^^^^^^^^^^^^^^^^^^^^^^^^^^^^^^^^^^^^^^^^^^^^^
  File "/home/alprostov/.local/share/virtualenvs/web-mek5ITq2/lib64/python3.11/site-packages/django/template/base.py", line 1005, in <listcomp>
    return SafeString("".join([node.render_annotated(context) for node in self]))
                               ^^^^^^^^^^^^^^^^^^^^^^^^^^^^^^
  File "/home/alprostov/.local/share/virtualenvs/web-mek5ITq2/lib64/python3.11/site-packages/django/template/base.py", line 966, in render_annotated
    return self.render(context)
           ^^^^^^^^^^^^^^^^^^^^
  File "/home/alprostov/.local/share/virtualenvs/web-mek5ITq2/lib64/python3.11/site-packages/slippers/templatetags/slippers.py", line 102, in render
    template = context.template.engine.get_template(self.template_path)
               ^^^^^^^^^^^^^^^^^^^^^^^^^^^^^^^^^^^^^^^^^^^^^^^^^^^^^^^^
  File "/home/alprostov/.local/share/virtualenvs/web-mek5ITq2/lib64/python3.11/site-packages/django/template/engine.py", line 175, in get_template
    template, origin = self.find_template(template_name)
                       ^^^^^^^^^^^^^^^^^^^^^^^^^^^^^^^^^
  File "/home/alprostov/.local/share/virtualenvs/web-mek5ITq2/lib64/python3.11/site-packages/django/template/engine.py", line 161, in find_template
    raise TemplateDoesNotExist(name, tried=tried)
django.template.exceptions.TemplateDoesNotExist:  partials/form_for_order.html

The above exception was the direct cause of the following exception:

Traceback (most recent call last):
  File "/home/alprostov/.local/share/virtualenvs/web-mek5ITq2/lib64/python3.11/site-packages/django/core/handlers/exception.py", line 55, in inner
    response = get_response(request)
               ^^^^^^^^^^^^^^^^^^^^^
  File "/home/alprostov/.local/share/virtualenvs/web-mek5ITq2/lib64/python3.11/site-packages/django/core/handlers/base.py", line 220, in _get_response
    response = response.render()
               ^^^^^^^^^^^^^^^^^
  File "/home/alprostov/.local/share/virtualenvs/web-mek5ITq2/lib64/python3.11/site-packages/django/template/response.py", line 111, in render
    self.content = self.rendered_content
                   ^^^^^^^^^^^^^^^^^^^^^
  File "/home/alprostov/.local/share/virtualenvs/web-mek5ITq2/lib64/python3.11/site-packages/django/template/response.py", line 89, in rendered_content
    return template.render(context, self._request)
           ^^^^^^^^^^^^^^^^^^^^^^^^^^^^^^^^^^^^^^^
  File "/home/alprostov/.local/share/virtualenvs/web-mek5ITq2/lib64/python3.11/site-packages/django/template/backends/django.py", line 63, in render
    reraise(exc, self.backend)
  File "/home/alprostov/.local/share/virtualenvs/web-mek5ITq2/lib64/python3.11/site-packages/django/template/backends/django.py", line 84, in reraise
    raise new from exc
django.template.exceptions.TemplateDoesNotExist:  partials/form_for_order.html
