WARNING:root:===========================================================
WARNING:root:ВРЕМЯ:     2024-02-25 19:28:09.012347
WARNING:root:ОШИБКА:        'QuerySet' object has no attribute 'objects'
WARNING:root:ТРЭЙСБЭК:     Traceback (most recent call last):
  File "/home/alprostov/PycharmProjects/sakhlis/sakhlis/web/app_site/exeptions.py", line 35, in dispatch
    response = super().dispatch(request, *args, **kwargs)
               ^^^^^^^^^^^^^^^^^^^^^^^^^^^^^^^^^^^^^^^^^^
  File "/home/alprostov/.local/share/virtualenvs/web-xbYPzM3q/lib64/python3.11/site-packages/django/contrib/auth/mixins.py", line 73, in dispatch
    return super().dispatch(request, *args, **kwargs)
           ^^^^^^^^^^^^^^^^^^^^^^^^^^^^^^^^^^^^^^^^^^
  File "/home/alprostov/.local/share/virtualenvs/web-xbYPzM3q/lib64/python3.11/site-packages/django/views/generic/base.py", line 143, in dispatch
    return handler(request, *args, **kwargs)
           ^^^^^^^^^^^^^^^^^^^^^^^^^^^^^^^^^
  File "/home/alprostov/.local/share/virtualenvs/web-xbYPzM3q/lib64/python3.11/site-packages/django/views/generic/list.py", line 174, in get
    context = self.get_context_data()
              ^^^^^^^^^^^^^^^^^^^^^^^
  File "/home/alprostov/PycharmProjects/sakhlis/sakhlis/web/app_site/views.py", line 181, in get_context_data
    c = DataFromInvoice(Invoice.objects.filter(order_id__in=list_b)).get_quantity_of_orders_by_type(
        ^^^^^^^^^^^^^^^^^^^^^^^^^^^^^^^^^^^^^^^^^^^^^^^^^^^^^^^^^^^^
  File "/home/alprostov/PycharmProjects/sakhlis/sakhlis/web/app_site/repository.py", line 76, in __init__
    self.query=query.objects
               ^^^^^^^^^^^^^
AttributeError: 'QuerySet' object has no attribute 'objects'

WARNING:root:============================================================
WARNING:django.request:Bad Request: /stat/
WARNING:root:===========================================================
WARNING:root:ВРЕМЯ:     2024-02-25 19:28:30.721813
WARNING:root:ОШИБКА:        'QuerySet' object has no attribute 'objects'
WARNING:root:ТРЭЙСБЭК:     Traceback (most recent call last):
  File "/home/alprostov/PycharmProjects/sakhlis/sakhlis/web/app_site/exeptions.py", line 35, in dispatch
    response = super().dispatch(request, *args, **kwargs)
               ^^^^^^^^^^^^^^^^^^^^^^^^^^^^^^^^^^^^^^^^^^
  File "/home/alprostov/.local/share/virtualenvs/web-xbYPzM3q/lib64/python3.11/site-packages/django/contrib/auth/mixins.py", line 73, in dispatch
    return super().dispatch(request, *args, **kwargs)
           ^^^^^^^^^^^^^^^^^^^^^^^^^^^^^^^^^^^^^^^^^^
  File "/home/alprostov/.local/share/virtualenvs/web-xbYPzM3q/lib64/python3.11/site-packages/django/views/generic/base.py", line 143, in dispatch
    return handler(request, *args, **kwargs)
           ^^^^^^^^^^^^^^^^^^^^^^^^^^^^^^^^^
  File "/home/alprostov/.local/share/virtualenvs/web-xbYPzM3q/lib64/python3.11/site-packages/django/views/generic/list.py", line 174, in get
    context = self.get_context_data()
              ^^^^^^^^^^^^^^^^^^^^^^^
  File "/home/alprostov/PycharmProjects/sakhlis/sakhlis/web/app_site/views.py", line 181, in get_context_data
    c = DataFromInvoice(Invoice.objects.filter(order_id__in=list_b)).get_quantity_of_orders_by_type(
        ^^^^^^^^^^^^^^^^^^^^^^^^^^^^^^^^^^^^^^^^^^^^^^^^^^^^^^^^^^^^
  File "/home/alprostov/PycharmProjects/sakhlis/sakhlis/web/app_site/repository.py", line 76, in __init__
    self.query=query
               ^^^^^^
AttributeError: 'QuerySet' object has no attribute 'objects'

WARNING:root:============================================================
WARNING:django.request:Bad Request: /stat/
INFO:django.utils.autoreload:/home/alprostov/PycharmProjects/sakhlis/sakhlis/web/app_site/repository.py changed, reloading.
INFO:django.utils.autoreload:/home/alprostov/PycharmProjects/sakhlis/sakhlis/web/app_site/views.py changed, reloading.
INFO:django.utils.autoreload:/home/alprostov/PycharmProjects/sakhlis/sakhlis/web/app_site/views.py changed, reloading.
INFO:django.utils.autoreload:/home/alprostov/PycharmProjects/sakhlis/sakhlis/web/app_site/views.py changed, reloading.
INFO:django.utils.autoreload:/home/alprostov/PycharmProjects/sakhlis/sakhlis/web/app_site/views.py changed, reloading.
WARNING:root:===========================================================
WARNING:root:ВРЕМЯ:     2024-02-25 19:38:10.296619
WARNING:root:ОШИБКА:        'DataFromInvoice' object has no attribute 'get_cost_of_orders_by_type'
WARNING:root:ТРЭЙСБЭК:     Traceback (most recent call last):
  File "/home/alprostov/PycharmProjects/sakhlis/sakhlis/web/app_site/exeptions.py", line 35, in dispatch
    response = super().dispatch(request, *args, **kwargs)
               ^^^^^^^^^^^^^^^^^^^^^^^^^^^^^^^^^^^^^^^^^^
  File "/home/alprostov/.local/share/virtualenvs/web-xbYPzM3q/lib64/python3.11/site-packages/django/contrib/auth/mixins.py", line 73, in dispatch
    return super().dispatch(request, *args, **kwargs)
           ^^^^^^^^^^^^^^^^^^^^^^^^^^^^^^^^^^^^^^^^^^
  File "/home/alprostov/.local/share/virtualenvs/web-xbYPzM3q/lib64/python3.11/site-packages/django/views/generic/base.py", line 143, in dispatch
    return handler(request, *args, **kwargs)
           ^^^^^^^^^^^^^^^^^^^^^^^^^^^^^^^^^
  File "/home/alprostov/.local/share/virtualenvs/web-xbYPzM3q/lib64/python3.11/site-packages/django/views/generic/list.py", line 174, in get
    context = self.get_context_data()
              ^^^^^^^^^^^^^^^^^^^^^^^
  File "/home/alprostov/PycharmProjects/sakhlis/sakhlis/web/app_site/views.py", line 188, in get_context_data
    context['d_'] = Graph(Object_to_get_data_for_graf.get_cost_of_orders_by_type(repairer=self.request.user),
                          ^^^^^^^^^^^^^^^^^^^^^^^^^^^^^^^^^^^^^^^^^^^^^^^^^^^^^^
AttributeError: 'DataFromInvoice' object has no attribute 'get_cost_of_orders_by_type'

WARNING:root:============================================================
WARNING:django.request:Bad Request: /stat/
INFO:django.utils.autoreload:/home/alprostov/PycharmProjects/sakhlis/sakhlis/web/app_site/repository.py changed, reloading.
WARNING:root:===========================================================
WARNING:root:ВРЕМЯ:     2024-02-25 19:38:11.964585
WARNING:root:ОШИБКА:        'DataFromInvoice' object has no attribute 'get_cost_of_orders_by_type'
WARNING:root:ТРЭЙСБЭК:     Traceback (most recent call last):
  File "/home/alprostov/PycharmProjects/sakhlis/sakhlis/web/app_site/exeptions.py", line 35, in dispatch
    response = super().dispatch(request, *args, **kwargs)
               ^^^^^^^^^^^^^^^^^^^^^^^^^^^^^^^^^^^^^^^^^^
  File "/home/alprostov/.local/share/virtualenvs/web-xbYPzM3q/lib64/python3.11/site-packages/django/contrib/auth/mixins.py", line 73, in dispatch
    return super().dispatch(request, *args, **kwargs)
           ^^^^^^^^^^^^^^^^^^^^^^^^^^^^^^^^^^^^^^^^^^
  File "/home/alprostov/.local/share/virtualenvs/web-xbYPzM3q/lib64/python3.11/site-packages/django/views/generic/base.py", line 143, in dispatch
    return handler(request, *args, **kwargs)
           ^^^^^^^^^^^^^^^^^^^^^^^^^^^^^^^^^
  File "/home/alprostov/.local/share/virtualenvs/web-xbYPzM3q/lib64/python3.11/site-packages/django/views/generic/list.py", line 174, in get
    context = self.get_context_data()
              ^^^^^^^^^^^^^^^^^^^^^^^
  File "/home/alprostov/PycharmProjects/sakhlis/sakhlis/web/app_site/views.py", line 188, in get_context_data
    context['d_'] = Graph(Object_to_get_data_for_graf.get_cost_of_orders_by_type(repairer=self.request.user),
                          ^^^^^^^^^^^^^^^^^^^^^^^^^^^^^^^^^^^^^^^^^^^^^^^^^^^^^^
AttributeError: 'DataFromInvoice' object has no attribute 'get_cost_of_orders_by_type'

WARNING:root:============================================================
WARNING:django.request:Bad Request: /stat/
WARNING:root:===========================================================
WARNING:root:ВРЕМЯ:     2024-02-25 19:39:03.975459
WARNING:root:ОШИБКА:        'DataFromInvoice' object has no attribute 'get_monthly_order_cost_from_OrderList'
WARNING:root:ТРЭЙСБЭК:     Traceback (most recent call last):
  File "/home/alprostov/PycharmProjects/sakhlis/sakhlis/web/app_site/exeptions.py", line 35, in dispatch
    response = super().dispatch(request, *args, **kwargs)
               ^^^^^^^^^^^^^^^^^^^^^^^^^^^^^^^^^^^^^^^^^^
  File "/home/alprostov/.local/share/virtualenvs/web-xbYPzM3q/lib64/python3.11/site-packages/django/contrib/auth/mixins.py", line 73, in dispatch
    return super().dispatch(request, *args, **kwargs)
           ^^^^^^^^^^^^^^^^^^^^^^^^^^^^^^^^^^^^^^^^^^
  File "/home/alprostov/.local/share/virtualenvs/web-xbYPzM3q/lib64/python3.11/site-packages/django/views/generic/base.py", line 143, in dispatch
    return handler(request, *args, **kwargs)
           ^^^^^^^^^^^^^^^^^^^^^^^^^^^^^^^^^
  File "/home/alprostov/.local/share/virtualenvs/web-xbYPzM3q/lib64/python3.11/site-packages/django/views/generic/list.py", line 174, in get
    context = self.get_context_data()
              ^^^^^^^^^^^^^^^^^^^^^^^
  File "/home/alprostov/PycharmProjects/sakhlis/sakhlis/web/app_site/views.py", line 192, in get_context_data
    # context['f'] = Graph(Object_to_get_data_for_graf.get_monthly_order_cost_from_OrderList(repairer=self.request.user),
                         ^^^^^^^^^^^^^^^^^^^^^^^^^^^^^^^^^^^^^^^^^^^^^^^^^^^^^^^^^^^^^^^^^
AttributeError: 'DataFromInvoice' object has no attribute 'get_monthly_order_cost_from_OrderList'

WARNING:root:============================================================
WARNING:django.request:Bad Request: /stat/
INFO:django.utils.autoreload:/home/alprostov/PycharmProjects/sakhlis/sakhlis/web/app_site/views.py changed, reloading.
INFO:django.utils.autoreload:/home/alprostov/PycharmProjects/sakhlis/sakhlis/web/app_site/views.py changed, reloading.
INFO:django.utils.autoreload:/home/alprostov/PycharmProjects/sakhlis/sakhlis/web/app_site/views.py changed, reloading.
INFO:django.utils.autoreload:/home/alprostov/PycharmProjects/sakhlis/sakhlis/web/app_site/views.py changed, reloading.
WARNING:root:===========================================================
WARNING:root:ВРЕМЯ:     2024-02-25 19:49:19.695350
WARNING:root:ОШИБКА:        DataFromInvoice.__init__() missing 1 required positional argument: 'query'
WARNING:root:ТРЭЙСБЭК:     Traceback (most recent call last):
  File "/home/alprostov/PycharmProjects/sakhlis/sakhlis/web/app_site/exeptions.py", line 35, in dispatch
    response = super().dispatch(request, *args, **kwargs)
               ^^^^^^^^^^^^^^^^^^^^^^^^^^^^^^^^^^^^^^^^^^
  File "/home/alprostov/.local/share/virtualenvs/web-xbYPzM3q/lib64/python3.11/site-packages/django/contrib/auth/mixins.py", line 73, in dispatch
    return super().dispatch(request, *args, **kwargs)
           ^^^^^^^^^^^^^^^^^^^^^^^^^^^^^^^^^^^^^^^^^^
  File "/home/alprostov/.local/share/virtualenvs/web-xbYPzM3q/lib64/python3.11/site-packages/django/views/generic/base.py", line 143, in dispatch
    return handler(request, *args, **kwargs)
           ^^^^^^^^^^^^^^^^^^^^^^^^^^^^^^^^^
  File "/home/alprostov/.local/share/virtualenvs/web-xbYPzM3q/lib64/python3.11/site-packages/django/views/generic/list.py", line 174, in get
    context = self.get_context_data()
              ^^^^^^^^^^^^^^^^^^^^^^^
  File "/home/alprostov/PycharmProjects/sakhlis/sakhlis/web/app_site/views.py", line 225, in get_context_data
    c = DataFromInvoice().get_total_cost_of_some_orders(list_of_orders=self.get_queryset())
        ^^^^^^^^^^^^^^^^^
TypeError: DataFromInvoice.__init__() missing 1 required positional argument: 'query'

WARNING:root:============================================================
WARNING:django.request:Bad Request: /ordersearch/
INFO:django.utils.autoreload:/home/alprostov/PycharmProjects/sakhlis/sakhlis/web/app_site/repository.py changed, reloading.
INFO:django.utils.autoreload:/home/alprostov/PycharmProjects/sakhlis/sakhlis/web/app_site/repository.py changed, reloading.
INFO:django.utils.autoreload:/home/alprostov/PycharmProjects/sakhlis/sakhlis/web/app_site/repository.py changed, reloading.
WARNING:root:===========================================================
WARNING:root:ВРЕМЯ:     2024-02-25 19:53:52.076888
WARNING:root:ОШИБКА:        'DataFromInvoice' object has no attribute 'get_monthly_order_cost_from_OrderList'
WARNING:root:ТРЭЙСБЭК:     Traceback (most recent call last):
  File "/home/alprostov/PycharmProjects/sakhlis/sakhlis/web/app_site/exeptions.py", line 35, in dispatch
    response = super().dispatch(request, *args, **kwargs)
               ^^^^^^^^^^^^^^^^^^^^^^^^^^^^^^^^^^^^^^^^^^
  File "/home/alprostov/.local/share/virtualenvs/web-xbYPzM3q/lib64/python3.11/site-packages/django/contrib/auth/mixins.py", line 73, in dispatch
    return super().dispatch(request, *args, **kwargs)
           ^^^^^^^^^^^^^^^^^^^^^^^^^^^^^^^^^^^^^^^^^^
  File "/home/alprostov/.local/share/virtualenvs/web-xbYPzM3q/lib64/python3.11/site-packages/django/views/generic/base.py", line 143, in dispatch
    return handler(request, *args, **kwargs)
           ^^^^^^^^^^^^^^^^^^^^^^^^^^^^^^^^^
  File "/home/alprostov/.local/share/virtualenvs/web-xbYPzM3q/lib64/python3.11/site-packages/django/views/generic/list.py", line 174, in get
    context = self.get_context_data()
              ^^^^^^^^^^^^^^^^^^^^^^^
  File "/home/alprostov/PycharmProjects/sakhlis/sakhlis/web/app_site/views.py", line 192, in get_context_data
    context['f'] = Graph(Object_to_get_data_for_graf.get_monthly_order_cost_from_OrderList(repairer=self.request.user),
                         ^^^^^^^^^^^^^^^^^^^^^^^^^^^^^^^^^^^^^^^^^^^^^^^^^^^^^^^^^^^^^^^^^
AttributeError: 'DataFromInvoice' object has no attribute 'get_monthly_order_cost_from_OrderList'

WARNING:root:============================================================
WARNING:django.request:Bad Request: /stat/
WARNING:root:===========================================================
WARNING:root:ВРЕМЯ:     2024-02-25 19:54:11.738488
WARNING:root:ОШИБКА:        'DataFromInvoice' object has no attribute 'get_monthly_order_cost_from_OrderList'
WARNING:root:ТРЭЙСБЭК:     Traceback (most recent call last):
  File "/home/alprostov/PycharmProjects/sakhlis/sakhlis/web/app_site/exeptions.py", line 35, in dispatch
    response = super().dispatch(request, *args, **kwargs)
               ^^^^^^^^^^^^^^^^^^^^^^^^^^^^^^^^^^^^^^^^^^
  File "/home/alprostov/.local/share/virtualenvs/web-xbYPzM3q/lib64/python3.11/site-packages/django/contrib/auth/mixins.py", line 73, in dispatch
    return super().dispatch(request, *args, **kwargs)
           ^^^^^^^^^^^^^^^^^^^^^^^^^^^^^^^^^^^^^^^^^^
  File "/home/alprostov/.local/share/virtualenvs/web-xbYPzM3q/lib64/python3.11/site-packages/django/views/generic/base.py", line 143, in dispatch
    return handler(request, *args, **kwargs)
           ^^^^^^^^^^^^^^^^^^^^^^^^^^^^^^^^^
  File "/home/alprostov/.local/share/virtualenvs/web-xbYPzM3q/lib64/python3.11/site-packages/django/views/generic/list.py", line 174, in get
    context = self.get_context_data()
              ^^^^^^^^^^^^^^^^^^^^^^^
  File "/home/alprostov/PycharmProjects/sakhlis/sakhlis/web/app_site/views.py", line 192, in get_context_data
    # context['f'] = Graph(Object_to_get_data_for_graf.get_monthly_order_cost_from_OrderList(repairer=self.request.user),
                         ^^^^^^^^^^^^^^^^^^^^^^^^^^^^^^^^^^^^^^^^^^^^^^^^^^^^^^^^^^^^^^^^^
AttributeError: 'DataFromInvoice' object has no attribute 'get_monthly_order_cost_from_OrderList'

WARNING:root:============================================================
WARNING:django.request:Bad Request: /stat/
INFO:django.utils.autoreload:/home/alprostov/PycharmProjects/sakhlis/sakhlis/web/app_site/views.py changed, reloading.
INFO:django.utils.autoreload:/home/alprostov/PycharmProjects/sakhlis/sakhlis/web/app_site/repository.py changed, reloading.
INFO:django.utils.autoreload:/home/alprostov/PycharmProjects/sakhlis/sakhlis/web/app_site/views.py changed, reloading.
INFO:django.utils.autoreload:/home/alprostov/PycharmProjects/sakhlis/sakhlis/web/app_site/views.py changed, reloading.
INFO:django.utils.autoreload:/home/alprostov/PycharmProjects/sakhlis/sakhlis/web/app_site/views.py changed, reloading.
INFO:django.utils.autoreload:/home/alprostov/PycharmProjects/sakhlis/sakhlis/web/app_site/views.py changed, reloading.
INFO:django.utils.autoreload:/home/alprostov/PycharmProjects/sakhlis/sakhlis/web/app_site/views.py changed, reloading.
INFO:django.utils.autoreload:/home/alprostov/PycharmProjects/sakhlis/sakhlis/web/app_site/views.py changed, reloading.
INFO:django.utils.autoreload:/home/alprostov/PycharmProjects/sakhlis/sakhlis/web/app_site/views.py changed, reloading.
INFO:django.utils.autoreload:/home/alprostov/PycharmProjects/sakhlis/sakhlis/web/app_site/filters.py changed, reloading.
INFO:django.utils.autoreload:/home/alprostov/PycharmProjects/sakhlis/sakhlis/web/app_site/views.py changed, reloading.
INFO:django.utils.autoreload:/home/alprostov/PycharmProjects/sakhlis/sakhlis/web/app_site/views.py changed, reloading.
INFO:django.utils.autoreload:/home/alprostov/PycharmProjects/sakhlis/sakhlis/web/app_site/views.py changed, reloading.
ERROR:django.request:Internal Server Error: /changestatus
Traceback (most recent call last):
  File "/home/alprostov/.local/share/virtualenvs/web-xbYPzM3q/lib64/python3.11/site-packages/django/core/handlers/exception.py", line 55, in inner
    response = get_response(request)
               ^^^^^^^^^^^^^^^^^^^^^
  File "/home/alprostov/.local/share/virtualenvs/web-xbYPzM3q/lib64/python3.11/site-packages/django/core/handlers/base.py", line 197, in _get_response
    response = wrapped_callback(request, *callback_args, **callback_kwargs)
               ^^^^^^^^^^^^^^^^^^^^^^^^^^^^^^^^^^^^^^^^^^^^^^^^^^^^^^^^^^^^
  File "/home/alprostov/.local/share/virtualenvs/web-xbYPzM3q/lib64/python3.11/site-packages/django/contrib/auth/decorators.py", line 23, in _wrapper_view
    return view_func(request, *args, **kwargs)
           ^^^^^^^^^^^^^^^^^^^^^^^^^^^^^^^^^^^
  File "/home/alprostov/PycharmProjects/sakhlis/sakhlis/web/app_site/views.py", line 310, in change_work_status
    if b.order_status=='END': b.time_out=timezone.now()
                                         ^^^^^^^^^^^^
AttributeError: type object 'datetime.timezone' has no attribute 'now'
INFO:django.utils.autoreload:/home/alprostov/PycharmProjects/sakhlis/sakhlis/web/app_site/views.py changed, reloading.
INFO:django.utils.autoreload:/home/alprostov/PycharmProjects/sakhlis/sakhlis/web/app_site/views.py changed, reloading.
INFO:django.utils.autoreload:/home/alprostov/PycharmProjects/sakhlis/sakhlis/web/app_site/views.py changed, reloading.
INFO:django.utils.autoreload:/home/alprostov/PycharmProjects/sakhlis/sakhlis/web/app_site/admin.py changed, reloading.
INFO:django.utils.autoreload:/home/alprostov/PycharmProjects/sakhlis/sakhlis/web/app_site/admin.py changed, reloading.
INFO:django.utils.autoreload:/home/alprostov/PycharmProjects/sakhlis/sakhlis/web/app_site/admin.py changed, reloading.
INFO:django.utils.autoreload:/home/alprostov/PycharmProjects/sakhlis/sakhlis/web/app_site/admin.py changed, reloading.
INFO:django.utils.autoreload:/home/alprostov/PycharmProjects/sakhlis/sakhlis/web/app_site/admin.py changed, reloading.
WARNING:django.request:Not Found: /favicon.ico
WARNING:root:===========================================================
WARNING:root:ВРЕМЯ:     2024-02-26 19:05:12.699034
WARNING:root:ОШИБКА:        No Order list found matching the query
WARNING:root:ТРЭЙСБЭК:     Traceback (most recent call last):
  File "/home/alprostov/.local/share/virtualenvs/web-xbYPzM3q/lib64/python3.11/site-packages/django/views/generic/detail.py", line 53, in get_object
    obj = queryset.get()
          ^^^^^^^^^^^^^^
  File "/home/alprostov/.local/share/virtualenvs/web-xbYPzM3q/lib64/python3.11/site-packages/django/db/models/query.py", line 637, in get
    raise self.model.DoesNotExist(
app_site.models.OrderList.DoesNotExist: OrderList matching query does not exist.

During handling of the above exception, another exception occurred:

Traceback (most recent call last):
  File "/home/alprostov/PycharmProjects/sakhlis/sakhlis/web/app_site/exeptions.py", line 35, in dispatch
    response = super().dispatch(request, *args, **kwargs)
               ^^^^^^^^^^^^^^^^^^^^^^^^^^^^^^^^^^^^^^^^^^
  File "/home/alprostov/.local/share/virtualenvs/web-xbYPzM3q/lib64/python3.11/site-packages/django/contrib/auth/mixins.py", line 73, in dispatch
    return super().dispatch(request, *args, **kwargs)
           ^^^^^^^^^^^^^^^^^^^^^^^^^^^^^^^^^^^^^^^^^^
  File "/home/alprostov/.local/share/virtualenvs/web-xbYPzM3q/lib64/python3.11/site-packages/django/views/generic/base.py", line 143, in dispatch
    return handler(request, *args, **kwargs)
           ^^^^^^^^^^^^^^^^^^^^^^^^^^^^^^^^^
  File "/home/alprostov/.local/share/virtualenvs/web-xbYPzM3q/lib64/python3.11/site-packages/django/views/generic/detail.py", line 108, in get
    self.object = self.get_object()
                  ^^^^^^^^^^^^^^^^^
  File "/home/alprostov/.local/share/virtualenvs/web-xbYPzM3q/lib64/python3.11/site-packages/django/views/generic/detail.py", line 55, in get_object
    raise Http404(
django.http.response.Http404: No Order list found matching the query

WARNING:root:============================================================
WARNING:django.request:Bad Request: /list_order/1250
WARNING:django.request:Not Found: /favicon.ico
WARNING:django.request:Not Found: /favicon.ico
WARNING:django.request:Not Found: /favicon.ico
WARNING:django.request:Not Found: /favicon.ico
WARNING:django.request:Not Found: /favicon.ico
WARNING:django.request:Not Found: /favicon.ico
WARNING:django.request:Not Found: /favicon.ico
INFO:django.utils.autoreload:/home/alprostov/PycharmProjects/sakhlis/sakhlis/web/web/settings/development.py changed, reloading.
WARNING:django.request:Not Found: /favicon.ico
INFO:django.utils.autoreload:/home/alprostov/PycharmProjects/sakhlis/sakhlis/web/web/settings/development.py changed, reloading.
WARNING:django.request:Not Found: /favicon.ico
WARNING:django.request:Not Found: /favicon.ico
WARNING:django.request:Not Found: /favicon.ico
WARNING:django.security.SuspiciousSession:Session data corrupted
WARNING:django.security.SuspiciousSession:Session data corrupted
WARNING:django.request:Not Found: /favicon.ico
WARNING:django.security.SuspiciousSession:Session data corrupted
WARNING:django.security.SuspiciousSession:Session data corrupted
INFO:django.utils.autoreload:/home/alprostov/PycharmProjects/sakhlis/web/web/settings/settings.py changed, reloading.
INFO:django.utils.autoreload:/home/alprostov/PycharmProjects/sakhlis/web/manage.py changed, reloading.
INFO:django.utils.autoreload:/home/alprostov/PycharmProjects/sakhlis/web/manage.py changed, reloading.
WARNING:django.security.SuspiciousSession:Session data corrupted
WARNING:django.security.SuspiciousSession:Session data corrupted
WARNING:django.security.SuspiciousSession:Session data corrupted
WARNING:django.security.SuspiciousSession:Session data corrupted
WARNING:django.request:Not Found: /favicon.ico
WARNING:django.request:Not Found: /favicon.ico
INFO:django.utils.autoreload:/home/alprostov/PycharmProjects/sakhlis/web/web/settings/development.py changed, reloading.
WARNING:django.request:Not Found: /favicon.ico
WARNING:django.request:Not Found: /favicon.ico
WARNING:django.request:Not Found: /favicon.ico
WARNING:root:===========================================================
WARNING:root:ВРЕМЯ:     2024-03-16 16:11:53.991572
WARNING:root:ОШИБКА:        module 'gi' has no attribute 'require_version'
WARNING:root:ТРЭЙСБЭК:     Traceback (most recent call last):
  File "/home/alprostov/PycharmProjects/sakhlis/web/app_site/exeptions.py", line 35, in dispatch
    response = super().dispatch(request, *args, **kwargs)
               ^^^^^^^^^^^^^^^^^^^^^^^^^^^^^^^^^^^^^^^^^^
  File "/home/alprostov/.local/share/virtualenvs/web-mek5ITq2/lib/python3.11/site-packages/django/contrib/auth/mixins.py", line 73, in dispatch
    return super().dispatch(request, *args, **kwargs)
           ^^^^^^^^^^^^^^^^^^^^^^^^^^^^^^^^^^^^^^^^^^
  File "/home/alprostov/.local/share/virtualenvs/web-mek5ITq2/lib/python3.11/site-packages/django/views/generic/base.py", line 143, in dispatch
    return handler(request, *args, **kwargs)
           ^^^^^^^^^^^^^^^^^^^^^^^^^^^^^^^^^
  File "/home/alprostov/.local/share/virtualenvs/web-mek5ITq2/lib/python3.11/site-packages/django/views/generic/list.py", line 174, in get
    context = self.get_context_data()
              ^^^^^^^^^^^^^^^^^^^^^^^
  File "/home/alprostov/PycharmProjects/sakhlis/web/app_site/views.py", line 186, in get_context_data
    context['d'] = Graph(data_from_invoice.get_quantity_of_orders_by_type(repairer=self.request.user),
                   ^^^^^^^^^^^^^^^^^^^^^^^^^^^^^^^^^^^^^^^^^^^^^^^^^^^^^^^^^^^^^^^^^^^^^^^^^^^^^^^^^^^
  File "/home/alprostov/PycharmProjects/sakhlis/web/app_site/utils.py", line 168, in __init__
    self.fig, self.ax = plt.subplots()
                        ^^^^^^^^^^^^^^
  File "/home/alprostov/.local/share/virtualenvs/web-mek5ITq2/lib/python3.11/site-packages/matplotlib/pyplot.py", line 1598, in subplots
    fig = figure(**fig_kw)
          ^^^^^^^^^^^^^^^^
  File "/home/alprostov/.local/share/virtualenvs/web-mek5ITq2/lib/python3.11/site-packages/matplotlib/pyplot.py", line 934, in figure
    manager = new_figure_manager(
              ^^^^^^^^^^^^^^^^^^^
  File "/home/alprostov/.local/share/virtualenvs/web-mek5ITq2/lib/python3.11/site-packages/matplotlib/pyplot.py", line 464, in new_figure_manager
    _warn_if_gui_out_of_main_thread()
  File "/home/alprostov/.local/share/virtualenvs/web-mek5ITq2/lib/python3.11/site-packages/matplotlib/pyplot.py", line 441, in _warn_if_gui_out_of_main_thread
    canvas_class = cast(type[FigureCanvasBase], _get_backend_mod().FigureCanvas)
                                                ^^^^^^^^^^^^^^^^^^
  File "/home/alprostov/.local/share/virtualenvs/web-mek5ITq2/lib/python3.11/site-packages/matplotlib/pyplot.py", line 280, in _get_backend_mod
    switch_backend(rcParams._get("backend"))  # type: ignore[attr-defined]
    ^^^^^^^^^^^^^^^^^^^^^^^^^^^^^^^^^^^^^^^^
  File "/home/alprostov/.local/share/virtualenvs/web-mek5ITq2/lib/python3.11/site-packages/matplotlib/pyplot.py", line 327, in switch_backend
    switch_backend(candidate)
  File "/home/alprostov/.local/share/virtualenvs/web-mek5ITq2/lib/python3.11/site-packages/matplotlib/pyplot.py", line 342, in switch_backend
    module = importlib.import_module(cbook._backend_module_name(newbackend))
             ^^^^^^^^^^^^^^^^^^^^^^^^^^^^^^^^^^^^^^^^^^^^^^^^^^^^^^^^^^^^^^^
  File "/usr/lib/python3.11/importlib/__init__.py", line 126, in import_module
    return _bootstrap._gcd_import(name[level:], package, level)
           ^^^^^^^^^^^^^^^^^^^^^^^^^^^^^^^^^^^^^^^^^^^^^^^^^^^^
  File "<frozen importlib._bootstrap>", line 1204, in _gcd_import
  File "<frozen importlib._bootstrap>", line 1176, in _find_and_load
  File "<frozen importlib._bootstrap>", line 1147, in _find_and_load_unlocked
  File "<frozen importlib._bootstrap>", line 690, in _load_unlocked
  File "<frozen importlib._bootstrap_external>", line 940, in exec_module
  File "<frozen importlib._bootstrap>", line 241, in _call_with_frames_removed
  File "/home/alprostov/.local/share/virtualenvs/web-mek5ITq2/lib/python3.11/site-packages/matplotlib/backends/backend_gtk4agg.py", line 4, in <module>
    from . import backend_agg, backend_gtk4
  File "/home/alprostov/.local/share/virtualenvs/web-mek5ITq2/lib/python3.11/site-packages/matplotlib/backends/backend_gtk4.py", line 19, in <module>
    gi.require_version("Gtk", "4.0")
    ^^^^^^^^^^^^^^^^^^
AttributeError: module 'gi' has no attribute 'require_version'

WARNING:root:============================================================
WARNING:django.request:Bad Request: /stat/
WARNING:root:===========================================================
WARNING:root:ВРЕМЯ:     2024-03-16 16:11:58.351803
WARNING:root:ОШИБКА:        module 'gi' has no attribute 'require_version'
WARNING:root:ТРЭЙСБЭК:     Traceback (most recent call last):
  File "/home/alprostov/PycharmProjects/sakhlis/web/app_site/exeptions.py", line 35, in dispatch
    response = super().dispatch(request, *args, **kwargs)
               ^^^^^^^^^^^^^^^^^^^^^^^^^^^^^^^^^^^^^^^^^^
  File "/home/alprostov/.local/share/virtualenvs/web-mek5ITq2/lib/python3.11/site-packages/django/contrib/auth/mixins.py", line 73, in dispatch
    return super().dispatch(request, *args, **kwargs)
           ^^^^^^^^^^^^^^^^^^^^^^^^^^^^^^^^^^^^^^^^^^
  File "/home/alprostov/.local/share/virtualenvs/web-mek5ITq2/lib/python3.11/site-packages/django/views/generic/base.py", line 143, in dispatch
    return handler(request, *args, **kwargs)
           ^^^^^^^^^^^^^^^^^^^^^^^^^^^^^^^^^
  File "/home/alprostov/.local/share/virtualenvs/web-mek5ITq2/lib/python3.11/site-packages/django/views/generic/list.py", line 174, in get
    context = self.get_context_data()
              ^^^^^^^^^^^^^^^^^^^^^^^
  File "/home/alprostov/PycharmProjects/sakhlis/web/app_site/views.py", line 186, in get_context_data
    context['d'] = Graph(data_from_invoice.get_quantity_of_orders_by_type(repairer=self.request.user),
                   ^^^^^^^^^^^^^^^^^^^^^^^^^^^^^^^^^^^^^^^^^^^^^^^^^^^^^^^^^^^^^^^^^^^^^^^^^^^^^^^^^^^
  File "/home/alprostov/PycharmProjects/sakhlis/web/app_site/utils.py", line 168, in __init__
    self.fig, self.ax = plt.subplots()
                        ^^^^^^^^^^^^^^
  File "/home/alprostov/.local/share/virtualenvs/web-mek5ITq2/lib/python3.11/site-packages/matplotlib/pyplot.py", line 1598, in subplots
    fig = figure(**fig_kw)
          ^^^^^^^^^^^^^^^^
  File "/home/alprostov/.local/share/virtualenvs/web-mek5ITq2/lib/python3.11/site-packages/matplotlib/pyplot.py", line 934, in figure
    manager = new_figure_manager(
              ^^^^^^^^^^^^^^^^^^^
  File "/home/alprostov/.local/share/virtualenvs/web-mek5ITq2/lib/python3.11/site-packages/matplotlib/pyplot.py", line 464, in new_figure_manager
    _warn_if_gui_out_of_main_thread()
  File "/home/alprostov/.local/share/virtualenvs/web-mek5ITq2/lib/python3.11/site-packages/matplotlib/pyplot.py", line 441, in _warn_if_gui_out_of_main_thread
    canvas_class = cast(type[FigureCanvasBase], _get_backend_mod().FigureCanvas)
                                                ^^^^^^^^^^^^^^^^^^
  File "/home/alprostov/.local/share/virtualenvs/web-mek5ITq2/lib/python3.11/site-packages/matplotlib/pyplot.py", line 280, in _get_backend_mod
    switch_backend(rcParams._get("backend"))  # type: ignore[attr-defined]
    ^^^^^^^^^^^^^^^^^^^^^^^^^^^^^^^^^^^^^^^^
  File "/home/alprostov/.local/share/virtualenvs/web-mek5ITq2/lib/python3.11/site-packages/matplotlib/pyplot.py", line 327, in switch_backend
    switch_backend(candidate)
  File "/home/alprostov/.local/share/virtualenvs/web-mek5ITq2/lib/python3.11/site-packages/matplotlib/pyplot.py", line 342, in switch_backend
    module = importlib.import_module(cbook._backend_module_name(newbackend))
             ^^^^^^^^^^^^^^^^^^^^^^^^^^^^^^^^^^^^^^^^^^^^^^^^^^^^^^^^^^^^^^^
  File "/usr/lib/python3.11/importlib/__init__.py", line 126, in import_module
    return _bootstrap._gcd_import(name[level:], package, level)
           ^^^^^^^^^^^^^^^^^^^^^^^^^^^^^^^^^^^^^^^^^^^^^^^^^^^^
  File "<frozen importlib._bootstrap>", line 1204, in _gcd_import
  File "<frozen importlib._bootstrap>", line 1176, in _find_and_load
  File "<frozen importlib._bootstrap>", line 1147, in _find_and_load_unlocked
  File "<frozen importlib._bootstrap>", line 690, in _load_unlocked
  File "<frozen importlib._bootstrap_external>", line 940, in exec_module
  File "<frozen importlib._bootstrap>", line 241, in _call_with_frames_removed
  File "/home/alprostov/.local/share/virtualenvs/web-mek5ITq2/lib/python3.11/site-packages/matplotlib/backends/backend_gtk4agg.py", line 4, in <module>
    from . import backend_agg, backend_gtk4
  File "/home/alprostov/.local/share/virtualenvs/web-mek5ITq2/lib/python3.11/site-packages/matplotlib/backends/backend_gtk4.py", line 19, in <module>
    gi.require_version("Gtk", "4.0")
    ^^^^^^^^^^^^^^^^^^
AttributeError: module 'gi' has no attribute 'require_version'

WARNING:root:============================================================
WARNING:django.request:Bad Request: /stat/
WARNING:root:===========================================================
WARNING:root:ВРЕМЯ:     2024-03-16 16:12:20.656381
WARNING:root:ОШИБКА:        module 'gi' has no attribute 'require_version'
WARNING:root:ТРЭЙСБЭК:     Traceback (most recent call last):
  File "/home/alprostov/PycharmProjects/sakhlis/web/app_site/exeptions.py", line 35, in dispatch
    response = super().dispatch(request, *args, **kwargs)
               ^^^^^^^^^^^^^^^^^^^^^^^^^^^^^^^^^^^^^^^^^^
  File "/home/alprostov/.local/share/virtualenvs/web-mek5ITq2/lib/python3.11/site-packages/django/contrib/auth/mixins.py", line 73, in dispatch
    return super().dispatch(request, *args, **kwargs)
           ^^^^^^^^^^^^^^^^^^^^^^^^^^^^^^^^^^^^^^^^^^
  File "/home/alprostov/.local/share/virtualenvs/web-mek5ITq2/lib/python3.11/site-packages/django/views/generic/base.py", line 143, in dispatch
    return handler(request, *args, **kwargs)
           ^^^^^^^^^^^^^^^^^^^^^^^^^^^^^^^^^
  File "/home/alprostov/.local/share/virtualenvs/web-mek5ITq2/lib/python3.11/site-packages/django/views/generic/list.py", line 174, in get
    context = self.get_context_data()
              ^^^^^^^^^^^^^^^^^^^^^^^
  File "/home/alprostov/PycharmProjects/sakhlis/web/app_site/views.py", line 186, in get_context_data
    context['d'] = Graph(data_from_invoice.get_quantity_of_orders_by_type(repairer=self.request.user),
                   ^^^^^^^^^^^^^^^^^^^^^^^^^^^^^^^^^^^^^^^^^^^^^^^^^^^^^^^^^^^^^^^^^^^^^^^^^^^^^^^^^^^
  File "/home/alprostov/PycharmProjects/sakhlis/web/app_site/utils.py", line 168, in __init__
    self.fig, self.ax = plt.subplots()
                        ^^^^^^^^^^^^^^
  File "/home/alprostov/.local/share/virtualenvs/web-mek5ITq2/lib/python3.11/site-packages/matplotlib/pyplot.py", line 1598, in subplots
    fig = figure(**fig_kw)
          ^^^^^^^^^^^^^^^^
  File "/home/alprostov/.local/share/virtualenvs/web-mek5ITq2/lib/python3.11/site-packages/matplotlib/pyplot.py", line 934, in figure
    manager = new_figure_manager(
              ^^^^^^^^^^^^^^^^^^^
  File "/home/alprostov/.local/share/virtualenvs/web-mek5ITq2/lib/python3.11/site-packages/matplotlib/pyplot.py", line 464, in new_figure_manager
    _warn_if_gui_out_of_main_thread()
  File "/home/alprostov/.local/share/virtualenvs/web-mek5ITq2/lib/python3.11/site-packages/matplotlib/pyplot.py", line 441, in _warn_if_gui_out_of_main_thread
    canvas_class = cast(type[FigureCanvasBase], _get_backend_mod().FigureCanvas)
                                                ^^^^^^^^^^^^^^^^^^
  File "/home/alprostov/.local/share/virtualenvs/web-mek5ITq2/lib/python3.11/site-packages/matplotlib/pyplot.py", line 280, in _get_backend_mod
    switch_backend(rcParams._get("backend"))  # type: ignore[attr-defined]
    ^^^^^^^^^^^^^^^^^^^^^^^^^^^^^^^^^^^^^^^^
  File "/home/alprostov/.local/share/virtualenvs/web-mek5ITq2/lib/python3.11/site-packages/matplotlib/pyplot.py", line 327, in switch_backend
    switch_backend(candidate)
  File "/home/alprostov/.local/share/virtualenvs/web-mek5ITq2/lib/python3.11/site-packages/matplotlib/pyplot.py", line 342, in switch_backend
    module = importlib.import_module(cbook._backend_module_name(newbackend))
             ^^^^^^^^^^^^^^^^^^^^^^^^^^^^^^^^^^^^^^^^^^^^^^^^^^^^^^^^^^^^^^^
  File "/usr/lib/python3.11/importlib/__init__.py", line 126, in import_module
    return _bootstrap._gcd_import(name[level:], package, level)
           ^^^^^^^^^^^^^^^^^^^^^^^^^^^^^^^^^^^^^^^^^^^^^^^^^^^^
  File "<frozen importlib._bootstrap>", line 1204, in _gcd_import
  File "<frozen importlib._bootstrap>", line 1176, in _find_and_load
  File "<frozen importlib._bootstrap>", line 1147, in _find_and_load_unlocked
  File "<frozen importlib._bootstrap>", line 690, in _load_unlocked
  File "<frozen importlib._bootstrap_external>", line 940, in exec_module
  File "<frozen importlib._bootstrap>", line 241, in _call_with_frames_removed
  File "/home/alprostov/.local/share/virtualenvs/web-mek5ITq2/lib/python3.11/site-packages/matplotlib/backends/backend_gtk4agg.py", line 4, in <module>
    from . import backend_agg, backend_gtk4
  File "/home/alprostov/.local/share/virtualenvs/web-mek5ITq2/lib/python3.11/site-packages/matplotlib/backends/backend_gtk4.py", line 19, in <module>
    gi.require_version("Gtk", "4.0")
    ^^^^^^^^^^^^^^^^^^
AttributeError: module 'gi' has no attribute 'require_version'

WARNING:root:============================================================
WARNING:django.request:Bad Request: /stat/
WARNING:root:===========================================================
WARNING:root:ВРЕМЯ:     2024-03-16 16:13:20.372658
WARNING:root:ОШИБКА:        module 'gi' has no attribute 'require_version'
WARNING:root:ТРЭЙСБЭК:     Traceback (most recent call last):
  File "/home/alprostov/PycharmProjects/sakhlis/web/app_site/exeptions.py", line 35, in dispatch
    response = super().dispatch(request, *args, **kwargs)
               ^^^^^^^^^^^^^^^^^^^^^^^^^^^^^^^^^^^^^^^^^^
  File "/home/alprostov/.local/share/virtualenvs/web-mek5ITq2/lib/python3.11/site-packages/django/contrib/auth/mixins.py", line 73, in dispatch
    return super().dispatch(request, *args, **kwargs)
           ^^^^^^^^^^^^^^^^^^^^^^^^^^^^^^^^^^^^^^^^^^
  File "/home/alprostov/.local/share/virtualenvs/web-mek5ITq2/lib/python3.11/site-packages/django/views/generic/base.py", line 143, in dispatch
    return handler(request, *args, **kwargs)
           ^^^^^^^^^^^^^^^^^^^^^^^^^^^^^^^^^
  File "/home/alprostov/.local/share/virtualenvs/web-mek5ITq2/lib/python3.11/site-packages/django/views/generic/list.py", line 174, in get
    context = self.get_context_data()
              ^^^^^^^^^^^^^^^^^^^^^^^
  File "/home/alprostov/PycharmProjects/sakhlis/web/app_site/views.py", line 186, in get_context_data
    context['d'] = Graph(data_from_invoice.get_quantity_of_orders_by_type(repairer=self.request.user),
                   ^^^^^^^^^^^^^^^^^^^^^^^^^^^^^^^^^^^^^^^^^^^^^^^^^^^^^^^^^^^^^^^^^^^^^^^^^^^^^^^^^^^
  File "/home/alprostov/PycharmProjects/sakhlis/web/app_site/utils.py", line 168, in __init__
    self.fig, self.ax = plt.subplots()
                        ^^^^^^^^^^^^^^
  File "/home/alprostov/.local/share/virtualenvs/web-mek5ITq2/lib/python3.11/site-packages/matplotlib/pyplot.py", line 1598, in subplots
    fig = figure(**fig_kw)
          ^^^^^^^^^^^^^^^^
  File "/home/alprostov/.local/share/virtualenvs/web-mek5ITq2/lib/python3.11/site-packages/matplotlib/pyplot.py", line 934, in figure
    manager = new_figure_manager(
              ^^^^^^^^^^^^^^^^^^^
  File "/home/alprostov/.local/share/virtualenvs/web-mek5ITq2/lib/python3.11/site-packages/matplotlib/pyplot.py", line 464, in new_figure_manager
    _warn_if_gui_out_of_main_thread()
  File "/home/alprostov/.local/share/virtualenvs/web-mek5ITq2/lib/python3.11/site-packages/matplotlib/pyplot.py", line 441, in _warn_if_gui_out_of_main_thread
    canvas_class = cast(type[FigureCanvasBase], _get_backend_mod().FigureCanvas)
                                                ^^^^^^^^^^^^^^^^^^
  File "/home/alprostov/.local/share/virtualenvs/web-mek5ITq2/lib/python3.11/site-packages/matplotlib/pyplot.py", line 280, in _get_backend_mod
    switch_backend(rcParams._get("backend"))  # type: ignore[attr-defined]
    ^^^^^^^^^^^^^^^^^^^^^^^^^^^^^^^^^^^^^^^^
  File "/home/alprostov/.local/share/virtualenvs/web-mek5ITq2/lib/python3.11/site-packages/matplotlib/pyplot.py", line 327, in switch_backend
    switch_backend(candidate)
  File "/home/alprostov/.local/share/virtualenvs/web-mek5ITq2/lib/python3.11/site-packages/matplotlib/pyplot.py", line 342, in switch_backend
    module = importlib.import_module(cbook._backend_module_name(newbackend))
             ^^^^^^^^^^^^^^^^^^^^^^^^^^^^^^^^^^^^^^^^^^^^^^^^^^^^^^^^^^^^^^^
  File "/usr/lib/python3.11/importlib/__init__.py", line 126, in import_module
    return _bootstrap._gcd_import(name[level:], package, level)
           ^^^^^^^^^^^^^^^^^^^^^^^^^^^^^^^^^^^^^^^^^^^^^^^^^^^^
  File "<frozen importlib._bootstrap>", line 1204, in _gcd_import
  File "<frozen importlib._bootstrap>", line 1176, in _find_and_load
  File "<frozen importlib._bootstrap>", line 1147, in _find_and_load_unlocked
  File "<frozen importlib._bootstrap>", line 690, in _load_unlocked
  File "<frozen importlib._bootstrap_external>", line 940, in exec_module
  File "<frozen importlib._bootstrap>", line 241, in _call_with_frames_removed
  File "/home/alprostov/.local/share/virtualenvs/web-mek5ITq2/lib/python3.11/site-packages/matplotlib/backends/backend_gtk4agg.py", line 4, in <module>
    from . import backend_agg, backend_gtk4
  File "/home/alprostov/.local/share/virtualenvs/web-mek5ITq2/lib/python3.11/site-packages/matplotlib/backends/backend_gtk4.py", line 19, in <module>
    gi.require_version("Gtk", "4.0")
    ^^^^^^^^^^^^^^^^^^
AttributeError: module 'gi' has no attribute 'require_version'

WARNING:root:============================================================
WARNING:django.request:Bad Request: /stat/
WARNING:root:===========================================================
WARNING:root:ВРЕМЯ:     2024-03-16 16:13:24.861978
WARNING:root:ОШИБКА:        module 'gi' has no attribute 'require_version'
WARNING:root:ТРЭЙСБЭК:     Traceback (most recent call last):
  File "/home/alprostov/PycharmProjects/sakhlis/web/app_site/exeptions.py", line 35, in dispatch
    response = super().dispatch(request, *args, **kwargs)
               ^^^^^^^^^^^^^^^^^^^^^^^^^^^^^^^^^^^^^^^^^^
  File "/home/alprostov/.local/share/virtualenvs/web-mek5ITq2/lib/python3.11/site-packages/django/contrib/auth/mixins.py", line 73, in dispatch
    return super().dispatch(request, *args, **kwargs)
           ^^^^^^^^^^^^^^^^^^^^^^^^^^^^^^^^^^^^^^^^^^
  File "/home/alprostov/.local/share/virtualenvs/web-mek5ITq2/lib/python3.11/site-packages/django/views/generic/base.py", line 143, in dispatch
    return handler(request, *args, **kwargs)
           ^^^^^^^^^^^^^^^^^^^^^^^^^^^^^^^^^
  File "/home/alprostov/.local/share/virtualenvs/web-mek5ITq2/lib/python3.11/site-packages/django/views/generic/list.py", line 174, in get
    context = self.get_context_data()
              ^^^^^^^^^^^^^^^^^^^^^^^
  File "/home/alprostov/PycharmProjects/sakhlis/web/app_site/views.py", line 186, in get_context_data
    context['d'] = Graph(data_from_invoice.get_quantity_of_orders_by_type(repairer=self.request.user),
                   ^^^^^^^^^^^^^^^^^^^^^^^^^^^^^^^^^^^^^^^^^^^^^^^^^^^^^^^^^^^^^^^^^^^^^^^^^^^^^^^^^^^
  File "/home/alprostov/PycharmProjects/sakhlis/web/app_site/utils.py", line 168, in __init__
    self.fig, self.ax = plt.subplots()
                        ^^^^^^^^^^^^^^
  File "/home/alprostov/.local/share/virtualenvs/web-mek5ITq2/lib/python3.11/site-packages/matplotlib/pyplot.py", line 1598, in subplots
    fig = figure(**fig_kw)
          ^^^^^^^^^^^^^^^^
  File "/home/alprostov/.local/share/virtualenvs/web-mek5ITq2/lib/python3.11/site-packages/matplotlib/pyplot.py", line 934, in figure
    manager = new_figure_manager(
              ^^^^^^^^^^^^^^^^^^^
  File "/home/alprostov/.local/share/virtualenvs/web-mek5ITq2/lib/python3.11/site-packages/matplotlib/pyplot.py", line 464, in new_figure_manager
    _warn_if_gui_out_of_main_thread()
  File "/home/alprostov/.local/share/virtualenvs/web-mek5ITq2/lib/python3.11/site-packages/matplotlib/pyplot.py", line 441, in _warn_if_gui_out_of_main_thread
    canvas_class = cast(type[FigureCanvasBase], _get_backend_mod().FigureCanvas)
                                                ^^^^^^^^^^^^^^^^^^
  File "/home/alprostov/.local/share/virtualenvs/web-mek5ITq2/lib/python3.11/site-packages/matplotlib/pyplot.py", line 280, in _get_backend_mod
    switch_backend(rcParams._get("backend"))  # type: ignore[attr-defined]
    ^^^^^^^^^^^^^^^^^^^^^^^^^^^^^^^^^^^^^^^^
  File "/home/alprostov/.local/share/virtualenvs/web-mek5ITq2/lib/python3.11/site-packages/matplotlib/pyplot.py", line 327, in switch_backend
    switch_backend(candidate)
  File "/home/alprostov/.local/share/virtualenvs/web-mek5ITq2/lib/python3.11/site-packages/matplotlib/pyplot.py", line 342, in switch_backend
    module = importlib.import_module(cbook._backend_module_name(newbackend))
             ^^^^^^^^^^^^^^^^^^^^^^^^^^^^^^^^^^^^^^^^^^^^^^^^^^^^^^^^^^^^^^^
  File "/usr/lib/python3.11/importlib/__init__.py", line 126, in import_module
    return _bootstrap._gcd_import(name[level:], package, level)
           ^^^^^^^^^^^^^^^^^^^^^^^^^^^^^^^^^^^^^^^^^^^^^^^^^^^^
  File "<frozen importlib._bootstrap>", line 1204, in _gcd_import
  File "<frozen importlib._bootstrap>", line 1176, in _find_and_load
  File "<frozen importlib._bootstrap>", line 1147, in _find_and_load_unlocked
  File "<frozen importlib._bootstrap>", line 690, in _load_unlocked
  File "<frozen importlib._bootstrap_external>", line 940, in exec_module
  File "<frozen importlib._bootstrap>", line 241, in _call_with_frames_removed
  File "/home/alprostov/.local/share/virtualenvs/web-mek5ITq2/lib/python3.11/site-packages/matplotlib/backends/backend_gtk4agg.py", line 4, in <module>
    from . import backend_agg, backend_gtk4
  File "/home/alprostov/.local/share/virtualenvs/web-mek5ITq2/lib/python3.11/site-packages/matplotlib/backends/backend_gtk4.py", line 19, in <module>
    gi.require_version("Gtk", "4.0")
    ^^^^^^^^^^^^^^^^^^
AttributeError: module 'gi' has no attribute 'require_version'

WARNING:root:============================================================
WARNING:django.request:Bad Request: /stat/
WARNING:root:===========================================================
WARNING:root:ВРЕМЯ:     2024-03-16 16:22:36.370846
WARNING:root:ОШИБКА:        module 'gi' has no attribute 'require_version'
WARNING:root:ТРЭЙСБЭК:     Traceback (most recent call last):
  File "/home/alprostov/PycharmProjects/sakhlis/web/app_site/exeptions.py", line 35, in dispatch
    response = super().dispatch(request, *args, **kwargs)
               ^^^^^^^^^^^^^^^^^^^^^^^^^^^^^^^^^^^^^^^^^^
  File "/home/alprostov/.local/share/virtualenvs/web-mek5ITq2/lib/python3.11/site-packages/django/contrib/auth/mixins.py", line 73, in dispatch
    return super().dispatch(request, *args, **kwargs)
           ^^^^^^^^^^^^^^^^^^^^^^^^^^^^^^^^^^^^^^^^^^
  File "/home/alprostov/.local/share/virtualenvs/web-mek5ITq2/lib/python3.11/site-packages/django/views/generic/base.py", line 143, in dispatch
    return handler(request, *args, **kwargs)
           ^^^^^^^^^^^^^^^^^^^^^^^^^^^^^^^^^
  File "/home/alprostov/.local/share/virtualenvs/web-mek5ITq2/lib/python3.11/site-packages/django/views/generic/list.py", line 174, in get
    context = self.get_context_data()
              ^^^^^^^^^^^^^^^^^^^^^^^
  File "/home/alprostov/PycharmProjects/sakhlis/web/app_site/views.py", line 186, in get_context_data
    context['d'] = Graph(data_from_invoice.get_quantity_of_orders_by_type(repairer=self.request.user),
                   ^^^^^^^^^^^^^^^^^^^^^^^^^^^^^^^^^^^^^^^^^^^^^^^^^^^^^^^^^^^^^^^^^^^^^^^^^^^^^^^^^^^
  File "/home/alprostov/PycharmProjects/sakhlis/web/app_site/utils.py", line 168, in __init__
    self.fig, self.ax = plt.subplots()
                        ^^^^^^^^^^^^^^
  File "/home/alprostov/.local/share/virtualenvs/web-mek5ITq2/lib/python3.11/site-packages/matplotlib/pyplot.py", line 1598, in subplots
    fig = figure(**fig_kw)
          ^^^^^^^^^^^^^^^^
  File "/home/alprostov/.local/share/virtualenvs/web-mek5ITq2/lib/python3.11/site-packages/matplotlib/pyplot.py", line 934, in figure
    manager = new_figure_manager(
              ^^^^^^^^^^^^^^^^^^^
  File "/home/alprostov/.local/share/virtualenvs/web-mek5ITq2/lib/python3.11/site-packages/matplotlib/pyplot.py", line 464, in new_figure_manager
    _warn_if_gui_out_of_main_thread()
  File "/home/alprostov/.local/share/virtualenvs/web-mek5ITq2/lib/python3.11/site-packages/matplotlib/pyplot.py", line 441, in _warn_if_gui_out_of_main_thread
    canvas_class = cast(type[FigureCanvasBase], _get_backend_mod().FigureCanvas)
                                                ^^^^^^^^^^^^^^^^^^
  File "/home/alprostov/.local/share/virtualenvs/web-mek5ITq2/lib/python3.11/site-packages/matplotlib/pyplot.py", line 280, in _get_backend_mod
    switch_backend(rcParams._get("backend"))  # type: ignore[attr-defined]
    ^^^^^^^^^^^^^^^^^^^^^^^^^^^^^^^^^^^^^^^^
  File "/home/alprostov/.local/share/virtualenvs/web-mek5ITq2/lib/python3.11/site-packages/matplotlib/pyplot.py", line 327, in switch_backend
    switch_backend(candidate)
  File "/home/alprostov/.local/share/virtualenvs/web-mek5ITq2/lib/python3.11/site-packages/matplotlib/pyplot.py", line 342, in switch_backend
    module = importlib.import_module(cbook._backend_module_name(newbackend))
             ^^^^^^^^^^^^^^^^^^^^^^^^^^^^^^^^^^^^^^^^^^^^^^^^^^^^^^^^^^^^^^^
  File "/usr/lib/python3.11/importlib/__init__.py", line 126, in import_module
    return _bootstrap._gcd_import(name[level:], package, level)
           ^^^^^^^^^^^^^^^^^^^^^^^^^^^^^^^^^^^^^^^^^^^^^^^^^^^^
  File "<frozen importlib._bootstrap>", line 1204, in _gcd_import
  File "<frozen importlib._bootstrap>", line 1176, in _find_and_load
  File "<frozen importlib._bootstrap>", line 1147, in _find_and_load_unlocked
  File "<frozen importlib._bootstrap>", line 690, in _load_unlocked
  File "<frozen importlib._bootstrap_external>", line 940, in exec_module
  File "<frozen importlib._bootstrap>", line 241, in _call_with_frames_removed
  File "/home/alprostov/.local/share/virtualenvs/web-mek5ITq2/lib/python3.11/site-packages/matplotlib/backends/backend_gtk4agg.py", line 4, in <module>
    from . import backend_agg, backend_gtk4
  File "/home/alprostov/.local/share/virtualenvs/web-mek5ITq2/lib/python3.11/site-packages/matplotlib/backends/backend_gtk4.py", line 19, in <module>
    gi.require_version("Gtk", "4.0")
    ^^^^^^^^^^^^^^^^^^
AttributeError: module 'gi' has no attribute 'require_version'

WARNING:root:============================================================
WARNING:django.request:Bad Request: /stat/
WARNING:django.request:Not Found: /favicon.ico
WARNING:root:===========================================================
WARNING:root:ВРЕМЯ:     2024-03-17 15:52:30.458012
WARNING:root:ОШИБКА:        module 'gi' has no attribute 'require_version'
WARNING:root:ТРЭЙСБЭК:     Traceback (most recent call last):
  File "/home/alprostov/PycharmProjects/sakhlis/web/app_site/exeptions.py", line 35, in dispatch
    response = super().dispatch(request, *args, **kwargs)
               ^^^^^^^^^^^^^^^^^^^^^^^^^^^^^^^^^^^^^^^^^^
  File "/home/alprostov/.local/share/virtualenvs/web-xbYPzM3q/lib/python3.11/site-packages/django/contrib/auth/mixins.py", line 73, in dispatch
    return super().dispatch(request, *args, **kwargs)
           ^^^^^^^^^^^^^^^^^^^^^^^^^^^^^^^^^^^^^^^^^^
  File "/home/alprostov/.local/share/virtualenvs/web-xbYPzM3q/lib/python3.11/site-packages/django/views/generic/base.py", line 143, in dispatch
    return handler(request, *args, **kwargs)
           ^^^^^^^^^^^^^^^^^^^^^^^^^^^^^^^^^
  File "/home/alprostov/.local/share/virtualenvs/web-xbYPzM3q/lib/python3.11/site-packages/django/views/generic/list.py", line 174, in get
    context = self.get_context_data()
              ^^^^^^^^^^^^^^^^^^^^^^^
  File "/home/alprostov/PycharmProjects/sakhlis/web/app_site/views.py", line 186, in get_context_data
    context['d'] = Graph(data_from_invoice.get_quantity_of_orders_by_type(repairer=self.request.user),
                   ^^^^^^^^^^^^^^^^^^^^^^^^^^^^^^^^^^^^^^^^^^^^^^^^^^^^^^^^^^^^^^^^^^^^^^^^^^^^^^^^^^^
  File "/home/alprostov/PycharmProjects/sakhlis/web/app_site/utils.py", line 168, in __init__
    self.fig, self.ax = plt.subplots()
                        ^^^^^^^^^^^^^^
  File "/home/alprostov/.local/share/virtualenvs/web-xbYPzM3q/lib/python3.11/site-packages/matplotlib/pyplot.py", line 1598, in subplots
    fig = figure(**fig_kw)
          ^^^^^^^^^^^^^^^^
  File "/home/alprostov/.local/share/virtualenvs/web-xbYPzM3q/lib/python3.11/site-packages/matplotlib/pyplot.py", line 934, in figure
    manager = new_figure_manager(
              ^^^^^^^^^^^^^^^^^^^
  File "/home/alprostov/.local/share/virtualenvs/web-xbYPzM3q/lib/python3.11/site-packages/matplotlib/pyplot.py", line 464, in new_figure_manager
    _warn_if_gui_out_of_main_thread()
  File "/home/alprostov/.local/share/virtualenvs/web-xbYPzM3q/lib/python3.11/site-packages/matplotlib/pyplot.py", line 441, in _warn_if_gui_out_of_main_thread
    canvas_class = cast(type[FigureCanvasBase], _get_backend_mod().FigureCanvas)
                                                ^^^^^^^^^^^^^^^^^^
  File "/home/alprostov/.local/share/virtualenvs/web-xbYPzM3q/lib/python3.11/site-packages/matplotlib/pyplot.py", line 280, in _get_backend_mod
    switch_backend(rcParams._get("backend"))  # type: ignore[attr-defined]
    ^^^^^^^^^^^^^^^^^^^^^^^^^^^^^^^^^^^^^^^^
  File "/home/alprostov/.local/share/virtualenvs/web-xbYPzM3q/lib/python3.11/site-packages/matplotlib/pyplot.py", line 327, in switch_backend
    switch_backend(candidate)
  File "/home/alprostov/.local/share/virtualenvs/web-xbYPzM3q/lib/python3.11/site-packages/matplotlib/pyplot.py", line 342, in switch_backend
    module = importlib.import_module(cbook._backend_module_name(newbackend))
             ^^^^^^^^^^^^^^^^^^^^^^^^^^^^^^^^^^^^^^^^^^^^^^^^^^^^^^^^^^^^^^^
  File "/usr/lib/python3.11/importlib/__init__.py", line 126, in import_module
    return _bootstrap._gcd_import(name[level:], package, level)
           ^^^^^^^^^^^^^^^^^^^^^^^^^^^^^^^^^^^^^^^^^^^^^^^^^^^^
  File "<frozen importlib._bootstrap>", line 1204, in _gcd_import
  File "<frozen importlib._bootstrap>", line 1176, in _find_and_load
  File "<frozen importlib._bootstrap>", line 1147, in _find_and_load_unlocked
  File "<frozen importlib._bootstrap>", line 690, in _load_unlocked
  File "<frozen importlib._bootstrap_external>", line 940, in exec_module
  File "<frozen importlib._bootstrap>", line 241, in _call_with_frames_removed
  File "/home/alprostov/.local/share/virtualenvs/web-xbYPzM3q/lib/python3.11/site-packages/matplotlib/backends/backend_gtk4agg.py", line 4, in <module>
    from . import backend_agg, backend_gtk4
  File "/home/alprostov/.local/share/virtualenvs/web-xbYPzM3q/lib/python3.11/site-packages/matplotlib/backends/backend_gtk4.py", line 19, in <module>
    gi.require_version("Gtk", "4.0")
    ^^^^^^^^^^^^^^^^^^
AttributeError: module 'gi' has no attribute 'require_version'

WARNING:root:============================================================
WARNING:django.request:Bad Request: /stat/
WARNING:django.request:Not Found: /favicon.ico
