WARNING:django.request:Not Found: /favicon.ico
WARNING:django.request:Not Found: /favicon.ico
WARNING:django.request:Not Found: /favicon.ico
WARNING:django.request:Not Found: /favicon.ico
WARNING:django.request:Not Found: /favicon.ico
WARNING:django.request:Not Found: /favicon.ico
ERROR:django.request:Internal Server Error: /
Traceback (most recent call last):
  File "/home/alprostov/.local/share/virtualenvs/web-mek5ITq2/lib64/python3.11/site-packages/django/template/backends/django.py", line 61, in render
    return self.template.render(context)
           ^^^^^^^^^^^^^^^^^^^^^^^^^^^^^
  File "/home/alprostov/.local/share/virtualenvs/web-mek5ITq2/lib64/python3.11/site-packages/django/template/base.py", line 175, in render
    return self._render(context)
           ^^^^^^^^^^^^^^^^^^^^^
  File "/home/alprostov/.local/share/virtualenvs/web-mek5ITq2/lib64/python3.11/site-packages/django/test/utils.py", line 112, in instrumented_test_render
    return self.nodelist.render(context)
           ^^^^^^^^^^^^^^^^^^^^^^^^^^^^^
  File "/home/alprostov/.local/share/virtualenvs/web-mek5ITq2/lib64/python3.11/site-packages/django/template/base.py", line 1005, in render
    return SafeString("".join([node.render_annotated(context) for node in self]))
                              ^^^^^^^^^^^^^^^^^^^^^^^^^^^^^^^^^^^^^^^^^^^^^^^^^
  File "/home/alprostov/.local/share/virtualenvs/web-mek5ITq2/lib64/python3.11/site-packages/django/template/base.py", line 1005, in <listcomp>
    return SafeString("".join([node.render_annotated(context) for node in self]))
                               ^^^^^^^^^^^^^^^^^^^^^^^^^^^^^^
  File "/home/alprostov/.local/share/virtualenvs/web-mek5ITq2/lib64/python3.11/site-packages/django/template/base.py", line 966, in render_annotated
    return self.render(context)
           ^^^^^^^^^^^^^^^^^^^^
  File "/home/alprostov/.local/share/virtualenvs/web-mek5ITq2/lib64/python3.11/site-packages/slippers/templatetags/slippers.py", line 102, in render
    template = context.template.engine.get_template(self.template_path)
               ^^^^^^^^^^^^^^^^^^^^^^^^^^^^^^^^^^^^^^^^^^^^^^^^^^^^^^^^
  File "/home/alprostov/.local/share/virtualenvs/web-mek5ITq2/lib64/python3.11/site-packages/django/template/engine.py", line 175, in get_template
    template, origin = self.find_template(template_name)
                       ^^^^^^^^^^^^^^^^^^^^^^^^^^^^^^^^^
  File "/home/alprostov/.local/share/virtualenvs/web-mek5ITq2/lib64/python3.11/site-packages/django/template/engine.py", line 161, in find_template
    raise TemplateDoesNotExist(name, tried=tried)
django.template.exceptions.TemplateDoesNotExist:  partials/form_for_order.html

The above exception was the direct cause of the following exception:

Traceback (most recent call last):
  File "/home/alprostov/.local/share/virtualenvs/web-mek5ITq2/lib64/python3.11/site-packages/django/core/handlers/exception.py", line 55, in inner
    response = get_response(request)
               ^^^^^^^^^^^^^^^^^^^^^
  File "/home/alprostov/.local/share/virtualenvs/web-mek5ITq2/lib64/python3.11/site-packages/django/core/handlers/base.py", line 220, in _get_response
    response = response.render()
               ^^^^^^^^^^^^^^^^^
  File "/home/alprostov/.local/share/virtualenvs/web-mek5ITq2/lib64/python3.11/site-packages/django/template/response.py", line 111, in render
    self.content = self.rendered_content
                   ^^^^^^^^^^^^^^^^^^^^^
  File "/home/alprostov/.local/share/virtualenvs/web-mek5ITq2/lib64/python3.11/site-packages/django/template/response.py", line 89, in rendered_content
    return template.render(context, self._request)
           ^^^^^^^^^^^^^^^^^^^^^^^^^^^^^^^^^^^^^^^
  File "/home/alprostov/.local/share/virtualenvs/web-mek5ITq2/lib64/python3.11/site-packages/django/template/backends/django.py", line 63, in render
    reraise(exc, self.backend)
  File "/home/alprostov/.local/share/virtualenvs/web-mek5ITq2/lib64/python3.11/site-packages/django/template/backends/django.py", line 84, in reraise
    raise new from exc
django.template.exceptions.TemplateDoesNotExist:  partials/form_for_order.html
ERROR:django.request:Internal Server Error: /
Traceback (most recent call last):
  File "/home/alprostov/.local/share/virtualenvs/web-mek5ITq2/lib64/python3.11/site-packages/django/template/backends/django.py", line 61, in render
    return self.template.render(context)
           ^^^^^^^^^^^^^^^^^^^^^^^^^^^^^
  File "/home/alprostov/.local/share/virtualenvs/web-mek5ITq2/lib64/python3.11/site-packages/django/template/base.py", line 175, in render
    return self._render(context)
           ^^^^^^^^^^^^^^^^^^^^^
  File "/home/alprostov/.local/share/virtualenvs/web-mek5ITq2/lib64/python3.11/site-packages/django/test/utils.py", line 112, in instrumented_test_render
    return self.nodelist.render(context)
           ^^^^^^^^^^^^^^^^^^^^^^^^^^^^^
  File "/home/alprostov/.local/share/virtualenvs/web-mek5ITq2/lib64/python3.11/site-packages/django/template/base.py", line 1005, in render
    return SafeString("".join([node.render_annotated(context) for node in self]))
                              ^^^^^^^^^^^^^^^^^^^^^^^^^^^^^^^^^^^^^^^^^^^^^^^^^
  File "/home/alprostov/.local/share/virtualenvs/web-mek5ITq2/lib64/python3.11/site-packages/django/template/base.py", line 1005, in <listcomp>
    return SafeString("".join([node.render_annotated(context) for node in self]))
                               ^^^^^^^^^^^^^^^^^^^^^^^^^^^^^^
  File "/home/alprostov/.local/share/virtualenvs/web-mek5ITq2/lib64/python3.11/site-packages/django/template/base.py", line 966, in render_annotated
    return self.render(context)
           ^^^^^^^^^^^^^^^^^^^^
  File "/home/alprostov/.local/share/virtualenvs/web-mek5ITq2/lib64/python3.11/site-packages/slippers/templatetags/slippers.py", line 102, in render
    template = context.template.engine.get_template(self.template_path)
               ^^^^^^^^^^^^^^^^^^^^^^^^^^^^^^^^^^^^^^^^^^^^^^^^^^^^^^^^
  File "/home/alprostov/.local/share/virtualenvs/web-mek5ITq2/lib64/python3.11/site-packages/django/template/engine.py", line 175, in get_template
    template, origin = self.find_template(template_name)
                       ^^^^^^^^^^^^^^^^^^^^^^^^^^^^^^^^^
  File "/home/alprostov/.local/share/virtualenvs/web-mek5ITq2/lib64/python3.11/site-packages/django/template/engine.py", line 161, in find_template
    raise TemplateDoesNotExist(name, tried=tried)
django.template.exceptions.TemplateDoesNotExist:  partials/form_for_order.html

The above exception was the direct cause of the following exception:

Traceback (most recent call last):
  File "/home/alprostov/.local/share/virtualenvs/web-mek5ITq2/lib64/python3.11/site-packages/django/core/handlers/exception.py", line 55, in inner
    response = get_response(request)
               ^^^^^^^^^^^^^^^^^^^^^
  File "/home/alprostov/.local/share/virtualenvs/web-mek5ITq2/lib64/python3.11/site-packages/django/core/handlers/base.py", line 220, in _get_response
    response = response.render()
               ^^^^^^^^^^^^^^^^^
  File "/home/alprostov/.local/share/virtualenvs/web-mek5ITq2/lib64/python3.11/site-packages/django/template/response.py", line 111, in render
    self.content = self.rendered_content
                   ^^^^^^^^^^^^^^^^^^^^^
  File "/home/alprostov/.local/share/virtualenvs/web-mek5ITq2/lib64/python3.11/site-packages/django/template/response.py", line 89, in rendered_content
    return template.render(context, self._request)
           ^^^^^^^^^^^^^^^^^^^^^^^^^^^^^^^^^^^^^^^
  File "/home/alprostov/.local/share/virtualenvs/web-mek5ITq2/lib64/python3.11/site-packages/django/template/backends/django.py", line 63, in render
    reraise(exc, self.backend)
  File "/home/alprostov/.local/share/virtualenvs/web-mek5ITq2/lib64/python3.11/site-packages/django/template/backends/django.py", line 84, in reraise
    raise new from exc
django.template.exceptions.TemplateDoesNotExist:  partials/form_for_order.html
WARNING:django.request:Not Found: /favicon.ico
WARNING:django.request:Not Found: /favicon.ico
WARNING:django.request:Not Found: /favicon.ico
WARNING:django.request:Not Found: /favicon.ico
WARNING:django.request:Not Found: /favicon.ico
WARNING:django.request:Not Found: /favicon.ico
INFO:django.utils.autoreload:/home/alprostov/PycharmProjects/sakhlis/web/app_site/models.py changed, reloading.
WARNING:django.request:Not Found: /favicon.ico
INFO:django.utils.autoreload:/home/alprostov/PycharmProjects/sakhlis/web/app_site/models.py changed, reloading.
WARNING:django.request:Not Found: /favicon.ico
ERROR:django.request:Internal Server Error: /list_order
Traceback (most recent call last):
  File "/home/alprostov/.local/share/virtualenvs/web-mek5ITq2/lib64/python3.11/site-packages/django/db/backends/utils.py", line 89, in _execute
    return self.cursor.execute(sql, params)
           ^^^^^^^^^^^^^^^^^^^^^^^^^^^^^^^^
  File "/home/alprostov/.local/share/virtualenvs/web-mek5ITq2/lib64/python3.11/site-packages/django/db/backends/sqlite3/base.py", line 328, in execute
    return super().execute(query, params)
           ^^^^^^^^^^^^^^^^^^^^^^^^^^^^^^
sqlite3.OperationalError: no such column: app_site_orderlist.apartment_id_id

The above exception was the direct cause of the following exception:

Traceback (most recent call last):
  File "/home/alprostov/.local/share/virtualenvs/web-mek5ITq2/lib64/python3.11/site-packages/django/core/handlers/exception.py", line 55, in inner
    response = get_response(request)
               ^^^^^^^^^^^^^^^^^^^^^
  File "/home/alprostov/.local/share/virtualenvs/web-mek5ITq2/lib64/python3.11/site-packages/django/core/handlers/base.py", line 220, in _get_response
    response = response.render()
               ^^^^^^^^^^^^^^^^^
  File "/home/alprostov/.local/share/virtualenvs/web-mek5ITq2/lib64/python3.11/site-packages/django/template/response.py", line 111, in render
    self.content = self.rendered_content
                   ^^^^^^^^^^^^^^^^^^^^^
  File "/home/alprostov/.local/share/virtualenvs/web-mek5ITq2/lib64/python3.11/site-packages/django/template/response.py", line 89, in rendered_content
    return template.render(context, self._request)
           ^^^^^^^^^^^^^^^^^^^^^^^^^^^^^^^^^^^^^^^
  File "/home/alprostov/.local/share/virtualenvs/web-mek5ITq2/lib64/python3.11/site-packages/django/template/backends/django.py", line 61, in render
    return self.template.render(context)
           ^^^^^^^^^^^^^^^^^^^^^^^^^^^^^
  File "/home/alprostov/.local/share/virtualenvs/web-mek5ITq2/lib64/python3.11/site-packages/django/template/base.py", line 175, in render
    return self._render(context)
           ^^^^^^^^^^^^^^^^^^^^^
  File "/home/alprostov/.local/share/virtualenvs/web-mek5ITq2/lib64/python3.11/site-packages/django/test/utils.py", line 112, in instrumented_test_render
    return self.nodelist.render(context)
           ^^^^^^^^^^^^^^^^^^^^^^^^^^^^^
  File "/home/alprostov/.local/share/virtualenvs/web-mek5ITq2/lib64/python3.11/site-packages/django/template/base.py", line 1005, in render
    return SafeString("".join([node.render_annotated(context) for node in self]))
                              ^^^^^^^^^^^^^^^^^^^^^^^^^^^^^^^^^^^^^^^^^^^^^^^^^
  File "/home/alprostov/.local/share/virtualenvs/web-mek5ITq2/lib64/python3.11/site-packages/django/template/base.py", line 1005, in <listcomp>
    return SafeString("".join([node.render_annotated(context) for node in self]))
                               ^^^^^^^^^^^^^^^^^^^^^^^^^^^^^^
  File "/home/alprostov/.local/share/virtualenvs/web-mek5ITq2/lib64/python3.11/site-packages/django/template/base.py", line 966, in render_annotated
    return self.render(context)
           ^^^^^^^^^^^^^^^^^^^^
  File "/home/alprostov/.local/share/virtualenvs/web-mek5ITq2/lib64/python3.11/site-packages/django/template/loader_tags.py", line 157, in render
    return compiled_parent._render(context)
           ^^^^^^^^^^^^^^^^^^^^^^^^^^^^^^^^
  File "/home/alprostov/.local/share/virtualenvs/web-mek5ITq2/lib64/python3.11/site-packages/django/test/utils.py", line 112, in instrumented_test_render
    return self.nodelist.render(context)
           ^^^^^^^^^^^^^^^^^^^^^^^^^^^^^
  File "/home/alprostov/.local/share/virtualenvs/web-mek5ITq2/lib64/python3.11/site-packages/django/template/base.py", line 1005, in render
    return SafeString("".join([node.render_annotated(context) for node in self]))
                              ^^^^^^^^^^^^^^^^^^^^^^^^^^^^^^^^^^^^^^^^^^^^^^^^^
  File "/home/alprostov/.local/share/virtualenvs/web-mek5ITq2/lib64/python3.11/site-packages/django/template/base.py", line 1005, in <listcomp>
    return SafeString("".join([node.render_annotated(context) for node in self]))
                               ^^^^^^^^^^^^^^^^^^^^^^^^^^^^^^
  File "/home/alprostov/.local/share/virtualenvs/web-mek5ITq2/lib64/python3.11/site-packages/django/template/base.py", line 966, in render_annotated
    return self.render(context)
           ^^^^^^^^^^^^^^^^^^^^
  File "/home/alprostov/.local/share/virtualenvs/web-mek5ITq2/lib64/python3.11/site-packages/django/template/loader_tags.py", line 63, in render
    result = block.nodelist.render(context)
             ^^^^^^^^^^^^^^^^^^^^^^^^^^^^^^
  File "/home/alprostov/.local/share/virtualenvs/web-mek5ITq2/lib64/python3.11/site-packages/django/template/base.py", line 1005, in render
    return SafeString("".join([node.render_annotated(context) for node in self]))
                              ^^^^^^^^^^^^^^^^^^^^^^^^^^^^^^^^^^^^^^^^^^^^^^^^^
  File "/home/alprostov/.local/share/virtualenvs/web-mek5ITq2/lib64/python3.11/site-packages/django/template/base.py", line 1005, in <listcomp>
    return SafeString("".join([node.render_annotated(context) for node in self]))
                               ^^^^^^^^^^^^^^^^^^^^^^^^^^^^^^
  File "/home/alprostov/.local/share/virtualenvs/web-mek5ITq2/lib64/python3.11/site-packages/django/template/base.py", line 966, in render_annotated
    return self.render(context)
           ^^^^^^^^^^^^^^^^^^^^
  File "/home/alprostov/.local/share/virtualenvs/web-mek5ITq2/lib64/python3.11/site-packages/django/template/defaulttags.py", line 194, in render
    len_values = len(values)
                 ^^^^^^^^^^^
  File "/home/alprostov/.local/share/virtualenvs/web-mek5ITq2/lib64/python3.11/site-packages/django/db/models/query.py", line 380, in __len__
    self._fetch_all()
  File "/home/alprostov/.local/share/virtualenvs/web-mek5ITq2/lib64/python3.11/site-packages/django/db/models/query.py", line 1881, in _fetch_all
    self._result_cache = list(self._iterable_class(self))
                         ^^^^^^^^^^^^^^^^^^^^^^^^^^^^^^^^
  File "/home/alprostov/.local/share/virtualenvs/web-mek5ITq2/lib64/python3.11/site-packages/django/db/models/query.py", line 91, in __iter__
    results = compiler.execute_sql(
              ^^^^^^^^^^^^^^^^^^^^^
  File "/home/alprostov/.local/share/virtualenvs/web-mek5ITq2/lib64/python3.11/site-packages/django/db/models/sql/compiler.py", line 1560, in execute_sql
    cursor.execute(sql, params)
  File "/home/alprostov/.local/share/virtualenvs/web-mek5ITq2/lib64/python3.11/site-packages/debug_toolbar/panels/sql/tracking.py", line 246, in execute
    return self._record(super().execute, sql, params)
           ^^^^^^^^^^^^^^^^^^^^^^^^^^^^^^^^^^^^^^^^^^
  File "/home/alprostov/.local/share/virtualenvs/web-mek5ITq2/lib64/python3.11/site-packages/debug_toolbar/panels/sql/tracking.py", line 167, in _record
    return method(sql, params)
           ^^^^^^^^^^^^^^^^^^^
  File "/home/alprostov/.local/share/virtualenvs/web-mek5ITq2/lib64/python3.11/site-packages/django/db/backends/utils.py", line 67, in execute
    return self._execute_with_wrappers(
           ^^^^^^^^^^^^^^^^^^^^^^^^^^^^
  File "/home/alprostov/.local/share/virtualenvs/web-mek5ITq2/lib64/python3.11/site-packages/django/db/backends/utils.py", line 80, in _execute_with_wrappers
    return executor(sql, params, many, context)
           ^^^^^^^^^^^^^^^^^^^^^^^^^^^^^^^^^^^^
  File "/home/alprostov/.local/share/virtualenvs/web-mek5ITq2/lib64/python3.11/site-packages/django/db/backends/utils.py", line 84, in _execute
    with self.db.wrap_database_errors:
  File "/home/alprostov/.local/share/virtualenvs/web-mek5ITq2/lib64/python3.11/site-packages/django/db/utils.py", line 91, in __exit__
    raise dj_exc_value.with_traceback(traceback) from exc_value
  File "/home/alprostov/.local/share/virtualenvs/web-mek5ITq2/lib64/python3.11/site-packages/django/db/backends/utils.py", line 89, in _execute
    return self.cursor.execute(sql, params)
           ^^^^^^^^^^^^^^^^^^^^^^^^^^^^^^^^
  File "/home/alprostov/.local/share/virtualenvs/web-mek5ITq2/lib64/python3.11/site-packages/django/db/backends/sqlite3/base.py", line 328, in execute
    return super().execute(query, params)
           ^^^^^^^^^^^^^^^^^^^^^^^^^^^^^^
django.db.utils.OperationalError: no such column: app_site_orderlist.apartment_id_id
INFO:django.utils.autoreload:/home/alprostov/PycharmProjects/sakhlis/web/app_site/models.py changed, reloading.
WARNING:django.request:Not Found: /schema
INFO:django.utils.autoreload:/home/alprostov/PycharmProjects/sakhlis/web/app_site/admin.py changed, reloading.
INFO:django.utils.autoreload:/home/alprostov/PycharmProjects/sakhlis/web/app_site/admin.py changed, reloading.
INFO:django.utils.autoreload:/home/alprostov/PycharmProjects/sakhlis/web/app_site/admin.py changed, reloading.
INFO:django.utils.autoreload:/home/alprostov/PycharmProjects/sakhlis/web/app_site/models.py changed, reloading.
INFO:django.utils.autoreload:/home/alprostov/PycharmProjects/sakhlis/web/app_site/models.py changed, reloading.
WARNING:django.request:Not Found: /favicon.ico
INFO:django.utils.autoreload:/home/alprostov/PycharmProjects/sakhlis/web/app_site/forms.py changed, reloading.
INFO:django.utils.autoreload:/home/alprostov/PycharmProjects/sakhlis/web/app_site/forms.py changed, reloading.
